Workbook

Sheet 001_01
C2: Campagne : | F2: PIRATA Fr28
C4: Données de campagne
C6: N° de station : | F6: 1 | H6: N° de palanquée : | P6: 1 | R6: Date d'analyse : | T6: 41699
G8: Position | I8: Degrés | J8: Minutes | P8: Cardinal | Q8: Décimale
G9: Latitude | I9: 11 | J9: 28.837 | K9: : | L9: =IF(P9=M9,"+","-") -> + | M9: N | N9: E | O9: =IF(ISBLANK(I9),"",IF(ISBLANK(J9),"",IF(P9=M10,L9&N11,N11))) -> 11°28.837 | P9: N | Q9: =IF(ISBLANK(I9),"",IF(ISBLANK(J9),"",IF(J9>60,"ERREUR !!",O11*(I9+(J9/60))))) -> 11.480617
G10: Longitude | I10: 22 | J10: 59.508 | K10: : | L10: =IF(P10=N9,"+","-") -> - | M10: S | N10: W | O10: =IF(ISBLANK(I10),"",IF(ISBLANK(J10),"",IF(P10=N10,L10&N12,N12))) -> -22°59.508 | P10: W | Q10: =IF(ISBLANK(I10),"",IF(ISBLANK(J10),"",IF(J10>60,"ERREUR !!",O12*(I10+(J10/60))))) -> -22.9918
G11: Prélèvement | I11: Date | J11: 41698 | N11: =I9&"°"&J9 -> 11°28.837 | O11: =IF(P9=M10,-1,1) -> 1 | P11: =TEXT(J11,"aaaa-mm-jj")&"T"&TEXT(J12,"hh:mm:ss")&"z" -> 2018-03-01T19:19:38z
I12: Heure | J12: 0.80530093 | N12: =I10&"°"&J10 -> 22°59.508 | O12: =IF(P10=N10,-1,1) -> -1
C13: Données :
C14: Température du laboratoire à la calibration ( t°c ) | Q14: t°c = | R14: 24.2 | S14: °C
C15: Température du laboratoire au début de la série d'analyses | Q15: t°lab = | R15: 24.2 | S15: °C
C16: Volume moyen de thiosulfate pour la titration à t°c | Q16: Vmoy.titr.t°c = | R16: 4.9718 | S16: mL
C17: Volume moyen de thiosulfate pour la détermination du blanc à t°c | Q17: Vmoy.titr.blanc.t°c = | R17: 0.005 | S17: mL
C18: Masse volumique de l'eau pure à la calibration | O18: ρ = | P18: =(0.999842594+(0.00006793952*$R$14)-(0.00000909529*$R$14^2)+(0.0000001001685*$R$14^3)-(0.000000001120083*$R$14^4)+(0.000000000006536332*$R$14^5)) -> 0.99724989
C19: Normalite de l'iodate (NIO3) à la température de calibration | O19: N(IO3) = | P19: =$P$24*($P$18/'Titre d''iodate'!E19) -> 0.019990103 | Q19: N
C20: Vol. de la prise d'essai d'iodate (VIO3) à 20°C | O20: V(IO3)20°C = | P20: =5+'Correction de volume'!G8 -> 5.0145248 | Q20: mL
C21: Vol. de la prise d'essai d'iodate (VIO3) à t°c | O21: V(IO3)t°c= | P21: =P20*(1+0.00001*(R14-20)) -> 5.0147354 | Q21: mL
C22: Volume moyen de thiosulfate pour la titration à 20° C | O22: Vmoy.titr.20°C = | P22: =$R$16*(1+0.00001*(20-$R$14)) -> 4.9715912 | Q22: mL
C23: Volume moyen de thiosulfate pour la détermination du blanc à 20° C | O23: Vmoy.titr.blanc.20°C = | P23: =$R$17*(1+0.00001*(20-$R$14)) -> 0.00499979 | Q23: mL
C24: Normalite de l'iodate (NIO3) à 20°C | O24: N(IO3)20°C = | P24: =MAX('Titre d''iodate'!F7:F10) -> 0.020009275 | Q24: N
C25: Titre du thiosulfate à 20°C | O25: V(Thio)20°C = | P25: =IF(ISBLANK(R14),"",IF(ISBLANK(P21),"",IF(ISBLANK(R17),"",(($P$24*$P$18)/($P$22-$P$23))))) -> 0.0040176946 | Q25: N
C26: Volume de réactif utilisé | O26: Vreg = | P26: =2+('Correction de volume'!G10+'Correction de volume'!G9) -> 2.0183067 | Q26: mL
O27: DOreg = | P27: 0.0017
E29: Choix de la série de flacons : | I29: IRD | O29: IRD
O30: LPO
C31: N° | D31: N° des Flacons | E31: T° prélèv. | F31: Volume de thio. | G31: Salinité | H31: Prof. Théorique | I31: Prof. Effective | J31: V. flacons 20°C | K31: A | L31: B | M31: Densité eau de mer à t° | N31: Vol. à t° prél. des flacons | O31: Densité eau pure à t° | P31: Oxygène dissous | T31: NO2 | V31: NO3 + NO2 | X31: NO3 | Z31: Phosphate | AB31: Silicate | AD31: chlorophyll-c3 | AE31: chlorophyll-c1+c2 | AF31: peridinin | AG31: 19'-butanoyloxyfucoxanthin | AH31: fucoxanthine | AI31: neoxanthin | AJ31: prasinoxanthin | AK31: violaxanthin | AL31: 19'-hexanoyloxyfucoxanthin | AM31: diadinoxanthin | AN31: alloxanthin | AO31: diatoxanthin | AP31: zeaxanthin | AQ31: lutein | AR31: divinyl chlorophyll-b | AS31: chlorophyll-b | AT31: total chlorophyll-b | AU31: alpha-carotene | AV31: beta-carotene | AW31: pheophorbide | AX31: divinyl chlorophyll-a | AY31: chlorophyll-a | AZ31: total chlorophyll-a | BA31: pheophytin_a | BB31: crocoxanthin
C33: BTL | E33: °C | F33: ml | H33: m | I33: dbar | J33: ml | P33: DOX1 | R33: DOXY | S33: DOX2 | T33: NTRI | U33: NTIW | V33: NTRZ | W33: NTZW | X33: NTRA | Y33: NTAW | Z33: PHOS | AA33: PHOW | AB33: SLCA | AC33: SLCW | AD33: CHC3 | AE33: CHCZ | AF33: PERP | AG33: BFUP | AH33: FUCP | AI33: NEXW | AJ33: PXAP | AK33: VIOW | AL33: HFUP | AM33: DXAP | AN33: AXAP | AO33: TXAP | AP33: ZXAP | AQ33: LUTW | AR33: CHBD | AS33: CH2P | AT33: CHLB | AU33: AACP | AV33: BBCP | AW33: PHEP | AX33: CHAD | AY33: CH1P | AZ33: CPHL | BA33: PHEA | BB33: CXAP
N34: mL | P34: ml/l | Q34: ml/kg | R34: µmol/l | S34: µmol/kg | T34: µmol/l | U34: µmol/kg | V34: µmol/l | W34: µmol/kg | X34: µmol/l | Y34: µmol/kg | Z34: µmol/l | AA34: µmol/kg | AB34: µmol/l | AC34: µmol/kg | AD34: µg.l-1 | AE34: µg.l-1 | AF34: µg.l-1 | AG34: µg.l-1 | AH34: µg.l-1 | AI34: µg.l-1 | AJ34: µg.l-1 | AK34: µg.l-1 | AL34: µg.l-1 | AM34: µg.l-1 | AN34: µg.l-1 | AO34: µg.l-1 | AP34: µg.l-1 | AQ34: µg.l-1 | AR34: µg.l-1 | AS34: µg.l-1 | AT34: µg.l-1 | AU34: µg.l-1 | AV34: µg.l-1 | AW34: µg.l-1 | AX34: µg.l-1 | AY34: µg.l-1 | AZ34: µg.l-1 | BA34: µg.l-1 | BB34: µg.l-1
A35: =IF(ISBLANK(VLOOKUP(D35,'Volumes flacons'!A5:C623,3)),0,1) -> 1 | B35: =IF(ISBLANK(D35),0,IF(ISBLANK(E35),0,IF(ISBLANK(F35),0,1))) -> 1 | C35: 1 | D35: 2186 | E35: 5.1 | F35: 5.443 | G35: 34.888067 | H35: 4000 | I35: 4060 | J35: 112.01 | K35: =IF(ISBLANK(E35),"",(0.000824493-(0.0000040899*E35)+(0.000000076438*E35^2)-(0.00000000082467*E35^3)+(0.0000000000053875*E35^4))) -> 0.00080551691 | L35: =IF(ISBLANK(E35),"",(-0.00000572466+(0.00000010227*E35)-(0.0000000016546*E35^2))) -> -5.2461191e-06 | M35: =IF(ISBLANK(E35),"",IF(ISBLANK(G35),(O35+(K35*35)+(L35*35^1.5)+(0.00000048314*35^2)),(O35+(K35*G35)+(L35*G35^1.5)+(0.00000048314*G35^2)))) -> 1.027575 | N35: =IF(ISBLANK(D35),"",IF(ISBLANK(G35),J35*(1+0.00001*(35-20)),J35*(1+0.00001*(G35-20)))) -> 112.02668 | O35: =IF(ISBLANK(E35),"",(0.999842594+(0.00006793952*E35)-(0.00000909529*E35^2)+(0.0000001001685*E35^3)-(0.000000001120083*E35^4)+(0.000000000006536332*E35^5))) -> 0.99996507 | P35: =IF(ISBLANK($R$16),"",IF(A35=0,"",IF(ISBLANK($R$17),"",IF(B35=0,"",IF($O$28=$I$29,"",IF(AND($I$29=$O$29,D35<1000),"N° Flac.",IF(AND($I$29=$O$30,D35>1000),"N° Flac.",IF(AND(D35>1202,D35<2001),"Err. N°",IF(AND(D35>499,D35<1141),"Err.N°",(((((F35)+'[1]Correction de volume'!$G$7)*(($P$21)*($P$19)*5598)/(($R$16)-($R$17)))-(($P$27)*1000))/((N35)-($P$26)))))))))))) -> 5.574651 | Q35: =IF(ISBLANK($R$16),"",IF(A35=0,"",IF(ISBLANK($R$17),"",IF(AND(D35>1202,D35<2001),"Err. N°",IF(AND(D35>499,D35<1141),"Err.N°",IF(B35=0,"",IF($O$28=$I$29,"",IF(AND($I$29=$O$29,D35<1000),"N° Flac.",IF(AND($I$29=$O$30,D35>1000),"N° Flac.",P35/M35))))))))) -> 5.4250552 | R35: =IF(ISBLANK($R$16),"",IF(A35=0,"",IF(ISBLANK($R$17),"",IF(B35=0,"",IF(ISBLANK(J35),"",IF(AND(D35>1202,D35<2001),"Err. N°",IF(AND(D35>499,D35<1141),"Err.N°",IF($I$29=$O$28,"",IF(AND($I$29=$O$29,D35<1000),"N° Flac.",IF(AND($I$29=$O$30,D35>1000),"N° Flac.",((44.66*P35)))))))))))) -> 248.96392 | S35: =IF(ISBLANK($R$16),"",IF(A35=0,"",IF(ISBLANK($R$17),"",IF(B35=0,"",IF(ISBLANK(J35),"",IF(AND(D35>1202,D35<2001),"Err. N°",IF(AND(D35>499,D35<1141),"Err.N°",IF($I$29=$O$28,"",IF(AND($I$29=$O$29,D35<1000),"N° Flac.",IF(AND($I$29=$O$30,D35>1000),"N° Flac.",((44.66*P35)/M35))))))))))) -> 242.28296 | T35: 0.02 | U35: 0.02 | V35: 23.1 | W35: 22.5 | X35: 23.1 | Y35: 22.5 | Z35: 1.45 | AA35: 1.42 | AB35: 45.5 | AC35: 44.4
A36: =IF(ISBLANK(VLOOKUP(D36,'Volumes flacons'!A5:C623,3)),0,1) -> 1 | B36: =IF(ISBLANK(D36),0,IF(ISBLANK(E36),0,IF(ISBLANK(F36),0,1))) -> 1 | C36: 2 | D36: 2187 | E36: 5.3 | F36: 5.428 | G36: 34.8905 | H36: 4000 | I36: 4062 | J36: 111.83 | K36: =IF(ISBLANK(E36),"",(0.000824493-(0.0000040899*E36)+(0.000000076438*E36^2)-(0.00000000082467*E36^3)+(0.0000000000053875*E36^4))) -> 0.00080484515 | L36: =IF(ISBLANK(E36),"",(-0.00000572466+(0.00000010227*E36)-(0.0000000016546*E36^2))) -> -5.2291067e-06 | M36: =IF(ISBLANK(E36),"",IF(ISBLANK(G36),(O36+(K36*35)+(L36*35^1.5)+(0.00000048314*35^2)),(O36+(K36*G36)+(L36*G36^1.5)+(0.00000048314*G36^2)))) -> 1.0275532 | N36: =IF(ISBLANK(D36),"",IF(ISBLANK(G36),J36*(1+0.00001*(35-20)),J36*(1+0.00001*(G36-20)))) -> 111.84665 | O36: =IF(ISBLANK(E36),"",(0.999842594+(0.00006793952*E36)-(0.00000909529*E36^2)+(0.0000001001685*E36^3)-(0.000000001120083*E36^4)+(0.000000000006536332*E36^5))) -> 0.99996124 | P36: =IF(ISBLANK($R$16),"",IF(A36=0,"",IF(ISBLANK($R$17),"",IF(B36=0,"",IF($O$28=$I$29,"",IF(AND($I$29=$O$29,D36<1000),"N° Flac.",IF(AND($I$29=$O$30,D36>1000),"N° Flac.",IF(AND(D36>1202,D36<2001),"Err. N°",IF(AND(D36>499,D36<1141),"Err.N°",(((((F36)+'[1]Correction de volume'!$G$7)*(($P$21)*($P$19)*5598)/(($R$16)-($R$17)))-(($P$27)*1000))/((N36)-($P$26)))))))))))) -> 5.5683576 | Q36: =IF(ISBLANK($R$16),"",IF(A36=0,"",IF(ISBLANK($R$17),"",IF(AND(D36>1202,D36<2001),"Err. N°",IF(AND(D36>499,D36<1141),"Err.N°",IF(B36=0,"",IF($O$28=$I$29,"",IF(AND($I$29=$O$29,D36<1000),"N° Flac.",IF(AND($I$29=$O$30,D36>1000),"N° Flac.",P36/M36))))))))) -> 5.4190457 | R36: =IF(ISBLANK($R$16),"",IF(A36=0,"",IF(ISBLANK($R$17),"",IF(B36=0,"",IF(ISBLANK(J36),"",IF(AND(D36>1202,D36<2001),"Err. N°",IF(AND(D36>499,D36<1141),"Err.N°",IF($I$29=$O$28,"",IF(AND($I$29=$O$29,D36<1000),"N° Flac.",IF(AND($I$29=$O$30,D36>1000),"N° Flac.",((44.66*P36)))))))))))) -> 248.68285 | S36: =IF(ISBLANK($R$16),"",IF(A36=0,"",IF(ISBLANK($R$17),"",IF(B36=0,"",IF(ISBLANK(J36),"",IF(AND(D36>1202,D36<2001),"Err. N°",IF(AND(D36>499,D36<1141),"Err.N°",IF($I$29=$O$28,"",IF(AND($I$29=$O$29,D36<1000),"N° Flac.",IF(AND($I$29=$O$30,D36>1000),"N° Flac.",((44.66*P36)/M36))))))))))) -> 242.01458 | T36: 0.01 | U36: 0.01 | V36: 23.1 | W36: 22.5 | X36: 23.1 | Y36: 22.5 | Z36: 1.43 | AA36: 1.4 | AB36: 45.8 | AC36: 44.7
A37: =IF(ISBLANK(VLOOKUP(D37,'Volumes flacons'!A5:C623,3)),0,1) -> 1 | B37: =IF(ISBLANK(D37),0,IF(ISBLANK(E37),0,IF(ISBLANK(F37),0,1))) -> 1 | C37: 3 | D37: 2188 | E37: 5.6 | F37: 5.54 | G37: 34.8878 | H37: 4000 | I37: 4062 | J37: 113.9 | K37: =IF(ISBLANK(E37),"",(0.000824493-(0.0000040899*E37)+(0.000000076438*E37^2)-(0.00000000082467*E37^3)+(0.0000000000053875*E37^4))) -> 0.00080384713 | L37: =IF(ISBLANK(E37),"",(-0.00000572466+(0.00000010227*E37)-(0.0000000016546*E37^2))) -> -5.2038363e-06 | M37: =IF(ISBLANK(E37),"",IF(ISBLANK(G37),(O37+(K37*35)+(L37*35^1.5)+(0.00000048314*35^2)),(O37+(K37*G37)+(L37*G37^1.5)+(0.00000048314*G37^2)))) -> 1.0275145 | N37: =IF(ISBLANK(D37),"",IF(ISBLANK(G37),J37*(1+0.00001*(35-20)),J37*(1+0.00001*(G37-20)))) -> 113.91696 | O37: =IF(ISBLANK(E37),"",(0.999842594+(0.00006793952*E37)-(0.00000909529*E37^2)+(0.0000001001685*E37^3)-(0.000000001120083*E37^4)+(0.000000000006536332*E37^5))) -> 0.99995435 | P37: =IF(ISBLANK($R$16),"",IF(A37=0,"",IF(ISBLANK($R$17),"",IF(B37=0,"",IF($O$28=$I$29,"",IF(AND($I$29=$O$29,D37<1000),"N° Flac.",IF(AND($I$29=$O$30,D37>1000),"N° Flac.",IF(AND(D37>1202,D37<2001),"Err. N°",IF(AND(D37>499,D37<1141),"Err.N°",(((((F37)+'[1]Correction de volume'!$G$7)*(($P$21)*($P$19)*5598)/(($R$16)-($R$17)))-(($P$27)*1000))/((N37)-($P$26)))))))))))) -> 5.578421 | Q37: =IF(ISBLANK($R$16),"",IF(A37=0,"",IF(ISBLANK($R$17),"",IF(AND(D37>1202,D37<2001),"Err. N°",IF(AND(D37>499,D37<1141),"Err.N°",IF(B37=0,"",IF($O$28=$I$29,"",IF(AND($I$29=$O$29,D37<1000),"N° Flac.",IF(AND($I$29=$O$30,D37>1000),"N° Flac.",P37/M37))))))))) -> 5.4290434 | R37: =IF(ISBLANK($R$16),"",IF(A37=0,"",IF(ISBLANK($R$17),"",IF(B37=0,"",IF(ISBLANK(J37),"",IF(AND(D37>1202,D37<2001),"Err. N°",IF(AND(D37>499,D37<1141),"Err.N°",IF($I$29=$O$28,"",IF(AND($I$29=$O$29,D37<1000),"N° Flac.",IF(AND($I$29=$O$30,D37>1000),"N° Flac.",((44.66*P37)))))))))))) -> 249.13228 | S37: =IF(ISBLANK($R$16),"",IF(A37=0,"",IF(ISBLANK($R$17),"",IF(B37=0,"",IF(ISBLANK(J37),"",IF(AND(D37>1202,D37<2001),"Err. N°",IF(AND(D37>499,D37<1141),"Err.N°",IF($I$29=$O$28,"",IF(AND($I$29=$O$29,D37<1000),"N° Flac.",IF(AND($I$29=$O$30,D37>1000),"N° Flac.",((44.66*P37)/M37))))))))))) -> 242.46108 | T37: 0.02 | U37: 0.02 | V37: 22.9 | W37: 22.4 | X37: 22.9 | Y37: 22.4 | Z37: 1.46 | AA37: 1.43 | AB37: 46.1 | AC37: 45
A38: =IF(ISBLANK(VLOOKUP(D38,'Volumes flacons'!A5:C623,3)),0,1) -> 1 | B38: =IF(ISBLANK(D38),0,IF(ISBLANK(E38),0,IF(ISBLANK(F38),0,1))) -> 1 | C38: 4 | D38: 2189 | E38: 5.8 | F38: 5.528 | G38: 34.88925 | H38: 4000 | I38: 4064 | J38: 113.62 | K38: =IF(ISBLANK(E38),"",(0.000824493-(0.0000040899*E38)+(0.000000076438*E38^2)-(0.00000000082467*E38^3)+(0.0000000000053875*E38^4))) -> 0.00080318815 | L38: =IF(ISBLANK(E38),"",(-0.00000572466+(0.00000010227*E38)-(0.0000000016546*E38^2))) -> -5.1871547e-06 | M38: =IF(ISBLANK(E38),"",IF(ISBLANK(G38),(O38+(K38*35)+(L38*35^1.5)+(0.00000048314*35^2)),(O38+(K38*G38)+(L38*G38^1.5)+(0.00000048314*G38^2)))) -> 1.0274908 | N38: =IF(ISBLANK(D38),"",IF(ISBLANK(G38),J38*(1+0.00001*(35-20)),J38*(1+0.00001*(G38-20)))) -> 113.63692 | O38: =IF(ISBLANK(E38),"",(0.999842594+(0.00006793952*E38)-(0.00000909529*E38^2)+(0.0000001001685*E38^3)-(0.000000001120083*E38^4)+(0.000000000006536332*E38^5))) -> 0.999949 | P38: =IF(ISBLANK($R$16),"",IF(A38=0,"",IF(ISBLANK($R$17),"",IF(B38=0,"",IF($O$28=$I$29,"",IF(AND($I$29=$O$29,D38<1000),"N° Flac.",IF(AND($I$29=$O$30,D38>1000),"N° Flac.",IF(AND(D38>1202,D38<2001),"Err. N°",IF(AND(D38>499,D38<1141),"Err.N°",(((((F38)+'[1]Correction de volume'!$G$7)*(($P$21)*($P$19)*5598)/(($R$16)-($R$17)))-(($P$27)*1000))/((N38)-($P$26)))))))))))) -> 5.5802698 | Q38: =IF(ISBLANK($R$16),"",IF(A38=0,"",IF(ISBLANK($R$17),"",IF(AND(D38>1202,D38<2001),"Err. N°",IF(AND(D38>499,D38<1141),"Err.N°",IF(B38=0,"",IF($O$28=$I$29,"",IF(AND($I$29=$O$29,D38<1000),"N° Flac.",IF(AND($I$29=$O$30,D38>1000),"N° Flac.",P38/M38))))))))) -> 5.4309684 | R38: =IF(ISBLANK($R$16),"",IF(A38=0,"",IF(ISBLANK($R$17),"",IF(B38=0,"",IF(ISBLANK(J38),"",IF(AND(D38>1202,D38<2001),"Err. N°",IF(AND(D38>499,D38<1141),"Err.N°",IF($I$29=$O$28,"",IF(AND($I$29=$O$29,D38<1000),"N° Flac.",IF(AND($I$29=$O$30,D38>1000),"N° Flac.",((44.66*P38)))))))))))) -> 249.21485 | S38: =IF(ISBLANK($R$16),"",IF(A38=0,"",IF(ISBLANK($R$17),"",IF(B38=0,"",IF(ISBLANK(J38),"",IF(AND(D38>1202,D38<2001),"Err. N°",IF(AND(D38>499,D38<1141),"Err.N°",IF($I$29=$O$28,"",IF(AND($I$29=$O$29,D38<1000),"N° Flac.",IF(AND($I$29=$O$30,D38>1000),"N° Flac.",((44.66*P38)/M38))))))))))) -> 242.54705 | T38: 0.01 | U38: 0.01 | V38: 22.9 | W38: 22.4 | X38: 22.9 | Y38: 22.4 | Z38: 1.45 | AA38: 1.42 | AB38: 46.1 | AC38: 45
A39: =IF(ISBLANK(VLOOKUP(D39,'Volumes flacons'!A5:C623,3)),0,1) -> 1 | B39: =IF(ISBLANK(D39),0,IF(ISBLANK(E39),0,IF(ISBLANK(F39),0,1))) -> 1 | C39: 5 | D39: 2190 | E39: 6.5 | F39: 5.408 | G39: 34.88935 | H39: 4000 | I39: 4064 | J39: 111.38 | K39: =IF(ISBLANK(E39),"",(0.000824493-(0.0000040899*E39)+(0.000000076438*E39^2)-(0.00000000082467*E39^3)+(0.0000000000053875*E39^4))) -> 0.0008009213 | L39: =IF(ISBLANK(E39),"",(-0.00000572466+(0.00000010227*E39)-(0.0000000016546*E39^2))) -> -5.1298118e-06 | M39: =IF(ISBLANK(E39),"",IF(ISBLANK(G39),(O39+(K39*35)+(L39*35^1.5)+(0.00000048314*35^2)),(O39+(K39*G39)+(L39*G39^1.5)+(0.00000048314*G39^2)))) -> 1.0274001 | N39: =IF(ISBLANK(D39),"",IF(ISBLANK(G39),J39*(1+0.00001*(35-20)),J39*(1+0.00001*(G39-20)))) -> 111.39658 | O39: =IF(ISBLANK(E39),"",(0.999842594+(0.00006793952*E39)-(0.00000909529*E39^2)+(0.0000001001685*E39^3)-(0.000000001120083*E39^4)+(0.000000000006536332*E39^5))) -> 0.99992551 | P39: =IF(ISBLANK($R$16),"",IF(A39=0,"",IF(ISBLANK($R$17),"",IF(B39=0,"",IF($O$28=$I$29,"",IF(AND($I$29=$O$29,D39<1000),"N° Flac.",IF(AND($I$29=$O$30,D39>1000),"N° Flac.",IF(AND(D39>1202,D39<2001),"Err. N°",IF(AND(D39>499,D39<1141),"Err.N°",(((((F39)+'[1]Correction de volume'!$G$7)*(($P$21)*($P$19)*5598)/(($R$16)-($R$17)))-(($P$27)*1000))/((N39)-($P$26)))))))))))) -> 5.5706108 | Q39: =IF(ISBLANK($R$16),"",IF(A39=0,"",IF(ISBLANK($R$17),"",IF(AND(D39>1202,D39<2001),"Err. N°",IF(AND(D39>499,D39<1141),"Err.N°",IF(B39=0,"",IF($O$28=$I$29,"",IF(AND($I$29=$O$29,D39<1000),"N° Flac.",IF(AND($I$29=$O$30,D39>1000),"N° Flac.",P39/M39))))))))) -> 5.4220463 | R39: =IF(ISBLANK($R$16),"",IF(A39=0,"",IF(ISBLANK($R$17),"",IF(B39=0,"",IF(ISBLANK(J39),"",IF(AND(D39>1202,D39<2001),"Err. N°",IF(AND(D39>499,D39<1141),"Err.N°",IF($I$29=$O$28,"",IF(AND($I$29=$O$29,D39<1000),"N° Flac.",IF(AND($I$29=$O$30,D39>1000),"N° Flac.",((44.66*P39)))))))))))) -> 248.78348 | S39: =IF(ISBLANK($R$16),"",IF(A39=0,"",IF(ISBLANK($R$17),"",IF(B39=0,"",IF(ISBLANK(J39),"",IF(AND(D39>1202,D39<2001),"Err. N°",IF(AND(D39>499,D39<1141),"Err.N°",IF($I$29=$O$28,"",IF(AND($I$29=$O$29,D39<1000),"N° Flac.",IF(AND($I$29=$O$30,D39>1000),"N° Flac.",((44.66*P39)/M39))))))))))) -> 242.14859 | T39: 0.06 | U39: 0.06 | V39: 22.9 | W39: 22.3 | X39: 22.8 | Y39: 22.3 | Z39: 1.45 | AA39: 1.42 | AB39: 46 | AC39: 44.9
A40: =IF(ISBLANK(VLOOKUP(D40,'Volumes flacons'!A5:C623,3)),0,1) -> 1 | B40: =IF(ISBLANK(D40),0,IF(ISBLANK(E40),0,IF(ISBLANK(F40),0,1))) -> 1 | C40: 6 | D40: 2191 | E40: 6.8 | F40: 5.555 | G40: 34.886867 | H40: 4000 | I40: 4064 | J40: 114.18 | K40: =IF(ISBLANK(E40),"",(0.000824493-(0.0000040899*E40)+(0.000000076438*E40^2)-(0.00000000082467*E40^3)+(0.0000000000053875*E40^4))) -> 0.00079996839 | L40: =IF(ISBLANK(E40),"",(-0.00000572466+(0.00000010227*E40)-(0.0000000016546*E40^2))) -> -5.1057327e-06 | M40: =IF(ISBLANK(E40),"",IF(ISBLANK(G40),(O40+(K40*35)+(L40*35^1.5)+(0.00000048314*35^2)),(O40+(K40*G40)+(L40*G40^1.5)+(0.00000048314*G40^2)))) -> 1.0273575 | N40: =IF(ISBLANK(D40),"",IF(ISBLANK(G40),J40*(1+0.00001*(35-20)),J40*(1+0.00001*(G40-20)))) -> 114.197 | O40: =IF(ISBLANK(E40),"",(0.999842594+(0.00006793952*E40)-(0.00000909529*E40^2)+(0.0000001001685*E40^3)-(0.000000001120083*E40^4)+(0.000000000006536332*E40^5))) -> 0.99991321 | P40: =IF(ISBLANK($R$16),"",IF(A40=0,"",IF(ISBLANK($R$17),"",IF(B40=0,"",IF($O$28=$I$29,"",IF(AND($I$29=$O$29,D40<1000),"N° Flac.",IF(AND($I$29=$O$30,D40>1000),"N° Flac.",IF(AND(D40>1202,D40<2001),"Err. N°",IF(AND(D40>499,D40<1141),"Err.N°",(((((F40)+'[1]Correction de volume'!$G$7)*(($P$21)*($P$19)*5598)/(($R$16)-($R$17)))-(($P$27)*1000))/((N40)-($P$26)))))))))))) -> 5.5796029 | Q40: =IF(ISBLANK($R$16),"",IF(A40=0,"",IF(ISBLANK($R$17),"",IF(AND(D40>1202,D40<2001),"Err. N°",IF(AND(D40>499,D40<1141),"Err.N°",IF(B40=0,"",IF($O$28=$I$29,"",IF(AND($I$29=$O$29,D40<1000),"N° Flac.",IF(AND($I$29=$O$30,D40>1000),"N° Flac.",P40/M40))))))))) -> 5.4310234 | R40: =IF(ISBLANK($R$16),"",IF(A40=0,"",IF(ISBLANK($R$17),"",IF(B40=0,"",IF(ISBLANK(J40),"",IF(AND(D40>1202,D40<2001),"Err. N°",IF(AND(D40>499,D40<1141),"Err.N°",IF($I$29=$O$28,"",IF(AND($I$29=$O$29,D40<1000),"N° Flac.",IF(AND($I$29=$O$30,D40>1000),"N° Flac.",((44.66*P40)))))))))))) -> 249.18506 | S40: =IF(ISBLANK($R$16),"",IF(A40=0,"",IF(ISBLANK($R$17),"",IF(B40=0,"",IF(ISBLANK(J40),"",IF(AND(D40>1202,D40<2001),"Err. N°",IF(AND(D40>499,D40<1141),"Err.N°",IF($I$29=$O$28,"",IF(AND($I$29=$O$29,D40<1000),"N° Flac.",IF(AND($I$29=$O$30,D40>1000),"N° Flac.",((44.66*P40)/M40))))))))))) -> 242.54951 | T40: 0.01 | U40: 0.01 | V40: 23.1 | W40: 22.5 | X40: 23.1 | Y40: 22.5 | Z40: 1.41 | AA40: 1.38 | AB40: 45.8 | AC40: 44.7
A41: =IF(ISBLANK(VLOOKUP(D41,'Volumes flacons'!A5:C623,3)),0,1) -> 1 | B41: =IF(ISBLANK(D41),0,IF(ISBLANK(E41),0,IF(ISBLANK(F41),0,1))) -> 1 | C41: 7 | D41: 2192 | E41: 7.3 | F41: 5.525 | G41: 34.8898 | H41: 4000 | I41: 4066 | J41: 113.56 | K41: =IF(ISBLANK(E41),"",(0.000824493-(0.0000040899*E41)+(0.000000076438*E41^2)-(0.00000000082467*E41^3)+(0.0000000000053875*E41^4))) -> 0.0007984046 | L41: =IF(ISBLANK(E41),"",(-0.00000572466+(0.00000010227*E41)-(0.0000000016546*E41^2))) -> -5.0662626e-06 | M41: =IF(ISBLANK(E41),"",IF(ISBLANK(G41),(O41+(K41*35)+(L41*35^1.5)+(0.00000048314*35^2)),(O41+(K41*G41)+(L41*G41^1.5)+(0.00000048314*G41^2)))) -> 1.02729 | N41: =IF(ISBLANK(D41),"",IF(ISBLANK(G41),J41*(1+0.00001*(35-20)),J41*(1+0.00001*(G41-20)))) -> 113.57691 | O41: =IF(ISBLANK(E41),"",(0.999842594+(0.00006793952*E41)-(0.00000909529*E41^2)+(0.0000001001685*E41^3)-(0.000000001120083*E41^4)+(0.000000000006536332*E41^5))) -> 0.99988979 | P41: =IF(ISBLANK($R$16),"",IF(A41=0,"",IF(ISBLANK($R$17),"",IF(B41=0,"",IF($O$28=$I$29,"",IF(AND($I$29=$O$29,D41<1000),"N° Flac.",IF(AND($I$29=$O$30,D41>1000),"N° Flac.",IF(AND(D41>1202,D41<2001),"Err. N°",IF(AND(D41>499,D41<1141),"Err.N°",(((((F41)+'[1]Correction de volume'!$G$7)*(($P$21)*($P$19)*5598)/(($R$16)-($R$17)))-(($P$27)*1000))/((N41)-($P$26)))))))))))) -> 5.5802331 | Q41: =IF(ISBLANK($R$16),"",IF(A41=0,"",IF(ISBLANK($R$17),"",IF(AND(D41>1202,D41<2001),"Err. N°",IF(AND(D41>499,D41<1141),"Err.N°",IF(B41=0,"",IF($O$28=$I$29,"",IF(AND($I$29=$O$29,D41<1000),"N° Flac.",IF(AND($I$29=$O$30,D41>1000),"N° Flac.",P41/M41))))))))) -> 5.431994 | R41: =IF(ISBLANK($R$16),"",IF(A41=0,"",IF(ISBLANK($R$17),"",IF(B41=0,"",IF(ISBLANK(J41),"",IF(AND(D41>1202,D41<2001),"Err. N°",IF(AND(D41>499,D41<1141),"Err.N°",IF($I$29=$O$28,"",IF(AND($I$29=$O$29,D41<1000),"N° Flac.",IF(AND($I$29=$O$30,D41>1000),"N° Flac.",((44.66*P41)))))))))))) -> 249.21321 | S41: =IF(ISBLANK($R$16),"",IF(A41=0,"",IF(ISBLANK($R$17),"",IF(B41=0,"",IF(ISBLANK(J41),"",IF(AND(D41>1202,D41<2001),"Err. N°",IF(AND(D41>499,D41<1141),"Err.N°",IF($I$29=$O$28,"",IF(AND($I$29=$O$29,D41<1000),"N° Flac.",IF(AND($I$29=$O$30,D41>1000),"N° Flac.",((44.66*P41)/M41))))))))))) -> 242.59285 | T41: 0.03 | U41: 0.03 | V41: 23 | W41: 22.4 | X41: 22.9 | Y41: 22.4 | Z41: 1.44 | AA41: 1.41 | AB41: 45.9 | AC41: 44.8
A42: =IF(ISBLANK(VLOOKUP(D42,'Volumes flacons'!A5:C623,3)),0,1) -> 1 | B42: =IF(ISBLANK(D42),0,IF(ISBLANK(E42),0,IF(ISBLANK(F42),0,1))) -> 1 | C42: 8 | D42: 2193 | E42: 7.4 | F42: 5.415 | G42: 34.89145 | H42: 4000 | I42: 4067 | J42: 111.44 | K42: =IF(ISBLANK(E42),"",(0.000824493-(0.0000040899*E42)+(0.000000076438*E42^2)-(0.00000000082467*E42^3)+(0.0000000000053875*E42^4))) -> 0.00079809546 | L42: =IF(ISBLANK(E42),"",(-0.00000572466+(0.00000010227*E42)-(0.0000000016546*E42^2))) -> -5.0584679e-06 | M42: =IF(ISBLANK(E42),"",IF(ISBLANK(G42),(O42+(K42*35)+(L42*35^1.5)+(0.00000048314*35^2)),(O42+(K42*G42)+(L42*G42^1.5)+(0.00000048314*G42^2)))) -> 1.027277 | N42: =IF(ISBLANK(D42),"",IF(ISBLANK(G42),J42*(1+0.00001*(35-20)),J42*(1+0.00001*(G42-20)))) -> 111.4566 | O42: =IF(ISBLANK(E42),"",(0.999842594+(0.00006793952*E42)-(0.00000909529*E42^2)+(0.0000001001685*E42^3)-(0.000000001120083*E42^4)+(0.000000000006536332*E42^5))) -> 0.99988467 | P42: =IF(ISBLANK($R$16),"",IF(A42=0,"",IF(ISBLANK($R$17),"",IF(B42=0,"",IF($O$28=$I$29,"",IF(AND($I$29=$O$29,D42<1000),"N° Flac.",IF(AND($I$29=$O$30,D42>1000),"N° Flac.",IF(AND(D42>1202,D42<2001),"Err. N°",IF(AND(D42>499,D42<1141),"Err.N°",(((((F42)+'[1]Correction de volume'!$G$7)*(($P$21)*($P$19)*5598)/(($R$16)-($R$17)))-(($P$27)*1000))/((N42)-($P$26)))))))))))) -> 5.5747829 | Q42: =IF(ISBLANK($R$16),"",IF(A42=0,"",IF(ISBLANK($R$17),"",IF(AND(D42>1202,D42<2001),"Err. N°",IF(AND(D42>499,D42<1141),"Err.N°",IF(B42=0,"",IF($O$28=$I$29,"",IF(AND($I$29=$O$29,D42<1000),"N° Flac.",IF(AND($I$29=$O$30,D42>1000),"N° Flac.",P42/M42))))))))) -> 5.4267573 | R42: =IF(ISBLANK($R$16),"",IF(A42=0,"",IF(ISBLANK($R$17),"",IF(B42=0,"",IF(ISBLANK(J42),"",IF(AND(D42>1202,D42<2001),"Err. N°",IF(AND(D42>499,D42<1141),"Err.N°",IF($I$29=$O$28,"",IF(AND($I$29=$O$29,D42<1000),"N° Flac.",IF(AND($I$29=$O$30,D42>1000),"N° Flac.",((44.66*P42)))))))))))) -> 248.96981 | S42: =IF(ISBLANK($R$16),"",IF(A42=0,"",IF(ISBLANK($R$17),"",IF(B42=0,"",IF(ISBLANK(J42),"",IF(AND(D42>1202,D42<2001),"Err. N°",IF(AND(D42>499,D42<1141),"Err.N°",IF($I$29=$O$28,"",IF(AND($I$29=$O$29,D42<1000),"N° Flac.",IF(AND($I$29=$O$30,D42>1000),"N° Flac.",((44.66*P42)/M42))))))))))) -> 242.35898 | T42: 0.03 | U42: 0.03 | V42: 22.8 | W42: 22.3 | X42: 22.8 | Y42: 22.3 | Z42: 1.44 | AA42: 1.41 | AB42: 45.8 | AC42: 44.8
A43: =IF(ISBLANK(VLOOKUP(D43,'Volumes flacons'!A5:C623,3)),0,1) -> 1 | B43: =IF(ISBLANK(D43),0,IF(ISBLANK(E43),0,IF(ISBLANK(F43),0,1))) -> 1 | C43: 9 | D43: 2194 | E43: 7.7 | F43: 5.438 | G43: 34.89395 | H43: 4000 | I43: 4068 | J43: 111.97 | K43: =IF(ISBLANK(E43),"",(0.000824493-(0.0000040899*E43)+(0.000000076438*E43^2)-(0.00000000082467*E43^3)+(0.0000000000053875*E43^4))) -> 0.00079717523 | L43: =IF(ISBLANK(E43),"",(-0.00000572466+(0.00000010227*E43)-(0.0000000016546*E43^2))) -> -5.0352822e-06 | M43: =IF(ISBLANK(E43),"",IF(ISBLANK(G43),(O43+(K43*35)+(L43*35^1.5)+(0.00000048314*35^2)),(O43+(K43*G43)+(L43*G43^1.5)+(0.00000048314*G43^2)))) -> 1.0272354 | N43: =IF(ISBLANK(D43),"",IF(ISBLANK(G43),J43*(1+0.00001*(35-20)),J43*(1+0.00001*(G43-20)))) -> 111.98668 | O43: =IF(ISBLANK(E43),"",(0.999842594+(0.00006793952*E43)-(0.00000909529*E43^2)+(0.0000001001685*E43^3)-(0.000000001120083*E43^4)+(0.000000000006536332*E43^5))) -> 0.99986844 | P43: =IF(ISBLANK($R$16),"",IF(A43=0,"",IF(ISBLANK($R$17),"",IF(B43=0,"",IF($O$28=$I$29,"",IF(AND($I$29=$O$29,D43<1000),"N° Flac.",IF(AND($I$29=$O$30,D43>1000),"N° Flac.",IF(AND(D43>1202,D43<2001),"Err. N°",IF(AND(D43>499,D43<1141),"Err.N°",(((((F43)+'[1]Correction de volume'!$G$7)*(($P$21)*($P$19)*5598)/(($R$16)-($R$17)))-(($P$27)*1000))/((N43)-($P$26)))))))))))) -> 5.5715416 | Q43: =IF(ISBLANK($R$16),"",IF(A43=0,"",IF(ISBLANK($R$17),"",IF(AND(D43>1202,D43<2001),"Err. N°",IF(AND(D43>499,D43<1141),"Err.N°",IF(B43=0,"",IF($O$28=$I$29,"",IF(AND($I$29=$O$29,D43<1000),"N° Flac.",IF(AND($I$29=$O$30,D43>1000),"N° Flac.",P43/M43))))))))) -> 5.4238216 | R43: =IF(ISBLANK($R$16),"",IF(A43=0,"",IF(ISBLANK($R$17),"",IF(B43=0,"",IF(ISBLANK(J43),"",IF(AND(D43>1202,D43<2001),"Err. N°",IF(AND(D43>499,D43<1141),"Err.N°",IF($I$29=$O$28,"",IF(AND($I$29=$O$29,D43<1000),"N° Flac.",IF(AND($I$29=$O$30,D43>1000),"N° Flac.",((44.66*P43)))))))))))) -> 248.82505 | S43: =IF(ISBLANK($R$16),"",IF(A43=0,"",IF(ISBLANK($R$17),"",IF(B43=0,"",IF(ISBLANK(J43),"",IF(AND(D43>1202,D43<2001),"Err. N°",IF(AND(D43>499,D43<1141),"Err.N°",IF($I$29=$O$28,"",IF(AND($I$29=$O$29,D43<1000),"N° Flac.",IF(AND($I$29=$O$30,D43>1000),"N° Flac.",((44.66*P43)/M43))))))))))) -> 242.22787 | T43: 0.03 | U43: 0.03 | V43: 22.9 | W43: 22.3 | X43: 22.8 | Y43: 22.3 | Z43: 1.44 | AA43: 1.41 | AB43: 45.9 | AC43: 44.8
A44: =IF(ISBLANK(VLOOKUP(D44,'Volumes flacons'!A5:C623,3)),0,1) -> 1 | B44: =IF(ISBLANK(D44),0,IF(ISBLANK(E44),0,IF(ISBLANK(F44),0,1))) -> 1 | C44: 10 | D44: 2197 | E44: 7.9 | F44: 5.536 | G44: 34.89585 | H44: 4000 | I44: 4067 | J44: 113.81 | K44: =IF(ISBLANK(E44),"",(0.000824493-(0.0000040899*E44)+(0.000000076438*E44^2)-(0.00000000082467*E44^3)+(0.0000000000053875*E44^4))) -> 0.00079656768 | L44: =IF(ISBLANK(E44),"",(-0.00000572466+(0.00000010227*E44)-(0.0000000016546*E44^2))) -> -5.0199906e-06 | M44: =IF(ISBLANK(E44),"",IF(ISBLANK(G44),(O44+(K44*35)+(L44*35^1.5)+(0.00000048314*35^2)),(O44+(K44*G44)+(L44*G44^1.5)+(0.00000048314*G44^2)))) -> 1.0272073 | N44: =IF(ISBLANK(D44),"",IF(ISBLANK(G44),J44*(1+0.00001*(35-20)),J44*(1+0.00001*(G44-20)))) -> 113.82695 | O44: =IF(ISBLANK(E44),"",(0.999842594+(0.00006793952*E44)-(0.00000909529*E44^2)+(0.0000001001685*E44^3)-(0.000000001120083*E44^4)+(0.000000000006536332*E44^5))) -> 0.9998569 | P44: =IF(ISBLANK($R$16),"",IF(A44=0,"",IF(ISBLANK($R$17),"",IF(B44=0,"",IF($O$28=$I$29,"",IF(AND($I$29=$O$29,D44<1000),"N° Flac.",IF(AND($I$29=$O$30,D44>1000),"N° Flac.",IF(AND(D44>1202,D44<2001),"Err. N°",IF(AND(D44>499,D44<1141),"Err.N°",(((((F44)+'[1]Correction de volume'!$G$7)*(($P$21)*($P$19)*5598)/(($R$16)-($R$17)))-(($P$27)*1000))/((N44)-($P$26)))))))))))) -> 5.5788694 | Q44: =IF(ISBLANK($R$16),"",IF(A44=0,"",IF(ISBLANK($R$17),"",IF(AND(D44>1202,D44<2001),"Err. N°",IF(AND(D44>499,D44<1141),"Err.N°",IF(B44=0,"",IF($O$28=$I$29,"",IF(AND($I$29=$O$29,D44<1000),"N° Flac.",IF(AND($I$29=$O$30,D44>1000),"N° Flac.",P44/M44))))))))) -> 5.4311037 | R44: =IF(ISBLANK($R$16),"",IF(A44=0,"",IF(ISBLANK($R$17),"",IF(B44=0,"",IF(ISBLANK(J44),"",IF(AND(D44>1202,D44<2001),"Err. N°",IF(AND(D44>499,D44<1141),"Err.N°",IF($I$29=$O$28,"",IF(AND($I$29=$O$29,D44<1000),"N° Flac.",IF(AND($I$29=$O$30,D44>1000),"N° Flac.",((44.66*P44)))))))))))) -> 249.15231 | S44: =IF(ISBLANK($R$16),"",IF(A44=0,"",IF(ISBLANK($R$17),"",IF(B44=0,"",IF(ISBLANK(J44),"",IF(AND(D44>1202,D44<2001),"Err. N°",IF(AND(D44>499,D44<1141),"Err.N°",IF($I$29=$O$28,"",IF(AND($I$29=$O$29,D44<1000),"N° Flac.",IF(AND($I$29=$O$30,D44>1000),"N° Flac.",((44.66*P44)/M44))))))))))) -> 242.55309 | T44: 0.02 | U44: 0.02 | V44: 22.9 | W44: 22.4 | X44: 22.9 | Y44: 22.3 | Z44: 1.44 | AA44: 1.41 | AB44: 45.9 | AC44: 44.9
A45: =IF(ISBLANK(VLOOKUP(D45,'Volumes flacons'!A5:C623,3)),0,1) -> 1 | B45: =IF(ISBLANK(D45),0,IF(ISBLANK(E45),0,IF(ISBLANK(F45),0,1))) -> 1 | C45: 11 | D45: 2198 | E45: 8 | F45: 5.499 | G45: 34.8972 | H45: 4000 | I45: 4070 | J45: 113.13 | K45: =IF(ISBLANK(E45),"",(0.000824493-(0.0000040899*E45)+(0.000000076438*E45^2)-(0.00000000082467*E45^3)+(0.0000000000053875*E45^4))) -> 0.00079626567 | L45: =IF(ISBLANK(E45),"",(-0.00000572466+(0.00000010227*E45)-(0.0000000016546*E45^2))) -> -5.0123944e-06 | M45: =IF(ISBLANK(E45),"",IF(ISBLANK(G45),(O45+(K45*35)+(L45*35^1.5)+(0.00000048314*35^2)),(O45+(K45*G45)+(L45*G45^1.5)+(0.00000048314*G45^2)))) -> 1.0271934 | N45: =IF(ISBLANK(D45),"",IF(ISBLANK(G45),J45*(1+0.00001*(35-20)),J45*(1+0.00001*(G45-20)))) -> 113.14685 | O45: =IF(ISBLANK(E45),"",(0.999842594+(0.00006793952*E45)-(0.00000909529*E45^2)+(0.0000001001685*E45^3)-(0.000000001120083*E45^4)+(0.000000000006536332*E45^5))) -> 0.99985092 | P45: =IF(ISBLANK($R$16),"",IF(A45=0,"",IF(ISBLANK($R$17),"",IF(B45=0,"",IF($O$28=$I$29,"",IF(AND($I$29=$O$29,D45<1000),"N° Flac.",IF(AND($I$29=$O$30,D45>1000),"N° Flac.",IF(AND(D45>1202,D45<2001),"Err. N°",IF(AND(D45>499,D45<1141),"Err.N°",(((((F45)+'[1]Correction de volume'!$G$7)*(($P$21)*($P$19)*5598)/(($R$16)-($R$17)))-(($P$27)*1000))/((N45)-($P$26)))))))))))) -> 5.5753938 | Q45: =IF(ISBLANK($R$16),"",IF(A45=0,"",IF(ISBLANK($R$17),"",IF(AND(D45>1202,D45<2001),"Err. N°",IF(AND(D45>499,D45<1141),"Err.N°",IF(B45=0,"",IF($O$28=$I$29,"",IF(AND($I$29=$O$29,D45<1000),"N° Flac.",IF(AND($I$29=$O$30,D45>1000),"N° Flac.",P45/M45))))))))) -> 5.4277935 | R45: =IF(ISBLANK($R$16),"",IF(A45=0,"",IF(ISBLANK($R$17),"",IF(B45=0,"",IF(ISBLANK(J45),"",IF(AND(D45>1202,D45<2001),"Err. N°",IF(AND(D45>499,D45<1141),"Err.N°",IF($I$29=$O$28,"",IF(AND($I$29=$O$29,D45<1000),"N° Flac.",IF(AND($I$29=$O$30,D45>1000),"N° Flac.",((44.66*P45)))))))))))) -> 248.99709 | S45: =IF(ISBLANK($R$16),"",IF(A45=0,"",IF(ISBLANK($R$17),"",IF(B45=0,"",IF(ISBLANK(J45),"",IF(AND(D45>1202,D45<2001),"Err. N°",IF(AND(D45>499,D45<1141),"Err.N°",IF($I$29=$O$28,"",IF(AND($I$29=$O$29,D45<1000),"N° Flac.",IF(AND($I$29=$O$30,D45>1000),"N° Flac.",((44.66*P45)/M45))))))))))) -> 242.40526 | T45: 0.02 | U45: 0.02 | V45: 22.9 | W45: 22.4 | X45: 22.9 | Y45: 22.4 | Z45: 1.43 | AA45: 1.4 | AB45: 45.9 | AC45: 44.9
A46: =IF(ISBLANK(VLOOKUP(D46,'Volumes flacons'!A5:C623,3)),0,1) -> 1 | B46: =IF(ISBLANK(D46),0,IF(ISBLANK(E46),0,IF(ISBLANK(F46),0,1))) -> 0 | C46: 12 | J46: =IF(ISBLANK(D46),"",IF(VLOOKUP(D46,'Volumes flacons'!$A$5:$C$1023,2)=0,"",IF(D46>'Volumes flacons'!$A$1023,"Mauvais numéro",IF(D46<'Volumes flacons'!$A$5,"Mauvais numéro",(VLOOKUP(D46,'Volumes flacons'!$A$5:$C$1023,3)))))) | K46: =IF(ISBLANK(E46),"",(0.000824493-(0.0000040899*E46)+(0.000000076438*E46^2)-(0.00000000082467*E46^3)+(0.0000000000053875*E46^4))) | L46: =IF(ISBLANK(E46),"",(-0.00000572466+(0.00000010227*E46)-(0.0000000016546*E46^2))) | M46: =IF(ISBLANK(E46),"",IF(ISBLANK(G46),(O46+(K46*35)+(L46*35^1.5)+(0.00000048314*35^2)),(O46+(K46*G46)+(L46*G46^1.5)+(0.00000048314*G46^2)))) | N46: =IF(ISBLANK(D46),"",IF(ISBLANK(G46),J46*(1+0.00001*(35-20)),J46*(1+0.00001*(G46-20)))) | O46: =IF(ISBLANK(E46),"",(0.999842594+(0.00006793952*E46)-(0.00000909529*E46^2)+(0.0000001001685*E46^3)-(0.000000001120083*E46^4)+(0.000000000006536332*E46^5))) | P46: =IF(ISBLANK($R$16),"",IF(A46=0,"",IF(ISBLANK($R$17),"",IF(B46=0,"",IF($O$28=$I$29,"",IF(AND($I$29=$O$29,D46<1000),"N° Flac.",IF(AND($I$29=$O$30,D46>1000),"N° Flac.",IF(AND(D46>1202,D46<2001),"Err. N°",IF(AND(D46>499,D46<1141),"Err.N°",(((((F46)+'Correction de volume'!$G$7)*(($P$21)*($P$19)*5598)/(($R$16)-($R$17)))-(($P$27)*1000))/((N46)-($P$26)))))))))))) | Q46: =IF(ISBLANK($R$16),"",IF(A46=0,"",IF(ISBLANK($R$17),"",IF(AND(D46>1202,D46<2001),"Err. N°",IF(AND(D46>499,D46<1141),"Err.N°",IF(B46=0,"",IF($O$28=$I$29,"",IF(AND($I$29=$O$29,D46<1000),"N° Flac.",IF(AND($I$29=$O$30,D46>1000),"N° Flac.",P46/M46))))))))) | R46: =IF(ISBLANK($R$16),"",IF(A46=0,"",IF(ISBLANK($R$17),"",IF(B46=0,"",IF(ISBLANK(J46),"",IF(AND(D46>1202,D46<2001),"Err. N°",IF(AND(D46>499,D46<1141),"Err.N°",IF($I$29=$O$28,"",IF(AND($I$29=$O$29,D46<1000),"N° Flac.",IF(AND($I$29=$O$30,D46>1000),"N° Flac.",((44.66*P46)))))))))))) | S46: =IF(ISBLANK($R$16),"",IF(A46=0,"",IF(ISBLANK($R$17),"",IF(B46=0,"",IF(ISBLANK(J46),"",IF(AND(D46>1202,D46<2001),"Err. N°",IF(AND(D46>499,D46<1141),"Err.N°",IF($I$29=$O$28,"",IF(AND($I$29=$O$29,D46<1000),"N° Flac.",IF(AND($I$29=$O$30,D46>1000),"N° Flac.",((44.66*P46)/M46)))))))))))
...

Sheet 002_01
C2: Campagne : | F2: PIRATA Fr28
C4: Données de campagne
C6: N° de station : | F6: 2 | H6: N° de palanquée : | P6: 1 | R6: Date d'analyse : | T6: 41702
G8: Position | I8: Degrés | J8: Minutes | P8: Cardinal | Q8: Décimale
G9: Latitude | I9: 0 | J9: 0.096 | K9: : | L9: =IF(P9=M9,"+","-") -> + | M9: N | N9: E | O9: =IF(ISBLANK(I9),"",IF(ISBLANK(J9),"",IF(P9=M10,L9&N11,N11))) -> 0°0.096 | P9: N | Q9: =IF(ISBLANK(I9),"",IF(ISBLANK(J9),"",IF(J9>60,"ERREUR !!",O11*(I9+(J9/60))))) -> 0.0016
G10: Longitude | I10: 23 | J10: 2.51 | K10: : | L10: =IF(P10=N9,"+","-") -> - | M10: S | N10: W | O10: =IF(ISBLANK(I10),"",IF(ISBLANK(J10),"",IF(P10=N10,L10&N12,N12))) -> -23°2.51 | P10: W | Q10: =IF(ISBLANK(I10),"",IF(ISBLANK(J10),"",IF(J10>60,"ERREUR !!",O12*(I10+(J10/60))))) -> -23.041833
G11: Prélèvement | I11: Date | J11: 41701 | N11: =I9&"°"&J9 -> 0°0.096 | O11: =IF(P9=M10,-1,1) -> 1 | P11: =TEXT(J11,"aaaa-mm-jj")&"T"&TEXT(J12,"hh:mm:ss")&"z" -> 2018-03-04T18:03:25z
I12: Heure | J12: 0.75237269 | N12: =I10&"°"&J10 -> 23°2.51 | O12: =IF(P10=N10,-1,1) -> -1
C13: Données :
C14: Température du laboratoire à la calibration ( t°c ) | Q14: t°c = | R14: 28 | S14: °C
C15: Température du laboratoire au début de la série d'analyses | Q15: t°lab = | R15: 28 | S15: °C | V15: 4.9736
C16: Volume moyen de thiosulfate pour la titration à t°c | Q16: Vmoy.titr.t°c = | R16: 4.97465 | S16: mL | V16: 4.9771
C17: Volume moyen de thiosulfate pour la détermination du blanc à t°c | Q17: Vmoy.titr.blanc.t°c = | R17: 0.0047 | S17: mL | V17: 4.968
C18: Masse volumique de l'eau pure à la calibration | O18: ρ = | P18: =(0.999842594+(0.00006793952*$R$14)-(0.00000909529*$R$14^2)+(0.0000001001685*$R$14^3)-(0.000000001120083*$R$14^4)+(0.000000000006536332*$R$14^5)) -> 0.99623712
C19: Normalite de l'iodate (NIO3) à la température de calibration | O19: N(IO3) = | P19: =$P$24*($P$18/'Titre d''iodate'!E19) -> 0.019969802 | Q19: N
C20: Vol. de la prise d'essai d'iodate (VIO3) à 20°C | O20: V(IO3)20°C = | P20: =5+'Correction de volume'!G8 -> 5.0145248 | Q20: mL
C21: Vol. de la prise d'essai d'iodate (VIO3) à t°c | O21: V(IO3)t°c= | P21: =P20*(1+0.00001*(R14-20)) -> 5.0149259 | Q21: mL
C22: Volume moyen de thiosulfate pour la titration à 20° C | O22: Vmoy.titr.20°C = | P22: =$R$16*(1+0.00001*(20-$R$14)) -> 4.974252 | Q22: mL
C23: Volume moyen de thiosulfate pour la détermination du blanc à 20° C | O23: Vmoy.titr.blanc.20°C = | P23: =$R$17*(1+0.00001*(20-$R$14)) -> 0.004699624 | Q23: mL
C24: Normalite de l'iodate (NIO3) à 20°C | O24: N(IO3)20°C = | P24: =MAX('Titre d''iodate'!F7:F10) -> 0.020009275 | Q24: N
C25: Titre du thiosulfate à 20°C | O25: V(Thio)20°C = | P25: =IF(ISBLANK(R14),"",IF(ISBLANK(P21),"",IF(ISBLANK(R17),"",(($P$24*$P$18)/($P$22-$P$23))))) -> 0.0040112229 | Q25: N
C26: Volume de réactif utilisé | O26: Vreg = | P26: =2+('Correction de volume'!G10+'Correction de volume'!G9) -> 2.0183067 | Q26: mL
O27: DOreg = | P27: 0.0017
V28: 4.9799
E29: Choix de la série de flacons : | I29: IRD | O29: IRD | V29: =AVERAGE(V15:V28) -> 4.97465
O30: LPO
C31: N° | D31: N° des Flacons | E31: T° prélèv. | F31: Volume de thio. | G31: Salinité | H31: Prof. Théorique | I31: Prof. Effective | J31: V. flacons 20°C | K31: A | L31: B | M31: Densité eau de mer à t° | N31: Vol. à t° prél. des flacons | O31: Densité eau pure à t° | P31: Oxygène dissous | T31: NO2 | V31: NO3 + NO2 | X31: NO3 | Z31: Phosphate | AB31: Silicate | AD31: chlorophyll-c3 | AE31: chlorophyll-c1+c2 | AF31: peridinin | AG31: 19'-butanoyloxyfucoxanthin | AH31: fucoxanthine | AI31: neoxanthin | AJ31: prasinoxanthin | AK31: violaxanthin | AL31: 19'-hexanoyloxyfucoxanthin | AM31: diadinoxanthin | AN31: alloxanthin | AO31: diatoxanthin | AP31: zeaxanthin | AQ31: lutein | AR31: divinyl chlorophyll-b | AS31: chlorophyll-b | AT31: total chlorophyll-b | AU31: alpha-carotene | AV31: beta-carotene | AW31: pheophorbide | AX31: divinyl chlorophyll-a | AY31: chlorophyll-a | AZ31: total chlorophyll-a | BA31: pheophytin_a | BB31: crocoxanthin
C33: BTL | E33: °C | F33: ml | H33: m | I33: dbar | J33: ml | P33: DOX1 | R33: DOXY | S33: DOX2 | T33: NTRI | U33: NTIW | V33: NTRZ | W33: NTZW | X33: NTRA | Y33: NTAW | Z33: PHOS | AA33: PHOW | AB33: SLCA | AC33: SLCW | AD33: CHC3 | AE33: CHCZ | AF33: PERP | AG33: BFUP | AH33: FUCP | AI33: NEXW | AJ33: PXAP | AK33: VIOW | AL33: HFUP | AM33: DXAP | AN33: AXAP | AO33: TXAP | AP33: ZXAP | AQ33: LUTW | AR33: CHBD | AS33: CH2P | AT33: CHLB | AU33: AACP | AV33: BBCP | AW33: PHEP | AX33: CHAD | AY33: CH1P | AZ33: CPHL | BA33: PHEA | BB33: CXAP
N34: mL | P34: ml/l | Q34: ml/kg | R34: µmol/l | S34: µmol/kg | T34: µmol/l | U34: µmol/kg | V34: µmol/l | W34: µmol/kg | X34: µmol/l | Y34: µmol/kg | Z34: µmol/l | AA34: µmol/kg | AB34: µmol/l | AC34: µmol/kg | AD34: µg.l-1 | AE34: µg.l-1 | AF34: µg.l-1 | AG34: µg.l-1 | AH34: µg.l-1 | AI34: µg.l-1 | AJ34: µg.l-1 | AK34: µg.l-1 | AL34: µg.l-1 | AM34: µg.l-1 | AN34: µg.l-1 | AO34: µg.l-1 | AP34: µg.l-1 | AQ34: µg.l-1 | AR34: µg.l-1 | AS34: µg.l-1 | AT34: µg.l-1 | AU34: µg.l-1 | AV34: µg.l-1 | AW34: µg.l-1 | AX34: µg.l-1 | AY34: µg.l-1 | AZ34: µg.l-1 | BA34: µg.l-1 | BB34: µg.l-1
A35: =IF(ISBLANK(VLOOKUP(D35,'Volumes flacons'!A5:C623,3)),0,1) -> 1 | B35: =IF(ISBLANK(D35),0,IF(ISBLANK(E35),0,IF(ISBLANK(F35),0,1))) -> 1 | C35: 1 | D35: 2001 | E35: 6.8 | F35: 5.5668 | G35: 34.96705 | H35: 2000 | I35: 2021 | J35: =IF(ISBLANK(D35),"",IF(VLOOKUP(D35,'Volumes flacons'!$A$5:$C$1023,2)=0,"",IF(D35>'Volumes flacons'!$A$1023,"Mauvais numéro",IF(D35<'Volumes flacons'!$A$5,"Mauvais numéro",(VLOOKUP(D35,'Volumes flacons'!$A$5:$C$1023,3)))))) -> 110.84 | K35: =IF(ISBLANK(E35),"",(0.000824493-(0.0000040899*E35)+(0.000000076438*E35^2)-(0.00000000082467*E35^3)+(0.0000000000053875*E35^4))) -> 0.00079996839 | L35: =IF(ISBLANK(E35),"",(-0.00000572466+(0.00000010227*E35)-(0.0000000016546*E35^2))) -> -5.1057327e-06 | M35: =IF(ISBLANK(E35),"",IF(ISBLANK(G35),(O35+(K35*35)+(L35*35^1.5)+(0.00000048314*35^2)),(O35+(K35*G35)+(L35*G35^1.5)+(0.00000048314*G35^2)))) -> 1.0274208 | N35: =IF(ISBLANK(D35),"",IF(ISBLANK(G35),J35*(1+0.00001*(35-20)),J35*(1+0.00001*(G35-20)))) -> 110.85659 | O35: =IF(ISBLANK(E35),"",(0.999842594+(0.00006793952*E35)-(0.00000909529*E35^2)+(0.0000001001685*E35^3)-(0.000000001120083*E35^4)+(0.000000000006536332*E35^5))) -> 0.99991321 | P35: =IF(ISBLANK($R$16),"",IF(A35=0,"",IF(ISBLANK($R$17),"",IF(B35=0,"",IF($O$28=$I$29,"",IF(AND($I$29=$O$29,D35<1000),"N° Flac.",IF(AND($I$29=$O$30,D35>1000),"N° Flac.",IF(AND(D35>1202,D35<2001),"Err. N°",IF(AND(D35>499,D35<1141),"Err.N°",(((((F35)+'Correction de volume'!$G$7)*(($P$21)*($P$19)*5598)/(($R$16)-($R$17)))-(($P$27)*1000))/((N35)-($P$26)))))))))))) -> 5.7537904 | Q35: =IF(ISBLANK($R$16),"",IF(A35=0,"",IF(ISBLANK($R$17),"",IF(AND(D35>1202,D35<2001),"Err. N°",IF(AND(D35>499,D35<1141),"Err.N°",IF(B35=0,"",IF($O$28=$I$29,"",IF(AND($I$29=$O$29,D35<1000),"N° Flac.",IF(AND($I$29=$O$30,D35>1000),"N° Flac.",P35/M35))))))))) -> 5.6002278 | R35: =IF(ISBLANK($R$16),"",IF(A35=0,"",IF(ISBLANK($R$17),"",IF(B35=0,"",IF(ISBLANK(J35),"",IF(AND(D35>1202,D35<2001),"Err. N°",IF(AND(D35>499,D35<1141),"Err.N°",IF($I$29=$O$28,"",IF(AND($I$29=$O$29,D35<1000),"N° Flac.",IF(AND($I$29=$O$30,D35>1000),"N° Flac.",((44.66*P35)))))))))))) -> 256.96428 | S35: =IF(ISBLANK($R$16),"",IF(A35=0,"",IF(ISBLANK($R$17),"",IF(B35=0,"",IF(ISBLANK(J35),"",IF(AND(D35>1202,D35<2001),"Err. N°",IF(AND(D35>499,D35<1141),"Err.N°",IF($I$29=$O$28,"",IF(AND($I$29=$O$29,D35<1000),"N° Flac.",IF(AND($I$29=$O$30,D35>1000),"N° Flac.",((44.66*P35)/M35))))))))))) -> 250.10617
A36: =IF(ISBLANK(VLOOKUP(D36,'Volumes flacons'!A5:C623,3)),0,1) -> 1 | B36: =IF(ISBLANK(D36),0,IF(ISBLANK(E36),0,IF(ISBLANK(F36),0,1))) -> 1 | C36: 2 | D36: 2002 | E36: 7.3 | F36: 5.4439 | G36: 34.9709 | H36: 2000 | I36: 2021 | J36: =IF(ISBLANK(D36),"",IF(VLOOKUP(D36,'Volumes flacons'!$A$5:$C$1023,2)=0,"",IF(D36>'Volumes flacons'!$A$1023,"Mauvais numéro",IF(D36<'Volumes flacons'!$A$5,"Mauvais numéro",(VLOOKUP(D36,'Volumes flacons'!$A$5:$C$1023,3)))))) -> 108.59 | K36: =IF(ISBLANK(E36),"",(0.000824493-(0.0000040899*E36)+(0.000000076438*E36^2)-(0.00000000082467*E36^3)+(0.0000000000053875*E36^4))) -> 0.0007984046 | L36: =IF(ISBLANK(E36),"",(-0.00000572466+(0.00000010227*E36)-(0.0000000016546*E36^2))) -> -5.0662626e-06 | M36: =IF(ISBLANK(E36),"",IF(ISBLANK(G36),(O36+(K36*35)+(L36*35^1.5)+(0.00000048314*35^2)),(O36+(K36*G36)+(L36*G36^1.5)+(0.00000048314*G36^2)))) -> 1.0273539 | N36: =IF(ISBLANK(D36),"",IF(ISBLANK(G36),J36*(1+0.00001*(35-20)),J36*(1+0.00001*(G36-20)))) -> 108.60626 | O36: =IF(ISBLANK(E36),"",(0.999842594+(0.00006793952*E36)-(0.00000909529*E36^2)+(0.0000001001685*E36^3)-(0.000000001120083*E36^4)+(0.000000000006536332*E36^5))) -> 0.99988979 | P36: =IF(ISBLANK($R$16),"",IF(A36=0,"",IF(ISBLANK($R$17),"",IF(B36=0,"",IF($O$28=$I$29,"",IF(AND($I$29=$O$29,D36<1000),"N° Flac.",IF(AND($I$29=$O$30,D36>1000),"N° Flac.",IF(AND(D36>1202,D36<2001),"Err. N°",IF(AND(D36>499,D36<1141),"Err.N°",(((((F36)+'Correction de volume'!$G$7)*(($P$21)*($P$19)*5598)/(($R$16)-($R$17)))-(($P$27)*1000))/((N36)-($P$26)))))))))))) -> 5.7452012 | Q36: =IF(ISBLANK($R$16),"",IF(A36=0,"",IF(ISBLANK($R$17),"",IF(AND(D36>1202,D36<2001),"Err. N°",IF(AND(D36>499,D36<1141),"Err.N°",IF(B36=0,"",IF($O$28=$I$29,"",IF(AND($I$29=$O$29,D36<1000),"N° Flac.",IF(AND($I$29=$O$30,D36>1000),"N° Flac.",P36/M36))))))))) -> 5.5922321 | R36: =IF(ISBLANK($R$16),"",IF(A36=0,"",IF(ISBLANK($R$17),"",IF(B36=0,"",IF(ISBLANK(J36),"",IF(AND(D36>1202,D36<2001),"Err. N°",IF(AND(D36>499,D36<1141),"Err.N°",IF($I$29=$O$28,"",IF(AND($I$29=$O$29,D36<1000),"N° Flac.",IF(AND($I$29=$O$30,D36>1000),"N° Flac.",((44.66*P36)))))))))))) -> 256.58069 | S36: =IF(ISBLANK($R$16),"",IF(A36=0,"",IF(ISBLANK($R$17),"",IF(B36=0,"",IF(ISBLANK(J36),"",IF(AND(D36>1202,D36<2001),"Err. N°",IF(AND(D36>499,D36<1141),"Err.N°",IF($I$29=$O$28,"",IF(AND($I$29=$O$29,D36<1000),"N° Flac.",IF(AND($I$29=$O$30,D36>1000),"N° Flac.",((44.66*P36)/M36))))))))))) -> 249.74909
A37: =IF(ISBLANK(VLOOKUP(D37,'Volumes flacons'!A5:C623,3)),0,1) -> 1 | B37: =IF(ISBLANK(D37),0,IF(ISBLANK(E37),0,IF(ISBLANK(F37),0,1))) -> 1 | C37: 3 | D37: 2004 | E37: 8.2 | F37: 4.0251 | G37: 34.82365 | H37: 1200 | I37: 1212 | J37: =IF(ISBLANK(D37),"",IF(VLOOKUP(D37,'Volumes flacons'!$A$5:$C$1023,2)=0,"",IF(D37>'Volumes flacons'!$A$1023,"Mauvais numéro",IF(D37<'Volumes flacons'!$A$5,"Mauvais numéro",(VLOOKUP(D37,'Volumes flacons'!$A$5:$C$1023,3)))))) -> 110.33 | K37: =IF(ISBLANK(E37),"",(0.000824493-(0.0000040899*E37)+(0.000000076438*E37^2)-(0.00000000082467*E37^3)+(0.0000000000053875*E37^4))) -> 0.00079566517 | L37: =IF(ISBLANK(E37),"",(-0.00000572466+(0.00000010227*E37)-(0.0000000016546*E37^2))) -> -4.9973013e-06 | M37: =IF(ISBLANK(E37),"",IF(ISBLANK(G37),(O37+(K37*35)+(L37*35^1.5)+(0.00000048314*35^2)),(O37+(K37*G37)+(L37*G37^1.5)+(0.00000048314*G37^2)))) -> 1.0271055 | N37: =IF(ISBLANK(D37),"",IF(ISBLANK(G37),J37*(1+0.00001*(35-20)),J37*(1+0.00001*(G37-20)))) -> 110.34635 | O37: =IF(ISBLANK(E37),"",(0.999842594+(0.00006793952*E37)-(0.00000909529*E37^2)+(0.0000001001685*E37^3)-(0.000000001120083*E37^4)+(0.000000000006536332*E37^5))) -> 0.99983854 | P37: =IF(ISBLANK($R$16),"",IF(A37=0,"",IF(ISBLANK($R$17),"",IF(B37=0,"",IF($O$28=$I$29,"",IF(AND($I$29=$O$29,D37<1000),"N° Flac.",IF(AND($I$29=$O$30,D37>1000),"N° Flac.",IF(AND(D37>1202,D37<2001),"Err. N°",IF(AND(D37>499,D37<1141),"Err.N°",(((((F37)+'Correction de volume'!$G$7)*(($P$21)*($P$19)*5598)/(($R$16)-($R$17)))-(($P$27)*1000))/((N37)-($P$26)))))))))))) -> 4.1755102 | Q37: =IF(ISBLANK($R$16),"",IF(A37=0,"",IF(ISBLANK($R$17),"",IF(AND(D37>1202,D37<2001),"Err. N°",IF(AND(D37>499,D37<1141),"Err.N°",IF(B37=0,"",IF($O$28=$I$29,"",IF(AND($I$29=$O$29,D37<1000),"N° Flac.",IF(AND($I$29=$O$30,D37>1000),"N° Flac.",P37/M37))))))))) -> 4.0653179 | R37: =IF(ISBLANK($R$16),"",IF(A37=0,"",IF(ISBLANK($R$17),"",IF(B37=0,"",IF(ISBLANK(J37),"",IF(AND(D37>1202,D37<2001),"Err. N°",IF(AND(D37>499,D37<1141),"Err.N°",IF($I$29=$O$28,"",IF(AND($I$29=$O$29,D37<1000),"N° Flac.",IF(AND($I$29=$O$30,D37>1000),"N° Flac.",((44.66*P37)))))))))))) -> 186.47829 | S37: =IF(ISBLANK($R$16),"",IF(A37=0,"",IF(ISBLANK($R$17),"",IF(B37=0,"",IF(ISBLANK(J37),"",IF(AND(D37>1202,D37<2001),"Err. N°",IF(AND(D37>499,D37<1141),"Err.N°",IF($I$29=$O$28,"",IF(AND($I$29=$O$29,D37<1000),"N° Flac.",IF(AND($I$29=$O$30,D37>1000),"N° Flac.",((44.66*P37)/M37))))))))))) -> 181.5571
A38: =IF(ISBLANK(VLOOKUP(D38,'Volumes flacons'!A5:C623,3)),0,1) -> 1 | B38: =IF(ISBLANK(D38),0,IF(ISBLANK(E38),0,IF(ISBLANK(F38),0,1))) -> 1 | C38: 4 | D38: 2005 | E38: 8.9 | F38: 2.2896 | G38: 34.5229 | H38: 800 | I38: 805.5 | J38: =IF(ISBLANK(D38),"",IF(VLOOKUP(D38,'Volumes flacons'!$A$5:$C$1023,2)=0,"",IF(D38>'Volumes flacons'!$A$1023,"Mauvais numéro",IF(D38<'Volumes flacons'!$A$5,"Mauvais numéro",(VLOOKUP(D38,'Volumes flacons'!$A$5:$C$1023,3)))))) -> 110.8 | K38: =IF(ISBLANK(E38),"",(0.000824493-(0.0000040899*E38)+(0.000000076438*E38^2)-(0.00000000082467*E38^3)+(0.0000000000053875*E38^4))) -> 0.00079359998 | L38: =IF(ISBLANK(E38),"",(-0.00000572466+(0.00000010227*E38)-(0.0000000016546*E38^2))) -> -4.9455179e-06 | M38: =IF(ISBLANK(E38),"",IF(ISBLANK(G38),(O38+(K38*35)+(L38*35^1.5)+(0.00000048314*35^2)),(O38+(K38*G38)+(L38*G38^1.5)+(0.00000048314*G38^2)))) -> 1.0267608 | N38: =IF(ISBLANK(D38),"",IF(ISBLANK(G38),J38*(1+0.00001*(35-20)),J38*(1+0.00001*(G38-20)))) -> 110.81609 | O38: =IF(ISBLANK(E38),"",(0.999842594+(0.00006793952*E38)-(0.00000909529*E38^2)+(0.0000001001685*E38^3)-(0.000000001120083*E38^4)+(0.000000000006536332*E38^5))) -> 0.99979077 | P38: =IF(ISBLANK($R$16),"",IF(A38=0,"",IF(ISBLANK($R$17),"",IF(B38=0,"",IF($O$28=$I$29,"",IF(AND($I$29=$O$29,D38<1000),"N° Flac.",IF(AND($I$29=$O$30,D38>1000),"N° Flac.",IF(AND(D38>1202,D38<2001),"Err. N°",IF(AND(D38>499,D38<1141),"Err.N°",(((((F38)+'Correction de volume'!$G$7)*(($P$21)*($P$19)*5598)/(($R$16)-($R$17)))-(($P$27)*1000))/((N38)-($P$26)))))))))))) -> 2.3580989 | Q38: =IF(ISBLANK($R$16),"",IF(A38=0,"",IF(ISBLANK($R$17),"",IF(AND(D38>1202,D38<2001),"Err. N°",IF(AND(D38>499,D38<1141),"Err.N°",IF(B38=0,"",IF($O$28=$I$29,"",IF(AND($I$29=$O$29,D38<1000),"N° Flac.",IF(AND($I$29=$O$30,D38>1000),"N° Flac.",P38/M38))))))))) -> 2.296639 | R38: =IF(ISBLANK($R$16),"",IF(A38=0,"",IF(ISBLANK($R$17),"",IF(B38=0,"",IF(ISBLANK(J38),"",IF(AND(D38>1202,D38<2001),"Err. N°",IF(AND(D38>499,D38<1141),"Err.N°",IF($I$29=$O$28,"",IF(AND($I$29=$O$29,D38<1000),"N° Flac.",IF(AND($I$29=$O$30,D38>1000),"N° Flac.",((44.66*P38)))))))))))) -> 105.3127 | S38: =IF(ISBLANK($R$16),"",IF(A38=0,"",IF(ISBLANK($R$17),"",IF(B38=0,"",IF(ISBLANK(J38),"",IF(AND(D38>1202,D38<2001),"Err. N°",IF(AND(D38>499,D38<1141),"Err.N°",IF($I$29=$O$28,"",IF(AND($I$29=$O$29,D38<1000),"N° Flac.",IF(AND($I$29=$O$30,D38>1000),"N° Flac.",((44.66*P38)/M38))))))))))) -> 102.5679
A39: =IF(ISBLANK(VLOOKUP(D39,'Volumes flacons'!A5:C623,3)),0,1) -> 1 | B39: =IF(ISBLANK(D39),0,IF(ISBLANK(E39),0,IF(ISBLANK(F39),0,1))) -> 1 | C39: 5 | D39: 2006 | E39: 12.2 | F39: 2.3123 | G39: 34.76475 | H39: 400 | I39: 403 | J39: =IF(ISBLANK(D39),"",IF(VLOOKUP(D39,'Volumes flacons'!$A$5:$C$1023,2)=0,"",IF(D39>'Volumes flacons'!$A$1023,"Mauvais numéro",IF(D39<'Volumes flacons'!$A$5,"Mauvais numéro",(VLOOKUP(D39,'Volumes flacons'!$A$5:$C$1023,3)))))) -> 108.87 | K39: =IF(ISBLANK(E39),"",(0.000824493-(0.0000040899*E39)+(0.000000076438*E39^2)-(0.00000000082467*E39^3)+(0.0000000000053875*E39^4))) -> 0.00078459513 | L39: =IF(ISBLANK(E39),"",(-0.00000572466+(0.00000010227*E39)-(0.0000000016546*E39^2))) -> -4.7232367e-06 | M39: =IF(ISBLANK(E39),"",IF(ISBLANK(G39),(O39+(K39*35)+(L39*35^1.5)+(0.00000048314*35^2)),(O39+(K39*G39)+(L39*G39^1.5)+(0.00000048314*G39^2)))) -> 1.0263686 | N39: =IF(ISBLANK(D39),"",IF(ISBLANK(G39),J39*(1+0.00001*(35-20)),J39*(1+0.00001*(G39-20)))) -> 108.88607 | O39: =IF(ISBLANK(E39),"",(0.999842594+(0.00006793952*E39)-(0.00000909529*E39^2)+(0.0000001001685*E39^3)-(0.000000001120083*E39^4)+(0.000000000006536332*E39^5))) -> 0.99947656 | P39: =IF(ISBLANK($R$16),"",IF(A39=0,"",IF(ISBLANK($R$17),"",IF(B39=0,"",IF($O$28=$I$29,"",IF(AND($I$29=$O$29,D39<1000),"N° Flac.",IF(AND($I$29=$O$30,D39>1000),"N° Flac.",IF(AND(D39>1202,D39<2001),"Err. N°",IF(AND(D39>499,D39<1141),"Err.N°",(((((F39)+'Correction de volume'!$G$7)*(($P$21)*($P$19)*5598)/(($R$16)-($R$17)))-(($P$27)*1000))/((N39)-($P$26)))))))))))) -> 2.4246465 | Q39: =IF(ISBLANK($R$16),"",IF(A39=0,"",IF(ISBLANK($R$17),"",IF(AND(D39>1202,D39<2001),"Err. N°",IF(AND(D39>499,D39<1141),"Err.N°",IF(B39=0,"",IF($O$28=$I$29,"",IF(AND($I$29=$O$29,D39<1000),"N° Flac.",IF(AND($I$29=$O$30,D39>1000),"N° Flac.",P39/M39))))))))) -> 2.3623546 | R39: =IF(ISBLANK($R$16),"",IF(A39=0,"",IF(ISBLANK($R$17),"",IF(B39=0,"",IF(ISBLANK(J39),"",IF(AND(D39>1202,D39<2001),"Err. N°",IF(AND(D39>499,D39<1141),"Err.N°",IF($I$29=$O$28,"",IF(AND($I$29=$O$29,D39<1000),"N° Flac.",IF(AND($I$29=$O$30,D39>1000),"N° Flac.",((44.66*P39)))))))))))) -> 108.28471 | S39: =IF(ISBLANK($R$16),"",IF(A39=0,"",IF(ISBLANK($R$17),"",IF(B39=0,"",IF(ISBLANK(J39),"",IF(AND(D39>1202,D39<2001),"Err. N°",IF(AND(D39>499,D39<1141),"Err.N°",IF($I$29=$O$28,"",IF(AND($I$29=$O$29,D39<1000),"N° Flac.",IF(AND($I$29=$O$30,D39>1000),"N° Flac.",((44.66*P39)/M39))))))))))) -> 105.50276
A40: =IF(ISBLANK(VLOOKUP(D40,'Volumes flacons'!A5:C623,3)),0,1) -> 1 | B40: =IF(ISBLANK(D40),0,IF(ISBLANK(E40),0,IF(ISBLANK(F40),0,1))) -> 1 | C40: 6 | D40: 2007 | E40: 17.6 | F40: 3.6963 | G40: 35.64645 | H40: 100 | I40: 100.8 | J40: =IF(ISBLANK(D40),"",IF(VLOOKUP(D40,'Volumes flacons'!$A$5:$C$1023,2)=0,"",IF(D40>'Volumes flacons'!$A$1023,"Mauvais numéro",IF(D40<'Volumes flacons'!$A$5,"Mauvais numéro",(VLOOKUP(D40,'Volumes flacons'!$A$5:$C$1023,3)))))) -> 109.77 | K40: =IF(ISBLANK(E40),"",(0.000824493-(0.0000040899*E40)+(0.000000076438*E40^2)-(0.00000000082467*E40^3)+(0.0000000000053875*E40^4))) -> 0.00077220922 | L40: =IF(ISBLANK(E40),"",(-0.00000572466+(0.00000010227*E40)-(0.0000000016546*E40^2))) -> -4.4372369e-06 | M40: =IF(ISBLANK(E40),"",IF(ISBLANK(G40),(O40+(K40*35)+(L40*35^1.5)+(0.00000048314*35^2)),(O40+(K40*G40)+(L40*G40^1.5)+(0.00000048314*G40^2)))) -> 1.0258667 | N40: =IF(ISBLANK(D40),"",IF(ISBLANK(G40),J40*(1+0.00001*(35-20)),J40*(1+0.00001*(G40-20)))) -> 109.78718 | O40: =IF(ISBLANK(E40),"",(0.999842594+(0.00006793952*E40)-(0.00000909529*E40^2)+(0.0000001001685*E40^3)-(0.000000001120083*E40^4)+(0.000000000006536332*E40^5))) -> 0.99867063 | P40: =IF(ISBLANK($R$16),"",IF(A40=0,"",IF(ISBLANK($R$17),"",IF(B40=0,"",IF($O$28=$I$29,"",IF(AND($I$29=$O$29,D40<1000),"N° Flac.",IF(AND($I$29=$O$30,D40>1000),"N° Flac.",IF(AND(D40>1202,D40<2001),"Err. N°",IF(AND(D40>499,D40<1141),"Err.N°",(((((F40)+'Correction de volume'!$G$7)*(($P$21)*($P$19)*5598)/(($R$16)-($R$17)))-(($P$27)*1000))/((N40)-($P$26)))))))))))) -> 3.8530179 | Q40: =IF(ISBLANK($R$16),"",IF(A40=0,"",IF(ISBLANK($R$17),"",IF(AND(D40>1202,D40<2001),"Err. N°",IF(AND(D40>499,D40<1141),"Err.N°",IF(B40=0,"",IF($O$28=$I$29,"",IF(AND($I$29=$O$29,D40<1000),"N° Flac.",IF(AND($I$29=$O$30,D40>1000),"N° Flac.",P40/M40))))))))) -> 3.755866 | R40: =IF(ISBLANK($R$16),"",IF(A40=0,"",IF(ISBLANK($R$17),"",IF(B40=0,"",IF(ISBLANK(J40),"",IF(AND(D40>1202,D40<2001),"Err. N°",IF(AND(D40>499,D40<1141),"Err.N°",IF($I$29=$O$28,"",IF(AND($I$29=$O$29,D40<1000),"N° Flac.",IF(AND($I$29=$O$30,D40>1000),"N° Flac.",((44.66*P40)))))))))))) -> 172.07578 | S40: =IF(ISBLANK($R$16),"",IF(A40=0,"",IF(ISBLANK($R$17),"",IF(B40=0,"",IF(ISBLANK(J40),"",IF(AND(D40>1202,D40<2001),"Err. N°",IF(AND(D40>499,D40<1141),"Err.N°",IF($I$29=$O$28,"",IF(AND($I$29=$O$29,D40<1000),"N° Flac.",IF(AND($I$29=$O$30,D40>1000),"N° Flac.",((44.66*P40)/M40))))))))))) -> 167.73698 | T40: 0.04 | U40: 0.04 | V40: 12.7 | W40: 12.5 | X40: 12.7 | Y40: 12.4 | Z40: 0.86 | AA40: 0.84 | AB40: 4.96 | AC40: 4.85 | AD40: 0.0119 | AE40: 0.0065 | AF40: -9999.9999 | AG40: 0.0166 | AH40: 0.0035 | AI40: -9999.9999 | AJ40: -9999.9999 | AK40: -9999.9999 | AL40: 0.0231 | AM40: 0.0014 | AN40: -9999.9999 | AO40: -9999.9999 | AP40: 0.0034 | AR40: 0.0236 | AS40: 0.0157 | AU40: 0.0095 | AV40: -9999.9999 | AX40: 0.0154 | AY40: 0.0517 | BA40: -9999.9999
A41: =IF(ISBLANK(VLOOKUP(D41,'Volumes flacons'!A5:C623,3)),0,1) -> 1 | B41: =IF(ISBLANK(D41),0,IF(ISBLANK(E41),0,IF(ISBLANK(F41),0,1))) -> 1 | C41: 7 | D41: 2008 | E41: 19.9 | F41: 3.7901 | G41: 36.02165 | H41: 80 | I41: 80 | J41: =IF(ISBLANK(D41),"",IF(VLOOKUP(D41,'Volumes flacons'!$A$5:$C$1023,2)=0,"",IF(D41>'Volumes flacons'!$A$1023,"Mauvais numéro",IF(D41<'Volumes flacons'!$A$5,"Mauvais numéro",(VLOOKUP(D41,'Volumes flacons'!$A$5:$C$1023,3)))))) -> 108.85 | K41: =IF(ISBLANK(E41),"",(0.000824493-(0.0000040899*E41)+(0.000000076438*E41^2)-(0.00000000082467*E41^3)+(0.0000000000053875*E41^4))) -> 0.0007677202 | L41: =IF(ISBLANK(E41),"",(-0.00000572466+(0.00000010227*E41)-(0.0000000016546*E41^2))) -> -4.3447251e-06 | M41: =IF(ISBLANK(E41),"",IF(ISBLANK(G41),(O41+(K41*35)+(L41*35^1.5)+(0.00000048314*35^2)),(O41+(K41*G41)+(L41*G41^1.5)+(0.00000048314*G41^2)))) -> 1.025569 | N41: =IF(ISBLANK(D41),"",IF(ISBLANK(G41),J41*(1+0.00001*(35-20)),J41*(1+0.00001*(G41-20)))) -> 108.86744 | O41: =IF(ISBLANK(E41),"",(0.999842594+(0.00006793952*E41)-(0.00000909529*E41^2)+(0.0000001001685*E41^3)-(0.000000001120083*E41^4)+(0.000000000006536332*E41^5))) -> 0.9982269 | P41: =IF(ISBLANK($R$16),"",IF(A41=0,"",IF(ISBLANK($R$17),"",IF(B41=0,"",IF($O$28=$I$29,"",IF(AND($I$29=$O$29,D41<1000),"N° Flac.",IF(AND($I$29=$O$30,D41>1000),"N° Flac.",IF(AND(D41>1202,D41<2001),"Err. N°",IF(AND(D41>499,D41<1141),"Err.N°",(((((F41)+'Correction de volume'!$G$7)*(($P$21)*($P$19)*5598)/(($R$16)-($R$17)))-(($P$27)*1000))/((N41)-($P$26)))))))))))) -> 3.9852103 | Q41: =IF(ISBLANK($R$16),"",IF(A41=0,"",IF(ISBLANK($R$17),"",IF(AND(D41>1202,D41<2001),"Err. N°",IF(AND(D41>499,D41<1141),"Err.N°",IF(B41=0,"",IF($O$28=$I$29,"",IF(AND($I$29=$O$29,D41<1000),"N° Flac.",IF(AND($I$29=$O$30,D41>1000),"N° Flac.",P41/M41))))))))) -> 3.8858527 | R41: =IF(ISBLANK($R$16),"",IF(A41=0,"",IF(ISBLANK($R$17),"",IF(B41=0,"",IF(ISBLANK(J41),"",IF(AND(D41>1202,D41<2001),"Err. N°",IF(AND(D41>499,D41<1141),"Err.N°",IF($I$29=$O$28,"",IF(AND($I$29=$O$29,D41<1000),"N° Flac.",IF(AND($I$29=$O$30,D41>1000),"N° Flac.",((44.66*P41)))))))))))) -> 177.97949 | S41: =IF(ISBLANK($R$16),"",IF(A41=0,"",IF(ISBLANK($R$17),"",IF(B41=0,"",IF(ISBLANK(J41),"",IF(AND(D41>1202,D41<2001),"Err. N°",IF(AND(D41>499,D41<1141),"Err.N°",IF($I$29=$O$28,"",IF(AND($I$29=$O$29,D41<1000),"N° Flac.",IF(AND($I$29=$O$30,D41>1000),"N° Flac.",((44.66*P41)/M41))))))))))) -> 173.54218 | T41: 0.06 | U41: 0.06 | V41: 8.81 | W41: 8.61 | X41: 8.75 | Y41: 8.55 | Z41: 0.66 | AA41: 0.64 | AB41: 3.4 | AC41: 3.32 | AD41: 0.0237 | AE41: 0.0168 | AF41: -9999.9999 | AG41: 0.0378 | AH41: 0.0071 | AI41: -9999.9999 | AJ41: -9999.9999 | AK41: -9999.9999 | AL41: 0.0407 | AM41: 0.0028 | AN41: -9999.9999 | AO41: -9999.9999 | AP41: 0.0124 | AR41: 0.0711 | AS41: 0.0354 | AU41: 0.0238 | AV41: -9999.9999 | AX41: 0.0537 | AY41: 0.1063 | BA41: 0.0025
A42: =IF(ISBLANK(VLOOKUP(D42,'Volumes flacons'!A5:C623,3)),0,1) -> 1 | B42: =IF(ISBLANK(D42),0,IF(ISBLANK(E42),0,IF(ISBLANK(F42),0,1))) -> 1 | C42: 8 | D42: 2009 | E42: 24.5 | F42: 3.9246 | G42: 36.47235 | H42: 60 | I42: 59 | J42: =IF(ISBLANK(D42),"",IF(VLOOKUP(D42,'Volumes flacons'!$A$5:$C$1023,2)=0,"",IF(D42>'Volumes flacons'!$A$1023,"Mauvais numéro",IF(D42<'Volumes flacons'!$A$5,"Mauvais numéro",(VLOOKUP(D42,'Volumes flacons'!$A$5:$C$1023,3)))))) -> 109.15 | K42: =IF(ISBLANK(E42),"",(0.000824493-(0.0000040899*E42)+(0.000000076438*E42^2)-(0.00000000082467*E42^3)+(0.0000000000053875*E42^4))) -> 0.00075998578 | L42: =IF(ISBLANK(E42),"",(-0.00000572466+(0.00000010227*E42)-(0.0000000016546*E42^2))) -> -4.2122186e-06 | M42: =IF(ISBLANK(E42),"",IF(ISBLANK(G42),(O42+(K42*35)+(L42*35^1.5)+(0.00000048314*35^2)),(O42+(K42*G42)+(L42*G42^1.5)+(0.00000048314*G42^2)))) -> 1.0246082 | N42: =IF(ISBLANK(D42),"",IF(ISBLANK(G42),J42*(1+0.00001*(35-20)),J42*(1+0.00001*(G42-20)))) -> 109.16798 | O42: =IF(ISBLANK(E42),"",(0.999842594+(0.00006793952*E42)-(0.00000909529*E42^2)+(0.0000001001685*E42^3)-(0.000000001120083*E42^4)+(0.000000000006536332*E42^5))) -> 0.99717489 | P42: =IF(ISBLANK($R$16),"",IF(A42=0,"",IF(ISBLANK($R$17),"",IF(B42=0,"",IF($O$28=$I$29,"",IF(AND($I$29=$O$29,D42<1000),"N° Flac.",IF(AND($I$29=$O$30,D42>1000),"N° Flac.",IF(AND(D42>1202,D42<2001),"Err. N°",IF(AND(D42>499,D42<1141),"Err.N°",(((((F42)+'Correction de volume'!$G$7)*(($P$21)*($P$19)*5598)/(($R$16)-($R$17)))-(($P$27)*1000))/((N42)-($P$26)))))))))))) -> 4.1156282 | Q42: =IF(ISBLANK($R$16),"",IF(A42=0,"",IF(ISBLANK($R$17),"",IF(AND(D42>1202,D42<2001),"Err. N°",IF(AND(D42>499,D42<1141),"Err.N°",IF(B42=0,"",IF($O$28=$I$29,"",IF(AND($I$29=$O$29,D42<1000),"N° Flac.",IF(AND($I$29=$O$30,D42>1000),"N° Flac.",P42/M42))))))))) -> 4.0167822 | R42: =IF(ISBLANK($R$16),"",IF(A42=0,"",IF(ISBLANK($R$17),"",IF(B42=0,"",IF(ISBLANK(J42),"",IF(AND(D42>1202,D42<2001),"Err. N°",IF(AND(D42>499,D42<1141),"Err.N°",IF($I$29=$O$28,"",IF(AND($I$29=$O$29,D42<1000),"N° Flac.",IF(AND($I$29=$O$30,D42>1000),"N° Flac.",((44.66*P42)))))))))))) -> 183.80395 | S42: =IF(ISBLANK($R$16),"",IF(A42=0,"",IF(ISBLANK($R$17),"",IF(B42=0,"",IF(ISBLANK(J42),"",IF(AND(D42>1202,D42<2001),"Err. N°",IF(AND(D42>499,D42<1141),"Err.N°",IF($I$29=$O$28,"",IF(AND($I$29=$O$29,D42<1000),"N° Flac.",IF(AND($I$29=$O$30,D42>1000),"N° Flac.",((44.66*P42)/M42))))))))))) -> 179.38949 | T42: 0.28 | U42: 0.27 | V42: 2.3 | W42: 2.25 | X42: 2.02 | Y42: 1.97 | Z42: 0.28 | AA42: 0.27 | AB42: 1.63 | AC42: 1.59 | AD42: 0.0646 | AE42: 0.0685 | AF42: 0.0144 | AG42: 0.0854 | AH42: 0.0263 | AI42: 0.0088 | AJ42: 0.0072 | AK42: 0.0042 | AL42: 0.1208 | AM42: 0.0095 | AN42: 0.0135 | AO42: -9999.9999 | AP42: 0.057 | AR42: 0.1376 | AS42: 0.1753 | AU42: 0.0661 | AV42: -9999.9999 | AX42: 0.185 | AY42: 0.3927 | BA42: 0.006
