Workbook

Sheet Station 001
C2: Campagne : | F2: PIRATA Fr27
C4: Données de campagne
C6: N° de station : | F6: 1 | H6: N° de palanquée : | P6: 1 | R6: Date d'analyse : | T6: 41332
G8: Position | I8: Degrés | J8: Minutes | P8: Cardinal | Q8: Décimale
G9: Latitude | I9: 11 | J9: 28.31 | K9: : | L9: =IF(P9=M9,"+","-") -> + | M9: N | N9: E | O9: =IF(ISBLANK(I9),"",IF(ISBLANK(J9),"",IF(P9=M10,L9&N11,N11))) -> 11°28.31 | P9: N | Q9: =IF(ISBLANK(I9),"",IF(ISBLANK(J9),"",IF(J9>60,"ERREUR !!",O11*(I9+(J9/60))))) -> 11.471833
G10: Longitude | I10: 23 | J10: 0.025 | K10: : | L10: =IF(P10=N9,"+","-") -> - | M10: S | N10: W | O10: =IF(ISBLANK(I10),"",IF(ISBLANK(J10),"",IF(P10=N10,L10&N12,N12))) -> -23°0.025 | P10: W | Q10: =IF(ISBLANK(I10),"",IF(ISBLANK(J10),"",IF(J10>60,"ERREUR !!",O12*(I10+(J10/60))))) -> -23.000417
G11: Prélèvement | I11: Date | J11: 41331 | N11: =I9&"°"&J9 -> 11°28.31 | O11: =IF(P9=M10,-1,1) -> 1 | P11: =TEXT(J11,"aaaa-mm-jj")&"T"&TEXT(J12,"hh:mm:ss")&"z" -> 2017-02-27T19:57:00z
I12: Heure | J12: 0.83125 | N12: =I10&"°"&J10 -> 23°0.025 | O12: =IF(P10=N10,-1,1) -> -1
C13: Données :
C14: Température du laboratoire à la calibration ( t°c ) | Q14: t°c = | R14: 21.6 | S14: °C
C15: Température du laboratoire au début de la série d'analyses | Q15: t°lab = | R15: 21.7 | S15: °C
C16: Volume moyen de thiosulfate pour la titration à t°c | Q16: Vmoy.titr.t°c = | R16: 4.998 | S16: mL
C17: Volume moyen de thiosulfate pour la détermination du blanc à t°c | Q17: Vmoy.titr.blanc.t°c = | R17: 0.005 | S17: mL
C18: Masse volumique de l'eau pure à la calibration | O18: ρ = | P18: =(0.999842594+(0.00006793952*$R$14)-(0.00000909529*$R$14^2)+(0.0000001001685*$R$14^3)-(0.000000001120083*$R$14^4)+(0.000000000006536332*$R$14^5)) -> 0.99786297
C19: Normalite de l'iodate (NIO3) à la température de calibration | O19: N(IO3) = | P19: =$P$24*($P$18/'Titre d''iodate'!E19) -> 0.020044858 | Q19: N
C20: Vol. de la prise d'essai d'iodate (VIO3) à 20°C | O20: V(IO3)20°C = | P20: =5+'Correction de volume'!G8 -> 5.00309 | Q20: mL
C21: Vol. de la prise d'essai d'iodate (VIO3) à t°c | O21: V(IO3)t°c= | P21: =P20*(1+0.00001*(R14-20)) -> 5.00317 | Q21: mL
C22: Volume moyen de thiosulfate pour la titration à 20° C | O22: Vmoy.titr.20°C = | P22: =$R$16*(1+0.00001*(20-$R$14)) -> 4.99792 | Q22: mL
C23: Volume moyen de thiosulfate pour la détermination du blanc à 20° C | O23: Vmoy.titr.blanc.20°C = | P23: =$R$17*(1+0.00001*(20-$R$14)) -> 0.00499992 | Q23: mL
C24: Normalite de l'iodate (NIO3) à 20°C | O24: N(IO3)20°C = | P24: =MAX('Titre d''iodate'!F7:F10) -> 0.020051755 | Q24: N
C25: Titre du thiosulfate à 20°C | O25: V(Thio)20°C = | P25: =IF(ISBLANK(R14),"",IF(ISBLANK(P21),"",IF(ISBLANK(R17),"",(($P$24*$P$18)/($P$22-$P$23))))) -> 0.0040074552 | Q25: N
C26: Volume de réactif utilisé | O26: Vreg = | P26: =2+('Correction de volume'!G10+'Correction de volume'!G9) -> 2.016394 | Q26: mL
O27: DOreg = | P27: 0.0017
E29: Choix de la série de flacons : | I29: IRD | O29: IRD
O30: LPO
C31: N° | D31: N° des Flacons | E31: T° prélèv. | F31: Volume de thio. | G31: Salinité | H31: Prof. Théorique | I31: Prof. Effective | J31: V. flacons 20°C | K31: A | L31: B | M31: Densité eau de mer à t° | N31: Vol. à t° prél. des flacons | O31: Densité eau pure à t° | P31: Oxygène dissous | T31: NO2 | V31: NO3 + NO2 | X31: NO3 | Z31: Phosphate | AB31: Silicate | AD31: chlorophyll-c3 | AE31: chlorophyll-c1+c2 | AF31: peridinin | AG31: 19'-butanoyloxyfucoxanthin | AH31: fucoxanthine | AI31: neoxanthin | AJ31: prasinoxanthin | AK31: violaxanthin | AL31: 19'-hexanoyloxyfucoxanthin | AM31: diadinoxanthin | AN31: alloxanthin | AO31: diatoxanthin | AP31: zeaxanthin | AQ31: lutein | AR31: divinyl chlorophyll-b | AS31: chlorophyll-b | AT31: total chlorophyll-b | AU31: alpha-carotene | AV31: beta-carotene | AW31: pheophorbide | AX31: divinyl chlorophyll-a | AY31: chlorophyll-a | AZ31: total chlorophyll-a | BA31: pheophytin_a | BB31: crocoxanthin
C33: BTL | E33: °C | F33: ml | H33: m | I33: m | J33: ml | P33: DOX1 | R33: DOXY | S33: DOX2 | T33: NTRI | U33: NTIW | V33: NTRZ | W33: NTZW | X33: NTRA | Y33: NTAW | Z33: PHOS | AA33: PHOW | AB33: SLCA | AC33: SLCW | AD33: CHC3 | AE33: CHCZ | AF33: PERP | AG33: BFUP | AH33: FUCP | AI33: NXAP | AJ33: PXAP | AK33: VXAP | AL33: HFUP | AM33: DXAP | AN33: AXAP | AO33: TXAP | AP33: ZXAP | AQ33: LUTP | AR33: CHBD | AS33: CH2P | AT33: CHLB | AU33: AACP | AV33: BBCP | AW33: PHEP | AX33: CHAD | AY33: CH1P | AZ33: CPHL | BA33: PHEA | BB33: CXAP
N34: mL | P34: ml/l | Q34: ml/kg | R34: µmol/l | S34: µmol/kg | T34: µmol/l | U34: µmol/kg | V34: µmol/l | W34: µmol/kg | X34: µmol/l | Y34: µmol/kg | Z34: µmol/l | AA34: µmol/kg | AB34: µmol/l | AC34: µmol/kg | AD34: µg.l-1 | AE34: µg.l-1 | AF34: µg.l-1 | AG34: µg.l-1 | AH34: µg.l-1 | AI34: µg.l-1 | AJ34: µg.l-1 | AK34: µg.l-1 | AL34: µg.l-1 | AM34: µg.l-1 | AN34: µg.l-1 | AO34: µg.l-1 | AP34: µg.l-1 | AQ34: µg.l-1 | AR34: µg.l-1 | AS34: µg.l-1 | AT34: µg.l-1 | AU34: µg.l-1 | AV34: µg.l-1 | AW34: µg.l-1 | AX34: µg.l-1 | AY34: µg.l-1 | AZ34: µg.l-1 | BA34: µg.l-1 | BB34: µg.l-1
A35: =IF(ISBLANK(VLOOKUP(D35,'Volumes flacons'!A5:C623,3)),0,1) -> 1 | B35: =IF(ISBLANK(D35),0,IF(ISBLANK(E35),0,IF(ISBLANK(F35),0,1))) -> 1 | C35: 1 | D35: 2029 | E35: 6.4 | F35: 5.189 | G35: 34.959 | H35: 2000 | I35: 2016 | J35: =IF(ISBLANK(D35),"",IF(VLOOKUP(D35,'Volumes flacons'!$A$5:$C$978,2)=0,"",IF(D35>'Volumes flacons'!$A$978,"Mauvais numéro",IF(D35<'Volumes flacons'!$A$5,"Mauvais numéro",(VLOOKUP(D35,'Volumes flacons'!$A$5:$C$978,3)))))) -> 108.87 | K35: =IF(ISBLANK(E35),"",(0.000824493-(0.0000040899*E35)+(0.000000076438*E35^2)-(0.00000000082467*E35^3)+(0.0000000000053875*E35^4))) -> 0.0008012414 | L35: =IF(ISBLANK(E35),"",(-0.00000572466+(0.00000010227*E35)-(0.0000000016546*E35^2))) -> -5.1379044e-06 | M35: =IF(ISBLANK(E35),"",IF(ISBLANK(G35),(O35+(K35*35)+(L35*35^1.5)+(0.00000048314*35^2)),(O35+(K35*G35)+(L35*G35^1.5)+(0.00000048314*G35^2)))) -> 1.0274684 | N35: =IF(ISBLANK(D35),"",IF(ISBLANK(G35),J35*(1+0.00001*(35-20)),J35*(1+0.00001*(G35-20)))) -> 108.88629 | O35: =IF(ISBLANK(E35),"",(0.999842594+(0.00006793952*E35)-(0.00000909529*E35^2)+(0.0000001001685*E35^3)-(0.000000001120083*E35^4)+(0.000000000006536332*E35^5))) -> 0.99992931 | P35: =IF(ISBLANK($R$16),"",IF(A35=0,"",IF(ISBLANK($R$17),"",IF(B35=0,"",IF($O$28=$I$29,"",IF(AND($I$29=$O$29,D35<1000),"N° Flac.",IF(AND($I$29=$O$30,D35>1000),"N° Flac.",IF(AND(D35>1202,D35<2001),"Err. N°",IF(AND(D35>499,D35<1141),"Err.N°",(((((F35)+'Correction de volume'!$G$7)*(($P$21)*($P$19)*5598)/(($R$16)-($R$17)))-(($P$27)*1000))/((N35)-($P$26)))))))))))) -> 5.4433722 | Q35: =IF(ISBLANK($R$16),"",IF(A35=0,"",IF(ISBLANK($R$17),"",IF(AND(D35>1202,D35<2001),"Err. N°",IF(AND(D35>499,D35<1141),"Err.N°",IF(B35=0,"",IF($O$28=$I$29,"",IF(AND($I$29=$O$29,D35<1000),"N° Flac.",IF(AND($I$29=$O$30,D35>1000),"N° Flac.",P35/M35))))))))) -> 5.2978489 | R35: =IF(ISBLANK($R$16),"",IF(A35=0,"",IF(ISBLANK($R$17),"",IF(B35=0,"",IF(ISBLANK(J35),"",IF(AND(D35>1202,D35<2001),"Err. N°",IF(AND(D35>499,D35<1141),"Err.N°",IF($I$29=$O$28,"",IF(AND($I$29=$O$29,D35<1000),"N° Flac.",IF(AND($I$29=$O$30,D35>1000),"N° Flac.",((44.66*P35)))))))))))) -> 243.101 | S35: =IF(ISBLANK($R$16),"",IF(A35=0,"",IF(ISBLANK($R$17),"",IF(B35=0,"",IF(ISBLANK(J35),"",IF(AND(D35>1202,D35<2001),"Err. N°",IF(AND(D35>499,D35<1141),"Err.N°",IF($I$29=$O$28,"",IF(AND($I$29=$O$29,D35<1000),"N° Flac.",IF(AND($I$29=$O$30,D35>1000),"N° Flac.",((44.66*P35)/M35))))))))))) -> 236.60193 | T35: 0 | U35: 0 | V35: 21.3 | W35: 20.8 | X35: 21.3 | Y35: 20.8 | Z35: 1.53 | AA35: 1.49 | AB35: 23.6 | AC35: 23
A36: =IF(ISBLANK(VLOOKUP(D36,'Volumes flacons'!A5:C623,3)),0,1) -> 1 | B36: =IF(ISBLANK(D36),0,IF(ISBLANK(E36),0,IF(ISBLANK(F36),0,1))) -> 1 | C36: 2 | D36: 2030 | E36: 6.8 | F36: 5.254 | G36: 34.96 | H36: 2000 | I36: 2017 | J36: =IF(ISBLANK(D36),"",IF(VLOOKUP(D36,'Volumes flacons'!$A$5:$C$978,2)=0,"",IF(D36>'Volumes flacons'!$A$978,"Mauvais numéro",IF(D36<'Volumes flacons'!$A$5,"Mauvais numéro",(VLOOKUP(D36,'Volumes flacons'!$A$5:$C$978,3)))))) -> 110.13 | K36: =IF(ISBLANK(E36),"",(0.000824493-(0.0000040899*E36)+(0.000000076438*E36^2)-(0.00000000082467*E36^3)+(0.0000000000053875*E36^4))) -> 0.00079996839 | L36: =IF(ISBLANK(E36),"",(-0.00000572466+(0.00000010227*E36)-(0.0000000016546*E36^2))) -> -5.1057327e-06 | M36: =IF(ISBLANK(E36),"",IF(ISBLANK(G36),(O36+(K36*35)+(L36*35^1.5)+(0.00000048314*35^2)),(O36+(K36*G36)+(L36*G36^1.5)+(0.00000048314*G36^2)))) -> 1.0274152 | N36: =IF(ISBLANK(D36),"",IF(ISBLANK(G36),J36*(1+0.00001*(35-20)),J36*(1+0.00001*(G36-20)))) -> 110.14648 | O36: =IF(ISBLANK(E36),"",(0.999842594+(0.00006793952*E36)-(0.00000909529*E36^2)+(0.0000001001685*E36^3)-(0.000000001120083*E36^4)+(0.000000000006536332*E36^5))) -> 0.99991321 | P36: =IF(ISBLANK($R$16),"",IF(A36=0,"",IF(ISBLANK($R$17),"",IF(B36=0,"",IF($O$28=$I$29,"",IF(AND($I$29=$O$29,D36<1000),"N° Flac.",IF(AND($I$29=$O$30,D36>1000),"N° Flac.",IF(AND(D36>1202,D36<2001),"Err. N°",IF(AND(D36>499,D36<1141),"Err.N°",(((((F36)+'Correction de volume'!$G$7)*(($P$21)*($P$19)*5598)/(($R$16)-($R$17)))-(($P$27)*1000))/((N36)-($P$26)))))))))))) -> 5.4475236 | Q36: =IF(ISBLANK($R$16),"",IF(A36=0,"",IF(ISBLANK($R$17),"",IF(AND(D36>1202,D36<2001),"Err. N°",IF(AND(D36>499,D36<1141),"Err.N°",IF(B36=0,"",IF($O$28=$I$29,"",IF(AND($I$29=$O$29,D36<1000),"N° Flac.",IF(AND($I$29=$O$30,D36>1000),"N° Flac.",P36/M36))))))))) -> 5.3021637 | R36: =IF(ISBLANK($R$16),"",IF(A36=0,"",IF(ISBLANK($R$17),"",IF(B36=0,"",IF(ISBLANK(J36),"",IF(AND(D36>1202,D36<2001),"Err. N°",IF(AND(D36>499,D36<1141),"Err.N°",IF($I$29=$O$28,"",IF(AND($I$29=$O$29,D36<1000),"N° Flac.",IF(AND($I$29=$O$30,D36>1000),"N° Flac.",((44.66*P36)))))))))))) -> 243.28641 | S36: =IF(ISBLANK($R$16),"",IF(A36=0,"",IF(ISBLANK($R$17),"",IF(B36=0,"",IF(ISBLANK(J36),"",IF(AND(D36>1202,D36<2001),"Err. N°",IF(AND(D36>499,D36<1141),"Err.N°",IF($I$29=$O$28,"",IF(AND($I$29=$O$29,D36<1000),"N° Flac.",IF(AND($I$29=$O$30,D36>1000),"N° Flac.",((44.66*P36)/M36))))))))))) -> 236.79463 | T36: 0 | U36: 0 | V36: 20.8 | W36: 20.3 | X36: 20.8 | Y36: 20.3 | Z36: 1.53 | AA36: 1.5 | AB36: 23.3 | AC36: 22.8
A37: =IF(ISBLANK(VLOOKUP(D37,'Volumes flacons'!A5:C623,3)),0,1) -> 1 | B37: =IF(ISBLANK(D37),0,IF(ISBLANK(E37),0,IF(ISBLANK(F37),0,1))) -> 1 | C37: 3 | D37: 2031 | E37: 7.1 | F37: 5.133 | G37: 34.96 | H37: 2000 | I37: 2017 | J37: =IF(ISBLANK(D37),"",IF(VLOOKUP(D37,'Volumes flacons'!$A$5:$C$978,2)=0,"",IF(D37>'Volumes flacons'!$A$978,"Mauvais numéro",IF(D37<'Volumes flacons'!$A$5,"Mauvais numéro",(VLOOKUP(D37,'Volumes flacons'!$A$5:$C$978,3)))))) -> 107.83 | K37: =IF(ISBLANK(E37),"",(0.000824493-(0.0000040899*E37)+(0.000000076438*E37^2)-(0.00000000082467*E37^3)+(0.0000000000053875*E37^4))) -> 0.00079902648 | L37: =IF(ISBLANK(E37),"",(-0.00000572466+(0.00000010227*E37)-(0.0000000016546*E37^2))) -> -5.0819514e-06 | M37: =IF(ISBLANK(E37),"",IF(ISBLANK(G37),(O37+(K37*35)+(L37*35^1.5)+(0.00000048314*35^2)),(O37+(K37*G37)+(L37*G37^1.5)+(0.00000048314*G37^2)))) -> 1.0273736 | N37: =IF(ISBLANK(D37),"",IF(ISBLANK(G37),J37*(1+0.00001*(35-20)),J37*(1+0.00001*(G37-20)))) -> 107.84613 | O37: =IF(ISBLANK(E37),"",(0.999842594+(0.00006793952*E37)-(0.00000909529*E37^2)+(0.0000001001685*E37^3)-(0.000000001120083*E37^4)+(0.000000000006536332*E37^5))) -> 0.99989959 | P37: =IF(ISBLANK($R$16),"",IF(A37=0,"",IF(ISBLANK($R$17),"",IF(B37=0,"",IF($O$28=$I$29,"",IF(AND($I$29=$O$29,D37<1000),"N° Flac.",IF(AND($I$29=$O$30,D37>1000),"N° Flac.",IF(AND(D37>1202,D37<2001),"Err. N°",IF(AND(D37>499,D37<1141),"Err.N°",(((((F37)+'Correction de volume'!$G$7)*(($P$21)*($P$19)*5598)/(($R$16)-($R$17)))-(($P$27)*1000))/((N37)-($P$26)))))))))))) -> 5.4373751 | Q37: =IF(ISBLANK($R$16),"",IF(A37=0,"",IF(ISBLANK($R$17),"",IF(AND(D37>1202,D37<2001),"Err. N°",IF(AND(D37>499,D37<1141),"Err.N°",IF(B37=0,"",IF($O$28=$I$29,"",IF(AND($I$29=$O$29,D37<1000),"N° Flac.",IF(AND($I$29=$O$30,D37>1000),"N° Flac.",P37/M37))))))))) -> 5.2925004 | R37: =IF(ISBLANK($R$16),"",IF(A37=0,"",IF(ISBLANK($R$17),"",IF(B37=0,"",IF(ISBLANK(J37),"",IF(AND(D37>1202,D37<2001),"Err. N°",IF(AND(D37>499,D37<1141),"Err.N°",IF($I$29=$O$28,"",IF(AND($I$29=$O$29,D37<1000),"N° Flac.",IF(AND($I$29=$O$30,D37>1000),"N° Flac.",((44.66*P37)))))))))))) -> 242.83317 | S37: =IF(ISBLANK($R$16),"",IF(A37=0,"",IF(ISBLANK($R$17),"",IF(B37=0,"",IF(ISBLANK(J37),"",IF(AND(D37>1202,D37<2001),"Err. N°",IF(AND(D37>499,D37<1141),"Err.N°",IF($I$29=$O$28,"",IF(AND($I$29=$O$29,D37<1000),"N° Flac.",IF(AND($I$29=$O$30,D37>1000),"N° Flac.",((44.66*P37)/M37))))))))))) -> 236.36307 | T37: 0 | U37: 0 | V37: 20.8 | W37: 20.3 | X37: 20.8 | Y37: 20.3 | Z37: 1.53 | AA37: 1.5 | AB37: 22.9 | AC37: 22.4
A38: =IF(ISBLANK(VLOOKUP(D38,'Volumes flacons'!A5:C623,3)),0,1) -> 1 | B38: =IF(ISBLANK(D38),0,IF(ISBLANK(E38),0,IF(ISBLANK(F38),0,1))) -> 1 | C38: 4 | D38: 2032 | E38: 7.3 | F38: 5.322 | G38: 34.96 | H38: 2000 | I38: 2017 | J38: =IF(ISBLANK(D38),"",IF(VLOOKUP(D38,'Volumes flacons'!$A$5:$C$978,2)=0,"",IF(D38>'Volumes flacons'!$A$978,"Mauvais numéro",IF(D38<'Volumes flacons'!$A$5,"Mauvais numéro",(VLOOKUP(D38,'Volumes flacons'!$A$5:$C$978,3)))))) -> 111.3 | K38: =IF(ISBLANK(E38),"",(0.000824493-(0.0000040899*E38)+(0.000000076438*E38^2)-(0.00000000082467*E38^3)+(0.0000000000053875*E38^4))) -> 0.0007984046 | L38: =IF(ISBLANK(E38),"",(-0.00000572466+(0.00000010227*E38)-(0.0000000016546*E38^2))) -> -5.0662626e-06 | M38: =IF(ISBLANK(E38),"",IF(ISBLANK(G38),(O38+(K38*35)+(L38*35^1.5)+(0.00000048314*35^2)),(O38+(K38*G38)+(L38*G38^1.5)+(0.00000048314*G38^2)))) -> 1.0273453 | N38: =IF(ISBLANK(D38),"",IF(ISBLANK(G38),J38*(1+0.00001*(35-20)),J38*(1+0.00001*(G38-20)))) -> 111.31665 | O38: =IF(ISBLANK(E38),"",(0.999842594+(0.00006793952*E38)-(0.00000909529*E38^2)+(0.0000001001685*E38^3)-(0.000000001120083*E38^4)+(0.000000000006536332*E38^5))) -> 0.99988979 | P38: =IF(ISBLANK($R$16),"",IF(A38=0,"",IF(ISBLANK($R$17),"",IF(B38=0,"",IF($O$28=$I$29,"",IF(AND($I$29=$O$29,D38<1000),"N° Flac.",IF(AND($I$29=$O$30,D38>1000),"N° Flac.",IF(AND(D38>1202,D38<2001),"Err. N°",IF(AND(D38>499,D38<1141),"Err.N°",(((((F38)+'Correction de volume'!$G$7)*(($P$21)*($P$19)*5598)/(($R$16)-($R$17)))-(($P$27)*1000))/((N38)-($P$26)))))))))))) -> 5.4591553 | Q38: =IF(ISBLANK($R$16),"",IF(A38=0,"",IF(ISBLANK($R$17),"",IF(AND(D38>1202,D38<2001),"Err. N°",IF(AND(D38>499,D38<1141),"Err.N°",IF(B38=0,"",IF($O$28=$I$29,"",IF(AND($I$29=$O$29,D38<1000),"N° Flac.",IF(AND($I$29=$O$30,D38>1000),"N° Flac.",P38/M38))))))))) -> 5.3138467 | R38: =IF(ISBLANK($R$16),"",IF(A38=0,"",IF(ISBLANK($R$17),"",IF(B38=0,"",IF(ISBLANK(J38),"",IF(AND(D38>1202,D38<2001),"Err. N°",IF(AND(D38>499,D38<1141),"Err.N°",IF($I$29=$O$28,"",IF(AND($I$29=$O$29,D38<1000),"N° Flac.",IF(AND($I$29=$O$30,D38>1000),"N° Flac.",((44.66*P38)))))))))))) -> 243.80587 | S38: =IF(ISBLANK($R$16),"",IF(A38=0,"",IF(ISBLANK($R$17),"",IF(B38=0,"",IF(ISBLANK(J38),"",IF(AND(D38>1202,D38<2001),"Err. N°",IF(AND(D38>499,D38<1141),"Err.N°",IF($I$29=$O$28,"",IF(AND($I$29=$O$29,D38<1000),"N° Flac.",IF(AND($I$29=$O$30,D38>1000),"N° Flac.",((44.66*P38)/M38))))))))))) -> 237.31639 | T38: 0 | U38: 0 | V38: 20.9 | W38: 20.4 | X38: 20.9 | Y38: 20.4 | Z38: 1.54 | AA38: 1.5 | AB38: 22.9 | AC38: 22.4
A39: =IF(ISBLANK(VLOOKUP(D39,'Volumes flacons'!A5:C623,3)),0,1) -> 1 | B39: =IF(ISBLANK(D39),0,IF(ISBLANK(E39),0,IF(ISBLANK(F39),0,1))) -> 0 | C39: 5 | H39: 2000 | J39: =IF(ISBLANK(D39),"",IF(VLOOKUP(D39,'Volumes flacons'!$A$5:$C$978,2)=0,"",IF(D39>'Volumes flacons'!$A$978,"Mauvais numéro",IF(D39<'Volumes flacons'!$A$5,"Mauvais numéro",(VLOOKUP(D39,'Volumes flacons'!$A$5:$C$978,3))))))
A40: =IF(ISBLANK(VLOOKUP(D40,'Volumes flacons'!A5:C623,3)),0,1) -> 1 | B40: =IF(ISBLANK(D40),0,IF(ISBLANK(E40),0,IF(ISBLANK(F40),0,1))) -> 1 | C40: 6 | D40: 2033 | E40: 7.5 | F40: 5.291 | G40: 34.961 | H40: 2000 | I40: 2017 | J40: =IF(ISBLANK(D40),"",IF(VLOOKUP(D40,'Volumes flacons'!$A$5:$C$978,2)=0,"",IF(D40>'Volumes flacons'!$A$978,"Mauvais numéro",IF(D40<'Volumes flacons'!$A$5,"Mauvais numéro",(VLOOKUP(D40,'Volumes flacons'!$A$5:$C$978,3)))))) -> 110.79 | K40: =IF(ISBLANK(E40),"",(0.000824493-(0.0000040899*E40)+(0.000000076438*E40^2)-(0.00000000082467*E40^3)+(0.0000000000053875*E40^4))) -> 0.00079778753 | L40: =IF(ISBLANK(E40),"",(-0.00000572466+(0.00000010227*E40)-(0.0000000016546*E40^2))) -> -5.0507063e-06 | M40: =IF(ISBLANK(E40),"",IF(ISBLANK(G40),(O40+(K40*35)+(L40*35^1.5)+(0.00000048314*35^2)),(O40+(K40*G40)+(L40*G40^1.5)+(0.00000048314*G40^2)))) -> 1.0273173 | N40: =IF(ISBLANK(D40),"",IF(ISBLANK(G40),J40*(1+0.00001*(35-20)),J40*(1+0.00001*(G40-20)))) -> 110.80658 | O40: =IF(ISBLANK(E40),"",(0.999842594+(0.00006793952*E40)-(0.00000909529*E40^2)+(0.0000001001685*E40^3)-(0.000000001120083*E40^4)+(0.000000000006536332*E40^5))) -> 0.9998794 | P40: =IF(ISBLANK($R$16),"",IF(A40=0,"",IF(ISBLANK($R$17),"",IF(B40=0,"",IF($O$28=$I$29,"",IF(AND($I$29=$O$29,D40<1000),"N° Flac.",IF(AND($I$29=$O$30,D40>1000),"N° Flac.",IF(AND(D40>1202,D40<2001),"Err. N°",IF(AND(D40>499,D40<1141),"Err.N°",(((((F40)+'Correction de volume'!$G$7)*(($P$21)*($P$19)*5598)/(($R$16)-($R$17)))-(($P$27)*1000))/((N40)-($P$26)))))))))))) -> 5.4527112 | Q40: =IF(ISBLANK($R$16),"",IF(A40=0,"",IF(ISBLANK($R$17),"",IF(AND(D40>1202,D40<2001),"Err. N°",IF(AND(D40>499,D40<1141),"Err.N°",IF(B40=0,"",IF($O$28=$I$29,"",IF(AND($I$29=$O$29,D40<1000),"N° Flac.",IF(AND($I$29=$O$30,D40>1000),"N° Flac.",P40/M40))))))))) -> 5.3077186 | R40: =IF(ISBLANK($R$16),"",IF(A40=0,"",IF(ISBLANK($R$17),"",IF(B40=0,"",IF(ISBLANK(J40),"",IF(AND(D40>1202,D40<2001),"Err. N°",IF(AND(D40>499,D40<1141),"Err.N°",IF($I$29=$O$28,"",IF(AND($I$29=$O$29,D40<1000),"N° Flac.",IF(AND($I$29=$O$30,D40>1000),"N° Flac.",((44.66*P40)))))))))))) -> 243.51808 | S40: =IF(ISBLANK($R$16),"",IF(A40=0,"",IF(ISBLANK($R$17),"",IF(B40=0,"",IF(ISBLANK(J40),"",IF(AND(D40>1202,D40<2001),"Err. N°",IF(AND(D40>499,D40<1141),"Err.N°",IF($I$29=$O$28,"",IF(AND($I$29=$O$29,D40<1000),"N° Flac.",IF(AND($I$29=$O$30,D40>1000),"N° Flac.",((44.66*P40)/M40))))))))))) -> 237.04271 | T40: 0 | U40: 0 | V40: 20.9 | W40: 20.4 | X40: 20.9 | Y40: 20.4 | Z40: 1.52 | AA40: 1.48 | AB40: 23.4 | AC40: 22.9
A41: =IF(ISBLANK(VLOOKUP(D41,'Volumes flacons'!A5:C623,3)),0,1) -> 1 | B41: =IF(ISBLANK(D41),0,IF(ISBLANK(E41),0,IF(ISBLANK(F41),0,1))) -> 1 | C41: 7 | D41: 2034 | E41: 7.9 | F41: 5.21 | G41: 34.961 | H41: 2000 | I41: 2017 | J41: =IF(ISBLANK(D41),"",IF(VLOOKUP(D41,'Volumes flacons'!$A$5:$C$978,2)=0,"",IF(D41>'Volumes flacons'!$A$978,"Mauvais numéro",IF(D41<'Volumes flacons'!$A$5,"Mauvais numéro",(VLOOKUP(D41,'Volumes flacons'!$A$5:$C$978,3)))))) -> 109.25 | K41: =IF(ISBLANK(E41),"",(0.000824493-(0.0000040899*E41)+(0.000000076438*E41^2)-(0.00000000082467*E41^3)+(0.0000000000053875*E41^4))) -> 0.00079656768 | L41: =IF(ISBLANK(E41),"",(-0.00000572466+(0.00000010227*E41)-(0.0000000016546*E41^2))) -> -5.0199906e-06 | M41: =IF(ISBLANK(E41),"",IF(ISBLANK(G41),(O41+(K41*35)+(L41*35^1.5)+(0.00000048314*35^2)),(O41+(K41*G41)+(L41*G41^1.5)+(0.00000048314*G41^2)))) -> 1.0272585 | N41: =IF(ISBLANK(D41),"",IF(ISBLANK(G41),J41*(1+0.00001*(35-20)),J41*(1+0.00001*(G41-20)))) -> 109.26634 | O41: =IF(ISBLANK(E41),"",(0.999842594+(0.00006793952*E41)-(0.00000909529*E41^2)+(0.0000001001685*E41^3)-(0.000000001120083*E41^4)+(0.000000000006536332*E41^5))) -> 0.9998569 | P41: =IF(ISBLANK($R$16),"",IF(A41=0,"",IF(ISBLANK($R$17),"",IF(B41=0,"",IF($O$28=$I$29,"",IF(AND($I$29=$O$29,D41<1000),"N° Flac.",IF(AND($I$29=$O$30,D41>1000),"N° Flac.",IF(AND(D41>1202,D41<2001),"Err. N°",IF(AND(D41>499,D41<1141),"Err.N°",(((((F41)+'Correction de volume'!$G$7)*(($P$21)*($P$19)*5598)/(($R$16)-($R$17)))-(($P$27)*1000))/((N41)-($P$26)))))))))))) -> 5.4460988 | Q41: =IF(ISBLANK($R$16),"",IF(A41=0,"",IF(ISBLANK($R$17),"",IF(AND(D41>1202,D41<2001),"Err. N°",IF(AND(D41>499,D41<1141),"Err.N°",IF(B41=0,"",IF($O$28=$I$29,"",IF(AND($I$29=$O$29,D41<1000),"N° Flac.",IF(AND($I$29=$O$30,D41>1000),"N° Flac.",P41/M41))))))))) -> 5.3015854 | R41: =IF(ISBLANK($R$16),"",IF(A41=0,"",IF(ISBLANK($R$17),"",IF(B41=0,"",IF(ISBLANK(J41),"",IF(AND(D41>1202,D41<2001),"Err. N°",IF(AND(D41>499,D41<1141),"Err.N°",IF($I$29=$O$28,"",IF(AND($I$29=$O$29,D41<1000),"N° Flac.",IF(AND($I$29=$O$30,D41>1000),"N° Flac.",((44.66*P41)))))))))))) -> 243.22277 | S41: =IF(ISBLANK($R$16),"",IF(A41=0,"",IF(ISBLANK($R$17),"",IF(B41=0,"",IF(ISBLANK(J41),"",IF(AND(D41>1202,D41<2001),"Err. N°",IF(AND(D41>499,D41<1141),"Err.N°",IF($I$29=$O$28,"",IF(AND($I$29=$O$29,D41<1000),"N° Flac.",IF(AND($I$29=$O$30,D41>1000),"N° Flac.",((44.66*P41)/M41))))))))))) -> 236.76881 | T41: 0 | U41: 0 | V41: 20.9 | W41: 20.5 | X41: 20.9 | Y41: 20.5 | Z41: 1.49 | AA41: 1.46 | AB41: 23.3 | AC41: 22.7
A42: =IF(ISBLANK(VLOOKUP(D42,'Volumes flacons'!A5:C623,3)),0,1) -> 1 | B42: =IF(ISBLANK(D42),0,IF(ISBLANK(E42),0,IF(ISBLANK(F42),0,1))) -> 1 | C42: 8 | D42: 2035 | E42: 21.5 | F42: 4.205 | G42: 35.743 | H42: 2000 | I42: 2017 | J42: =IF(ISBLANK(D42),"",IF(VLOOKUP(D42,'Volumes flacons'!$A$5:$C$978,2)=0,"",IF(D42>'Volumes flacons'!$A$978,"Mauvais numéro",IF(D42<'Volumes flacons'!$A$5,"Mauvais numéro",(VLOOKUP(D42,'Volumes flacons'!$A$5:$C$978,3)))))) -> 110.1 | K42: =IF(ISBLANK(E42),"",(0.000824493-(0.0000040899*E42)+(0.000000076438*E42^2)-(0.00000000082467*E42^3)+(0.0000000000053875*E42^4))) -> 0.00076484891 | L42: =IF(ISBLANK(E42),"",(-0.00000572466+(0.00000010227*E42)-(0.0000000016546*E42^2))) -> -4.2906938e-06 | M42: =IF(ISBLANK(E42),"",IF(ISBLANK(G42),(O42+(K42*35)+(L42*35^1.5)+(0.00000048314*35^2)),(O42+(K42*G42)+(L42*G42^1.5)+(0.00000048314*G42^2)))) -> 1.0249236 | N42: =IF(ISBLANK(D42),"",IF(ISBLANK(G42),J42*(1+0.00001*(35-20)),J42*(1+0.00001*(G42-20)))) -> 110.11733 | O42: =IF(ISBLANK(E42),"",(0.999842594+(0.00006793952*E42)-(0.00000909529*E42^2)+(0.0000001001685*E42^3)-(0.000000001120083*E42^4)+(0.000000000006536332*E42^5))) -> 0.9978852 | P42: =IF(ISBLANK($R$16),"",IF(A42=0,"",IF(ISBLANK($R$17),"",IF(B42=0,"",IF($O$28=$I$29,"",IF(AND($I$29=$O$29,D42<1000),"N° Flac.",IF(AND($I$29=$O$30,D42>1000),"N° Flac.",IF(AND(D42>1202,D42<2001),"Err. N°",IF(AND(D42>499,D42<1141),"Err.N°",(((((F42)+'Correction de volume'!$G$7)*(($P$21)*($P$19)*5598)/(($R$16)-($R$17)))-(($P$27)*1000))/((N42)-($P$26)))))))))))) -> 4.3578896 | Q42: =IF(ISBLANK($R$16),"",IF(A42=0,"",IF(ISBLANK($R$17),"",IF(AND(D42>1202,D42<2001),"Err. N°",IF(AND(D42>499,D42<1141),"Err.N°",IF(B42=0,"",IF($O$28=$I$29,"",IF(AND($I$29=$O$29,D42<1000),"N° Flac.",IF(AND($I$29=$O$30,D42>1000),"N° Flac.",P42/M42))))))))) -> 4.2519167 | R42: =IF(ISBLANK($R$16),"",IF(A42=0,"",IF(ISBLANK($R$17),"",IF(B42=0,"",IF(ISBLANK(J42),"",IF(AND(D42>1202,D42<2001),"Err. N°",IF(AND(D42>499,D42<1141),"Err.N°",IF($I$29=$O$28,"",IF(AND($I$29=$O$29,D42<1000),"N° Flac.",IF(AND($I$29=$O$30,D42>1000),"N° Flac.",((44.66*P42)))))))))))) -> 194.62335 | S42: =IF(ISBLANK($R$16),"",IF(A42=0,"",IF(ISBLANK($R$17),"",IF(B42=0,"",IF(ISBLANK(J42),"",IF(AND(D42>1202,D42<2001),"Err. N°",IF(AND(D42>499,D42<1141),"Err.N°",IF($I$29=$O$28,"",IF(AND($I$29=$O$29,D42<1000),"N° Flac.",IF(AND($I$29=$O$30,D42>1000),"N° Flac.",((44.66*P42)/M42))))))))))) -> 189.8906 | T42: 0.01 | U42: 0.01 | V42: 4.81 | W42: 4.7 | X42: 4.8 | Y42: 4.69 | Z42: 0.37 | AA42: 0.36 | AB42: 2.23 | AC42: 2.18
A43: =IF(ISBLANK(VLOOKUP(D43,'Volumes flacons'!A5:C623,3)),0,1) -> 1 | B43: =IF(ISBLANK(D43),0,IF(ISBLANK(E43),0,IF(ISBLANK(F43),0,1))) -> 1 | C43: 9 | D43: 2036 | E43: 8.2 | F43: 5.224 | G43: 34.961 | H43: 2000 | I43: 2017 | J43: =IF(ISBLANK(D43),"",IF(VLOOKUP(D43,'Volumes flacons'!$A$5:$C$978,2)=0,"",IF(D43>'Volumes flacons'!$A$978,"Mauvais numéro",IF(D43<'Volumes flacons'!$A$5,"Mauvais numéro",(VLOOKUP(D43,'Volumes flacons'!$A$5:$C$978,3)))))) -> 109.39 | K43: =IF(ISBLANK(E43),"",(0.000824493-(0.0000040899*E43)+(0.000000076438*E43^2)-(0.00000000082467*E43^3)+(0.0000000000053875*E43^4))) -> 0.00079566517 | L43: =IF(ISBLANK(E43),"",(-0.00000572466+(0.00000010227*E43)-(0.0000000016546*E43^2))) -> -4.9973013e-06 | M43: =IF(ISBLANK(E43),"",IF(ISBLANK(G43),(O43+(K43*35)+(L43*35^1.5)+(0.00000048314*35^2)),(O43+(K43*G43)+(L43*G43^1.5)+(0.00000048314*G43^2)))) -> 1.0272133 | N43: =IF(ISBLANK(D43),"",IF(ISBLANK(G43),J43*(1+0.00001*(35-20)),J43*(1+0.00001*(G43-20)))) -> 109.40637 | O43: =IF(ISBLANK(E43),"",(0.999842594+(0.00006793952*E43)-(0.00000909529*E43^2)+(0.0000001001685*E43^3)-(0.000000001120083*E43^4)+(0.000000000006536332*E43^5))) -> 0.99983854 | P43: =IF(ISBLANK($R$16),"",IF(A43=0,"",IF(ISBLANK($R$17),"",IF(B43=0,"",IF($O$28=$I$29,"",IF(AND($I$29=$O$29,D43<1000),"N° Flac.",IF(AND($I$29=$O$30,D43>1000),"N° Flac.",IF(AND(D43>1202,D43<2001),"Err. N°",IF(AND(D43>499,D43<1141),"Err.N°",(((((F43)+'Correction de volume'!$G$7)*(($P$21)*($P$19)*5598)/(($R$16)-($R$17)))-(($P$27)*1000))/((N43)-($P$26)))))))))))) -> 5.4536562 | Q43: =IF(ISBLANK($R$16),"",IF(A43=0,"",IF(ISBLANK($R$17),"",IF(AND(D43>1202,D43<2001),"Err. N°",IF(AND(D43>499,D43<1141),"Err.N°",IF(B43=0,"",IF($O$28=$I$29,"",IF(AND($I$29=$O$29,D43<1000),"N° Flac.",IF(AND($I$29=$O$30,D43>1000),"N° Flac.",P43/M43))))))))) -> 5.309176 | R43: =IF(ISBLANK($R$16),"",IF(A43=0,"",IF(ISBLANK($R$17),"",IF(B43=0,"",IF(ISBLANK(J43),"",IF(AND(D43>1202,D43<2001),"Err. N°",IF(AND(D43>499,D43<1141),"Err.N°",IF($I$29=$O$28,"",IF(AND($I$29=$O$29,D43<1000),"N° Flac.",IF(AND($I$29=$O$30,D43>1000),"N° Flac.",((44.66*P43)))))))))))) -> 243.56029 | S43: =IF(ISBLANK($R$16),"",IF(A43=0,"",IF(ISBLANK($R$17),"",IF(B43=0,"",IF(ISBLANK(J43),"",IF(AND(D43>1202,D43<2001),"Err. N°",IF(AND(D43>499,D43<1141),"Err.N°",IF($I$29=$O$28,"",IF(AND($I$29=$O$29,D43<1000),"N° Flac.",IF(AND($I$29=$O$30,D43>1000),"N° Flac.",((44.66*P43)/M43))))))))))) -> 237.1078 | T43: 0 | U43: 0 | V43: 21.3 | W43: 20.8 | X43: 21.3 | Y43: 20.8 | Z43: 1.45 | AA43: 1.42 | AB43: 23.6 | AC43: 23.1
A44: =IF(ISBLANK(VLOOKUP(D44,'Volumes flacons'!A5:C623,3)),0,1) -> 1 | B44: =IF(ISBLANK(D44),0,IF(ISBLANK(E44),0,IF(ISBLANK(F44),0,1))) -> 1 | C44: 10 | D44: 2037 | E44: 8.4 | F44: 5.29 | G44: 34.961 | H44: 2000 | I44: 2017 | J44: =IF(ISBLANK(D44),"",IF(VLOOKUP(D44,'Volumes flacons'!$A$5:$C$978,2)=0,"",IF(D44>'Volumes flacons'!$A$978,"Mauvais numéro",IF(D44<'Volumes flacons'!$A$5,"Mauvais numéro",(VLOOKUP(D44,'Volumes flacons'!$A$5:$C$978,3)))))) -> 110.47 | K44: =IF(ISBLANK(E44),"",(0.000824493-(0.0000040899*E44)+(0.000000076438*E44^2)-(0.00000000082467*E44^3)+(0.0000000000053875*E44^4))) -> 0.00079506934 | L44: =IF(ISBLANK(E44),"",(-0.00000572466+(0.00000010227*E44)-(0.0000000016546*E44^2))) -> -4.9823406e-06 | M44: =IF(ISBLANK(E44),"",IF(ISBLANK(G44),(O44+(K44*35)+(L44*35^1.5)+(0.00000048314*35^2)),(O44+(K44*G44)+(L44*G44^1.5)+(0.00000048314*G44^2)))) -> 1.0271826 | N44: =IF(ISBLANK(D44),"",IF(ISBLANK(G44),J44*(1+0.00001*(35-20)),J44*(1+0.00001*(G44-20)))) -> 110.48653 | O44: =IF(ISBLANK(E44),"",(0.999842594+(0.00006793952*E44)-(0.00000909529*E44^2)+(0.0000001001685*E44^3)-(0.000000001120083*E44^4)+(0.000000000006536332*E44^5))) -> 0.99982559 | P44: =IF(ISBLANK($R$16),"",IF(A44=0,"",IF(ISBLANK($R$17),"",IF(B44=0,"",IF($O$28=$I$29,"",IF(AND($I$29=$O$29,D44<1000),"N° Flac.",IF(AND($I$29=$O$30,D44>1000),"N° Flac.",IF(AND(D44>1202,D44<2001),"Err. N°",IF(AND(D44>499,D44<1141),"Err.N°",(((((F44)+'Correction de volume'!$G$7)*(($P$21)*($P$19)*5598)/(($R$16)-($R$17)))-(($P$27)*1000))/((N44)-($P$26)))))))))))) -> 5.4677632 | Q44: =IF(ISBLANK($R$16),"",IF(A44=0,"",IF(ISBLANK($R$17),"",IF(AND(D44>1202,D44<2001),"Err. N°",IF(AND(D44>499,D44<1141),"Err.N°",IF(B44=0,"",IF($O$28=$I$29,"",IF(AND($I$29=$O$29,D44<1000),"N° Flac.",IF(AND($I$29=$O$30,D44>1000),"N° Flac.",P44/M44))))))))) -> 5.3230683 | R44: =IF(ISBLANK($R$16),"",IF(A44=0,"",IF(ISBLANK($R$17),"",IF(B44=0,"",IF(ISBLANK(J44),"",IF(AND(D44>1202,D44<2001),"Err. N°",IF(AND(D44>499,D44<1141),"Err.N°",IF($I$29=$O$28,"",IF(AND($I$29=$O$29,D44<1000),"N° Flac.",IF(AND($I$29=$O$30,D44>1000),"N° Flac.",((44.66*P44)))))))))))) -> 244.1903 | S44: =IF(ISBLANK($R$16),"",IF(A44=0,"",IF(ISBLANK($R$17),"",IF(B44=0,"",IF(ISBLANK(J44),"",IF(AND(D44>1202,D44<2001),"Err. N°",IF(AND(D44>499,D44<1141),"Err.N°",IF($I$29=$O$28,"",IF(AND($I$29=$O$29,D44<1000),"N° Flac.",IF(AND($I$29=$O$30,D44>1000),"N° Flac.",((44.66*P44)/M44))))))))))) -> 237.72823 | T44: 0 | U44: 0 | V44: 21.1 | W44: 20.6 | X44: 21.1 | Y44: 20.6 | Z44: 1.44 | AA44: 1.4 | AB44: 23.1 | AC44: 22.6
A45: =IF(ISBLANK(VLOOKUP(D45,'Volumes flacons'!A5:C623,3)),0,1) -> 1 | B45: =IF(ISBLANK(D45),0,IF(ISBLANK(E45),0,IF(ISBLANK(F45),0,1))) -> 1 | C45: 11 | D45: 2038 | E45: 8.7 | F45: 5.338 | G45: 34.961 | H45: 2000 | I45: 2017 | J45: =IF(ISBLANK(D45),"",IF(VLOOKUP(D45,'Volumes flacons'!$A$5:$C$978,2)=0,"",IF(D45>'Volumes flacons'!$A$978,"Mauvais numéro",IF(D45<'Volumes flacons'!$A$5,"Mauvais numéro",(VLOOKUP(D45,'Volumes flacons'!$A$5:$C$978,3)))))) -> 111.51 | K45: =IF(ISBLANK(E45),"",(0.000824493-(0.0000040899*E45)+(0.000000076438*E45^2)-(0.00000000082467*E45^3)+(0.0000000000053875*E45^4))) -> 0.00079418428 | L45: =IF(ISBLANK(E45),"",(-0.00000572466+(0.00000010227*E45)-(0.0000000016546*E45^2))) -> -4.9601477e-06 | M45: =IF(ISBLANK(E45),"",IF(ISBLANK(G45),(O45+(K45*35)+(L45*35^1.5)+(0.00000048314*35^2)),(O45+(K45*G45)+(L45*G45^1.5)+(0.00000048314*G45^2)))) -> 1.0271358 | N45: =IF(ISBLANK(D45),"",IF(ISBLANK(G45),J45*(1+0.00001*(35-20)),J45*(1+0.00001*(G45-20)))) -> 111.52668 | O45: =IF(ISBLANK(E45),"",(0.999842594+(0.00006793952*E45)-(0.00000909529*E45^2)+(0.0000001001685*E45^3)-(0.000000001120083*E45^4)+(0.000000000006536332*E45^5))) -> 0.99980512 | P45: =IF(ISBLANK($R$16),"",IF(A45=0,"",IF(ISBLANK($R$17),"",IF(B45=0,"",IF($O$28=$I$29,"",IF(AND($I$29=$O$29,D45<1000),"N° Flac.",IF(AND($I$29=$O$30,D45>1000),"N° Flac.",IF(AND(D45>1202,D45<2001),"Err. N°",IF(AND(D45>499,D45<1141),"Err.N°",(((((F45)+'Correction de volume'!$G$7)*(($P$21)*($P$19)*5598)/(($R$16)-($R$17)))-(($P$27)*1000))/((N45)-($P$26)))))))))))) -> 5.465113 | Q45: =IF(ISBLANK($R$16),"",IF(A45=0,"",IF(ISBLANK($R$17),"",IF(AND(D45>1202,D45<2001),"Err. N°",IF(AND(D45>499,D45<1141),"Err.N°",IF(B45=0,"",IF($O$28=$I$29,"",IF(AND($I$29=$O$29,D45<1000),"N° Flac.",IF(AND($I$29=$O$30,D45>1000),"N° Flac.",P45/M45))))))))) -> 5.3207309 | R45: =IF(ISBLANK($R$16),"",IF(A45=0,"",IF(ISBLANK($R$17),"",IF(B45=0,"",IF(ISBLANK(J45),"",IF(AND(D45>1202,D45<2001),"Err. N°",IF(AND(D45>499,D45<1141),"Err.N°",IF($I$29=$O$28,"",IF(AND($I$29=$O$29,D45<1000),"N° Flac.",IF(AND($I$29=$O$30,D45>1000),"N° Flac.",((44.66*P45)))))))))))) -> 244.07195 | S45: =IF(ISBLANK($R$16),"",IF(A45=0,"",IF(ISBLANK($R$17),"",IF(B45=0,"",IF(ISBLANK(J45),"",IF(AND(D45>1202,D45<2001),"Err. N°",IF(AND(D45>499,D45<1141),"Err.N°",IF($I$29=$O$28,"",IF(AND($I$29=$O$29,D45<1000),"N° Flac.",IF(AND($I$29=$O$30,D45>1000),"N° Flac.",((44.66*P45)/M45))))))))))) -> 237.62384 | T45: 0 | U45: 0 | V45: 20.8 | W45: 20.3 | X45: 20.8 | Y45: 20.3 | Z45: 1.44 | AA45: 1.4 | AB45: 23.3 | AC45: 22.8
A46: =IF(ISBLANK(VLOOKUP(D46,'Volumes flacons'!A5:C623,3)),0,1) -> 1 | B46: =IF(ISBLANK(D46),0,IF(ISBLANK(E46),0,IF(ISBLANK(F46),0,1))) -> 0 | C46: 12 | J46: =IF(ISBLANK(D46),"",IF(VLOOKUP(D46,'Volumes flacons'!$A$5:$C$989,2)=0,"",IF(D46>'Volumes flacons'!$A$989,"Mauvais numéro",IF(D46<'Volumes flacons'!$A$5,"Mauvais numéro",(VLOOKUP(D46,'Volumes flacons'!$A$5:$C$989,3)))))) | K46: =IF(ISBLANK(E46),"",(0.000824493-(0.0000040899*E46)+(0.000000076438*E46^2)-(0.00000000082467*E46^3)+(0.0000000000053875*E46^4))) | L46: =IF(ISBLANK(E46),"",(-0.00000572466+(0.00000010227*E46)-(0.0000000016546*E46^2))) | M46: =IF(ISBLANK(E46),"",IF(ISBLANK(G46),(O46+(K46*35)+(L46*35^1.5)+(0.00000048314*35^2)),(O46+(K46*G46)+(L46*G46^1.5)+(0.00000048314*G46^2)))) | N46: =IF(ISBLANK(D46),"",IF(ISBLANK(G46),J46*(1+0.00001*(35-20)),J46*(1+0.00001*(G46-20)))) | O46: =IF(ISBLANK(E46),"",(0.999842594+(0.00006793952*E46)-(0.00000909529*E46^2)+(0.0000001001685*E46^3)-(0.000000001120083*E46^4)+(0.000000000006536332*E46^5))) | P46: =IF(ISBLANK($R$16),"",IF(A46=0,"",IF(ISBLANK($R$17),"",IF(B46=0,"",IF($O$28=$I$29,"",IF(AND($I$29=$O$29,D46<1000),"N° Flac.",IF(AND($I$29=$O$30,D46>1000),"N° Flac.",IF(AND(D46>1202,D46<2001),"Err. N°",IF(AND(D46>499,D46<1141),"Err.N°",(((((F46)+'Correction de volume'!$G$7)*(($P$21)*($P$19)*5598)/(($R$16)-($R$17)))-(($P$27)*1000))/((N46)-($P$26)))))))))))) | Q46: =IF(ISBLANK($R$16),"",IF(A46=0,"",IF(ISBLANK($R$17),"",IF(AND(D46>1202,D46<2001),"Err. N°",IF(AND(D46>499,D46<1141),"Err.N°",IF(B46=0,"",IF($O$28=$I$29,"",IF(AND($I$29=$O$29,D46<1000),"N° Flac.",IF(AND($I$29=$O$30,D46>1000),"N° Flac.",P46/M46))))))))) | R46: =IF(ISBLANK($R$16),"",IF(A46=0,"",IF(ISBLANK($R$17),"",IF(B46=0,"",IF(ISBLANK(J46),"",IF(AND(D46>1202,D46<2001),"Err. N°",IF(AND(D46>499,D46<1141),"Err.N°",IF($I$29=$O$28,"",IF(AND($I$29=$O$29,D46<1000),"N° Flac.",IF(AND($I$29=$O$30,D46>1000),"N° Flac.",((44.66*P46)))))))))))) | S46: =IF(ISBLANK($R$16),"",IF(A46=0,"",IF(ISBLANK($R$17),"",IF(B46=0,"",IF(ISBLANK(J46),"",IF(AND(D46>1202,D46<2001),"Err. N°",IF(AND(D46>499,D46<1141),"Err.N°",IF($I$29=$O$28,"",IF(AND($I$29=$O$29,D46<1000),"N° Flac.",IF(AND($I$29=$O$30,D46>1000),"N° Flac.",((44.66*P46)/M46)))))))))))
...

Sheet Station 002
C2: Campagne : | F2: PIRATA Fr27
C4: Données de campagne
C6: N° de station : | F6: 2 | H6: N° de palanquée : | P6: 1 | R6: Date d'analyse : | T6: 41334
G8: Position | I8: Degrés | J8: Minutes | P8: Cardinal | Q8: Décimale
G9: Latitude | I9: 2 | J9: 0 | K9: : | L9: =IF(P9=M9,"+","-") -> + | M9: N | N9: E | O9: =IF(ISBLANK(I9),"",IF(ISBLANK(J9),"",IF(P9=M10,L9&N11,N11))) -> 2°0 | P9: N | Q9: =IF(ISBLANK(I9),"",IF(ISBLANK(J9),"",IF(J9>60,"ERREUR !!",O11*(I9+(J9/60))))) -> 2
G10: Longitude | I10: 23 | J10: 0 | K10: : | L10: =IF(P10=N9,"+","-") -> - | M10: S | N10: W | O10: =IF(ISBLANK(I10),"",IF(ISBLANK(J10),"",IF(P10=N10,L10&N12,N12))) -> -23°0 | P10: W | Q10: =IF(ISBLANK(I10),"",IF(ISBLANK(J10),"",IF(J10>60,"ERREUR !!",O12*(I10+(J10/60))))) -> -23
G11: Prélèvement | I11: Date | J11: 41334 | N11: =I9&"°"&J9 -> 2°0 | O11: =IF(P9=M10,-1,1) -> 1 | P11: =TEXT(J11,"aaaa-mm-jj")&"T"&TEXT(J12,"hh:mm:ss")&"z" -> 2017-03-02T00:02:00z
I12: Heure | J12: 0.0013888889 | N12: =I10&"°"&J10 -> 23°0 | O12: =IF(P10=N10,-1,1) -> -1
C13: Données :
C14: Température du laboratoire à la calibration ( t°c ) | Q14: t°c = | R14: 21.5 | S14: °C
C15: Température du laboratoire au début de la série d'analyses | Q15: t°lab = | R15: 21.2 | S15: °C
C16: Volume moyen de thiosulfate pour la titration à t°c | Q16: Vmoy.titr.t°c = | R16: 4.9894 | S16: mL
C17: Volume moyen de thiosulfate pour la détermination du blanc à t°c | Q17: Vmoy.titr.blanc.t°c = | R17: 0.005 | S17: mL
C18: Masse volumique de l'eau pure à la calibration | O18: ρ = | P18: =(0.999842594+(0.00006793952*$R$14)-(0.00000909529*$R$14^2)+(0.0000001001685*$R$14^3)-(0.000000001120083*$R$14^4)+(0.000000000006536332*$R$14^5)) -> 0.9978852 | U18: 4.973
C19: Normalite de l'iodate (NIO3) à la température de calibration | O19: N(IO3) = | P19: =$P$24*($P$18/'Titre d''iodate'!E19) -> 0.020045304 | Q19: N
C20: Vol. de la prise d'essai d'iodate (VIO3) à 20°C | O20: V(IO3)20°C = | P20: =5+'Correction de volume'!G8 -> 5.00309 | Q20: mL
C21: Vol. de la prise d'essai d'iodate (VIO3) à t°c | O21: V(IO3)t°c= | P21: =P20*(1+0.00001*(R14-20)) -> 5.003165 | Q21: mL
C22: Volume moyen de thiosulfate pour la titration à 20° C | O22: Vmoy.titr.20°C = | P22: =$R$16*(1+0.00001*(20-$R$14)) -> 4.9893252 | Q22: mL
C23: Volume moyen de thiosulfate pour la détermination du blanc à 20° C | O23: Vmoy.titr.blanc.20°C = | P23: =$R$17*(1+0.00001*(20-$R$14)) -> 0.004999925 | Q23: mL
C24: Normalite de l'iodate (NIO3) à 20°C | O24: N(IO3)20°C = | P24: =MAX('Titre d''iodate'!F7:F10) -> 0.020051755 | Q24: N
C25: Titre du thiosulfate à 20°C | O25: V(Thio)20°C = | P25: =IF(ISBLANK(R14),"",IF(ISBLANK(P21),"",IF(ISBLANK(R17),"",(($P$24*$P$18)/($P$22-$P$23))))) -> 0.004014455 | Q25: N
C26: Volume de réactif utilisé | O26: Vreg = | P26: =2+('Correction de volume'!G10+'Correction de volume'!G9) -> 2.016394 | Q26: mL
O27: DOreg = | P27: 0.0017
E29: Choix de la série de flacons : | I29: IRD | O29: IRD
O30: LPO
C31: N° | D31: N° des Flacons | E31: T° prélèv. | F31: Volume de thio. | G31: Salinité | H31: Prof. Théorique | I31: Prof. Effective | J31: V. flacons 20°C | K31: A | L31: B | M31: Densité eau de mer à t° | N31: Vol. à t° prél. des flacons | O31: Densité eau pure à t° | P31: Oxygène dissous | T31: NO2 | V31: NO3 + NO2 | X31: NO3 | Z31: Phosphate | AB31: Silicate | AD31: chlorophyll-c3 | AE31: chlorophyll-c1+c2 | AF31: peridinin | AG31: 19'-butanoyloxyfucoxanthin | AH31: fucoxanthine | AI31: neoxanthin | AJ31: prasinoxanthin | AK31: violaxanthin | AL31: 19'-hexanoyloxyfucoxanthin | AM31: diadinoxanthin | AN31: alloxanthin | AO31: diatoxanthin | AP31: zeaxanthin | AQ31: lutein | AR31: divinyl chlorophyll-b | AS31: chlorophyll-b | AT31: total chlorophyll-b | AU31: alpha-carotene | AV31: beta-carotene | AW31: pheophorbide | AX31: divinyl chlorophyll-a | AY31: chlorophyll-a | AZ31: total chlorophyll-a | BA31: pheophytin_a | BB31: crocoxanthin
C33: BTL | E33: °C | F33: ml | H33: m | I33: m | J33: ml | P33: DOX1 | R33: DOXY | S33: DOX2 | T33: NTRI | U33: NTIW | V33: NTRZ | W33: NTZW | X33: NTRA | Y33: NTAW | Z33: PHOS | AA33: PHOW | AB33: SLCA | AC33: SLCW | AD33: CHC3 | AE33: CHCZ | AF33: PERP | AG33: BFUP | AH33: FUCP | AI33: NXAP | AJ33: PXAP | AK33: VXAP | AL33: HFUP | AM33: DXAP | AN33: AXAP | AO33: TXAP | AP33: ZXAP | AQ33: LUTP | AR33: CHBD | AS33: CH2P | AT33: CHLB | AU33: AACP | AV33: BBCP | AW33: PHEP | AX33: CHAD | AY33: CH1P | AZ33: CPHL | BA33: PHEA | BB33: CXAP
N34: mL | P34: ml/l | Q34: ml/kg | R34: µmol/l | S34: µmol/kg | T34: µmol/l | U34: µmol/kg | V34: µmol/l | W34: µmol/kg | X34: µmol/l | Y34: µmol/kg | Z34: µmol/l | AA34: µmol/kg | AB34: µmol/l | AC34: µmol/kg | AD34: µg.l-1 | AE34: µg.l-1 | AF34: µg.l-1 | AG34: µg.l-1 | AH34: µg.l-1 | AI34: µg.l-1 | AJ34: µg.l-1 | AK34: µg.l-1 | AL34: µg.l-1 | AM34: µg.l-1 | AN34: µg.l-1 | AO34: µg.l-1 | AP34: µg.l-1 | AQ34: µg.l-1 | AR34: µg.l-1 | AS34: µg.l-1 | AT34: µg.l-1 | AU34: µg.l-1 | AV34: µg.l-1 | AW34: µg.l-1 | AX34: µg.l-1 | AY34: µg.l-1 | AZ34: µg.l-1 | BA34: µg.l-1 | BB34: µg.l-1
A35: =IF(ISBLANK(VLOOKUP(D35,'Volumes flacons'!A5:C623,3)),0,1) -> 1 | B35: =IF(ISBLANK(D35),0,IF(ISBLANK(E35),0,IF(ISBLANK(F35),0,1))) -> 1 | C35: 1 | D35: 2002 | E35: 9.8 | F35: 5.403 | G35: 34.961 | H35: 2000 | I35: 2020.8 | J35: =IF(ISBLANK(D35),"",IF(VLOOKUP(D35,'Volumes flacons'!$A$5:$C$978,2)=0,"",IF(D35>'Volumes flacons'!$A$978,"Mauvais numéro",IF(D35<'Volumes flacons'!$A$5,"Mauvais numéro",(VLOOKUP(D35,'Volumes flacons'!$A$5:$C$978,3)))))) -> 108.59 | K35: =IF(ISBLANK(E35),"",(0.000824493-(0.0000040899*E35)+(0.000000076438*E35^2)-(0.00000000082467*E35^3)+(0.0000000000053875*E35^4))) -> 0.00079102661 | L35: =IF(ISBLANK(E35),"",(-0.00000572466+(0.00000010227*E35)-(0.0000000016546*E35^2))) -> -4.8813218e-06 | M35: =IF(ISBLANK(E35),"",IF(ISBLANK(G35),(O35+(K35*35)+(L35*35^1.5)+(0.00000048314*35^2)),(O35+(K35*G35)+(L35*G35^1.5)+(0.00000048314*G35^2)))) -> 1.026956 | N35: =IF(ISBLANK(D35),"",IF(ISBLANK(G35),J35*(1+0.00001*(35-20)),J35*(1+0.00001*(G35-20)))) -> 108.60625 | O35: =IF(ISBLANK(E35),"",(0.999842594+(0.00006793952*E35)-(0.00000909529*E35^2)+(0.0000001001685*E35^3)-(0.000000001120083*E35^4)+(0.000000000006536332*E35^5))) -> 0.99971943 | P35: =IF(ISBLANK($R$16),"",IF(A35=0,"",IF(ISBLANK($R$17),"",IF(B35=0,"",IF($O$28=$I$29,"",IF(AND($I$29=$O$29,D35<1000),"N° Flac.",IF(AND($I$29=$O$30,D35>1000),"N° Flac.",IF(AND(D35>1202,D35<2001),"Err. N°",IF(AND(D35>499,D35<1141),"Err.N°",(((((F35)+'Correction de volume'!$G$7)*(($P$21)*($P$19)*5598)/(($R$16)-($R$17)))-(($P$27)*1000))/((N35)-($P$26)))))))))))) -> 5.6933731 | Q35: =IF(ISBLANK($R$16),"",IF(A35=0,"",IF(ISBLANK($R$17),"",IF(AND(D35>1202,D35<2001),"Err. N°",IF(AND(D35>499,D35<1141),"Err.N°",IF(B35=0,"",IF($O$28=$I$29,"",IF(AND($I$29=$O$29,D35<1000),"N° Flac.",IF(AND($I$29=$O$30,D35>1000),"N° Flac.",P35/M35))))))))) -> 5.543931 | R35: =IF(ISBLANK($R$16),"",IF(A35=0,"",IF(ISBLANK($R$17),"",IF(B35=0,"",IF(ISBLANK(J35),"",IF(AND(D35>1202,D35<2001),"Err. N°",IF(AND(D35>499,D35<1141),"Err.N°",IF($I$29=$O$28,"",IF(AND($I$29=$O$29,D35<1000),"N° Flac.",IF(AND($I$29=$O$30,D35>1000),"N° Flac.",((44.66*P35)))))))))))) -> 254.26604 | S35: =IF(ISBLANK($R$16),"",IF(A35=0,"",IF(ISBLANK($R$17),"",IF(B35=0,"",IF(ISBLANK(J35),"",IF(AND(D35>1202,D35<2001),"Err. N°",IF(AND(D35>499,D35<1141),"Err.N°",IF($I$29=$O$28,"",IF(AND($I$29=$O$29,D35<1000),"N° Flac.",IF(AND($I$29=$O$30,D35>1000),"N° Flac.",((44.66*P35)/M35))))))))))) -> 247.59196
A36: =IF(ISBLANK(VLOOKUP(D36,'Volumes flacons'!A5:C623,3)),0,1) -> 1 | B36: =IF(ISBLANK(D36),0,IF(ISBLANK(E36),0,IF(ISBLANK(F36),0,1))) -> 1 | C36: 2 | D36: 2004 | E36: 9.5 | F36: 5.502 | G36: 34.961 | H36: 2000 | I36: 2020.8 | J36: =IF(ISBLANK(D36),"",IF(VLOOKUP(D36,'Volumes flacons'!$A$5:$C$978,2)=0,"",IF(D36>'Volumes flacons'!$A$978,"Mauvais numéro",IF(D36<'Volumes flacons'!$A$5,"Mauvais numéro",(VLOOKUP(D36,'Volumes flacons'!$A$5:$C$978,3)))))) -> 110.33 | K36: =IF(ISBLANK(E36),"",(0.000824493-(0.0000040899*E36)+(0.000000076438*E36^2)-(0.00000000082467*E36^3)+(0.0000000000053875*E36^4))) -> 0.00079187431 | L36: =IF(ISBLANK(E36),"",(-0.00000572466+(0.00000010227*E36)-(0.0000000016546*E36^2))) -> -4.9024226e-06 | M36: =IF(ISBLANK(E36),"",IF(ISBLANK(G36),(O36+(K36*35)+(L36*35^1.5)+(0.00000048314*35^2)),(O36+(K36*G36)+(L36*G36^1.5)+(0.00000048314*G36^2)))) -> 1.0270063 | N36: =IF(ISBLANK(D36),"",IF(ISBLANK(G36),J36*(1+0.00001*(35-20)),J36*(1+0.00001*(G36-20)))) -> 110.34651 | O36: =IF(ISBLANK(E36),"",(0.999842594+(0.00006793952*E36)-(0.00000909529*E36^2)+(0.0000001001685*E36^3)-(0.000000001120083*E36^4)+(0.000000000006536332*E36^5))) -> 0.99974443 | P36: =IF(ISBLANK($R$16),"",IF(A36=0,"",IF(ISBLANK($R$17),"",IF(B36=0,"",IF($O$28=$I$29,"",IF(AND($I$29=$O$29,D36<1000),"N° Flac.",IF(AND($I$29=$O$30,D36>1000),"N° Flac.",IF(AND(D36>1202,D36<2001),"Err. N°",IF(AND(D36>499,D36<1141),"Err.N°",(((((F36)+'Correction de volume'!$G$7)*(($P$21)*($P$19)*5598)/(($R$16)-($R$17)))-(($P$27)*1000))/((N36)-($P$26)))))))))))) -> 5.7048475 | Q36: =IF(ISBLANK($R$16),"",IF(A36=0,"",IF(ISBLANK($R$17),"",IF(AND(D36>1202,D36<2001),"Err. N°",IF(AND(D36>499,D36<1141),"Err.N°",IF(B36=0,"",IF($O$28=$I$29,"",IF(AND($I$29=$O$29,D36<1000),"N° Flac.",IF(AND($I$29=$O$30,D36>1000),"N° Flac.",P36/M36))))))))) -> 5.5548322 | R36: =IF(ISBLANK($R$16),"",IF(A36=0,"",IF(ISBLANK($R$17),"",IF(B36=0,"",IF(ISBLANK(J36),"",IF(AND(D36>1202,D36<2001),"Err. N°",IF(AND(D36>499,D36<1141),"Err.N°",IF($I$29=$O$28,"",IF(AND($I$29=$O$29,D36<1000),"N° Flac.",IF(AND($I$29=$O$30,D36>1000),"N° Flac.",((44.66*P36)))))))))))) -> 254.77849 | S36: =IF(ISBLANK($R$16),"",IF(A36=0,"",IF(ISBLANK($R$17),"",IF(B36=0,"",IF(ISBLANK(J36),"",IF(AND(D36>1202,D36<2001),"Err. N°",IF(AND(D36>499,D36<1141),"Err.N°",IF($I$29=$O$28,"",IF(AND($I$29=$O$29,D36<1000),"N° Flac.",IF(AND($I$29=$O$30,D36>1000),"N° Flac.",((44.66*P36)/M36))))))))))) -> 248.0788
A37: =IF(ISBLANK(VLOOKUP(D37,'Volumes flacons'!A5:C623,3)),0,1) -> 1 | B37: =IF(ISBLANK(D37),0,IF(ISBLANK(E37),0,IF(ISBLANK(F37),0,1))) -> 1 | C37: 3 | D37: 2005 | E37: 10.6 | F37: 3.537 | G37: 34.665 | H37: 1000 | I37: 1009 | J37: =IF(ISBLANK(D37),"",IF(VLOOKUP(D37,'Volumes flacons'!$A$5:$C$978,2)=0,"",IF(D37>'Volumes flacons'!$A$978,"Mauvais numéro",IF(D37<'Volumes flacons'!$A$5,"Mauvais numéro",(VLOOKUP(D37,'Volumes flacons'!$A$5:$C$978,3)))))) -> 110.8 | K37: =IF(ISBLANK(E37),"",(0.000824493-(0.0000040899*E37)+(0.000000076438*E37^2)-(0.00000000082467*E37^3)+(0.0000000000053875*E37^4))) -> 0.00078881445 | L37: =IF(ISBLANK(E37),"",(-0.00000572466+(0.00000010227*E37)-(0.0000000016546*E37^2))) -> -4.8265089e-06 | M37: =IF(ISBLANK(E37),"",IF(ISBLANK(G37),(O37+(K37*35)+(L37*35^1.5)+(0.00000048314*35^2)),(O37+(K37*G37)+(L37*G37^1.5)+(0.00000048314*G37^2)))) -> 1.0265866 | N37: =IF(ISBLANK(D37),"",IF(ISBLANK(G37),J37*(1+0.00001*(35-20)),J37*(1+0.00001*(G37-20)))) -> 110.81625 | O37: =IF(ISBLANK(E37),"",(0.999842594+(0.00006793952*E37)-(0.00000909529*E37^2)+(0.0000001001685*E37^3)-(0.000000001120083*E37^4)+(0.000000000006536332*E37^5))) -> 0.99964684 | P37: =IF(ISBLANK($R$16),"",IF(A37=0,"",IF(ISBLANK($R$17),"",IF(B37=0,"",IF($O$28=$I$29,"",IF(AND($I$29=$O$29,D37<1000),"N° Flac.",IF(AND($I$29=$O$30,D37>1000),"N° Flac.",IF(AND(D37>1202,D37<2001),"Err. N°",IF(AND(D37>499,D37<1141),"Err.N°",(((((F37)+'Correction de volume'!$G$7)*(($P$21)*($P$19)*5598)/(($R$16)-($R$17)))-(($P$27)*1000))/((N37)-($P$26)))))))))))) -> 3.6459321 | Q37: =IF(ISBLANK($R$16),"",IF(A37=0,"",IF(ISBLANK($R$17),"",IF(AND(D37>1202,D37<2001),"Err. N°",IF(AND(D37>499,D37<1141),"Err.N°",IF(B37=0,"",IF($O$28=$I$29,"",IF(AND($I$29=$O$29,D37<1000),"N° Flac.",IF(AND($I$29=$O$30,D37>1000),"N° Flac.",P37/M37))))))))) -> 3.5515096 | R37: =IF(ISBLANK($R$16),"",IF(A37=0,"",IF(ISBLANK($R$17),"",IF(B37=0,"",IF(ISBLANK(J37),"",IF(AND(D37>1202,D37<2001),"Err. N°",IF(AND(D37>499,D37<1141),"Err.N°",IF($I$29=$O$28,"",IF(AND($I$29=$O$29,D37<1000),"N° Flac.",IF(AND($I$29=$O$30,D37>1000),"N° Flac.",((44.66*P37)))))))))))) -> 162.82733 | S37: =IF(ISBLANK($R$16),"",IF(A37=0,"",IF(ISBLANK($R$17),"",IF(B37=0,"",IF(ISBLANK(J37),"",IF(AND(D37>1202,D37<2001),"Err. N°",IF(AND(D37>499,D37<1141),"Err.N°",IF($I$29=$O$28,"",IF(AND($I$29=$O$29,D37<1000),"N° Flac.",IF(AND($I$29=$O$30,D37>1000),"N° Flac.",((44.66*P37)/M37))))))))))) -> 158.61042
A38: =IF(ISBLANK(VLOOKUP(D38,'Volumes flacons'!A5:C623,3)),0,1) -> 1 | B38: =IF(ISBLANK(D38),0,IF(ISBLANK(E38),0,IF(ISBLANK(F38),0,1))) -> 1 | C38: 4 | D38: 2006 | E38: 12.3 | F38: 2.586 | G38: 34.656 | H38: 500 | I38: 505 | J38: =IF(ISBLANK(D38),"",IF(VLOOKUP(D38,'Volumes flacons'!$A$5:$C$978,2)=0,"",IF(D38>'Volumes flacons'!$A$978,"Mauvais numéro",IF(D38<'Volumes flacons'!$A$5,"Mauvais numéro",(VLOOKUP(D38,'Volumes flacons'!$A$5:$C$978,3)))))) -> 108.87 | K38: =IF(ISBLANK(E38),"",(0.000824493-(0.0000040899*E38)+(0.000000076438*E38^2)-(0.00000000082467*E38^3)+(0.0000000000053875*E38^4))) -> 0.00078434025 | L38: =IF(ISBLANK(E38),"",(-0.00000572466+(0.00000010227*E38)-(0.0000000016546*E38^2))) -> -4.7170634e-06 | M38: =IF(ISBLANK(E38),"",IF(ISBLANK(G38),(O38+(K38*35)+(L38*35^1.5)+(0.00000048314*35^2)),(O38+(K38*G38)+(L38*G38^1.5)+(0.00000048314*G38^2)))) -> 1.0262648 | N38: =IF(ISBLANK(D38),"",IF(ISBLANK(G38),J38*(1+0.00001*(35-20)),J38*(1+0.00001*(G38-20)))) -> 108.88596 | O38: =IF(ISBLANK(E38),"",(0.999842594+(0.00006793952*E38)-(0.00000909529*E38^2)+(0.0000001001685*E38^3)-(0.000000001120083*E38^4)+(0.000000000006536332*E38^5))) -> 0.99946483 | P38: =IF(ISBLANK($R$16),"",IF(A38=0,"",IF(ISBLANK($R$17),"",IF(B38=0,"",IF($O$28=$I$29,"",IF(AND($I$29=$O$29,D38<1000),"N° Flac.",IF(AND($I$29=$O$30,D38>1000),"N° Flac.",IF(AND(D38>1202,D38<2001),"Err. N°",IF(AND(D38>499,D38<1141),"Err.N°",(((((F38)+'Correction de volume'!$G$7)*(($P$21)*($P$19)*5598)/(($R$16)-($R$17)))-(($P$27)*1000))/((N38)-($P$26)))))))))))) -> 2.709471 | Q38: =IF(ISBLANK($R$16),"",IF(A38=0,"",IF(ISBLANK($R$17),"",IF(AND(D38>1202,D38<2001),"Err. N°",IF(AND(D38>499,D38<1141),"Err.N°",IF(B38=0,"",IF($O$28=$I$29,"",IF(AND($I$29=$O$29,D38<1000),"N° Flac.",IF(AND($I$29=$O$30,D38>1000),"N° Flac.",P38/M38))))))))) -> 2.6401285 | R38: =IF(ISBLANK($R$16),"",IF(A38=0,"",IF(ISBLANK($R$17),"",IF(B38=0,"",IF(ISBLANK(J38),"",IF(AND(D38>1202,D38<2001),"Err. N°",IF(AND(D38>499,D38<1141),"Err.N°",IF($I$29=$O$28,"",IF(AND($I$29=$O$29,D38<1000),"N° Flac.",IF(AND($I$29=$O$30,D38>1000),"N° Flac.",((44.66*P38)))))))))))) -> 121.00498 | S38: =IF(ISBLANK($R$16),"",IF(A38=0,"",IF(ISBLANK($R$17),"",IF(B38=0,"",IF(ISBLANK(J38),"",IF(AND(D38>1202,D38<2001),"Err. N°",IF(AND(D38>499,D38<1141),"Err.N°",IF($I$29=$O$28,"",IF(AND($I$29=$O$29,D38<1000),"N° Flac.",IF(AND($I$29=$O$30,D38>1000),"N° Flac.",((44.66*P38)/M38))))))))))) -> 117.90814
A39: =IF(ISBLANK(VLOOKUP(D39,'Volumes flacons'!A5:C623,3)),0,1) -> 1 | B39: =IF(ISBLANK(D39),0,IF(ISBLANK(E39),0,IF(ISBLANK(F39),0,1))) -> 1 | C39: 5 | D39: 2007 | E39: 17.9 | F39: 2.497 | G39: 35.553 | H39: 100 | I39: 101 | J39: =IF(ISBLANK(D39),"",IF(VLOOKUP(D39,'Volumes flacons'!$A$5:$C$978,2)=0,"",IF(D39>'Volumes flacons'!$A$978,"Mauvais numéro",IF(D39<'Volumes flacons'!$A$5,"Mauvais numéro",(VLOOKUP(D39,'Volumes flacons'!$A$5:$C$978,3)))))) -> 109.77 | K39: =IF(ISBLANK(E39),"",(0.000824493-(0.0000040899*E39)+(0.000000076438*E39^2)-(0.00000000082467*E39^3)+(0.0000000000053875*E39^4))) -> 0.00077159862 | L39: =IF(ISBLANK(E39),"",(-0.00000572466+(0.00000010227*E39)-(0.0000000016546*E39^2))) -> -4.4241774e-06 | M39: =IF(ISBLANK(E39),"",IF(ISBLANK(G39),(O39+(K39*35)+(L39*35^1.5)+(0.00000048314*35^2)),(O39+(K39*G39)+(L39*G39^1.5)+(0.00000048314*G39^2)))) -> 1.0257215 | N39: =IF(ISBLANK(D39),"",IF(ISBLANK(G39),J39*(1+0.00001*(35-20)),J39*(1+0.00001*(G39-20)))) -> 109.78707 | O39: =IF(ISBLANK(E39),"",(0.999842594+(0.00006793952*E39)-(0.00000909529*E39^2)+(0.0000001001685*E39^3)-(0.000000001120083*E39^4)+(0.000000000006536332*E39^5))) -> 0.99861601 | P39: =IF(ISBLANK($R$16),"",IF(A39=0,"",IF(ISBLANK($R$17),"",IF(B39=0,"",IF($O$28=$I$29,"",IF(AND($I$29=$O$29,D39<1000),"N° Flac.",IF(AND($I$29=$O$30,D39>1000),"N° Flac.",IF(AND(D39>1202,D39<2001),"Err. N°",IF(AND(D39>499,D39<1141),"Err.N°",(((((F39)+'Correction de volume'!$G$7)*(($P$21)*($P$19)*5598)/(($R$16)-($R$17)))-(($P$27)*1000))/((N39)-($P$26)))))))))))) -> 2.593798 | Q39: =IF(ISBLANK($R$16),"",IF(A39=0,"",IF(ISBLANK($R$17),"",IF(AND(D39>1202,D39<2001),"Err. N°",IF(AND(D39>499,D39<1141),"Err.N°",IF(B39=0,"",IF($O$28=$I$29,"",IF(AND($I$29=$O$29,D39<1000),"N° Flac.",IF(AND($I$29=$O$30,D39>1000),"N° Flac.",P39/M39))))))))) -> 2.5287547 | R39: =IF(ISBLANK($R$16),"",IF(A39=0,"",IF(ISBLANK($R$17),"",IF(B39=0,"",IF(ISBLANK(J39),"",IF(AND(D39>1202,D39<2001),"Err. N°",IF(AND(D39>499,D39<1141),"Err.N°",IF($I$29=$O$28,"",IF(AND($I$29=$O$29,D39<1000),"N° Flac.",IF(AND($I$29=$O$30,D39>1000),"N° Flac.",((44.66*P39)))))))))))) -> 115.83902 | S39: =IF(ISBLANK($R$16),"",IF(A39=0,"",IF(ISBLANK($R$17),"",IF(B39=0,"",IF(ISBLANK(J39),"",IF(AND(D39>1202,D39<2001),"Err. N°",IF(AND(D39>499,D39<1141),"Err.N°",IF($I$29=$O$28,"",IF(AND($I$29=$O$29,D39<1000),"N° Flac.",IF(AND($I$29=$O$30,D39>1000),"N° Flac.",((44.66*P39)/M39))))))))))) -> 112.93419 | T39: 0 | U39: 0 | V39: 20 | W39: 19.6 | X39: 20 | Y39: 19.6 | Z39: 1.46 | AA39: 1.43 | AB39: 7.15 | AC39: 6.99 | AD39: 0.0099 | AE39: 0.0069 | AF39: -99999 | AG39: 0.0134 | AH39: 0.0072 | AI39: 0.0008 | AJ39: -99999 | AK39: -99999 | AL39: 0.0187 | AM39: 0.0017 | AN39: -99999 | AO39: -99999 | AP39: 0.001 | AR39: 0.016 | AS39: 0.0076 | AU39: 0.0054 | AV39: -99999 | AX39: 0.008 | AY39: 0.0361 | BA39: -99999
A40: =IF(ISBLANK(VLOOKUP(D40,'Volumes flacons'!A5:C623,3)),0,1) -> 1 | B40: =IF(ISBLANK(D40),0,IF(ISBLANK(E40),0,IF(ISBLANK(F40),0,1))) -> 1 | C40: 6 | D40: 2008 | E40: 18.4 | F40: 2.435 | G40: 35.617 | H40: 80 | I40: 81.9 | J40: =IF(ISBLANK(D40),"",IF(VLOOKUP(D40,'Volumes flacons'!$A$5:$C$978,2)=0,"",IF(D40>'Volumes flacons'!$A$978,"Mauvais numéro",IF(D40<'Volumes flacons'!$A$5,"Mauvais numéro",(VLOOKUP(D40,'Volumes flacons'!$A$5:$C$978,3)))))) -> 108.85 | K40: =IF(ISBLANK(E40),"",(0.000824493-(0.0000040899*E40)+(0.000000076438*E40^2)-(0.00000000082467*E40^3)+(0.0000000000053875*E40^4))) -> 0.00077059793 | L40: =IF(ISBLANK(E40),"",(-0.00000572466+(0.00000010227*E40)-(0.0000000016546*E40^2))) -> -4.4030734e-06 | M40: =IF(ISBLANK(E40),"",IF(ISBLANK(G40),(O40+(K40*35)+(L40*35^1.5)+(0.00000048314*35^2)),(O40+(K40*G40)+(L40*G40^1.5)+(0.00000048314*G40^2)))) -> 1.0256461 | N40: =IF(ISBLANK(D40),"",IF(ISBLANK(G40),J40*(1+0.00001*(35-20)),J40*(1+0.00001*(G40-20)))) -> 108.867 | O40: =IF(ISBLANK(E40),"",(0.999842594+(0.00006793952*E40)-(0.00000909529*E40^2)+(0.0000001001685*E40^3)-(0.000000001120083*E40^4)+(0.000000000006536332*E40^5))) -> 0.99852278 | P40: =IF(ISBLANK($R$16),"",IF(A40=0,"",IF(ISBLANK($R$17),"",IF(B40=0,"",IF($O$28=$I$29,"",IF(AND($I$29=$O$29,D40<1000),"N° Flac.",IF(AND($I$29=$O$30,D40>1000),"N° Flac.",IF(AND(D40>1202,D40<2001),"Err. N°",IF(AND(D40>499,D40<1141),"Err.N°",(((((F40)+'Correction de volume'!$G$7)*(($P$21)*($P$19)*5598)/(($R$16)-($R$17)))-(($P$27)*1000))/((N40)-($P$26)))))))))))) -> 2.5507758 | Q40: =IF(ISBLANK($R$16),"",IF(A40=0,"",IF(ISBLANK($R$17),"",IF(AND(D40>1202,D40<2001),"Err. N°",IF(AND(D40>499,D40<1141),"Err.N°",IF(B40=0,"",IF($O$28=$I$29,"",IF(AND($I$29=$O$29,D40<1000),"N° Flac.",IF(AND($I$29=$O$30,D40>1000),"N° Flac.",P40/M40))))))))) -> 2.486994 | R40: =IF(ISBLANK($R$16),"",IF(A40=0,"",IF(ISBLANK($R$17),"",IF(B40=0,"",IF(ISBLANK(J40),"",IF(AND(D40>1202,D40<2001),"Err. N°",IF(AND(D40>499,D40<1141),"Err.N°",IF($I$29=$O$28,"",IF(AND($I$29=$O$29,D40<1000),"N° Flac.",IF(AND($I$29=$O$30,D40>1000),"N° Flac.",((44.66*P40)))))))))))) -> 113.91765 | S40: =IF(ISBLANK($R$16),"",IF(A40=0,"",IF(ISBLANK($R$17),"",IF(B40=0,"",IF(ISBLANK(J40),"",IF(AND(D40>1202,D40<2001),"Err. N°",IF(AND(D40>499,D40<1141),"Err.N°",IF($I$29=$O$28,"",IF(AND($I$29=$O$29,D40<1000),"N° Flac.",IF(AND($I$29=$O$30,D40>1000),"N° Flac.",((44.66*P40)/M40))))))))))) -> 111.06915 | T40: 0.03 | U40: 0.03 | V40: 18.4 | W40: 18 | X40: 18.4 | Y40: 17.9 | Z40: 1.31 | AA40: 1.28 | AB40: 5.96 | AC40: 5.83 | AD40: 0.0219 | AE40: 0.0142 | AF40: -99999 | AG40: 0.0325 | AH40: 0.0124 | AI40: 0.0014 | AJ40: 0.0016 | AK40: 0.0008 | AL40: 0.0359 | AM40: 0.0032 | AN40: -99999 | AO40: -99999 | AP40: 0.0095 | AR40: 0.0714 | AS40: 0.0269 | AU40: 0.021 | AV40: -99999 | AX40: 0.0387 | AY40: 0.0937 | BA40: -99999
A41: =IF(ISBLANK(VLOOKUP(D41,'Volumes flacons'!A5:C623,3)),0,1) -> 1 | B41: =IF(ISBLANK(D41),0,IF(ISBLANK(E41),0,IF(ISBLANK(F41),0,1))) -> 1 | C41: 7 | D41: 2009 | E41: 20.3 | F41: 2.473 | G41: 35.751 | H41: 60 | I41: 61 | J41: =IF(ISBLANK(D41),"",IF(VLOOKUP(D41,'Volumes flacons'!$A$5:$C$978,2)=0,"",IF(D41>'Volumes flacons'!$A$978,"Mauvais numéro",IF(D41<'Volumes flacons'!$A$5,"Mauvais numéro",(VLOOKUP(D41,'Volumes flacons'!$A$5:$C$978,3)))))) -> 109.15 | K41: =IF(ISBLANK(E41),"",(0.000824493-(0.0000040899*E41)+(0.000000076438*E41^2)-(0.00000000082467*E41^3)+(0.0000000000053875*E41^4))) -> 0.00076698354 | L41: =IF(ISBLANK(E41),"",(-0.00000572466+(0.00000010227*E41)-(0.0000000016546*E41^2))) -> -4.3304231e-06 | M41: =IF(ISBLANK(E41),"",IF(ISBLANK(G41),(O41+(K41*35)+(L41*35^1.5)+(0.00000048314*35^2)),(O41+(K41*G41)+(L41*G41^1.5)+(0.00000048314*G41^2)))) -> 1.0252562 | N41: =IF(ISBLANK(D41),"",IF(ISBLANK(G41),J41*(1+0.00001*(35-20)),J41*(1+0.00001*(G41-20)))) -> 109.16719 | O41: =IF(ISBLANK(E41),"",(0.999842594+(0.00006793952*E41)-(0.00000909529*E41^2)+(0.0000001001685*E41^3)-(0.000000001120083*E41^4)+(0.000000000006536332*E41^5))) -> 0.99814396 | P41: =IF(ISBLANK($R$16),"",IF(A41=0,"",IF(ISBLANK($R$17),"",IF(B41=0,"",IF($O$28=$I$29,"",IF(AND($I$29=$O$29,D41<1000),"N° Flac.",IF(AND($I$29=$O$30,D41>1000),"N° Flac.",IF(AND(D41>1202,D41<2001),"Err. N°",IF(AND(D41>499,D41<1141),"Err.N°",(((((F41)+'Correction de volume'!$G$7)*(($P$21)*($P$19)*5598)/(($R$16)-($R$17)))-(($P$27)*1000))/((N41)-($P$26)))))))))))) -> 2.5835749 | Q41: =IF(ISBLANK($R$16),"",IF(A41=0,"",IF(ISBLANK($R$17),"",IF(AND(D41>1202,D41<2001),"Err. N°",IF(AND(D41>499,D41<1141),"Err.N°",IF(B41=0,"",IF($O$28=$I$29,"",IF(AND($I$29=$O$29,D41<1000),"N° Flac.",IF(AND($I$29=$O$30,D41>1000),"N° Flac.",P41/M41))))))))) -> 2.5199309 | R41: =IF(ISBLANK($R$16),"",IF(A41=0,"",IF(ISBLANK($R$17),"",IF(B41=0,"",IF(ISBLANK(J41),"",IF(AND(D41>1202,D41<2001),"Err. N°",IF(AND(D41>499,D41<1141),"Err.N°",IF($I$29=$O$28,"",IF(AND($I$29=$O$29,D41<1000),"N° Flac.",IF(AND($I$29=$O$30,D41>1000),"N° Flac.",((44.66*P41)))))))))))) -> 115.38245 | S41: =IF(ISBLANK($R$16),"",IF(A41=0,"",IF(ISBLANK($R$17),"",IF(B41=0,"",IF(ISBLANK(J41),"",IF(AND(D41>1202,D41<2001),"Err. N°",IF(AND(D41>499,D41<1141),"Err.N°",IF($I$29=$O$28,"",IF(AND($I$29=$O$29,D41<1000),"N° Flac.",IF(AND($I$29=$O$30,D41>1000),"N° Flac.",((44.66*P41)/M41))))))))))) -> 112.54011 | T41: 0.1 | U41: 0.09 | V41: 15.1 | W41: 14.8 | X41: 15 | Y41: 14.7 | Z41: 1.03 | AA41: 1 | AB41: 4.13 | AC41: 4.03 | AD41: 0.0463 | AE41: 0.0402 | AF41: 0.0068 | AG41: 0.0735 | AH41: 0.0248 | AI41: 0.0079 | AJ41: 0.0119 | AK41: 0.0043 | AL41: 0.0905 | AM41: 0.0086 | AN41: 0.0056 | AO41: -99999 | AP41: 0.0342 | AR41: 0.0593 | AS41: 0.1234 | AU41: 0.0326 | AV41: -99999 | AX41: 0.0656 | AY41: 0.3284 | BA41: -99999
A42: =IF(ISBLANK(VLOOKUP(D42,'Volumes flacons'!A5:C623,3)),0,1) -> 1 | B42: =IF(ISBLANK(D42),0,IF(ISBLANK(E42),0,IF(ISBLANK(F42),0,1))) -> 1 | C42: 8 | D42: 2010 | E42: 26.3 | F42: 3.939 | G42: 36.261 | H42: 40 | I42: 41 | J42: =IF(ISBLANK(D42),"",IF(VLOOKUP(D42,'Volumes flacons'!$A$5:$C$978,2)=0,"",IF(D42>'Volumes flacons'!$A$978,"Mauvais numéro",IF(D42<'Volumes flacons'!$A$5,"Mauvais numéro",(VLOOKUP(D42,'Volumes flacons'!$A$5:$C$978,3)))))) -> 109.42 | K42: =IF(ISBLANK(E42),"",(0.000824493-(0.0000040899*E42)+(0.000000076438*E42^2)-(0.00000000082467*E42^3)+(0.0000000000053875*E42^4))) -> 0.00075737566 | L42: =IF(ISBLANK(E42),"",(-0.00000572466+(0.00000010227*E42)-(0.0000000016546*E42^2))) -> -4.1794293e-06 | M42: =IF(ISBLANK(E42),"",IF(ISBLANK(G42),(O42+(K42*35)+(L42*35^1.5)+(0.00000048314*35^2)),(O42+(K42*G42)+(L42*G42^1.5)+(0.00000048314*G42^2)))) -> 1.0238927 | N42: =IF(ISBLANK(D42),"",IF(ISBLANK(G42),J42*(1+0.00001*(35-20)),J42*(1+0.00001*(G42-20)))) -> 109.43779 | O42: =IF(ISBLANK(E42),"",(0.999842594+(0.00006793952*E42)-(0.00000909529*E42^2)+(0.0000001001685*E42^3)-(0.000000001120083*E42^4)+(0.000000000006536332*E42^5))) -> 0.99670685 | P42: =IF(ISBLANK($R$16),"",IF(A42=0,"",IF(ISBLANK($R$17),"",IF(B42=0,"",IF($O$28=$I$29,"",IF(AND($I$29=$O$29,D42<1000),"N° Flac.",IF(AND($I$29=$O$30,D42>1000),"N° Flac.",IF(AND(D42>1202,D42<2001),"Err. N°",IF(AND(D42>499,D42<1141),"Err.N°",(((((F42)+'Correction de volume'!$G$7)*(($P$21)*($P$19)*5598)/(($R$16)-($R$17)))-(($P$27)*1000))/((N42)-($P$26)))))))))))) -> 4.1142323 | Q42: =IF(ISBLANK($R$16),"",IF(A42=0,"",IF(ISBLANK($R$17),"",IF(AND(D42>1202,D42<2001),"Err. N°",IF(AND(D42>499,D42<1141),"Err.N°",IF(B42=0,"",IF($O$28=$I$29,"",IF(AND($I$29=$O$29,D42<1000),"N° Flac.",IF(AND($I$29=$O$30,D42>1000),"N° Flac.",P42/M42))))))))) -> 4.0182259 | R42: =IF(ISBLANK($R$16),"",IF(A42=0,"",IF(ISBLANK($R$17),"",IF(B42=0,"",IF(ISBLANK(J42),"",IF(AND(D42>1202,D42<2001),"Err. N°",IF(AND(D42>499,D42<1141),"Err.N°",IF($I$29=$O$28,"",IF(AND($I$29=$O$29,D42<1000),"N° Flac.",IF(AND($I$29=$O$30,D42>1000),"N° Flac.",((44.66*P42)))))))))))) -> 183.74161 | S42: =IF(ISBLANK($R$16),"",IF(A42=0,"",IF(ISBLANK($R$17),"",IF(B42=0,"",IF(ISBLANK(J42),"",IF(AND(D42>1202,D42<2001),"Err. N°",IF(AND(D42>499,D42<1141),"Err.N°",IF($I$29=$O$28,"",IF(AND($I$29=$O$29,D42<1000),"N° Flac.",IF(AND($I$29=$O$30,D42>1000),"N° Flac.",((44.66*P42)/M42))))))))))) -> 179.45397 | T42: 0.14 | U42: 0.14 | V42: 1.57 | W42: 1.53 | X42: 1.43 | Y42: 1.39 | Z42: 0.21 | AA42: 0.2 | AB42: 1.69 | AC42: 1.65 | AD42: 0.0236 | AE42: 0.0279 | AF42: 0.0066 | AG42: 0.0304 | AH42: 0.0113 | AI42: 0.0037 | AJ42: 0.0058 | AK42: 0.004 | AL42: 0.0767 | AM42: 0.0085 | AN42: 0.0061 | AO42: -99999 | AP42: 0.1042 | AR42: 0.0832 | AS42: -99999 | AU42: 0.0449 | AV42: -99999 | AX42: 0.1147 | AY42: 0.2506 | BA42: -99999
