Workbook

Sheet 001_01
C2: Campagne : | F2: PIRATA Fr26
C4: Données de campagne
C6: N° de station : | F6: 1 | H6: N° de palanquée : | P6: 1 | R6: Date d'analyse : | T6: 40979
G8: Position | I8: Degrés | J8: Minutes | P8: Cardinal | Q8: Décimale
G9: Latitude | I9: 11 | J9: 27.953 | K9: : | L9: =IF(P9=M9,"+","-") -> + | M9: N | N9: E | O9: =IF(ISBLANK(I9),"",IF(ISBLANK(J9),"",IF(P9=M10,L9&N11,N11))) -> 11°27,953 | P9: N | Q9: =IF(ISBLANK(I9),"",IF(ISBLANK(J9),"",IF(J9>60,"ERREUR !!",O11*(I9+(J9/60))))) -> 11.465883
G10: Longitude | I10: 23 | J10: 0 | K10: : | L10: =IF(P10=N9,"+","-") -> - | M10: S | N10: W | O10: =IF(ISBLANK(I10),"",IF(ISBLANK(J10),"",IF(P10=N10,L10&N12,N12))) -> -23°0 | P10: W | Q10: =IF(ISBLANK(I10),"",IF(ISBLANK(J10),"",IF(J10>60,"ERREUR !!",O12*(I10+(J10/60))))) -> -23
G11: Prélèvement | I11: Date | J11: 40976 | N11: =I9&"°"&J9 -> 11°27,953 | O11: =IF(P9=M10,-1,1) -> 1 | P11: =TEXT(J11,"aaaa-mm-jj")&"T"&TEXT(J12,"hh:mm:ss")&"z" -> 2016-03-09T19:43:00z
I12: Heure | J12: 0.82152778 | N12: =I10&"°"&J10 -> 23°0 | O12: =IF(P10=N10,-1,1) -> -1
C13: Données :
C14: Température du laboratoire à la calibration ( t°c ) | Q14: t°c = | R14: 23 | S14: °C
C15: Température du laboratoire au début de la série d'analyses | Q15: t°lab = | R15: 23.2 | S15: °C
C16: Volume moyen de thiosulfate pour la titration à t°c | Q16: Vmoy.titr.t°c = | R16: 4.975 | S16: mL
C17: Volume moyen de thiosulfate pour la détermination du blanc à t°c | Q17: Vmoy.titr.blanc.t°c = | R17: 0.005 | S17: mL
C18: Masse volumique de l'eau pure à la calibration | O18: ρ = | P18: =(0.999842594+(0.00006793952*$R$14)-(0.00000909529*$R$14^2)+(0.0000001001685*$R$14^3)-(0.000000001120083*$R$14^4)+(0.000000000006536332*$R$14^5)) -> 0.99754117
C19: Normalite de l'iodate (NIO3) à la température de calibration | O19: N(IO3) = | P19: =$P$24*($P$18/'Titre d''iodate'!E19) -> 0.019982863 | Q19: N
C20: Vol. de la prise d'essai d'iodate (VIO3) à 20°C | O20: V(IO3)20°C = | P20: =5+'Correction de volume'!G8 -> 5.00309 | Q20: mL
C21: Vol. de la prise d'essai d'iodate (VIO3) à t°c | O21: V(IO3)t°c= | P21: =P20*(1+0.00001*(R14-20)) -> 5.0032401 | Q21: mL
C22: Volume moyen de thiosulfate pour la titration à 20° C | O22: Vmoy.titr.20°C = | P22: =$R$16*(1+0.00001*(20-$R$14)) -> 4.9748507 | Q22: mL
C23: Volume moyen de thiosulfate pour la détermination du blanc à 20° C | O23: Vmoy.titr.blanc.20°C = | P23: =$R$17*(1+0.00001*(20-$R$14)) -> 0.00499985 | Q23: mL
C24: Normalite de l'iodate (NIO3) à 20°C | O24: N(IO3)20°C = | P24: =MAX('Titre d''iodate'!F7:F10) -> 0.019996187 | Q24: N
C25: Titre du thiosulfate à 20°C | O25: V(Thio)20°C = | P25: =IF(ISBLANK(R14),"",IF(ISBLANK(P21),"",IF(ISBLANK(R17),"",(($P$24*$P$18)/($P$22-$P$23))))) -> 0.0040136053 | Q25: N
C26: Volume de réactif utilisé | O26: Vreg = | P26: =2+('Correction de volume'!G10+'Correction de volume'!G9) -> 2.016394 | Q26: mL
O27: DOreg = | P27: 0.0017
E29: Choix de la série de flacons : | I29: IRD | O29: IRD
O30: LPO
C31: N° | D31: N° des Flacons | E31: T° prélèv. | F31: Volume de thio. | G31: Salinité | H31: Prof. Théorique | I31: Prof. Effective | J31: V. flacons 20°C | K31: A | L31: B | M31: Densité eau de mer à t° | N31: Vol. à t° prél. des flacons | O31: Densité eau pure à t° | P31: Oxygène dissous | T31: NO2 | V31: NO3 + NO2 | X31: NO3 | Z31: Phosphate | AB31: Silicate | AD31: chlorophyll-c3 | AE31: chlorophyll-c1+c2 | AF31: peridinin | AG31: 19'-butanoyloxyfucoxanthin | AH31: fucoxanthine | AI31: neoxanthin | AJ31: prasinoxanthin | AK31: violaxanthin | AL31: 19'-hexanoyloxyfucoxanthin | AM31: diadinoxanthin | AN31: alloxanthin | AO31: diatoxanthin | AP31: zeaxanthin | AQ31: lutein | AR31: divinyl chlorophyll-b | AS31: chlorophyll-b | AT31: total chlorophyll-b | AU31: alpha-carotene | AV31: beta-carotene | AW31: pheophorbide | AX31: divinyl chlorophyll-a | AY31: chlorophyll-a | AZ31: total chlorophyll-a | BA31: pheophytin_a | BB31: crocoxanthin
C33: BTL | E33: °C | F33: ml | H33: m | I33: m | J33: ml | P33: DOX1 | R33: DOXY | S33: DOX2 | T33: NTRI | U33: NTIW | V33: NTRZ | W33: NTZW | X33: NTRA | Y33: NTAW | Z33: PHOS | AA33: PHOW | AB33: SLCA | AC33: SLCW | AD33: CHC3 | AE33: CHCZ | AF33: PERP | AG33: BFUP | AH33: FUCP | AI33: NEXW | AJ33: PXAP | AK33: VIOW | AL33: HFUP | AM33: DXAP | AN33: AXAP | AO33: TXAP | AP33: ZXAP | AQ33: LUTW | AR33: CHBD | AS33: CH2P | AT33: CHLB | AU33: AACP | AV33: BBCP | AW33: PHEP | AX33: CHAD | AY33: CH1P | AZ33: CPHL | BA33: PHEA | BB33: CXAP
N34: mL | P34: ml/l | Q34: ml/kg | R34: µmol/l | S34: µmol/kg | T34: µmol/l | U34: µmol/kg | V34: µmol/l | W34: µmol/kg | X34: µmol/l | Y34: µmol/kg | Z34: µmol/l | AA34: µmol/kg | AB34: µmol/l | AC34: µmol/kg | AD34: µg.l-1 | AE34: µg.l-1 | AF34: µg.l-1 | AG34: µg.l-1 | AH34: µg.l-1 | AI34: µg.l-1 | AJ34: µg.l-1 | AK34: µg.l-1 | AL34: µg.l-1 | AM34: µg.l-1 | AN34: µg.l-1 | AO34: µg.l-1 | AP34: µg.l-1 | AQ34: µg.l-1 | AR34: µg.l-1 | AS34: µg.l-1 | AT34: µg.l-1 | AU34: µg.l-1 | AV34: µg.l-1 | AW34: µg.l-1 | AX34: µg.l-1 | AY34: µg.l-1 | AZ34: µg.l-1 | BA34: µg.l-1 | BB34: µg.l-1
A35: =IF(ISBLANK(VLOOKUP(D35,'Volumes flacons'!A5:C623,3)),0,1) -> 1 | B35: =IF(ISBLANK(D35),0,IF(ISBLANK(E35),0,IF(ISBLANK(F35),0,1))) -> 1 | C35: 1 | D35: 2122 | E35: 6.5 | F35: 5.213 | G35: 34.9635 | H35: 2000 | I35: 2021 | J35: 109.007 | K35: =IF(ISBLANK(E35),"",(0.000824493-(0.0000040899*E35)+(0.000000076438*E35^2)-(0.00000000082467*E35^3)+(0.0000000000053875*E35^4))) -> 0.0008009213 | L35: =IF(ISBLANK(E35),"",(-0.00000572466+(0.00000010227*E35)-(0.0000000016546*E35^2))) -> -5.1298118e-06 | M35: =IF(ISBLANK(E35),"",IF(ISBLANK(G35),(O35+(K35*35)+(L35*35^1.5)+(0.00000048314*35^2)),(O35+(K35*G35)+(L35*G35^1.5)+(0.00000048314*G35^2)))) -> 1.0274586 | N35: =IF(ISBLANK(D35),"",IF(ISBLANK(G35),J35*(1+0.00001*(35-20)),J35*(1+0.00001*(G35-20)))) -> 109.02331 | O35: =IF(ISBLANK(E35),"",(0.999842594+(0.00006793952*E35)-(0.00000909529*E35^2)+(0.0000001001685*E35^3)-(0.000000001120083*E35^4)+(0.000000000006536332*E35^5))) -> 0.99992551 | P35: 5.47 | Q35: 5.324 | R35: 244.3 | S35: 237.8 | T35: 0 | U35: 0 | V35: 20 | W35: 19.5 | X35: 20 | Y35: 19.5 | Z35: 1.28 | AA35: 1.25 | AB35: 22.8 | AC35: 22.2
A36: =IF(ISBLANK(VLOOKUP(D36,'Volumes flacons'!A5:C623,3)),0,1) -> 1 | B36: =IF(ISBLANK(D36),0,IF(ISBLANK(E36),0,IF(ISBLANK(F36),0,1))) -> 1 | C36: 2 | D36: 2100 | E36: 5.8 | F36: 5.292 | G36: 34.9635 | H36: 2000 | I36: 2021 | J36: 110.746 | K36: =IF(ISBLANK(E36),"",(0.000824493-(0.0000040899*E36)+(0.000000076438*E36^2)-(0.00000000082467*E36^3)+(0.0000000000053875*E36^4))) -> 0.00080318815 | L36: =IF(ISBLANK(E36),"",(-0.00000572466+(0.00000010227*E36)-(0.0000000016546*E36^2))) -> -5.1871547e-06 | M36: =IF(ISBLANK(E36),"",IF(ISBLANK(G36),(O36+(K36*35)+(L36*35^1.5)+(0.00000048314*35^2)),(O36+(K36*G36)+(L36*G36^1.5)+(0.00000048314*G36^2)))) -> 1.0275495 | N36: =IF(ISBLANK(D36),"",IF(ISBLANK(G36),J36*(1+0.00001*(35-20)),J36*(1+0.00001*(G36-20)))) -> 110.76257 | O36: =IF(ISBLANK(E36),"",(0.999842594+(0.00006793952*E36)-(0.00000909529*E36^2)+(0.0000001001685*E36^3)-(0.000000001120083*E36^4)+(0.000000000006536332*E36^5))) -> 0.999949 | P36: 5.464 | Q36: 5.318 | R36: 244 | S36: 237.5 | T36: 0 | U36: 0 | V36: 20 | W36: 19.5 | X36: 20 | Y36: 19.5 | Z36: 1.4 | AA36: 1.36 | AB36: 23.5 | AC36: 22.9
A37: =IF(ISBLANK(VLOOKUP(D37,'Volumes flacons'!A5:C623,3)),0,1) -> 1 | B37: =IF(ISBLANK(D37),0,IF(ISBLANK(E37),0,IF(ISBLANK(F37),0,1))) -> 1 | C37: 3 | D37: 2101 | E37: 6.5 | F37: 5.109 | G37: 34.9653 | H37: 2000 | I37: 2021 | J37: 106.838 | K37: =IF(ISBLANK(E37),"",(0.000824493-(0.0000040899*E37)+(0.000000076438*E37^2)-(0.00000000082467*E37^3)+(0.0000000000053875*E37^4))) -> 0.0008009213 | L37: =IF(ISBLANK(E37),"",(-0.00000572466+(0.00000010227*E37)-(0.0000000016546*E37^2))) -> -5.1298118e-06 | M37: =IF(ISBLANK(E37),"",IF(ISBLANK(G37),(O37+(K37*35)+(L37*35^1.5)+(0.00000048314*35^2)),(O37+(K37*G37)+(L37*G37^1.5)+(0.00000048314*G37^2)))) -> 1.02746 | N37: =IF(ISBLANK(D37),"",IF(ISBLANK(G37),J37*(1+0.00001*(35-20)),J37*(1+0.00001*(G37-20)))) -> 106.85399 | O37: =IF(ISBLANK(E37),"",(0.999842594+(0.00006793952*E37)-(0.00000909529*E37^2)+(0.0000001001685*E37^3)-(0.000000001120083*E37^4)+(0.000000000006536332*E37^5))) -> 0.99992551 | P37: 5.472 | Q37: 5.325 | R37: 244.4 | S37: 237.8 | T37: 0 | U37: 0 | V37: 19.9 | W37: 19.4 | X37: 19.9 | Y37: 19.4 | Z37: 1.45 | AA37: 1.41 | AB37: 23.5 | AC37: 22.9
A38: =IF(ISBLANK(VLOOKUP(D38,'Volumes flacons'!A5:C623,3)),0,1) -> 1 | B38: =IF(ISBLANK(D38),0,IF(ISBLANK(E38),0,IF(ISBLANK(F38),0,1))) -> 1 | C38: 4 | D38: 2102 | E38: 6.6 | F38: 5.335 | G38: 34.9671 | H38: 2000 | I38: 2021 | J38: 111.55 | K38: =IF(ISBLANK(E38),"",(0.000824493-(0.0000040899*E38)+(0.000000076438*E38^2)-(0.00000000082467*E38^3)+(0.0000000000053875*E38^4))) -> 0.00080060243 | L38: =IF(ISBLANK(E38),"",(-0.00000572466+(0.00000010227*E38)-(0.0000000016546*E38^2))) -> -5.1217524e-06 | M38: =IF(ISBLANK(E38),"",IF(ISBLANK(G38),(O38+(K38*35)+(L38*35^1.5)+(0.00000048314*35^2)),(O38+(K38*G38)+(L38*G38^1.5)+(0.00000048314*G38^2)))) -> 1.027448 | N38: =IF(ISBLANK(D38),"",IF(ISBLANK(G38),J38*(1+0.00001*(35-20)),J38*(1+0.00001*(G38-20)))) -> 111.5667 | O38: =IF(ISBLANK(E38),"",(0.999842594+(0.00006793952*E38)-(0.00000909529*E38^2)+(0.0000001001685*E38^3)-(0.000000001120083*E38^4)+(0.000000000006536332*E38^5))) -> 0.99992156 | P38: 5.468 | Q38: 5.322 | R38: 244.2 | S38: 237.7 | T38: 0 | U38: 0 | V38: 20 | W38: 19.5 | X38: 20 | Y38: 19.5 | Z38: 1.46 | AA38: 1.42 | AB38: 23.5 | AC38: 22.9
A39: =IF(ISBLANK(VLOOKUP(D39,'Volumes flacons'!A5:C623,3)),0,1) -> 1 | B39: =IF(ISBLANK(D39),0,IF(ISBLANK(E39),0,IF(ISBLANK(F39),0,1))) -> 1 | C39: 5 | D39: 2103 | E39: 6.8 | F39: 5.14 | G39: 34.9655 | H39: 2000 | I39: 2021 | J39: 107.335 | K39: =IF(ISBLANK(E39),"",(0.000824493-(0.0000040899*E39)+(0.000000076438*E39^2)-(0.00000000082467*E39^3)+(0.0000000000053875*E39^4))) -> 0.00079996839 | L39: =IF(ISBLANK(E39),"",(-0.00000572466+(0.00000010227*E39)-(0.0000000016546*E39^2))) -> -5.1057327e-06 | M39: =IF(ISBLANK(E39),"",IF(ISBLANK(G39),(O39+(K39*35)+(L39*35^1.5)+(0.00000048314*35^2)),(O39+(K39*G39)+(L39*G39^1.5)+(0.00000048314*G39^2)))) -> 1.0274195 | N39: =IF(ISBLANK(D39),"",IF(ISBLANK(G39),J39*(1+0.00001*(35-20)),J39*(1+0.00001*(G39-20)))) -> 107.35106 | O39: =IF(ISBLANK(E39),"",(0.999842594+(0.00006793952*E39)-(0.00000909529*E39^2)+(0.0000001001685*E39^3)-(0.000000001120083*E39^4)+(0.000000000006536332*E39^5))) -> 0.99991321 | P39: 5.479 | Q39: 5.333 | R39: 244.7 | S39: 238.2 | T39: 0 | U39: 0 | V39: 20 | W39: 19.5 | X39: 20 | Y39: 19.5 | Z39: 1.48 | AA39: 1.44 | AB39: 23.6 | AC39: 23
A40: =IF(ISBLANK(VLOOKUP(D40,'Volumes flacons'!A5:C623,3)),0,1) -> 1 | B40: =IF(ISBLANK(D40),0,IF(ISBLANK(E40),0,IF(ISBLANK(F40),0,1))) -> 1 | C40: 6 | D40: 2104 | E40: 7.2 | F40: 5.22 | G40: 34.9643 | H40: 2000 | I40: 2021 | J40: 109.069 | K40: =IF(ISBLANK(E40),"",(0.000824493-(0.0000040899*E40)+(0.000000076438*E40^2)-(0.00000000082467*E40^3)+(0.0000000000053875*E40^4))) -> 0.00079871494 | L40: =IF(ISBLANK(E40),"",(-0.00000572466+(0.00000010227*E40)-(0.0000000016546*E40^2))) -> -5.0740905e-06 | M40: =IF(ISBLANK(E40),"",IF(ISBLANK(G40),(O40+(K40*35)+(L40*35^1.5)+(0.00000048314*35^2)),(O40+(K40*G40)+(L40*G40^1.5)+(0.00000048314*G40^2)))) -> 1.0273629 | N40: =IF(ISBLANK(D40),"",IF(ISBLANK(G40),J40*(1+0.00001*(35-20)),J40*(1+0.00001*(G40-20)))) -> 109.08532 | O40: =IF(ISBLANK(E40),"",(0.999842594+(0.00006793952*E40)-(0.00000909529*E40^2)+(0.0000001001685*E40^3)-(0.000000001120083*E40^4)+(0.000000000006536332*E40^5))) -> 0.99989476 | P40: 5.474 | Q40: 5.328 | R40: 244.5 | S40: 238 | T40: 0 | U40: 0 | V40: 20.1 | W40: 19.6 | X40: 20.1 | Y40: 19.6 | Z40: 1.47 | AA40: 1.43 | AB40: 23.8 | AC40: 23.2
A41: =IF(ISBLANK(VLOOKUP(D41,'Volumes flacons'!A5:C623,3)),0,1) -> 1 | B41: =IF(ISBLANK(D41),0,IF(ISBLANK(E41),0,IF(ISBLANK(F41),0,1))) -> 1 | C41: 7 | D41: 2105 | E41: 7.3 | F41: 5.285 | G41: 34.9667 | H41: 2000 | I41: 2021 | J41: 110.493 | K41: =IF(ISBLANK(E41),"",(0.000824493-(0.0000040899*E41)+(0.000000076438*E41^2)-(0.00000000082467*E41^3)+(0.0000000000053875*E41^4))) -> 0.0007984046 | L41: =IF(ISBLANK(E41),"",(-0.00000572466+(0.00000010227*E41)-(0.0000000016546*E41^2))) -> -5.0662626e-06 | M41: =IF(ISBLANK(E41),"",IF(ISBLANK(G41),(O41+(K41*35)+(L41*35^1.5)+(0.00000048314*35^2)),(O41+(K41*G41)+(L41*G41^1.5)+(0.00000048314*G41^2)))) -> 1.0273505 | N41: =IF(ISBLANK(D41),"",IF(ISBLANK(G41),J41*(1+0.00001*(35-20)),J41*(1+0.00001*(G41-20)))) -> 110.50954 | O41: =IF(ISBLANK(E41),"",(0.999842594+(0.00006793952*E41)-(0.00000909529*E41^2)+(0.0000001001685*E41^3)-(0.000000001120083*E41^4)+(0.000000000006536332*E41^5))) -> 0.99988979 | P41: 5.47 | Q41: 5.324 | R41: 244.3 | S41: 237.8 | T41: 0 | U41: 0 | V41: 20 | W41: 19.5 | X41: 20 | Y41: 19.5 | Z41: 1.48 | AA41: 1.44 | AB41: 23.6 | AC41: 23
A42: =IF(ISBLANK(VLOOKUP(D42,'Volumes flacons'!A5:C623,3)),0,1) -> 1 | B42: =IF(ISBLANK(D42),0,IF(ISBLANK(E42),0,IF(ISBLANK(F42),0,1))) -> 1 | C42: 8 | D42: 2106 | E42: 7.6 | F42: 5.216 | G42: 34.9655 | H42: 2000 | I42: 2021 | J42: 109.009 | K42: =IF(ISBLANK(E42),"",(0.000824493-(0.0000040899*E42)+(0.000000076438*E42^2)-(0.00000000082467*E42^3)+(0.0000000000053875*E42^4))) -> 0.00079748078 | L42: =IF(ISBLANK(E42),"",(-0.00000572466+(0.00000010227*E42)-(0.0000000016546*E42^2))) -> -5.0429777e-06 | M42: =IF(ISBLANK(E42),"",IF(ISBLANK(G42),(O42+(K42*35)+(L42*35^1.5)+(0.00000048314*35^2)),(O42+(K42*G42)+(L42*G42^1.5)+(0.00000048314*G42^2)))) -> 1.0273063 | N42: =IF(ISBLANK(D42),"",IF(ISBLANK(G42),J42*(1+0.00001*(35-20)),J42*(1+0.00001*(G42-20)))) -> 109.02531 | O42: =IF(ISBLANK(E42),"",(0.999842594+(0.00006793952*E42)-(0.00000909529*E42^2)+(0.0000001001685*E42^3)-(0.000000001120083*E42^4)+(0.000000000006536332*E42^5))) -> 0.99987399 | P42: 5.473 | Q42: 5.328 | R42: 244.4 | S42: 237.9 | T42: 0 | U42: 0 | V42: 19.9 | W42: 19.4 | X42: 19.9 | Y42: 19.4 | Z42: 1.48 | AA42: 1.44 | AB42: 23.5 | AC42: 22.9
A43: =IF(ISBLANK(VLOOKUP(D43,'Volumes flacons'!A5:C623,3)),0,1) -> 1 | B43: =IF(ISBLANK(D43),0,IF(ISBLANK(E43),0,IF(ISBLANK(F43),0,1))) -> 1 | C43: 9 | D43: 2107 | E43: 7.7 | F43: 5.256 | G43: 34.9654 | H43: 2000 | I43: 2021 | J43: 109.899 | K43: =IF(ISBLANK(E43),"",(0.000824493-(0.0000040899*E43)+(0.000000076438*E43^2)-(0.00000000082467*E43^3)+(0.0000000000053875*E43^4))) -> 0.00079717523 | L43: =IF(ISBLANK(E43),"",(-0.00000572466+(0.00000010227*E43)-(0.0000000016546*E43^2))) -> -5.0352822e-06 | M43: =IF(ISBLANK(E43),"",IF(ISBLANK(G43),(O43+(K43*35)+(L43*35^1.5)+(0.00000048314*35^2)),(O43+(K43*G43)+(L43*G43^1.5)+(0.00000048314*G43^2)))) -> 1.0272916 | N43: =IF(ISBLANK(D43),"",IF(ISBLANK(G43),J43*(1+0.00001*(35-20)),J43*(1+0.00001*(G43-20)))) -> 109.91545 | O43: =IF(ISBLANK(E43),"",(0.999842594+(0.00006793952*E43)-(0.00000909529*E43^2)+(0.0000001001685*E43^3)-(0.000000001120083*E43^4)+(0.000000000006536332*E43^5))) -> 0.99986844 | P43: 5.47 | Q43: 5.324 | R43: 244.3 | S43: 237.8 | T43: 0 | U43: 0 | V43: 19.9 | W43: 19.4 | X43: 19.9 | Y43: 19.4 | Z43: 1.48 | AA43: 1.44 | AB43: 23.6 | AC43: 23
A44: =IF(ISBLANK(VLOOKUP(D44,'Volumes flacons'!A5:C623,3)),0,1) -> 1 | B44: =IF(ISBLANK(D44),0,IF(ISBLANK(E44),0,IF(ISBLANK(F44),0,1))) -> 1 | C44: 10 | D44: 2108 | E44: 7.9 | F44: 5.26 | G44: 34.9648 | H44: 2000 | I44: 2021 | J44: 109.904 | K44: =IF(ISBLANK(E44),"",(0.000824493-(0.0000040899*E44)+(0.000000076438*E44^2)-(0.00000000082467*E44^3)+(0.0000000000053875*E44^4))) -> 0.00079656768 | L44: =IF(ISBLANK(E44),"",(-0.00000572466+(0.00000010227*E44)-(0.0000000016546*E44^2))) -> -5.0199906e-06 | M44: =IF(ISBLANK(E44),"",IF(ISBLANK(G44),(O44+(K44*35)+(L44*35^1.5)+(0.00000048314*35^2)),(O44+(K44*G44)+(L44*G44^1.5)+(0.00000048314*G44^2)))) -> 1.0272615 | N44: =IF(ISBLANK(D44),"",IF(ISBLANK(G44),J44*(1+0.00001*(35-20)),J44*(1+0.00001*(G44-20)))) -> 109.92045 | O44: =IF(ISBLANK(E44),"",(0.999842594+(0.00006793952*E44)-(0.00000909529*E44^2)+(0.0000001001685*E44^3)-(0.000000001120083*E44^4)+(0.000000000006536332*E44^5))) -> 0.9998569 | P44: 5.474 | Q44: 5.328 | R44: 244.5 | S44: 238 | T44: 0 | U44: 0 | V44: 19.8 | W44: 19.3 | X44: 19.8 | Y44: 19.3 | Z44: 1.47 | AA44: 1.43 | AB44: 23.4 | AC44: 22.8
A45: =IF(ISBLANK(VLOOKUP(D45,'Volumes flacons'!A5:C623,3)),0,1) -> 1 | B45: =IF(ISBLANK(D45),0,IF(ISBLANK(E45),0,IF(ISBLANK(F45),0,1))) -> 1 | C45: 11 | D45: 2109 | E45: 8.2 | F45: 5.096 | G45: 34.9668 | H45: 2000 | I45: 2021 | J45: 106.604 | K45: =IF(ISBLANK(E45),"",(0.000824493-(0.0000040899*E45)+(0.000000076438*E45^2)-(0.00000000082467*E45^3)+(0.0000000000053875*E45^4))) -> 0.00079566517 | L45: =IF(ISBLANK(E45),"",(-0.00000572466+(0.00000010227*E45)-(0.0000000016546*E45^2))) -> -4.9973013e-06 | M45: =IF(ISBLANK(E45),"",IF(ISBLANK(G45),(O45+(K45*35)+(L45*35^1.5)+(0.00000048314*35^2)),(O45+(K45*G45)+(L45*G45^1.5)+(0.00000048314*G45^2)))) -> 1.0272178 | N45: =IF(ISBLANK(D45),"",IF(ISBLANK(G45),J45*(1+0.00001*(35-20)),J45*(1+0.00001*(G45-20)))) -> 106.61996 | O45: =IF(ISBLANK(E45),"",(0.999842594+(0.00006793952*E45)-(0.00000909529*E45^2)+(0.0000001001685*E45^3)-(0.000000001120083*E45^4)+(0.000000000006536332*E45^5))) -> 0.99983854 | P45: 5.47 | Q45: 5.325 | R45: 244.3 | S45: 237.8 | T45: 0 | U45: 0 | V45: 19.9 | W45: 19.4 | X45: 19.9 | Y45: 19.4 | Z45: 1.47 | AA45: 1.43 | AB45: 23.5 | AC45: 22.9
A46: =IF(ISBLANK(VLOOKUP(D46,'Volumes flacons'!A5:C623,3)),0,1) -> 1 | B46: =IF(ISBLANK(D46),0,IF(ISBLANK(E46),0,IF(ISBLANK(F46),0,1))) -> 0 | C46: 12 | J46: =IF(ISBLANK(D46),"",IF(VLOOKUP(D46,'Volumes flacons'!$A$5:$C$978,2)=0,"",IF(D46>'Volumes flacons'!$A$978,"Mauvais numéro",IF(D46<'Volumes flacons'!$A$5,"Mauvais numéro",(VLOOKUP(D46,'Volumes flacons'!$A$5:$C$978,3)))))) | K46: =IF(ISBLANK(E46),"",(0.000824493-(0.0000040899*E46)+(0.000000076438*E46^2)-(0.00000000082467*E46^3)+(0.0000000000053875*E46^4))) | L46: =IF(ISBLANK(E46),"",(-0.00000572466+(0.00000010227*E46)-(0.0000000016546*E46^2))) | M46: =IF(ISBLANK(E46),"",IF(ISBLANK(G46),(O46+(K46*35)+(L46*35^1.5)+(0.00000048314*35^2)),(O46+(K46*G46)+(L46*G46^1.5)+(0.00000048314*G46^2)))) | N46: =IF(ISBLANK(D46),"",IF(ISBLANK(G46),J46*(1+0.00001*(35-20)),J46*(1+0.00001*(G46-20)))) | O46: =IF(ISBLANK(E46),"",(0.999842594+(0.00006793952*E46)-(0.00000909529*E46^2)+(0.0000001001685*E46^3)-(0.000000001120083*E46^4)+(0.000000000006536332*E46^5))) | P46: =IF(ISBLANK($R$16),"",IF(A46=0,"",IF(ISBLANK($R$17),"",IF(B46=0,"",IF($O$28=$I$29,"",IF(AND($I$29=$O$29,D46<1000),"N° Flac.",IF(AND($I$29=$O$30,D46>1000),"N° Flac.",IF(AND(D46>1202,D46<2001),"Err. N°",IF(AND(D46>499,D46<1141),"Err.N°",(((((F46)+'Correction de volume'!$G$7)*(($P$21)*($P$19)*5598)/(($R$16)-($R$17)))-(($P$27)*1000))/((N46)-($P$26)))))))))))) | Q46: =IF(ISBLANK($R$16),"",IF(A46=0,"",IF(ISBLANK($R$17),"",IF(AND(D46>1202,D46<2001),"Err. N°",IF(AND(D46>499,D46<1141),"Err.N°",IF(B46=0,"",IF($O$28=$I$29,"",IF(AND($I$29=$O$29,D46<1000),"N° Flac.",IF(AND($I$29=$O$30,D46>1000),"N° Flac.",P46/M46))))))))) | R46: =IF(ISBLANK($R$16),"",IF(A46=0,"",IF(ISBLANK($R$17),"",IF(B46=0,"",IF(ISBLANK(J46),"",IF(AND(D46>1202,D46<2001),"Err. N°",IF(AND(D46>499,D46<1141),"Err.N°",IF($I$29=$O$28,"",IF(AND($I$29=$O$29,D46<1000),"N° Flac.",IF(AND($I$29=$O$30,D46>1000),"N° Flac.",((44.66*P46)))))))))))) | S46: =IF(ISBLANK($R$16),"",IF(A46=0,"",IF(ISBLANK($R$17),"",IF(B46=0,"",IF(ISBLANK(J46),"",IF(AND(D46>1202,D46<2001),"Err. N°",IF(AND(D46>499,D46<1141),"Err.N°",IF($I$29=$O$28,"",IF(AND($I$29=$O$29,D46<1000),"N° Flac.",IF(AND($I$29=$O$30,D46>1000),"N° Flac.",((44.66*P46)/M46)))))))))))
...

Sheet 002_01
C2: Campagne : | F2: PIRATA Fr26
C4: Données de campagne
C6: N° de station : | F6: 2 | H6: N° de palanquée : | P6: 1 | R6: Date d'analyse : | T6: 40979
G8: Position | I8: Degrés | J8: Minutes | P8: Cardinal | Q8: Décimale
G9: Latitude | I9: 2 | J9: 0 | K9: : | L9: =IF(P9=M9,"+","-") -> + | M9: N | N9: E | O9: =IF(ISBLANK(I9),"",IF(ISBLANK(J9),"",IF(P9=M10,L9&N11,N11))) -> 2°0 | P9: N | Q9: =IF(ISBLANK(I9),"",IF(ISBLANK(J9),"",IF(J9>60,"ERREUR !!",O11*(I9+(J9/60))))) -> 2
G10: Longitude | I10: 23 | J10: 0 | K10: : | L10: =IF(P10=N9,"+","-") -> - | M10: S | N10: W | O10: =IF(ISBLANK(I10),"",IF(ISBLANK(J10),"",IF(P10=N10,L10&N12,N12))) -> -23°0 | P10: W | Q10: =IF(ISBLANK(I10),"",IF(ISBLANK(J10),"",IF(J10>60,"ERREUR !!",O12*(I10+(J10/60))))) -> -23
G11: Prélèvement | I11: Date | J11: 40978 | N11: =I9&"°"&J9 -> 2°0 | O11: =IF(P9=M10,-1,1) -> 1 | P11: =TEXT(J11,"aaaa-mm-jj")&"T"&TEXT(J12,"hh:mm:ss")&"z" -> 2016-03-11T22:00:00z
I12: Heure | J12: 0.91666667 | N12: =I10&"°"&J10 -> 23°0 | O12: =IF(P10=N10,-1,1) -> -1
C13: Données :
C14: Température du laboratoire à la calibration ( t°c ) | Q14: t°c = | R14: 23 | S14: °C
C15: Température du laboratoire au début de la série d'analyses | Q15: t°lab = | R15: 23.2 | S15: °C
C16: Volume moyen de thiosulfate pour la titration à t°c | Q16: Vmoy.titr.t°c = | R16: 4.975 | S16: mL
C17: Volume moyen de thiosulfate pour la détermination du blanc à t°c | Q17: Vmoy.titr.blanc.t°c = | R17: 0.005 | S17: mL
C18: Masse volumique de l'eau pure à la calibration | O18: ρ = | P18: =(0.999842594+(0.00006793952*$R$14)-(0.00000909529*$R$14^2)+(0.0000001001685*$R$14^3)-(0.000000001120083*$R$14^4)+(0.000000000006536332*$R$14^5)) -> 0.99754117
C19: Normalite de l'iodate (NIO3) à la température de calibration | O19: N(IO3) = | P19: =$P$24*($P$18/'Titre d''iodate'!E19) -> 0.019982863 | Q19: N
C20: Vol. de la prise d'essai d'iodate (VIO3) à 20°C | O20: V(IO3)20°C = | P20: =5+'Correction de volume'!G8 -> 5.00309 | Q20: mL
C21: Vol. de la prise d'essai d'iodate (VIO3) à t°c | O21: V(IO3)t°c= | P21: =P20*(1+0.00001*(R14-20)) -> 5.0032401 | Q21: mL
C22: Volume moyen de thiosulfate pour la titration à 20° C | O22: Vmoy.titr.20°C = | P22: =$R$16*(1+0.00001*(20-$R$14)) -> 4.9748507 | Q22: mL
C23: Volume moyen de thiosulfate pour la détermination du blanc à 20° C | O23: Vmoy.titr.blanc.20°C = | P23: =$R$17*(1+0.00001*(20-$R$14)) -> 0.00499985 | Q23: mL
C24: Normalite de l'iodate (NIO3) à 20°C | O24: N(IO3)20°C = | P24: =MAX('Titre d''iodate'!F7:F10) -> 0.019996187 | Q24: N
C25: Titre du thiosulfate à 20°C | O25: V(Thio)20°C = | P25: =IF(ISBLANK(R14),"",IF(ISBLANK(P21),"",IF(ISBLANK(R17),"",(($P$24*$P$18)/($P$22-$P$23))))) -> 0.0040136053 | Q25: N
C26: Volume de réactif utilisé | O26: Vreg = | P26: =2+('Correction de volume'!G10+'Correction de volume'!G9) -> 2.016394 | Q26: mL
O27: DOreg = | P27: 0.0017
E29: Choix de la série de flacons : | I29: IRD | O29: IRD
O30: LPO
C31: N° | D31: N° des Flacons | E31: T° prélèv. | F31: Volume de thio. | G31: Salinité | H31: Prof. Théorique | I31: Prof. Effective | J31: V. flacons 20°C | K31: A | L31: B | M31: Densité eau de mer à t° | N31: Vol. à t° prél. des flacons | O31: Densité eau pure à t° | P31: Oxygène dissous | T31: NO2 | V31: NO3 + NO2 | X31: NO3 | Z31: Phosphate | AB31: Silicate | AD31: chlorophyll-c3 | AE31: chlorophyll-c1+c2 | AF31: peridinin | AG31: 19'-butanoyloxyfucoxanthin | AH31: fucoxanthine | AI31: neoxanthin | AJ31: prasinoxanthin | AK31: violaxanthin | AL31: 19'-hexanoyloxyfucoxanthin | AM31: diadinoxanthin | AN31: alloxanthin | AO31: diatoxanthin | AP31: zeaxanthin | AQ31: lutein | AR31: divinyl chlorophyll-b | AS31: chlorophyll-b | AT31: total chlorophyll-b | AU31: alpha-carotene | AV31: beta-carotene | AW31: pheophorbide | AX31: divinyl chlorophyll-a | AY31: chlorophyll-a | AZ31: total chlorophyll-a | BA31: pheophytin_a | BB31: crocoxanthin
C33: BTL | E33: °C | F33: ml | H33: m | I33: m | J33: ml | P33: DOX1 | R33: DOXY | S33: DOX2 | T33: NTRI | U33: NTIW | V33: NTRZ | W33: NTZW | X33: NTRA | Y33: NTAW | Z33: PHOS | AA33: PHOW | AB33: SLCA | AC33: SLCW | AD33: CHC3 | AE33: CHCZ | AF33: PERP | AG33: BFUP | AH33: FUCP | AI33: NEXW | AJ33: PXAP | AK33: VIOW | AL33: HFUP | AM33: DXAP | AN33: AXAP | AO33: TXAP | AP33: ZXAP | AQ33: LUTW | AR33: CHBD | AS33: CH2P | AT33: CHLB | AU33: AACP | AV33: BBCP | AW33: PHEP | AX33: CHAD | AY33: CH1P | AZ33: CPHL | BA33: PHEA | BB33: CXAP
N34: mL | P34: ml/l | Q34: ml/kg | R34: µmol/l | S34: µmol/kg | T34: µmol/l | U34: µmol/kg | V34: µmol/l | W34: µmol/kg | X34: µmol/l | Y34: µmol/kg | Z34: µmol/l | AA34: µmol/kg | AB34: µmol/l | AC34: µmol/kg | AD34: µg.l-1 | AE34: µg.l-1 | AF34: µg.l-1 | AG34: µg.l-1 | AH34: µg.l-1 | AI34: µg.l-1 | AJ34: µg.l-1 | AK34: µg.l-1 | AL34: µg.l-1 | AM34: µg.l-1 | AN34: µg.l-1 | AO34: µg.l-1 | AP34: µg.l-1 | AQ34: µg.l-1 | AR34: µg.l-1 | AS34: µg.l-1 | AT34: µg.l-1 | AU34: µg.l-1 | AV34: µg.l-1 | AW34: µg.l-1 | AX34: µg.l-1 | AY34: µg.l-1 | AZ34: µg.l-1 | BA34: µg.l-1 | BB34: µg.l-1
A35: =IF(ISBLANK(VLOOKUP(D35,'Volumes flacons'!A5:C623,3)),0,1) -> 1 | B35: =IF(ISBLANK(D35),0,IF(ISBLANK(E35),0,IF(ISBLANK(F35),0,1))) -> 1 | C35: 1 | D35: 3155 | E35: 6.4 | F35: 5.799 | H35: 2000 | I35: 2020.8 | J35: 116.07 | K35: =IF(ISBLANK(E35),"",(0.000824493-(0.0000040899*E35)+(0.000000076438*E35^2)-(0.00000000082467*E35^3)+(0.0000000000053875*E35^4))) -> 0.0008012414 | L35: =IF(ISBLANK(E35),"",(-0.00000572466+(0.00000010227*E35)-(0.0000000016546*E35^2))) -> -5.1379044e-06 | M35: =IF(ISBLANK(E35),"",IF(ISBLANK(G35),(O35+(K35*35)+(L35*35^1.5)+(0.00000048314*35^2)),(O35+(K35*G35)+(L35*G35^1.5)+(0.00000048314*G35^2)))) -> 1.0275007 | N35: =IF(ISBLANK(D35),"",IF(ISBLANK(G35),J35*(1+0.00001*(35-20)),J35*(1+0.00001*(G35-20)))) -> 116.08741 | O35: =IF(ISBLANK(E35),"",(0.999842594+(0.00006793952*E35)-(0.00000909529*E35^2)+(0.0000001001685*E35^3)-(0.000000001120083*E35^4)+(0.000000000006536332*E35^5))) -> 0.99992931 | P35: 5.71 | Q35: 5.557 | R35: 255 | S35: 248.2
A36: =IF(ISBLANK(VLOOKUP(D36,'Volumes flacons'!A5:C623,3)),0,1) -> 1 | B36: =IF(ISBLANK(D36),0,IF(ISBLANK(E36),0,IF(ISBLANK(F36),0,1))) -> 1 | C36: 2 | D36: 3156 | E36: 6.6 | F36: 5.761 | G36: 34.9654 | H36: 2000 | I36: 2020.8 | J36: 115.6 | K36: =IF(ISBLANK(E36),"",(0.000824493-(0.0000040899*E36)+(0.000000076438*E36^2)-(0.00000000082467*E36^3)+(0.0000000000053875*E36^4))) -> 0.00080060243 | L36: =IF(ISBLANK(E36),"",(-0.00000572466+(0.00000010227*E36)-(0.0000000016546*E36^2))) -> -5.1217524e-06 | M36: =IF(ISBLANK(E36),"",IF(ISBLANK(G36),(O36+(K36*35)+(L36*35^1.5)+(0.00000048314*35^2)),(O36+(K36*G36)+(L36*G36^1.5)+(0.00000048314*G36^2)))) -> 1.0274467 | N36: =IF(ISBLANK(D36),"",IF(ISBLANK(G36),J36*(1+0.00001*(35-20)),J36*(1+0.00001*(G36-20)))) -> 115.6173 | O36: =IF(ISBLANK(E36),"",(0.999842594+(0.00006793952*E36)-(0.00000909529*E36^2)+(0.0000001001685*E36^3)-(0.000000001120083*E36^4)+(0.000000000006536332*E36^5))) -> 0.99992156 | P36: 5.696 | Q36: 5.544 | R36: 254.4 | S36: 247.6
A37: =IF(ISBLANK(VLOOKUP(D37,'Volumes flacons'!A5:C623,3)),0,1) -> 1 | B37: =IF(ISBLANK(D37),0,IF(ISBLANK(E37),0,IF(ISBLANK(F37),0,1))) -> 1 | C37: 3 | D37: 3157 | E37: 8 | F37: 3.673 | G37: 34.6793 | H37: 1000 | I37: 1008.7 | J37: 114.35 | K37: =IF(ISBLANK(E37),"",(0.000824493-(0.0000040899*E37)+(0.000000076438*E37^2)-(0.00000000082467*E37^3)+(0.0000000000053875*E37^4))) -> 0.00079626567 | L37: =IF(ISBLANK(E37),"",(-0.00000572466+(0.00000010227*E37)-(0.0000000016546*E37^2))) -> -5.0123944e-06 | M37: =IF(ISBLANK(E37),"",IF(ISBLANK(G37),(O37+(K37*35)+(L37*35^1.5)+(0.00000048314*35^2)),(O37+(K37*G37)+(L37*G37^1.5)+(0.00000048314*G37^2)))) -> 1.0270223 | N37: =IF(ISBLANK(D37),"",IF(ISBLANK(G37),J37*(1+0.00001*(35-20)),J37*(1+0.00001*(G37-20)))) -> 114.36679 | O37: =IF(ISBLANK(E37),"",(0.999842594+(0.00006793952*E37)-(0.00000909529*E37^2)+(0.0000001001685*E37^3)-(0.000000001120083*E37^4)+(0.000000000006536332*E37^5))) -> 0.99985092 | P37: 3.666 | Q37: 3.57 | R37: 163.7 | S37: 159.4
A38: =IF(ISBLANK(VLOOKUP(D38,'Volumes flacons'!A5:C623,3)),0,1) -> 1 | B38: =IF(ISBLANK(D38),0,IF(ISBLANK(E38),0,IF(ISBLANK(F38),0,1))) -> 1 | C38: 4 | D38: 3159 | E38: 10.3 | F38: 3.075 | G38: 34.655 | H38: 500 | I38: 505 | J38: 116.17 | K38: =IF(ISBLANK(E38),"",(0.000824493-(0.0000040899*E38)+(0.000000076438*E38^2)-(0.00000000082467*E38^3)+(0.0000000000053875*E38^4))) -> 0.00078963584 | L38: =IF(ISBLANK(E38),"",(-0.00000572466+(0.00000010227*E38)-(0.0000000016546*E38^2))) -> -4.8468155e-06 | M38: =IF(ISBLANK(E38),"",IF(ISBLANK(G38),(O38+(K38*35)+(L38*35^1.5)+(0.00000048314*35^2)),(O38+(K38*G38)+(L38*G38^1.5)+(0.00000048314*G38^2)))) -> 1.0266313 | N38: =IF(ISBLANK(D38),"",IF(ISBLANK(G38),J38*(1+0.00001*(35-20)),J38*(1+0.00001*(G38-20)))) -> 116.18702 | O38: =IF(ISBLANK(E38),"",(0.999842594+(0.00006793952*E38)-(0.00000909529*E38^2)+(0.0000001001685*E38^3)-(0.000000001120083*E38^4)+(0.000000000006536332*E38^5))) -> 0.99967506 | P38: 3.018 | Q38: 2.94 | R38: 134.8 | S38: 131.3
A39: =IF(ISBLANK(VLOOKUP(D39,'Volumes flacons'!A5:C623,3)),0,1) -> 1 | B39: =IF(ISBLANK(D39),0,IF(ISBLANK(E39),0,IF(ISBLANK(F39),0,1))) -> 1 | C39: 5 | D39: 3160 | E39: 17 | F39: 2.595 | G39: 35.6029 | H39: 100 | I39: 101.2 | J39: 116.77 | K39: =IF(ISBLANK(E39),"",(0.000824493-(0.0000040899*E39)+(0.000000076438*E39^2)-(0.00000000082467*E39^3)+(0.0000000000053875*E39^4))) -> 0.00077345365 | L39: =IF(ISBLANK(E39),"",(-0.00000572466+(0.00000010227*E39)-(0.0000000016546*E39^2))) -> -4.4642494e-06 | M39: =IF(ISBLANK(E39),"",IF(ISBLANK(G39),(O39+(K39*35)+(L39*35^1.5)+(0.00000048314*35^2)),(O39+(K39*G39)+(L39*G39^1.5)+(0.00000048314*G39^2)))) -> 1.0259781 | N39: =IF(ISBLANK(D39),"",IF(ISBLANK(G39),J39*(1+0.00001*(35-20)),J39*(1+0.00001*(G39-20)))) -> 116.78822 | O39: =IF(ISBLANK(E39),"",(0.999842594+(0.00006793952*E39)-(0.00000909529*E39^2)+(0.0000001001685*E39^3)-(0.000000001120083*E39^4)+(0.000000000006536332*E39^5))) -> 0.99877689 | P39: 2.531 | Q39: 2.467 | R39: 113 | S39: 110.2 | T39: 0.04 | U39: 0.04 | V39: 19.3 | W39: 18.8 | X39: 19.2 | Y39: 18.7 | Z39: 1.31 | AA39: 1.28 | AB39: 6.2 | AC39: 6 | AD39: 0.0239 | AE39: 0.0126 | AF39: -99999 | AG39: 0.0346 | AH39: 0.015 | AI39: 0.0015 | AJ39: 0.0015 | AK39: -99999 | AL39: 0.0383 | AM39: 0.0028 | AN39: -99999 | AO39: -99999 | AP39: 0.0141 | AR39: 0.087 | AS39: 0.0273 | AU39: 0.0208 | AV39: -99999 | AX39: 0.0475 | AY39: 0.0919 | BA39: 0.004
A40: =IF(ISBLANK(VLOOKUP(D40,'Volumes flacons'!A5:C623,3)),0,1) -> 1 | B40: =IF(ISBLANK(D40),0,IF(ISBLANK(E40),0,IF(ISBLANK(F40),0,1))) -> 1 | C40: 6 | D40: 3161 | E40: 18.2 | F40: 2.628 | G40: 35.6868 | H40: 80 | I40: 81.3 | J40: 119.09 | K40: =IF(ISBLANK(E40),"",(0.000824493-(0.0000040899*E40)+(0.000000076438*E40^2)-(0.00000000082467*E40^3)+(0.0000000000053875*E40^4))) -> 0.00077099568 | L40: =IF(ISBLANK(E40),"",(-0.00000572466+(0.00000010227*E40)-(0.0000000016546*E40^2))) -> -4.4114157e-06 | M40: =IF(ISBLANK(E40),"",IF(ISBLANK(G40),(O40+(K40*35)+(L40*35^1.5)+(0.00000048314*35^2)),(O40+(K40*G40)+(L40*G40^1.5)+(0.00000048314*G40^2)))) -> 1.0257496 | N40: =IF(ISBLANK(D40),"",IF(ISBLANK(G40),J40*(1+0.00001*(35-20)),J40*(1+0.00001*(G40-20)))) -> 119.10868 | O40: =IF(ISBLANK(E40),"",(0.999842594+(0.00006793952*E40)-(0.00000909529*E40^2)+(0.0000001001685*E40^3)-(0.000000001120083*E40^4)+(0.000000000006536332*E40^5))) -> 0.9985604 | P40: 2.513 | Q40: 2.45 | R40: 112.2 | S40: 109.4 | T40: 0.08 | U40: 0.08 | V40: 18.1 | W40: 17.6 | X40: 18 | Y40: 17.5 | Z40: 1.17 | AA40: 1.14 | AB40: 5.1 | AC40: 5 | AD40: 0.047 | AE40: 0.0271 | AF40: 0.003 | AG40: 0.0589 | AH40: 0.0275 | AI40: 0.0056 | AJ40: 0.005 | AK40: 0.0017 | AL40: 0.0536 | AM40: 0.0073 | AN40: 0.002 | AO40: -99999 | AP40: 0.0328 | AR40: 0.1225 | AS40: 0.0665 | AU40: 0.0334 | AV40: -99999 | AX40: 0.0784 | AY40: 0.1999 | BA40: 0.0056
A41: =IF(ISBLANK(VLOOKUP(D41,'Volumes flacons'!A5:C623,3)),0,1) -> 1 | B41: =IF(ISBLANK(D41),0,IF(ISBLANK(E41),0,IF(ISBLANK(F41),0,1))) -> 1 | C41: 7 | D41: 3163 | E41: 23.8 | F41: 4.086 | G41: 35.9464 | H41: 60 | I41: 60.2 | J41: 117.68 | K41: =IF(ISBLANK(E41),"",(0.000824493-(0.0000040899*E41)+(0.000000076438*E41^2)-(0.00000000082467*E41^3)+(0.0000000000053875*E41^4))) -> 0.00076106192 | L41: =IF(ISBLANK(E41),"",(-0.00000572466+(0.00000010227*E41)-(0.0000000016546*E41^2))) -> -4.2278656e-06 | M41: =IF(ISBLANK(E41),"",IF(ISBLANK(G41),(O41+(K41*35)+(L41*35^1.5)+(0.00000048314*35^2)),(O41+(K41*G41)+(L41*G41^1.5)+(0.00000048314*G41^2)))) -> 1.0244191 | N41: =IF(ISBLANK(D41),"",IF(ISBLANK(G41),J41*(1+0.00001*(35-20)),J41*(1+0.00001*(G41-20)))) -> 117.69877 | O41: =IF(ISBLANK(E41),"",(0.999842594+(0.00006793952*E41)-(0.00000909529*E41^2)+(0.0000001001685*E41^3)-(0.000000001120083*E41^4)+(0.000000000006536332*E41^5))) -> 0.99734855 | P41: 3.963 | Q41: 3.868 | R41: 177 | S41: 172.8 | T41: 0.07 | U41: 0.07 | V41: 0.7 | W41: 0.7 | X41: 0.6 | Y41: 0.6 | Z41: 0.17 | AA41: 0.17 | AB41: 1.7 | AC41: 1.7 | AD41: 0.1271 | AE41: 0.0972 | AF41: 0.0137 | AG41: 0.1515 | AH41: 0.0423 | AI41: 0.0156 | AJ41: 0.0176 | AK41: 0.0156 | AL41: 0.2419 | AM41: 0.0215 | AN41: 0.0114 | AO41: -99999 | AP41: 0.1171 | AR41: 0.0816 | AS41: 0.2 | AU41: 0.0553 | AV41: -99999 | AX41: 0.2101 | AY41: 0.5889 | BA41: 0.0143
A42: =IF(ISBLANK(VLOOKUP(D42,'Volumes flacons'!A5:C623,3)),0,1) -> 1 | B42: =IF(ISBLANK(D42),0,IF(ISBLANK(E42),0,IF(ISBLANK(F42),0,1))) -> 1 | C42: 8 | D42: 3166 | E42: 28 | F42: 4.797 | G42: 35.8462 | H42: 40 | I42: 40.2 | J42: 115.58 | K42: =IF(ISBLANK(E42),"",(0.000824493-(0.0000040899*E42)+(0.000000076438*E42^2)-(0.00000000082467*E42^3)+(0.0000000000053875*E42^4))) -> 0.0007551115 | L42: =IF(ISBLANK(E42),"",(-0.00000572466+(0.00000010227*E42)-(0.0000000016546*E42^2))) -> -4.1583064e-06 | M42: =IF(ISBLANK(E42),"",IF(ISBLANK(G42),(O42+(K42*35)+(L42*35^1.5)+(0.00000048314*35^2)),(O42+(K42*G42)+(L42*G42^1.5)+(0.00000048314*G42^2)))) -> 1.0230334 | N42: =IF(ISBLANK(D42),"",IF(ISBLANK(G42),J42*(1+0.00001*(35-20)),J42*(1+0.00001*(G42-20)))) -> 115.59832 | O42: =IF(ISBLANK(E42),"",(0.999842594+(0.00006793952*E42)-(0.00000909529*E42^2)+(0.0000001001685*E42^3)-(0.000000001120083*E42^4)+(0.000000000006536332*E42^5))) -> 0.99623712 | P42: 4.741 | Q42: 4.634 | R42: 211.7 | S42: 207 | T42: 0 | U42: 0 | V42: 0 | W42: 0 | X42: 0 | Y42: 0 | Z42: 0.02 | AA42: 0.02 | AB42: 0.6 | AC42: 0.6 | AD42: 0.0092 | AE42: 0.0122 | AF42: 0.0063 | AG42: 0.0109 | AH42: 0.0096 | AI42: -99999 | AJ42: -99999 | AK42: -99999 | AL42: 0.0356 | AM42: 0.0102 | AN42: -99999 | AO42: -99999 | AP42: 0.1165 | AR42: 0.0089 | AS42: 0.0092 | AU42: 0.0228 | AV42: -99999 | AX42: 0.0861 | AY42: 0.1105 | BA42: -99999
A43: =IF(ISBLANK(VLOOKUP(D43,'Volumes flacons'!A5:C623,3)),0,1) -> 1 | B43: =IF(ISBLANK(D43),0,IF(ISBLANK(E43),0,IF(ISBLANK(F43),0,1))) -> 1 | C43: 9 | D43: 3167 | E43: 28.8 | F43: 4.714 | G43: 35.9094 | H43: 20 | I43: 20.2 | J43: 117.58 | K43: =IF(ISBLANK(E43),"",(0.000824493-(0.0000040899*E43)+(0.000000076438*E43^2)-(0.00000000082467*E43^3)+(0.0000000000053875*E43^4))) -> 0.00075411145 | L43: =IF(ISBLANK(E43),"",(-0.00000572466+(0.00000010227*E43)-(0.0000000016546*E43^2))) -> -4.1516754e-06 | M43: =IF(ISBLANK(E43),"",IF(ISBLANK(G43),(O43+(K43*35)+(L43*35^1.5)+(0.00000048314*35^2)),(O43+(K43*G43)+(L43*G43^1.5)+(0.00000048314*G43^2)))) -> 1.0228163 | N43: =IF(ISBLANK(D43),"",IF(ISBLANK(G43),J43*(1+0.00001*(35-20)),J43*(1+0.00001*(G43-20)))) -> 117.59871 | O43: =IF(ISBLANK(E43),"",(0.999842594+(0.00006793952*E43)-(0.00000909529*E43^2)+(0.0000001001685*E43^3)-(0.000000001120083*E43^4)+(0.000000000006536332*E43^5))) -> 0.99600699 | P43: 4.578 | Q43: 4.476 | R43: 204.5 | S43: 199.9 | T43: 0 | U43: 0 | V43: 0.1 | W43: 0.1 | X43: 0.1 | Y43: 0.1 | Z43: 0.03 | AA43: 0.03 | AB43: 0.7 | AC43: 0.7 | AD43: 0.0026 | AE43: 0.0053 | AF43: 0.0023 | AG43: 0.0063 | AH43: 0.0073 | AI43: -99999 | AJ43: -99999 | AK43: 0.0007 | AL43: 0.0125 | AM43: 0.0056 | AN43: -99999 | AO43: -99999 | AP43: 0.1234 | AR43: 0.0046 | AS43: 0.0073 | AU43: 0.0152 | AV43: -99999 | AX43: 0.0511 | AY43: 0.0594 | BA43: -99999
A44: =IF(ISBLANK(VLOOKUP(D44,'Volumes flacons'!A5:C623,3)),0,1) -> 1 | B44: =IF(ISBLANK(D44),0,IF(ISBLANK(E44),0,IF(ISBLANK(F44),0,1))) -> 1 | C44: 10 | D44: 3169 | E44: 28.9 | F44: 4.621 | G44: 35.5515 | H44: 10 | I44: 9.7 | J44: 116.45 | K44: =IF(ISBLANK(E44),"",(0.000824493-(0.0000040899*E44)+(0.000000076438*E44^2)-(0.00000000082467*E44^3)+(0.0000000000053875*E44^4))) -> 0.00075398933 | L44: =IF(ISBLANK(E44),"",(-0.00000572466+(0.00000010227*E44)-(0.0000000016546*E44^2))) -> -4.1509955e-06 | M44: =IF(ISBLANK(E44),"",IF(ISBLANK(G44),(O44+(K44*35)+(L44*35^1.5)+(0.00000048314*35^2)),(O44+(K44*G44)+(L44*G44^1.5)+(0.00000048314*G44^2)))) -> 1.022514 | N44: =IF(ISBLANK(D44),"",IF(ISBLANK(G44),J44*(1+0.00001*(35-20)),J44*(1+0.00001*(G44-20)))) -> 116.46811 | O44: =IF(ISBLANK(E44),"",(0.999842594+(0.00006793952*E44)-(0.00000909529*E44^2)+(0.0000001001685*E44^3)-(0.000000001120083*E44^4)+(0.000000000006536332*E44^5))) -> 0.99597782 | P44: 4.532 | Q44: 4.432 | R44: 202.4 | S44: 197.9
A45: =IF(ISBLANK(VLOOKUP(D45,'Volumes flacons'!A5:C623,3)),0,1) -> 1 | B45: =IF(ISBLANK(D45),0,IF(ISBLANK(E45),0,IF(ISBLANK(F45),0,1))) -> 1 | C45: 11 | D45: 3171 | E45: 28.8 | F45: 4.656 | G45: 35.4546 | H45: 0 | I45: 2.1 | J45: 117.64 | K45: =IF(ISBLANK(E45),"",(0.000824493-(0.0000040899*E45)+(0.000000076438*E45^2)-(0.00000000082467*E45^3)+(0.0000000000053875*E45^4))) -> 0.00075411145 | L45: =IF(ISBLANK(E45),"",(-0.00000572466+(0.00000010227*E45)-(0.0000000016546*E45^2))) -> -4.1516754e-06 | M45: =IF(ISBLANK(E45),"",IF(ISBLANK(G45),(O45+(K45*35)+(L45*35^1.5)+(0.00000048314*35^2)),(O45+(K45*G45)+(L45*G45^1.5)+(0.00000048314*G45^2)))) -> 1.0224746 | N45: =IF(ISBLANK(D45),"",IF(ISBLANK(G45),J45*(1+0.00001*(35-20)),J45*(1+0.00001*(G45-20)))) -> 117.65818 | O45: =IF(ISBLANK(E45),"",(0.999842594+(0.00006793952*E45)-(0.00000909529*E45^2)+(0.0000001001685*E45^3)-(0.000000001120083*E45^4)+(0.000000000006536332*E45^5))) -> 0.99600699 | P45: 4.519 | Q45: 4.42 | R45: 201.8 | S45: 197.4 | T45: 0 | U45: 0 | V45: 0.1 | W45: 0.1 | X45: 0.1 | Y45: 0.1 | Z45: 0 | AA45: 0 | AB45: 0.6 | AC45: 0.6 | AD45: 0.0078 | AE45: 0.0092 | AF45: 0.0029 | AG45: 0.0095 | AH45: 0.0108 | AI45: -99999 | AJ45: -99999 | AK45: 0.001 | AL45: 0.0262 | AM45: 0.0121 | AN45: -99999 | AO45: -99999 | AP45: 0.1582 | AR45: 0.0039 | AS45: 0.0065 | AU45: -99999 | AV45: 0.0258 | AX45: 0.0471 | AY45: 0.1125 | BA45: -99999
A46: =IF(ISBLANK(VLOOKUP(D46,'Volumes flacons'!A5:C623,3)),0,1) -> 1 | B46: =IF(ISBLANK(D46),0,IF(ISBLANK(E46),0,IF(ISBLANK(F46),0,1))) -> 0 | C46: 12 | J46: =IF(ISBLANK(D46),"",IF(VLOOKUP(D46,'Volumes flacons'!$A$5:$C$978,2)=0,"",IF(D46>'Volumes flacons'!$A$978,"Mauvais numéro",IF(D46<'Volumes flacons'!$A$5,"Mauvais numéro",(VLOOKUP(D46,'Volumes flacons'!$A$5:$C$978,3)))))) | K46: =IF(ISBLANK(E46),"",(0.000824493-(0.0000040899*E46)+(0.000000076438*E46^2)-(0.00000000082467*E46^3)+(0.0000000000053875*E46^4))) | L46: =IF(ISBLANK(E46),"",(-0.00000572466+(0.00000010227*E46)-(0.0000000016546*E46^2))) | M46: =IF(ISBLANK(E46),"",IF(ISBLANK(G46),(O46+(K46*35)+(L46*35^1.5)+(0.00000048314*35^2)),(O46+(K46*G46)+(L46*G46^1.5)+(0.00000048314*G46^2)))) | N46: =IF(ISBLANK(D46),"",IF(ISBLANK(G46),J46*(1+0.00001*(35-20)),J46*(1+0.00001*(G46-20)))) | O46: =IF(ISBLANK(E46),"",(0.999842594+(0.00006793952*E46)-(0.00000909529*E46^2)+(0.0000001001685*E46^3)-(0.000000001120083*E46^4)+(0.000000000006536332*E46^5))) | P46: =IF(ISBLANK($R$16),"",IF(A46=0,"",IF(ISBLANK($R$17),"",IF(B46=0,"",IF($O$28=$I$29,"",IF(AND($I$29=$O$29,D46<1000),"N° Flac.",IF(AND($I$29=$O$30,D46>1000),"N° Flac.",IF(AND(D46>1202,D46<2001),"Err. N°",IF(AND(D46>499,D46<1141),"Err.N°",(((((F46)+'Correction de volume'!$G$7)*(($P$21)*($P$19)*5598)/(($R$16)-($R$17)))-(($P$27)*1000))/((N46)-($P$26)))))))))))) | Q46: =IF(ISBLANK($R$16),"",IF(A46=0,"",IF(ISBLANK($R$17),"",IF(AND(D46>1202,D46<2001),"Err. N°",IF(AND(D46>499,D46<1141),"Err.N°",IF(B46=0,"",IF($O$28=$I$29,"",IF(AND($I$29=$O$29,D46<1000),"N° Flac.",IF(AND($I$29=$O$30,D46>1000),"N° Flac.",P46/M46))))))))) | R46: =IF(ISBLANK($R$16),"",IF(A46=0,"",IF(ISBLANK($R$17),"",IF(B46=0,"",IF(ISBLANK(J46),"",IF(AND(D46>1202,D46<2001),"Err. N°",IF(AND(D46>499,D46<1141),"Err.N°",IF($I$29=$O$28,"",IF(AND($I$29=$O$29,D46<1000),"N° Flac.",IF(AND($I$29=$O$30,D46>1000),"N° Flac.",((44.66*P46)))))))))))) | S46: =IF(ISBLANK($R$16),"",IF(A46=0,"",IF(ISBLANK($R$17),"",IF(B46=0,"",IF(ISBLANK(J46),"",IF(AND(D46>1202,D46<2001),"Err. N°",IF(AND(D46>499,D46<1141),"Err.N°",IF($I$29=$O$28,"",IF(AND($I$29=$O$29,D46<1000),"N° Flac.",IF(AND($I$29=$O$30,D46>1000),"N° Flac.",((44.66*P46)/M46)))))))))))
...

Sheet 003_01
C2: Campagne : | F2: PIRATA Fr26
C4: Données de campagne
C6: N° de station : | F6: 3 | H6: N° de palanquée : | P6: 1 | R6: Date d'analyse : | T6: 40979
G8: Position | I8: Degrés | J8: Minutes | P8: Cardinal | Q8: Décimale
G9: Latitude | I9: 1 | J9: 30 | K9: : | L9: =IF(P9=M9,"+","-") -> + | M9: N | N9: E | O9: =IF(ISBLANK(I9),"",IF(ISBLANK(J9),"",IF(P9=M10,L9&N11,N11))) -> 1°30 | P9: N | Q9: =IF(ISBLANK(I9),"",IF(ISBLANK(J9),"",IF(J9>60,"ERREUR !!",O11*(I9+(J9/60))))) -> 1.5
G10: Longitude | I10: 23 | J10: 0 | K10: : | L10: =IF(P10=N9,"+","-") -> - | M10: S | N10: W | O10: =IF(ISBLANK(I10),"",IF(ISBLANK(J10),"",IF(P10=N10,L10&N12,N12))) -> -23°0 | P10: W | Q10: =IF(ISBLANK(I10),"",IF(ISBLANK(J10),"",IF(J10>60,"ERREUR !!",O12*(I10+(J10/60))))) -> -23
G11: Prélèvement | I11: Date | J11: 40979 | N11: =I9&"°"&J9 -> 1°30 | O11: =IF(P9=M10,-1,1) -> 1 | P11: =TEXT(J11,"aaaa-mm-jj")&"T"&TEXT(J12,"hh:mm:ss")&"z" -> 2016-03-12T04:30:00z
I12: Heure | J12: 0.1875 | N12: =I10&"°"&J10 -> 23°0 | O12: =IF(P10=N10,-1,1) -> -1
C13: Données :
C14: Température du laboratoire à la calibration ( t°c ) | Q14: t°c = | R14: 23 | S14: °C
C15: Température du laboratoire au début de la série d'analyses | Q15: t°lab = | R15: 23.2 | S15: °C
C16: Volume moyen de thiosulfate pour la titration à t°c | Q16: Vmoy.titr.t°c = | R16: 4.975 | S16: mL
C17: Volume moyen de thiosulfate pour la détermination du blanc à t°c | Q17: Vmoy.titr.blanc.t°c = | R17: 0.005 | S17: mL
C18: Masse volumique de l'eau pure à la calibration | O18: ρ = | P18: =(0.999842594+(0.00006793952*$R$14)-(0.00000909529*$R$14^2)+(0.0000001001685*$R$14^3)-(0.000000001120083*$R$14^4)+(0.000000000006536332*$R$14^5)) -> 0.99754117
C19: Normalite de l'iodate (NIO3) à la température de calibration | O19: N(IO3) = | P19: =$P$24*($P$18/'Titre d''iodate'!E19) -> 0.019982863 | Q19: N
C20: Vol. de la prise d'essai d'iodate (VIO3) à 20°C | O20: V(IO3)20°C = | P20: =5+'Correction de volume'!G8 -> 5.00309 | Q20: mL
C21: Vol. de la prise d'essai d'iodate (VIO3) à t°c | O21: V(IO3)t°c= | P21: =P20*(1+0.00001*(R14-20)) -> 5.0032401 | Q21: mL
C22: Volume moyen de thiosulfate pour la titration à 20° C | O22: Vmoy.titr.20°C = | P22: =$R$16*(1+0.00001*(20-$R$14)) -> 4.9748507 | Q22: mL
C23: Volume moyen de thiosulfate pour la détermination du blanc à 20° C | O23: Vmoy.titr.blanc.20°C = | P23: =$R$17*(1+0.00001*(20-$R$14)) -> 0.00499985 | Q23: mL
C24: Normalite de l'iodate (NIO3) à 20°C | O24: N(IO3)20°C = | P24: =MAX('Titre d''iodate'!F7:F10) -> 0.019996187 | Q24: N
C25: Titre du thiosulfate à 20°C | O25: V(Thio)20°C = | P25: =IF(ISBLANK(R14),"",IF(ISBLANK(P21),"",IF(ISBLANK(R17),"",(($P$24*$P$18)/($P$22-$P$23))))) -> 0.0040136053 | Q25: N
C26: Volume de réactif utilisé | O26: Vreg = | P26: =2+('Correction de volume'!G10+'Correction de volume'!G9) -> 2.016394 | Q26: mL
O27: DOreg = | P27: 0.0017
E29: Choix de la série de flacons : | I29: IRD | O29: IRD
O30: LPO
C31: N° | D31: N° des Flacons | E31: T° prélèv. | F31: Volume de thio. | G31: Salinité | H31: Prof. Théorique | I31: Prof. Effective | J31: V. flacons 20°C | K31: A | L31: B | M31: Densité eau de mer à t° | N31: Vol. à t° prél. des flacons | O31: Densité eau pure à t° | P31: Oxygène dissous | T31: NO2 | V31: NO3 + NO2 | X31: NO3 | Z31: Phosphate | AB31: Silicate | AD31: chlorophyll-c3 | AE31: chlorophyll-c1+c2 | AF31: peridinin | AG31: 19'-butanoyloxyfucoxanthin | AH31: fucoxanthine | AI31: neoxanthin | AJ31: prasinoxanthin | AK31: violaxanthin | AL31: 19'-hexanoyloxyfucoxanthin | AM31: diadinoxanthin | AN31: alloxanthin | AO31: diatoxanthin | AP31: zeaxanthin | AQ31: lutein | AR31: divinyl chlorophyll-b | AS31: chlorophyll-b | AT31: total chlorophyll-b | AU31: alpha-carotene | AV31: beta-carotene | AW31: pheophorbide | AX31: divinyl chlorophyll-a | AY31: chlorophyll-a | AZ31: total chlorophyll-a | BA31: pheophytin_a | BB31: crocoxanthin
C33: BTL | E33: °C | F33: ml | H33: m | I33: m | J33: ml | P33: DOX1 | R33: DOXY | S33: DOX2 | T33: NTRI | U33: NTIW | V33: NTRZ | W33: NTZW | X33: NTRA | Y33: NTAW | Z33: PHOS | AA33: PHOW | AB33: SLCA | AC33: SLCW | AD33: CHC3 | AE33: CHCZ | AF33: PERP | AG33: BFUP | AH33: FUCP | AI33: NEXW | AJ33: PXAP | AK33: VIOW | AL33: HFUP | AM33: DXAP | AN33: AXAP | AO33: TXAP | AP33: ZXAP | AQ33: LUTW | AR33: CHBD | AS33: CH2P | AT33: CHLB | AU33: AACP | AV33: BBCP | AW33: PHEP | AX33: CHAD | AY33: CH1P | AZ33: CPHL | BA33: PHEA | BB33: CXAP
N34: mL | P34: ml/l | Q34: ml/kg | R34: µmol/l | S34: µmol/kg | T34: µmol/l | U34: µmol/kg | V34: µmol/l | W34: µmol/kg | X34: µmol/l | Y34: µmol/kg | Z34: µmol/l | AA34: µmol/kg | AB34: µmol/l | AC34: µmol/kg | AD34: µg.l-1 | AE34: µg.l-1 | AF34: µg.l-1 | AG34: µg.l-1 | AH34: µg.l-1 | AI34: µg.l-1 | AJ34: µg.l-1 | AK34: µg.l-1 | AL34: µg.l-1 | AM34: µg.l-1 | AN34: µg.l-1 | AO34: µg.l-1 | AP34: µg.l-1 | AQ34: µg.l-1 | AR34: µg.l-1 | AS34: µg.l-1 | AT34: µg.l-1 | AU34: µg.l-1 | AV34: µg.l-1 | AW34: µg.l-1 | AX34: µg.l-1 | AY34: µg.l-1 | AZ34: µg.l-1 | BA34: µg.l-1 | BB34: µg.l-1
A35: =IF(ISBLANK(VLOOKUP(D35,'Volumes flacons'!A5:C623,3)),0,1) -> 1 | B35: =IF(ISBLANK(D35),0,IF(ISBLANK(E35),0,IF(ISBLANK(F35),0,1))) -> 1 | C35: 1 | D35: 2075 | E35: 8.1 | F35: 5.536 | G35: 34.9665 | H35: 2000 | I35: 2020 | J35: 111.195 | K35: 0.00079596484 | L35: -5.0048313e-06 | M35: 1.0272328 | N35: 111.21164 | O35: 0.9998448 | P35: 5.694 | Q35: 5.543 | R35: 254.3 | S35: 247.5
A36: =IF(ISBLANK(VLOOKUP(D36,'Volumes flacons'!A5:C623,3)),0,1) -> 1 | B36: =IF(ISBLANK(D36),0,IF(ISBLANK(E36),0,IF(ISBLANK(F36),0,1))) -> 1 | C36: 2 | D36: 2076 | E36: 9.1 | F36: 3.402 | G36: 34.6674 | H36: 1000 | I36: 1009 | J36: 106.588 | K36: 0.00079302024 | L36: -4.9310204e-06 | M36: 1.026842 | N36: 106.60363 | O36: 0.99977587 | P36: 3.647 | Q36: 3.551 | R36: 162.9 | S36: 158.6
A37: =IF(ISBLANK(VLOOKUP(D37,'Volumes flacons'!A5:C623,3)),0,1) -> 1 | B37: =IF(ISBLANK(D37),0,IF(ISBLANK(E37),0,IF(ISBLANK(F37),0,1))) -> 1 | C37: 3 | D37: 2077 | E37: 9.4 | F37: 3.761 | G37: 34.6689 | H37: 1000 | I37: 1008.8 | J37: 117.865 | K37: 0.00079215911 | L37: -4.9095225e-06 | M37: 1.0267943 | N37: 117.88229 | O37: 0.9997525 | P37: 3.641 | Q37: 3.546 | R37: 162.6 | S37: 158.3
A38: =IF(ISBLANK(VLOOKUP(D38,'Volumes flacons'!A5:C623,3)),0,1) -> 1 | B38: =IF(ISBLANK(D38),0,IF(ISBLANK(E38),0,IF(ISBLANK(F38),0,1))) -> 1 | C38: 4 | D38: 2078 | E38: 11.8 | F38: 2.801 | G38: 34.6471 | H38: 500 | I38: 503.6 | J38: 110.287 | K38: 0.0007856249 | L38: -4.7482605e-06 | M38: 1.0263535 | N38: 110.30315 | O38: 0.99952221 | P38: 2.897 | Q38: 2.823 | R38: 129.4 | S38: 126.1
A39: =IF(ISBLANK(VLOOKUP(D39,'Volumes flacons'!A5:C623,3)),0,1) -> 1 | B39: =IF(ISBLANK(D39),0,IF(ISBLANK(E39),0,IF(ISBLANK(F39),0,1))) -> 1 | C39: 5 | D39: 2079 | E39: 17.9 | F39: 2.406 | G39: 35.5978 | H39: 100 | I39: 101.2 | J39: 107.908 | K39: 0.00077159862 | L39: -4.4241774e-06 | M39: 1.0257558 | N39: 107.92483 | O39: 0.99861601 | P39: 2.542 | Q39: 2.478 | R39: 113.5 | S39: 110.7 | T39: 0.03 | U39: 0.03 | V39: 19.2 | W39: 18.7 | X39: 19.1 | Y39: 18.6 | Z39: 1.29 | AA39: 1.26 | AB39: 6 | AC39: 5.8
A40: =IF(ISBLANK(VLOOKUP(D40,'Volumes flacons'!A5:C623,3)),0,1) -> 1 | B40: =IF(ISBLANK(D40),0,IF(ISBLANK(E40),0,IF(ISBLANK(F40),0,1))) -> 1 | C40: 6 | D40: 2080 | E40: 18.8 | F40: 2.879 | G40: 35.7226 | H40: 80 | I40: 80.2 | J40: 108.915 | K40: 0.00076981247 | L40: -4.3867858e-06 | M40: 1.0256259 | N40: 108.93212 | O40: 0.99844623 | P40: 3.016 | Q40: 2.941 | R40: 134.7 | S40: 131.3 | T40: 0.08 | U40: 0.08 | V40: 15.6 | W40: 15.2 | X40: 15.6 | Y40: 15.2 | Z40: 1.08 | AA40: 1.05 | AB40: 4.8 | AC40: 4.7
A41: =IF(ISBLANK(VLOOKUP(D41,'Volumes flacons'!A5:C623,3)),0,1) -> 1 | B41: =IF(ISBLANK(D41),0,IF(ISBLANK(E41),0,IF(ISBLANK(F41),0,1))) -> 1 | C41: 7 | D41: 2081 | E41: 22.9 | F41: 3.589 | G41: 35.9175 | H41: 60 | I41: 60.3 | J41: 119.616 | K41: 0.00076249728 | L41: -4.2503658e-06 | M41: 1.0246602 | N41: 119.63504 | O41: 0.9975648 | P41: 3.422 | Q41: 3.339 | R41: 152.8 | S41: 149.1 | T41: 0.25 | U41: 0.24 | V41: 6.6 | W41: 6.4 | X41: 6.4 | Y41: 6.2 | Z41: 0.54 | AA41: 0.53 | AB41: 2.4 | AC41: 2.3
A42: =IF(ISBLANK(VLOOKUP(D42,'Volumes flacons'!A5:C623,3)),0,1) -> 1 | B42: =IF(ISBLANK(D42),0,IF(ISBLANK(E42),0,IF(ISBLANK(F42),0,1))) -> 1 | C42: 8 | D42: 2082 | E42: 26.9 | F42: 4.498 | G42: 36.0944 | H42: 40 | I42: 40.9 | J42: 111.381 | K42: 0.00075655466 | L42: -4.1708821e-06 | M42: 1.0235765 | N42: 111.39893 | O42: 0.99654409 | P42: 4.615 | Q42: 4.509 | R42: 206.1 | S42: 201.4 | T42: 0 | U42: 0 | V42: 0 | W42: 0 | X42: 0 | Y42: 0 | Z42: 0.07 | AA42: 0.07 | AB42: 0.7 | AC42: 0.7
A43: =IF(ISBLANK(VLOOKUP(D43,'Volumes flacons'!A5:C623,3)),0,1) -> 1 | B43: =IF(ISBLANK(D43),0,IF(ISBLANK(E43),0,IF(ISBLANK(F43),0,1))) -> 1 | C43: 9 | D43: 2083 | E43: 28.1 | F43: 4.419 | G43: 36.0481 | H43: 20 | I43: 20.5 | J43: 109.621 | K43: 0.00075498423 | L43: -4.1573617e-06 | M43: 1.0231524 | N43: 109.63859 | O43: 0.99620867 | P43: 4.608 | Q43: 4.504 | R43: 205.8 | S43: 201.1 | T43: 0 | U43: 0 | V43: 0 | W43: 0 | X43: 0 | Y43: 0 | Z43: 0.06 | AA43: 0.06 | AB43: 0.6 | AC43: 0.6
A44: =IF(ISBLANK(VLOOKUP(D44,'Volumes flacons'!A5:C623,3)),0,1) -> 1 | B44: =IF(ISBLANK(D44),0,IF(ISBLANK(E44),0,IF(ISBLANK(F44),0,1))) -> 1 | C44: 10 | D44: 2084 | E44: 28.4 | F44: 4.346 | G44: 36.0705 | H44: 10 | I44: 10 | J44: 109.474 | K44: 0.00075460631 | L44: -4.1547262e-06 | M44: 1.0230703 | N44: 109.49159 | O44: 0.99612277 | P44: 4.538 | Q44: 4.435 | R44: 202.7 | S44: 198.1
A45: =IF(ISBLANK(VLOOKUP(D45,'Volumes flacons'!A5:C623,3)),0,1) -> 1 | B45: =IF(ISBLANK(D45),0,IF(ISBLANK(E45),0,IF(ISBLANK(F45),0,1))) -> 1 | C45: 11 | D45: 2085 | E45: 28.4 | F45: 4.612 | G45: 35.9517 | H45: 0 | I45: 1.9 | J45: 116.369 | K45: 0.00075460631 | L45: -4.1547262e-06 | M45: 1.022981 | N45: 116.38756 | O45: 0.99612277 | P45: 4.526 | Q45: 4.424 | R45: 202.1 | S45: 197.6 | T45: 0 | U45: 0 | V45: 0.1 | W45: 0.1 | X45: 0 | Y45: 0 | Z45: 0.05 | AA45: 0.05 | AB45: 0.6 | AC45: 0.6
A46: =IF(ISBLANK(VLOOKUP(D46,'Volumes flacons'!A5:C623,3)),0,1) -> 1 | B46: =IF(ISBLANK(D46),0,IF(ISBLANK(E46),0,IF(ISBLANK(F46),0,1))) -> 0 | C46: 12 | J46: =IF(ISBLANK(D46),"",IF(VLOOKUP(D46,'Volumes flacons'!$A$5:$C$978,2)=0,"",IF(D46>'Volumes flacons'!$A$978,"Mauvais numéro",IF(D46<'Volumes flacons'!$A$5,"Mauvais numéro",(VLOOKUP(D46,'Volumes flacons'!$A$5:$C$978,3)))))) | K46: =IF(ISBLANK(E46),"",(0.000824493-(0.0000040899*E46)+(0.000000076438*E46^2)-(0.00000000082467*E46^3)+(0.0000000000053875*E46^4))) | L46: =IF(ISBLANK(E46),"",(-0.00000572466+(0.00000010227*E46)-(0.0000000016546*E46^2))) | M46: =IF(ISBLANK(E46),"",IF(ISBLANK(G46),(O46+(K46*35)+(L46*35^1.5)+(0.00000048314*35^2)),(O46+(K46*G46)+(L46*G46^1.5)+(0.00000048314*G46^2)))) | N46: =IF(ISBLANK(D46),"",IF(ISBLANK(G46),J46*(1+0.00001*(35-20)),J46*(1+0.00001*(G46-20)))) | O46: =IF(ISBLANK(E46),"",(0.999842594+(0.00006793952*E46)-(0.00000909529*E46^2)+(0.0000001001685*E46^3)-(0.000000001120083*E46^4)+(0.000000000006536332*E46^5))) | P46: =IF(ISBLANK($R$16),"",IF(A46=0,"",IF(ISBLANK($R$17),"",IF(B46=0,"",IF($O$28=$I$29,"",IF(AND($I$29=$O$29,D46<1000),"N° Flac.",IF(AND($I$29=$O$30,D46>1000),"N° Flac.",IF(AND(D46>1202,D46<2001),"Err. N°",IF(AND(D46>499,D46<1141),"Err.N°",(((((F46)+'Correction de volume'!$G$7)*(($P$21)*($P$19)*5598)/(($R$16)-($R$17)))-(($P$27)*1000))/((N46)-($P$26)))))))))))) | Q46: =IF(ISBLANK($R$16),"",IF(A46=0,"",IF(ISBLANK($R$17),"",IF(AND(D46>1202,D46<2001),"Err. N°",IF(AND(D46>499,D46<1141),"Err.N°",IF(B46=0,"",IF($O$28=$I$29,"",IF(AND($I$29=$O$29,D46<1000),"N° Flac.",IF(AND($I$29=$O$30,D46>1000),"N° Flac.",P46/M46))))))))) | R46: =IF(ISBLANK($R$16),"",IF(A46=0,"",IF(ISBLANK($R$17),"",IF(B46=0,"",IF(ISBLANK(J46),"",IF(AND(D46>1202,D46<2001),"Err. N°",IF(AND(D46>499,D46<1141),"Err.N°",IF($I$29=$O$28,"",IF(AND($I$29=$O$29,D46<1000),"N° Flac.",IF(AND($I$29=$O$30,D46>1000),"N° Flac.",((44.66*P46)))))))))))) | S46: =IF(ISBLANK($R$16),"",IF(A46=0,"",IF(ISBLANK($R$17),"",IF(B46=0,"",IF(ISBLANK(J46),"",IF(AND(D46>1202,D46<2001),"Err. N°",IF(AND(D46>499,D46<1141),"Err.N°",IF($I$29=$O$28,"",IF(AND($I$29=$O$29,D46<1000),"N° Flac.",IF(AND($I$29=$O$30,D46>1000),"N° Flac.",((44.66*P46)/M46)))))))))))
...

Sheet 004_01
C2: Campagne : | F2: PIRATA Fr26
C4: Données de campagne
C6: N° de station : | F6: 4 | H6: N° de palanquée : | P6: 1 | R6: Date d'analyse : | T6: 40979
G8: Position | I8: Degrés | J8: Minutes | P8: Cardinal | Q8: Décimale
G9: Latitude | I9: 1 | J9: 0 | K9: : | L9: =IF(P9=M9,"+","-") -> + | M9: N | N9: E | O9: =IF(ISBLANK(I9),"",IF(ISBLANK(J9),"",IF(P9=M10,L9&N11,N11))) -> 1°0 | P9: N | Q9: =IF(ISBLANK(I9),"",IF(ISBLANK(J9),"",IF(J9>60,"ERREUR !!",O11*(I9+(J9/60))))) -> 1
G10: Longitude | I10: 23 | J10: 0 | K10: : | L10: =IF(P10=N9,"+","-") -> - | M10: S | N10: W | O10: =IF(ISBLANK(I10),"",IF(ISBLANK(J10),"",IF(P10=N10,L10&N12,N12))) -> -23°0 | P10: W | Q10: =IF(ISBLANK(I10),"",IF(ISBLANK(J10),"",IF(J10>60,"ERREUR !!",O12*(I10+(J10/60))))) -> -23
G11: Prélèvement | I11: Date | J11: 40979 | N11: =I9&"°"&J9 -> 1°0 | O11: =IF(P9=M10,-1,1) -> 1 | P11: =TEXT(J11,"aaaa-mm-jj")&"T"&TEXT(J12,"hh:mm:ss")&"z" -> 2016-03-12T08:50:00z
I12: Heure | J12: 0.36805556 | N12: =I10&"°"&J10 -> 23°0 | O12: =IF(P10=N10,-1,1) -> -1
C13: Données :
C14: Température du laboratoire à la calibration ( t°c ) | Q14: t°c = | R14: 23 | S14: °C
C15: Température du laboratoire au début de la série d'analyses | Q15: t°lab = | R15: 23.2 | S15: °C
C16: Volume moyen de thiosulfate pour la titration à t°c | Q16: Vmoy.titr.t°c = | R16: 4.975 | S16: mL
C17: Volume moyen de thiosulfate pour la détermination du blanc à t°c | Q17: Vmoy.titr.blanc.t°c = | R17: 0.005 | S17: mL
C18: Masse volumique de l'eau pure à la calibration | O18: ρ = | P18: =(0.999842594+(0.00006793952*$R$14)-(0.00000909529*$R$14^2)+(0.0000001001685*$R$14^3)-(0.000000001120083*$R$14^4)+(0.000000000006536332*$R$14^5)) -> 0.99754117
C19: Normalite de l'iodate (NIO3) à la température de calibration | O19: N(IO3) = | P19: =$P$24*($P$18/'Titre d''iodate'!E19) -> 0.019982863 | Q19: N
C20: Vol. de la prise d'essai d'iodate (VIO3) à 20°C | O20: V(IO3)20°C = | P20: =5+'Correction de volume'!G8 -> 5.00309 | Q20: mL
C21: Vol. de la prise d'essai d'iodate (VIO3) à t°c | O21: V(IO3)t°c= | P21: =P20*(1+0.00001*(R14-20)) -> 5.0032401 | Q21: mL
C22: Volume moyen de thiosulfate pour la titration à 20° C | O22: Vmoy.titr.20°C = | P22: =$R$16*(1+0.00001*(20-$R$14)) -> 4.9748507 | Q22: mL
C23: Volume moyen de thiosulfate pour la détermination du blanc à 20° C | O23: Vmoy.titr.blanc.20°C = | P23: =$R$17*(1+0.00001*(20-$R$14)) -> 0.00499985 | Q23: mL
C24: Normalite de l'iodate (NIO3) à 20°C | O24: N(IO3)20°C = | P24: =MAX('Titre d''iodate'!F7:F10) -> 0.019996187 | Q24: N
C25: Titre du thiosulfate à 20°C | O25: V(Thio)20°C = | P25: =IF(ISBLANK(R14),"",IF(ISBLANK(P21),"",IF(ISBLANK(R17),"",(($P$24*$P$18)/($P$22-$P$23))))) -> 0.0040136053 | Q25: N
C26: Volume de réactif utilisé | O26: Vreg = | P26: =2+('Correction de volume'!G10+'Correction de volume'!G9) -> 2.016394 | Q26: mL
O27: DOreg = | P27: 0.0017
E29: Choix de la série de flacons : | I29: IRD | O29: IRD
O30: LPO
C31: N° | D31: N° des Flacons | E31: T° prélèv. | F31: Volume de thio. | G31: Salinité | H31: Prof. Théorique | I31: Prof. Effective | J31: V. flacons 20°C | K31: A | L31: B | M31: Densité eau de mer à t° | N31: Vol. à t° prél. des flacons | O31: Densité eau pure à t° | P31: Oxygène dissous | T31: NO2 | V31: NO3 + NO2 | X31: NO3 | Z31: Phosphate | AB31: Silicate | AD31: chlorophyll-c3 | AE31: chlorophyll-c1+c2 | AF31: peridinin | AG31: 19'-butanoyloxyfucoxanthin | AH31: fucoxanthine | AI31: neoxanthin | AJ31: prasinoxanthin | AK31: violaxanthin | AL31: 19'-hexanoyloxyfucoxanthin | AM31: diadinoxanthin | AN31: alloxanthin | AO31: diatoxanthin | AP31: zeaxanthin | AQ31: lutein | AR31: divinyl chlorophyll-b | AS31: chlorophyll-b | AT31: total chlorophyll-b | AU31: alpha-carotene | AV31: beta-carotene | AW31: pheophorbide | AX31: divinyl chlorophyll-a | AY31: chlorophyll-a | AZ31: total chlorophyll-a | BA31: pheophytin_a | BB31: crocoxanthin
C33: BTL | E33: °C | F33: ml | H33: m | I33: m | J33: ml | P33: DOX1 | R33: DOXY | S33: DOX2 | T33: NTRI | U33: NTIW | V33: NTRZ | W33: NTZW | X33: NTRA | Y33: NTAW | Z33: PHOS | AA33: PHOW | AB33: SLCA | AC33: SLCW | AD33: CHC3 | AE33: CHCZ | AF33: PERP | AG33: BFUP | AH33: FUCP | AI33: NEXW | AJ33: PXAP | AK33: VIOW | AL33: HFUP | AM33: DXAP | AN33: AXAP | AO33: TXAP | AP33: ZXAP | AQ33: LUTW | AR33: CHBD | AS33: CH2P | AT33: CHLB | AU33: AACP | AV33: BBCP | AW33: PHEP | AX33: CHAD | AY33: CH1P | AZ33: CPHL | BA33: PHEA | BB33: CXAP
N34: mL | P34: ml/l | Q34: ml/kg | R34: µmol/l | S34: µmol/kg | T34: µmol/l | U34: µmol/kg | V34: µmol/l | W34: µmol/kg | X34: µmol/l | Y34: µmol/kg | Z34: µmol/l | AA34: µmol/kg | AB34: µmol/l | AC34: µmol/kg | AD34: µg.l-1 | AE34: µg.l-1 | AF34: µg.l-1 | AG34: µg.l-1 | AH34: µg.l-1 | AI34: µg.l-1 | AJ34: µg.l-1 | AK34: µg.l-1 | AL34: µg.l-1 | AM34: µg.l-1 | AN34: µg.l-1 | AO34: µg.l-1 | AP34: µg.l-1 | AQ34: µg.l-1 | AR34: µg.l-1 | AS34: µg.l-1 | AT34: µg.l-1 | AU34: µg.l-1 | AV34: µg.l-1 | AW34: µg.l-1 | AX34: µg.l-1 | AY34: µg.l-1 | AZ34: µg.l-1 | BA34: µg.l-1 | BB34: µg.l-1
A35: =IF(ISBLANK(VLOOKUP(D35,'Volumes flacons'!A5:C623,3)),0,1) -> 1 | B35: =IF(ISBLANK(D35),0,IF(ISBLANK(E35),0,IF(ISBLANK(F35),0,1))) -> 1 | C35: 1 | D35: 3196 | E35: 6.6 | F35: 5.862 | G35: 34.9655 | H35: 2000 | I35: 2021 | J35: 117.25 | K35: =IF(ISBLANK(E35),"",(0.000824493-(0.0000040899*E35)+(0.000000076438*E35^2)-(0.00000000082467*E35^3)+(0.0000000000053875*E35^4))) -> 0.00080060243 | L35: =IF(ISBLANK(E35),"",(-0.00000572466+(0.00000010227*E35)-(0.0000000016546*E35^2))) -> -5.1217524e-06 | M35: =IF(ISBLANK(E35),"",IF(ISBLANK(G35),(O35+(K35*35)+(L35*35^1.5)+(0.00000048314*35^2)),(O35+(K35*G35)+(L35*G35^1.5)+(0.00000048314*G35^2)))) -> 1.0274467 | N35: =IF(ISBLANK(D35),"",IF(ISBLANK(G35),J35*(1+0.00001*(35-20)),J35*(1+0.00001*(G35-20)))) -> 117.26755 | O35: =IF(ISBLANK(E35),"",(0.999842594+(0.00006793952*E35)-(0.00000909529*E35^2)+(0.0000001001685*E35^3)-(0.000000001120083*E35^4)+(0.000000000006536332*E35^5))) -> 0.99992156 | P35: 5.713 | Q35: 5.56 | R35: 255.1 | S35: 248.3
A36: =IF(ISBLANK(VLOOKUP(D36,'Volumes flacons'!A5:C623,3)),0,1) -> 1 | B36: =IF(ISBLANK(D36),0,IF(ISBLANK(E36),0,IF(ISBLANK(F36),0,1))) -> 1 | C36: 2 | D36: 3198 | E36: 7.7 | F36: 3.711 | G36: 34.6473 | H36: 1000 | I36: 1009 | J36: 117.21 | K36: =IF(ISBLANK(E36),"",(0.000824493-(0.0000040899*E36)+(0.000000076438*E36^2)-(0.00000000082467*E36^3)+(0.0000000000053875*E36^4))) -> 0.00079717523 | L36: =IF(ISBLANK(E36),"",(-0.00000572466+(0.00000010227*E36)-(0.0000000016546*E36^2))) -> -5.0352822e-06 | M36: =IF(ISBLANK(E36),"",IF(ISBLANK(G36),(O36+(K36*35)+(L36*35^1.5)+(0.00000048314*35^2)),(O36+(K36*G36)+(L36*G36^1.5)+(0.00000048314*G36^2)))) -> 1.0270415 | N36: =IF(ISBLANK(D36),"",IF(ISBLANK(G36),J36*(1+0.00001*(35-20)),J36*(1+0.00001*(G36-20)))) -> 117.22717 | O36: =IF(ISBLANK(E36),"",(0.999842594+(0.00006793952*E36)-(0.00000909529*E36^2)+(0.0000001001685*E36^3)-(0.000000001120083*E36^4)+(0.000000000006536332*E36^5))) -> 0.99986844 | P36: 3.612 | Q36: 3.517 | R36: 161.3 | S36: 157.1
