Workbook

Sheet 001_01
C2: Campagne : | F2: PIRATA Fr29
C4: Données de campagne
C6: N° de station : | F6: 1 | H6: N° de palanquée : | P6: 1 | R6: Date d'analyse : | T6: 42065
G8: Position | I8: Degrés | J8: Minutes | P8: Cardinal | Q8: Décimale
G9: Latitude | I9: 12 | J9: 29.57 | K9: : | L9: =IF(P9=M9,"+","-") -> + | M9: N | N9: E | O9: =IF(ISBLANK(I9),"",IF(ISBLANK(J9),"",IF(P9=M10,L9&N11,N11))) -> 12°29,57 | P9: N | Q9: =IF(ISBLANK(I9),"",IF(ISBLANK(J9),"",IF(J9>60,"ERREUR !!",O11*(I9+(J9/60))))) -> 12.492833
G10: Longitude | I10: 23 | J10: 20.56 | K10: : | L10: =IF(P10=N9,"+","-") -> - | M10: S | N10: W | O10: =IF(ISBLANK(I10),"",IF(ISBLANK(J10),"",IF(P10=N10,L10&N12,N12))) -> -23°20,56 | P10: W | Q10: =IF(ISBLANK(I10),"",IF(ISBLANK(J10),"",IF(J10>60,"ERREUR !!",O12*(I10+(J10/60))))) -> -23.342667
G11: Prélèvement | I11: Date | J11: 42064 | N11: =I9&"°"&J9 -> 12°29,57 | O11: =IF(P9=M10,-1,1) -> 1 | P11: =TEXT(J11,"aaaa-mm-jj")&"T"&TEXT(J12,"hh:mm:ss")&"z" -> 2019-03-02T17:46:13z | V11: 4.977
I12: Heure | J12: 0.74042824 | N12: =I10&"°"&J10 -> 23°20,56 | O12: =IF(P10=N10,-1,1) -> -1 | V12: 4.984
C13: Données : | V13: 4.989
C14: Température du laboratoire à la calibration ( t°c ) | Q14: t°c = | R14: 21.8 | S14: °C | V14: 4.9833
C15: Température du laboratoire au début de la série d'analyses | Q15: t°lab = | R15: 21.8 | S15: °C | V15: 4.9817
C16: Volume moyen de thiosulfate pour la titration à t°c | Q16: Vmoy.titr.t°c = | R16: 4.983 | S16: mL | V16: =AVERAGE(V11:V15) -> 4.983
C17: Volume moyen de thiosulfate pour la détermination du blanc à t°c | Q17: Vmoy.titr.blanc.t°c = | R17: 0.006 | S17: mL
C18: Masse volumique de l'eau pure à la calibration | O18: ρ = | P18: =(0.999842594+(0.00006793952*$R$14)-(0.00000909529*$R$14^2)+(0.0000001001685*$R$14^3)-(0.000000001120083*$R$14^4)+(0.000000000006536332*$R$14^5)) -> 0.99781821
C19: Normalite de l'iodate (NIO3) à la température de calibration | O19: N(IO3) = | P19: =$P$24*($P$18/'Titre d''iodate'!E19) -> 0.020021743 | Q19: N
C20: Vol. de la prise d'essai d'iodate (VIO3) à 20°C | O20: V(IO3)20°C = | P20: =5+'Correction de volume'!G8 -> 5.0112146 | Q20: mL
C21: Vol. de la prise d'essai d'iodate (VIO3) à t°c | O21: V(IO3)t°c= | P21: =P20*(1+0.00001*(R14-20)) -> 5.0113048 | Q21: mL
C22: Volume moyen de thiosulfate pour la titration à 20° C | O22: Vmoy.titr.20°C = | P22: =$R$16*(1+0.00001*(20-$R$14)) -> 4.9829103 | Q22: mL
C23: Volume moyen de thiosulfate pour la détermination du blanc à 20° C | O23: Vmoy.titr.blanc.20°C = | P23: =$R$17*(1+0.00001*(20-$R$14)) -> 0.005999892 | Q23: mL
C24: Normalite de l'iodate (NIO3) à 20°C | O24: N(IO3)20°C = | P24: =MAX('Titre d''iodate'!F7:F10) -> 0.020029531 | Q24: N
C25: Titre du thiosulfate à 20°C | O25: V(Thio)20°C = | P25: =IF(ISBLANK(R14),"",IF(ISBLANK(P21),"",IF(ISBLANK(R17),"",(($P$24*$P$18)/($P$22-$P$23))))) -> 0.0040157103 | Q25: N
C26: Volume de réactif utilisé | O26: Vreg = | P26: =2+('Correction de volume'!G10+'Correction de volume'!G9) -> 2.0304948 | Q26: mL
O27: DOreg = | P27: 0.0017
E29: Choix de la série de flacons : | I29: IRD | O29: IRD
O30: LPO
C31: N° | D31: N° des Flacons | E31: T° prélèv. | F31: Volume de thio. | G31: Salinité | H31: Prof. Théorique | I31: Prof. Effective | J31: V. flacons 20°C | K31: A | L31: B | M31: Densité eau de mer à t° | N31: Vol. à t° prél. des flacons | O31: Densité eau pure à t° | P31: Oxygène dissous | T31: NO2 | V31: NO3 + NO2 | X31: NO3 | Z31: Phosphate | AB31: Silicate | AD31: chlorophyll-c3 | AE31: chlorophyll-c1+c2 | AF31: peridinin | AG31: 19'-butanoyloxyfucoxanthin | AH31: fucoxanthine | AI31: neoxanthin | AJ31: prasinoxanthin | AK31: violaxanthin | AL31: 19'-hexanoyloxyfucoxanthin | AM31: diadinoxanthin | AN31: alloxanthin | AO31: diatoxanthin | AP31: zeaxanthin | AQ31: lutein | AR31: divinyl chlorophyll-b | AS31: chlorophyll-b | AT31: total chlorophyll-b | AU31: alpha-carotene | AV31: beta-carotene | AW31: pheophorbide | AX31: divinyl chlorophyll-a | AY31: chlorophyll-a | AZ31: total chlorophyll-a | BA31: pheophytin_a | BB31: crocoxanthin
C33: BTL | E33: °C | F33: ml | H33: m | I33: dbar | J33: ml | P33: DOX1 | R33: DOXY | S33: DOX2 | T33: NTRI | U33: NTIW | V33: NTRZ | W33: NTZW | X33: NTRA | Y33: NTAW | Z33: PHOS | AA33: PHOW | AB33: SLCA | AC33: SLCW | AD33: CHC3 | AE33: CHCZ | AF33: PERP | AG33: BFUP | AH33: FUCP | AI33: NEXW | AJ33: PXAP | AK33: VIOW | AL33: HFUP | AM33: DXAP | AN33: AXAP | AO33: TXAP | AP33: ZXAP | AQ33: LUTW | AR33: CHBD | AS33: CH2P | AT33: CHLB | AU33: AACP | AV33: BBCP | AW33: PHEP | AX33: CHAD | AY33: CH1P | AZ33: CPHL | BA33: PHEA | BB33: CXAP
N34: mL | P34: ml/l | Q34: ml/kg | R34: µmol/l | S34: µmol/kg | T34: µmol/l | U34: µmol/kg | V34: µmol/l | W34: µmol/kg | X34: µmol/l | Y34: µmol/kg | Z34: µmol/l | AA34: µmol/kg | AB34: µmol/l | AC34: µmol/kg | AD34: µg.l-1 | AE34: µg.l-1 | AF34: µg.l-1 | AG34: µg.l-1 | AH34: µg.l-1 | AI34: µg.l-1 | AJ34: µg.l-1 | AK34: µg.l-1 | AL34: µg.l-1 | AM34: µg.l-1 | AN34: µg.l-1 | AO34: µg.l-1 | AP34: µg.l-1 | AQ34: µg.l-1 | AR34: µg.l-1 | AS34: µg.l-1 | AT34: µg.l-1 | AU34: µg.l-1 | AV34: µg.l-1 | AW34: µg.l-1 | AX34: µg.l-1 | AY34: µg.l-1 | AZ34: µg.l-1 | BA34: µg.l-1 | BB34: µg.l-1
A35: =IF(ISBLANK(VLOOKUP(D35,'Volumes flacons'!A5:C623,3)),0,1) -> 1 | B35: =IF(ISBLANK(D35),0,IF(ISBLANK(E35),0,IF(ISBLANK(F35),0,1))) -> 1 | C35: 1 | D35: 2001 | E35: 6.4 | F35: 5.346 | G35: 34.88955 | H35: 4000 | I35: 4068 | J35: =IF(ISBLANK(D35),"",IF(VLOOKUP(D35,'Volumes flacons'!$A$5:$C$1023,2)=0,"",IF(D35>'Volumes flacons'!$A$1023,"Mauvais numéro",IF(D35<'Volumes flacons'!$A$5,"Mauvais numéro",(VLOOKUP(D35,'Volumes flacons'!$A$5:$C$1023,3)))))) -> 110.84 | K35: =IF(ISBLANK(E35),"",(0.000824493-(0.0000040899*E35)+(0.000000076438*E35^2)-(0.00000000082467*E35^3)+(0.0000000000053875*E35^4))) -> 0.0008012414 | L35: =IF(ISBLANK(E35),"",(-0.00000572466+(0.00000010227*E35)-(0.0000000016546*E35^2))) -> -5.1379044e-06 | M35: =IF(ISBLANK(E35),"",IF(ISBLANK(G35),(O35+(K35*35)+(L35*35^1.5)+(0.00000048314*35^2)),(O35+(K35*G35)+(L35*G35^1.5)+(0.00000048314*G35^2)))) -> 1.0274135 | N35: =IF(ISBLANK(D35),"",IF(ISBLANK(G35),J35*(1+0.00001*(35-20)),J35*(1+0.00001*(G35-20)))) -> 110.8565 | O35: =IF(ISBLANK(E35),"",(0.999842594+(0.00006793952*E35)-(0.00000909529*E35^2)+(0.0000001001685*E35^3)-(0.000000001120083*E35^4)+(0.000000000006536332*E35^5))) -> 0.99992931 | P35: =IF(ISBLANK($R$16),"",IF(A35=0,"",IF(ISBLANK($R$17),"",IF(B35=0,"",IF($O$28=$I$29,"",IF(AND($I$29=$O$29,D35<1000),"N° Flac.",IF(AND($I$29=$O$30,D35>1000),"N° Flac.",IF(AND(D35>1202,D35<2001),"Err. N°",IF(AND(D35>499,D35<1141),"Err.N°",(((((F35)+'Correction de volume'!$G$7)*(($P$21)*($P$19)*5598)/(($R$16)-($R$17)))-(($P$27)*1000))/((N35)-($P$26)))))))))))) -> 5.5281081 | Q35: =IF(ISBLANK($R$16),"",IF(A35=0,"",IF(ISBLANK($R$17),"",IF(AND(D35>1202,D35<2001),"Err. N°",IF(AND(D35>499,D35<1141),"Err.N°",IF(B35=0,"",IF($O$28=$I$29,"",IF(AND($I$29=$O$29,D35<1000),"N° Flac.",IF(AND($I$29=$O$30,D35>1000),"N° Flac.",P35/M35))))))))) -> 5.3806066 | R35: =IF(ISBLANK($R$16),"",IF(A35=0,"",IF(ISBLANK($R$17),"",IF(B35=0,"",IF(ISBLANK(J35),"",IF(AND(D35>1202,D35<2001),"Err. N°",IF(AND(D35>499,D35<1141),"Err.N°",IF($I$29=$O$28,"",IF(AND($I$29=$O$29,D35<1000),"N° Flac.",IF(AND($I$29=$O$30,D35>1000),"N° Flac.",((44.66*P35)))))))))))) -> 246.88531 | S35: =IF(ISBLANK($R$16),"",IF(A35=0,"",IF(ISBLANK($R$17),"",IF(B35=0,"",IF(ISBLANK(J35),"",IF(AND(D35>1202,D35<2001),"Err. N°",IF(AND(D35>499,D35<1141),"Err.N°",IF($I$29=$O$28,"",IF(AND($I$29=$O$29,D35<1000),"N° Flac.",IF(AND($I$29=$O$30,D35>1000),"N° Flac.",((44.66*P35)/M35))))))))))) -> 240.29789 | T35: 0 | U35: 0 | V35: 22.99 | W35: 22.47 | X35: 22.99 | Y35: 22.47 | Z35: 1.44 | AA35: 1.41 | AB35: 47.74 | AC35: 46.65
A36: =IF(ISBLANK(VLOOKUP(D36,'Volumes flacons'!A5:C623,3)),0,1) -> 1 | B36: =IF(ISBLANK(D36),0,IF(ISBLANK(E36),0,IF(ISBLANK(F36),0,1))) -> 1 | C36: 2 | D36: 2002 | E36: 6.5 | F36: 5.2301 | G36: 34.89145 | H36: 4000 | I36: 4067 | J36: =IF(ISBLANK(D36),"",IF(VLOOKUP(D36,'Volumes flacons'!$A$5:$C$1023,2)=0,"",IF(D36>'Volumes flacons'!$A$1023,"Mauvais numéro",IF(D36<'Volumes flacons'!$A$5,"Mauvais numéro",(VLOOKUP(D36,'Volumes flacons'!$A$5:$C$1023,3)))))) -> 108.59 | K36: =IF(ISBLANK(E36),"",(0.000824493-(0.0000040899*E36)+(0.000000076438*E36^2)-(0.00000000082467*E36^3)+(0.0000000000053875*E36^4))) -> 0.0008009213 | L36: =IF(ISBLANK(E36),"",(-0.00000572466+(0.00000010227*E36)-(0.0000000016546*E36^2))) -> -5.1298118e-06 | M36: =IF(ISBLANK(E36),"",IF(ISBLANK(G36),(O36+(K36*35)+(L36*35^1.5)+(0.00000048314*35^2)),(O36+(K36*G36)+(L36*G36^1.5)+(0.00000048314*G36^2)))) -> 1.0274017 | N36: =IF(ISBLANK(D36),"",IF(ISBLANK(G36),J36*(1+0.00001*(35-20)),J36*(1+0.00001*(G36-20)))) -> 108.60617 | O36: =IF(ISBLANK(E36),"",(0.999842594+(0.00006793952*E36)-(0.00000909529*E36^2)+(0.0000001001685*E36^3)-(0.000000001120083*E36^4)+(0.000000000006536332*E36^5))) -> 0.99992551 | P36: =IF(ISBLANK($R$16),"",IF(A36=0,"",IF(ISBLANK($R$17),"",IF(B36=0,"",IF($O$28=$I$29,"",IF(AND($I$29=$O$29,D36<1000),"N° Flac.",IF(AND($I$29=$O$30,D36>1000),"N° Flac.",IF(AND(D36>1202,D36<2001),"Err. N°",IF(AND(D36>499,D36<1141),"Err.N°",(((((F36)+'Correction de volume'!$G$7)*(($P$21)*($P$19)*5598)/(($R$16)-($R$17)))-(($P$27)*1000))/((N36)-($P$26)))))))))))) -> 5.5221056 | Q36: =IF(ISBLANK($R$16),"",IF(A36=0,"",IF(ISBLANK($R$17),"",IF(AND(D36>1202,D36<2001),"Err. N°",IF(AND(D36>499,D36<1141),"Err.N°",IF(B36=0,"",IF($O$28=$I$29,"",IF(AND($I$29=$O$29,D36<1000),"N° Flac.",IF(AND($I$29=$O$30,D36>1000),"N° Flac.",P36/M36))))))))) -> 5.374826 | R36: =IF(ISBLANK($R$16),"",IF(A36=0,"",IF(ISBLANK($R$17),"",IF(B36=0,"",IF(ISBLANK(J36),"",IF(AND(D36>1202,D36<2001),"Err. N°",IF(AND(D36>499,D36<1141),"Err.N°",IF($I$29=$O$28,"",IF(AND($I$29=$O$29,D36<1000),"N° Flac.",IF(AND($I$29=$O$30,D36>1000),"N° Flac.",((44.66*P36)))))))))))) -> 246.61723 | S36: =IF(ISBLANK($R$16),"",IF(A36=0,"",IF(ISBLANK($R$17),"",IF(B36=0,"",IF(ISBLANK(J36),"",IF(AND(D36>1202,D36<2001),"Err. N°",IF(AND(D36>499,D36<1141),"Err.N°",IF($I$29=$O$28,"",IF(AND($I$29=$O$29,D36<1000),"N° Flac.",IF(AND($I$29=$O$30,D36>1000),"N° Flac.",((44.66*P36)/M36))))))))))) -> 240.03973 | T36: 0 | U36: 0 | V36: 23.05 | W36: 22.52 | X36: 23.05 | Y36: 22.52 | Z36: 1.46 | AA36: 1.43 | AB36: 47.79 | AC36: 46.7
A37: =IF(ISBLANK(VLOOKUP(D37,'Volumes flacons'!A5:C623,3)),0,1) -> 1 | B37: =IF(ISBLANK(D37),0,IF(ISBLANK(E37),0,IF(ISBLANK(F37),0,1))) -> 1 | C37: 3 | D37: 2004 | E37: 7.6 | F37: 5.3296 | G37: 34.89015 | H37: 4000 | I37: 4069 | J37: =IF(ISBLANK(D37),"",IF(VLOOKUP(D37,'Volumes flacons'!$A$5:$C$1023,2)=0,"",IF(D37>'Volumes flacons'!$A$1023,"Mauvais numéro",IF(D37<'Volumes flacons'!$A$5,"Mauvais numéro",(VLOOKUP(D37,'Volumes flacons'!$A$5:$C$1023,3)))))) -> 110.33 | K37: =IF(ISBLANK(E37),"",(0.000824493-(0.0000040899*E37)+(0.000000076438*E37^2)-(0.00000000082467*E37^3)+(0.0000000000053875*E37^4))) -> 0.00079748078 | L37: =IF(ISBLANK(E37),"",(-0.00000572466+(0.00000010227*E37)-(0.0000000016546*E37^2))) -> -5.0429777e-06 | M37: =IF(ISBLANK(E37),"",IF(ISBLANK(G37),(O37+(K37*35)+(L37*35^1.5)+(0.00000048314*35^2)),(O37+(K37*G37)+(L37*G37^1.5)+(0.00000048314*G37^2)))) -> 1.0272471 | N37: =IF(ISBLANK(D37),"",IF(ISBLANK(G37),J37*(1+0.00001*(35-20)),J37*(1+0.00001*(G37-20)))) -> 110.34643 | O37: =IF(ISBLANK(E37),"",(0.999842594+(0.00006793952*E37)-(0.00000909529*E37^2)+(0.0000001001685*E37^3)-(0.000000001120083*E37^4)+(0.000000000006536332*E37^5))) -> 0.99987399 | P37: =IF(ISBLANK($R$16),"",IF(A37=0,"",IF(ISBLANK($R$17),"",IF(B37=0,"",IF($O$28=$I$29,"",IF(AND($I$29=$O$29,D37<1000),"N° Flac.",IF(AND($I$29=$O$30,D37>1000),"N° Flac.",IF(AND(D37>1202,D37<2001),"Err. N°",IF(AND(D37>499,D37<1141),"Err.N°",(((((F37)+'Correction de volume'!$G$7)*(($P$21)*($P$19)*5598)/(($R$16)-($R$17)))-(($P$27)*1000))/((N37)-($P$26)))))))))))) -> 5.5370536 | Q37: =IF(ISBLANK($R$16),"",IF(A37=0,"",IF(ISBLANK($R$17),"",IF(AND(D37>1202,D37<2001),"Err. N°",IF(AND(D37>499,D37<1141),"Err.N°",IF(B37=0,"",IF($O$28=$I$29,"",IF(AND($I$29=$O$29,D37<1000),"N° Flac.",IF(AND($I$29=$O$30,D37>1000),"N° Flac.",P37/M37))))))))) -> 5.3901869 | R37: =IF(ISBLANK($R$16),"",IF(A37=0,"",IF(ISBLANK($R$17),"",IF(B37=0,"",IF(ISBLANK(J37),"",IF(AND(D37>1202,D37<2001),"Err. N°",IF(AND(D37>499,D37<1141),"Err.N°",IF($I$29=$O$28,"",IF(AND($I$29=$O$29,D37<1000),"N° Flac.",IF(AND($I$29=$O$30,D37>1000),"N° Flac.",((44.66*P37)))))))))))) -> 247.28481 | S37: =IF(ISBLANK($R$16),"",IF(A37=0,"",IF(ISBLANK($R$17),"",IF(B37=0,"",IF(ISBLANK(J37),"",IF(AND(D37>1202,D37<2001),"Err. N°",IF(AND(D37>499,D37<1141),"Err.N°",IF($I$29=$O$28,"",IF(AND($I$29=$O$29,D37<1000),"N° Flac.",IF(AND($I$29=$O$30,D37>1000),"N° Flac.",((44.66*P37)/M37))))))))))) -> 240.72575 | T37: 0 | U37: 0 | V37: 23.08 | W37: 22.55 | X37: 23.08 | Y37: 22.55 | Z37: 1.47 | AA37: 1.44 | AB37: 47.8 | AC37: 46.71
A38: =IF(ISBLANK(VLOOKUP(D38,'Volumes flacons'!A5:C623,3)),0,1) -> 1 | B38: =IF(ISBLANK(D38),0,IF(ISBLANK(E38),0,IF(ISBLANK(F38),0,1))) -> 1 | C38: 4 | D38: 2006 | E38: 7.4 | F38: 5.2629 | G38: 34.88985 | H38: 4000 | I38: 4067 | J38: =IF(ISBLANK(D38),"",IF(VLOOKUP(D38,'Volumes flacons'!$A$5:$C$1023,2)=0,"",IF(D38>'Volumes flacons'!$A$1023,"Mauvais numéro",IF(D38<'Volumes flacons'!$A$5,"Mauvais numéro",(VLOOKUP(D38,'Volumes flacons'!$A$5:$C$1023,3)))))) -> 108.87 | K38: =IF(ISBLANK(E38),"",(0.000824493-(0.0000040899*E38)+(0.000000076438*E38^2)-(0.00000000082467*E38^3)+(0.0000000000053875*E38^4))) -> 0.00079809546 | L38: =IF(ISBLANK(E38),"",(-0.00000572466+(0.00000010227*E38)-(0.0000000016546*E38^2))) -> -5.0584679e-06 | M38: =IF(ISBLANK(E38),"",IF(ISBLANK(G38),(O38+(K38*35)+(L38*35^1.5)+(0.00000048314*35^2)),(O38+(K38*G38)+(L38*G38^1.5)+(0.00000048314*G38^2)))) -> 1.0272757 | N38: =IF(ISBLANK(D38),"",IF(ISBLANK(G38),J38*(1+0.00001*(35-20)),J38*(1+0.00001*(G38-20)))) -> 108.88621 | O38: =IF(ISBLANK(E38),"",(0.999842594+(0.00006793952*E38)-(0.00000909529*E38^2)+(0.0000001001685*E38^3)-(0.000000001120083*E38^4)+(0.000000000006536332*E38^5))) -> 0.99988467 | P38: =IF(ISBLANK($R$16),"",IF(A38=0,"",IF(ISBLANK($R$17),"",IF(B38=0,"",IF($O$28=$I$29,"",IF(AND($I$29=$O$29,D38<1000),"N° Flac.",IF(AND($I$29=$O$30,D38>1000),"N° Flac.",IF(AND(D38>1202,D38<2001),"Err. N°",IF(AND(D38>499,D38<1141),"Err.N°",(((((F38)+'Correction de volume'!$G$7)*(($P$21)*($P$19)*5598)/(($R$16)-($R$17)))-(($P$27)*1000))/((N38)-($P$26)))))))))))) -> 5.5422749 | Q38: =IF(ISBLANK($R$16),"",IF(A38=0,"",IF(ISBLANK($R$17),"",IF(AND(D38>1202,D38<2001),"Err. N°",IF(AND(D38>499,D38<1141),"Err.N°",IF(B38=0,"",IF($O$28=$I$29,"",IF(AND($I$29=$O$29,D38<1000),"N° Flac.",IF(AND($I$29=$O$30,D38>1000),"N° Flac.",P38/M38))))))))) -> 5.395119 | R38: =IF(ISBLANK($R$16),"",IF(A38=0,"",IF(ISBLANK($R$17),"",IF(B38=0,"",IF(ISBLANK(J38),"",IF(AND(D38>1202,D38<2001),"Err. N°",IF(AND(D38>499,D38<1141),"Err.N°",IF($I$29=$O$28,"",IF(AND($I$29=$O$29,D38<1000),"N° Flac.",IF(AND($I$29=$O$30,D38>1000),"N° Flac.",((44.66*P38)))))))))))) -> 247.518 | S38: =IF(ISBLANK($R$16),"",IF(A38=0,"",IF(ISBLANK($R$17),"",IF(B38=0,"",IF(ISBLANK(J38),"",IF(AND(D38>1202,D38<2001),"Err. N°",IF(AND(D38>499,D38<1141),"Err.N°",IF($I$29=$O$28,"",IF(AND($I$29=$O$29,D38<1000),"N° Flac.",IF(AND($I$29=$O$30,D38>1000),"N° Flac.",((44.66*P38)/M38))))))))))) -> 240.94602 | T38: 0 | U38: 0 | V38: 22.89 | W38: 22.37 | X38: 22.89 | Y38: 22.37 | Z38: 1.47 | AA38: 1.44 | AB38: 47.85 | AC38: 46.76
A39: =IF(ISBLANK(VLOOKUP(D39,'Volumes flacons'!A5:C623,3)),0,1) -> 1 | B39: =IF(ISBLANK(D39),0,IF(ISBLANK(E39),0,IF(ISBLANK(F39),0,1))) -> 1 | C39: 5 | D39: 2007 | E39: 7.5 | F39: 5.3084 | G39: 34.891 | H39: 4000 | I39: 4067 | J39: =IF(ISBLANK(D39),"",IF(VLOOKUP(D39,'Volumes flacons'!$A$5:$C$1023,2)=0,"",IF(D39>'Volumes flacons'!$A$1023,"Mauvais numéro",IF(D39<'Volumes flacons'!$A$5,"Mauvais numéro",(VLOOKUP(D39,'Volumes flacons'!$A$5:$C$1023,3)))))) -> 109.77 | K39: =IF(ISBLANK(E39),"",(0.000824493-(0.0000040899*E39)+(0.000000076438*E39^2)-(0.00000000082467*E39^3)+(0.0000000000053875*E39^4))) -> 0.00079778753 | L39: =IF(ISBLANK(E39),"",(-0.00000572466+(0.00000010227*E39)-(0.0000000016546*E39^2))) -> -5.0507063e-06 | M39: =IF(ISBLANK(E39),"",IF(ISBLANK(G39),(O39+(K39*35)+(L39*35^1.5)+(0.00000048314*35^2)),(O39+(K39*G39)+(L39*G39^1.5)+(0.00000048314*G39^2)))) -> 1.0272622 | N39: =IF(ISBLANK(D39),"",IF(ISBLANK(G39),J39*(1+0.00001*(35-20)),J39*(1+0.00001*(G39-20)))) -> 109.78635 | O39: =IF(ISBLANK(E39),"",(0.999842594+(0.00006793952*E39)-(0.00000909529*E39^2)+(0.0000001001685*E39^3)-(0.000000001120083*E39^4)+(0.000000000006536332*E39^5))) -> 0.9998794 | P39: =IF(ISBLANK($R$16),"",IF(A39=0,"",IF(ISBLANK($R$17),"",IF(B39=0,"",IF($O$28=$I$29,"",IF(AND($I$29=$O$29,D39<1000),"N° Flac.",IF(AND($I$29=$O$30,D39>1000),"N° Flac.",IF(AND(D39>1202,D39<2001),"Err. N°",IF(AND(D39>499,D39<1141),"Err.N°",(((((F39)+'Correction de volume'!$G$7)*(($P$21)*($P$19)*5598)/(($R$16)-($R$17)))-(($P$27)*1000))/((N39)-($P$26)))))))))))) -> 5.5436305 | Q39: =IF(ISBLANK($R$16),"",IF(A39=0,"",IF(ISBLANK($R$17),"",IF(AND(D39>1202,D39<2001),"Err. N°",IF(AND(D39>499,D39<1141),"Err.N°",IF(B39=0,"",IF($O$28=$I$29,"",IF(AND($I$29=$O$29,D39<1000),"N° Flac.",IF(AND($I$29=$O$30,D39>1000),"N° Flac.",P39/M39))))))))) -> 5.3965096 | R39: =IF(ISBLANK($R$16),"",IF(A39=0,"",IF(ISBLANK($R$17),"",IF(B39=0,"",IF(ISBLANK(J39),"",IF(AND(D39>1202,D39<2001),"Err. N°",IF(AND(D39>499,D39<1141),"Err.N°",IF($I$29=$O$28,"",IF(AND($I$29=$O$29,D39<1000),"N° Flac.",IF(AND($I$29=$O$30,D39>1000),"N° Flac.",((44.66*P39)))))))))))) -> 247.57854 | S39: =IF(ISBLANK($R$16),"",IF(A39=0,"",IF(ISBLANK($R$17),"",IF(B39=0,"",IF(ISBLANK(J39),"",IF(AND(D39>1202,D39<2001),"Err. N°",IF(AND(D39>499,D39<1141),"Err.N°",IF($I$29=$O$28,"",IF(AND($I$29=$O$29,D39<1000),"N° Flac.",IF(AND($I$29=$O$30,D39>1000),"N° Flac.",((44.66*P39)/M39))))))))))) -> 241.00812 | T39: 0.01 | U39: 0.01 | V39: 22.85 | W39: 22.33 | X39: 22.84 | Y39: 22.32 | Z39: 1.48 | AA39: 1.45 | AB39: 47.88 | AC39: 46.79
A40: =IF(ISBLANK(VLOOKUP(D40,'Volumes flacons'!A5:C623,3)),0,1) -> 1 | B40: =IF(ISBLANK(D40),0,IF(ISBLANK(E40),0,IF(ISBLANK(F40),0,1))) -> 1 | C40: 6 | D40: 2008 | E40: 7.7 | F40: 5.2729 | G40: 34.8898 | H40: 4000 | I40: 4068 | J40: =IF(ISBLANK(D40),"",IF(VLOOKUP(D40,'Volumes flacons'!$A$5:$C$1023,2)=0,"",IF(D40>'Volumes flacons'!$A$1023,"Mauvais numéro",IF(D40<'Volumes flacons'!$A$5,"Mauvais numéro",(VLOOKUP(D40,'Volumes flacons'!$A$5:$C$1023,3)))))) -> 108.85 | K40: =IF(ISBLANK(E40),"",(0.000824493-(0.0000040899*E40)+(0.000000076438*E40^2)-(0.00000000082467*E40^3)+(0.0000000000053875*E40^4))) -> 0.00079717523 | L40: =IF(ISBLANK(E40),"",(-0.00000572466+(0.00000010227*E40)-(0.0000000016546*E40^2))) -> -5.0352822e-06 | M40: =IF(ISBLANK(E40),"",IF(ISBLANK(G40),(O40+(K40*35)+(L40*35^1.5)+(0.00000048314*35^2)),(O40+(K40*G40)+(L40*G40^1.5)+(0.00000048314*G40^2)))) -> 1.0272321 | N40: =IF(ISBLANK(D40),"",IF(ISBLANK(G40),J40*(1+0.00001*(35-20)),J40*(1+0.00001*(G40-20)))) -> 108.86621 | O40: =IF(ISBLANK(E40),"",(0.999842594+(0.00006793952*E40)-(0.00000909529*E40^2)+(0.0000001001685*E40^3)-(0.000000001120083*E40^4)+(0.000000000006536332*E40^5))) -> 0.99986844 | P40: =IF(ISBLANK($R$16),"",IF(A40=0,"",IF(ISBLANK($R$17),"",IF(B40=0,"",IF($O$28=$I$29,"",IF(AND($I$29=$O$29,D40<1000),"N° Flac.",IF(AND($I$29=$O$30,D40>1000),"N° Flac.",IF(AND(D40>1202,D40<2001),"Err. N°",IF(AND(D40>499,D40<1141),"Err.N°",(((((F40)+'Correction de volume'!$G$7)*(($P$21)*($P$19)*5598)/(($R$16)-($R$17)))-(($P$27)*1000))/((N40)-($P$26)))))))))))) -> 5.5538759 | Q40: =IF(ISBLANK($R$16),"",IF(A40=0,"",IF(ISBLANK($R$17),"",IF(AND(D40>1202,D40<2001),"Err. N°",IF(AND(D40>499,D40<1141),"Err.N°",IF(B40=0,"",IF($O$28=$I$29,"",IF(AND($I$29=$O$29,D40<1000),"N° Flac.",IF(AND($I$29=$O$30,D40>1000),"N° Flac.",P40/M40))))))))) -> 5.4066415 | R40: =IF(ISBLANK($R$16),"",IF(A40=0,"",IF(ISBLANK($R$17),"",IF(B40=0,"",IF(ISBLANK(J40),"",IF(AND(D40>1202,D40<2001),"Err. N°",IF(AND(D40>499,D40<1141),"Err.N°",IF($I$29=$O$28,"",IF(AND($I$29=$O$29,D40<1000),"N° Flac.",IF(AND($I$29=$O$30,D40>1000),"N° Flac.",((44.66*P40)))))))))))) -> 248.0361 | S40: =IF(ISBLANK($R$16),"",IF(A40=0,"",IF(ISBLANK($R$17),"",IF(B40=0,"",IF(ISBLANK(J40),"",IF(AND(D40>1202,D40<2001),"Err. N°",IF(AND(D40>499,D40<1141),"Err.N°",IF($I$29=$O$28,"",IF(AND($I$29=$O$29,D40<1000),"N° Flac.",IF(AND($I$29=$O$30,D40>1000),"N° Flac.",((44.66*P40)/M40))))))))))) -> 241.46061 | T40: 0 | U40: 0 | V40: 22.95 | W40: 22.43 | X40: 22.95 | Y40: 22.43 | Z40: 1.51 | AA40: 1.48 | AB40: 47.99 | AC40: 46.9
A41: =IF(ISBLANK(VLOOKUP(D41,'Volumes flacons'!A5:C623,3)),0,1) -> 1 | B41: =IF(ISBLANK(D41),0,IF(ISBLANK(E41),0,IF(ISBLANK(F41),0,1))) -> 1 | C41: 7 | D41: 2009 | E41: 8.2 | F41: 5.3093 | G41: 34.89355 | H41: 4000 | I41: 4067 | J41: =IF(ISBLANK(D41),"",IF(VLOOKUP(D41,'Volumes flacons'!$A$5:$C$1023,2)=0,"",IF(D41>'Volumes flacons'!$A$1023,"Mauvais numéro",IF(D41<'Volumes flacons'!$A$5,"Mauvais numéro",(VLOOKUP(D41,'Volumes flacons'!$A$5:$C$1023,3)))))) -> 109.15 | K41: =IF(ISBLANK(E41),"",(0.000824493-(0.0000040899*E41)+(0.000000076438*E41^2)-(0.00000000082467*E41^3)+(0.0000000000053875*E41^4))) -> 0.00079566517 | L41: =IF(ISBLANK(E41),"",(-0.00000572466+(0.00000010227*E41)-(0.0000000016546*E41^2))) -> -4.9973013e-06 | M41: =IF(ISBLANK(E41),"",IF(ISBLANK(G41),(O41+(K41*35)+(L41*35^1.5)+(0.00000048314*35^2)),(O41+(K41*G41)+(L41*G41^1.5)+(0.00000048314*G41^2)))) -> 1.0271603 | N41: =IF(ISBLANK(D41),"",IF(ISBLANK(G41),J41*(1+0.00001*(35-20)),J41*(1+0.00001*(G41-20)))) -> 109.16626 | O41: =IF(ISBLANK(E41),"",(0.999842594+(0.00006793952*E41)-(0.00000909529*E41^2)+(0.0000001001685*E41^3)-(0.000000001120083*E41^4)+(0.000000000006536332*E41^5))) -> 0.99983854 | P41: =IF(ISBLANK($R$16),"",IF(A41=0,"",IF(ISBLANK($R$17),"",IF(B41=0,"",IF($O$28=$I$29,"",IF(AND($I$29=$O$29,D41<1000),"N° Flac.",IF(AND($I$29=$O$30,D41>1000),"N° Flac.",IF(AND(D41>1202,D41<2001),"Err. N°",IF(AND(D41>499,D41<1141),"Err.N°",(((((F41)+'Correction de volume'!$G$7)*(($P$21)*($P$19)*5598)/(($R$16)-($R$17)))-(($P$27)*1000))/((N41)-($P$26)))))))))))) -> 5.5766644 | Q41: =IF(ISBLANK($R$16),"",IF(A41=0,"",IF(ISBLANK($R$17),"",IF(AND(D41>1202,D41<2001),"Err. N°",IF(AND(D41>499,D41<1141),"Err.N°",IF(B41=0,"",IF($O$28=$I$29,"",IF(AND($I$29=$O$29,D41<1000),"N° Flac.",IF(AND($I$29=$O$30,D41>1000),"N° Flac.",P41/M41))))))))) -> 5.4292054 | R41: =IF(ISBLANK($R$16),"",IF(A41=0,"",IF(ISBLANK($R$17),"",IF(B41=0,"",IF(ISBLANK(J41),"",IF(AND(D41>1202,D41<2001),"Err. N°",IF(AND(D41>499,D41<1141),"Err.N°",IF($I$29=$O$28,"",IF(AND($I$29=$O$29,D41<1000),"N° Flac.",IF(AND($I$29=$O$30,D41>1000),"N° Flac.",((44.66*P41)))))))))))) -> 249.05383 | S41: =IF(ISBLANK($R$16),"",IF(A41=0,"",IF(ISBLANK($R$17),"",IF(B41=0,"",IF(ISBLANK(J41),"",IF(AND(D41>1202,D41<2001),"Err. N°",IF(AND(D41>499,D41<1141),"Err.N°",IF($I$29=$O$28,"",IF(AND($I$29=$O$29,D41<1000),"N° Flac.",IF(AND($I$29=$O$30,D41>1000),"N° Flac.",((44.66*P41)/M41))))))))))) -> 242.46831 | T41: 0.01 | U41: 0.01 | V41: 22.94 | W41: 22.42 | X41: 22.93 | Y41: 22.41 | Z41: 1.46 | AA41: 1.43 | AB41: 47.64 | AC41: 46.55
A42: =IF(ISBLANK(VLOOKUP(D42,'Volumes flacons'!A5:C623,3)),0,1) -> 1 | B42: =IF(ISBLANK(D42),0,IF(ISBLANK(E42),0,IF(ISBLANK(F42),0,1))) -> 1 | C42: 8 | D42: 2010 | E42: 8.4 | F42: 5.3008 | G42: 34.8926 | H42: 4000 | I42: 4071 | J42: =IF(ISBLANK(D42),"",IF(VLOOKUP(D42,'Volumes flacons'!$A$5:$C$1023,2)=0,"",IF(D42>'Volumes flacons'!$A$1023,"Mauvais numéro",IF(D42<'Volumes flacons'!$A$5,"Mauvais numéro",(VLOOKUP(D42,'Volumes flacons'!$A$5:$C$1023,3)))))) -> 109.42 | K42: =IF(ISBLANK(E42),"",(0.000824493-(0.0000040899*E42)+(0.000000076438*E42^2)-(0.00000000082467*E42^3)+(0.0000000000053875*E42^4))) -> 0.00079506934 | L42: =IF(ISBLANK(E42),"",(-0.00000572466+(0.00000010227*E42)-(0.0000000016546*E42^2))) -> -4.9823406e-06 | M42: =IF(ISBLANK(E42),"",IF(ISBLANK(G42),(O42+(K42*35)+(L42*35^1.5)+(0.00000048314*35^2)),(O42+(K42*G42)+(L42*G42^1.5)+(0.00000048314*G42^2)))) -> 1.0271289 | N42: =IF(ISBLANK(D42),"",IF(ISBLANK(G42),J42*(1+0.00001*(35-20)),J42*(1+0.00001*(G42-20)))) -> 109.4363 | O42: =IF(ISBLANK(E42),"",(0.999842594+(0.00006793952*E42)-(0.00000909529*E42^2)+(0.0000001001685*E42^3)-(0.000000001120083*E42^4)+(0.000000000006536332*E42^5))) -> 0.99982559 | P42: =IF(ISBLANK($R$16),"",IF(A42=0,"",IF(ISBLANK($R$17),"",IF(B42=0,"",IF($O$28=$I$29,"",IF(AND($I$29=$O$29,D42<1000),"N° Flac.",IF(AND($I$29=$O$30,D42>1000),"N° Flac.",IF(AND(D42>1202,D42<2001),"Err. N°",IF(AND(D42>499,D42<1141),"Err.N°",(((((F42)+'Correction de volume'!$G$7)*(($P$21)*($P$19)*5598)/(($R$16)-($R$17)))-(($P$27)*1000))/((N42)-($P$26)))))))))))) -> 5.5537124 | Q42: =IF(ISBLANK($R$16),"",IF(A42=0,"",IF(ISBLANK($R$17),"",IF(AND(D42>1202,D42<2001),"Err. N°",IF(AND(D42>499,D42<1141),"Err.N°",IF(B42=0,"",IF($O$28=$I$29,"",IF(AND($I$29=$O$29,D42<1000),"N° Flac.",IF(AND($I$29=$O$30,D42>1000),"N° Flac.",P42/M42))))))))) -> 5.4070256 | R42: =IF(ISBLANK($R$16),"",IF(A42=0,"",IF(ISBLANK($R$17),"",IF(B42=0,"",IF(ISBLANK(J42),"",IF(AND(D42>1202,D42<2001),"Err. N°",IF(AND(D42>499,D42<1141),"Err.N°",IF($I$29=$O$28,"",IF(AND($I$29=$O$29,D42<1000),"N° Flac.",IF(AND($I$29=$O$30,D42>1000),"N° Flac.",((44.66*P42)))))))))))) -> 248.0288 | S42: =IF(ISBLANK($R$16),"",IF(A42=0,"",IF(ISBLANK($R$17),"",IF(B42=0,"",IF(ISBLANK(J42),"",IF(AND(D42>1202,D42<2001),"Err. N°",IF(AND(D42>499,D42<1141),"Err.N°",IF($I$29=$O$28,"",IF(AND($I$29=$O$29,D42<1000),"N° Flac.",IF(AND($I$29=$O$30,D42>1000),"N° Flac.",((44.66*P42)/M42))))))))))) -> 241.47776 | T42: 0 | U42: 0 | V42: 23.07 | W42: 22.54 | X42: 23.07 | Y42: 22.54 | Z42: 1.46 | AA42: 1.43 | AB42: 47.6 | AC42: 46.51
A43: =IF(ISBLANK(VLOOKUP(D43,'Volumes flacons'!A5:C623,3)),0,1) -> 1 | B43: =IF(ISBLANK(D43),0,IF(ISBLANK(E43),0,IF(ISBLANK(F43),0,1))) -> 1 | C43: 9 | D43: 2011 | E43: 8.5 | F43: 5.3686 | G43: 34.89085 | H43: 4000 | I43: 4072 | J43: =IF(ISBLANK(D43),"",IF(VLOOKUP(D43,'Volumes flacons'!$A$5:$C$1023,2)=0,"",IF(D43>'Volumes flacons'!$A$1023,"Mauvais numéro",IF(D43<'Volumes flacons'!$A$5,"Mauvais numéro",(VLOOKUP(D43,'Volumes flacons'!$A$5:$C$1023,3)))))) -> 110.81 | K43: =IF(ISBLANK(E43),"",(0.000824493-(0.0000040899*E43)+(0.000000076438*E43^2)-(0.00000000082467*E43^3)+(0.0000000000053875*E43^4))) -> 0.00079477317 | L43: =IF(ISBLANK(E43),"",(-0.00000572466+(0.00000010227*E43)-(0.0000000016546*E43^2))) -> -4.9749099e-06 | M43: =IF(ISBLANK(E43),"",IF(ISBLANK(G43),(O43+(K43*35)+(L43*35^1.5)+(0.00000048314*35^2)),(O43+(K43*G43)+(L43*G43^1.5)+(0.00000048314*G43^2)))) -> 1.0271121 | N43: =IF(ISBLANK(D43),"",IF(ISBLANK(G43),J43*(1+0.00001*(35-20)),J43*(1+0.00001*(G43-20)))) -> 110.8265 | O43: =IF(ISBLANK(E43),"",(0.999842594+(0.00006793952*E43)-(0.00000909529*E43^2)+(0.0000001001685*E43^3)-(0.000000001120083*E43^4)+(0.000000000006536332*E43^5))) -> 0.9998189 | P43: =IF(ISBLANK($R$16),"",IF(A43=0,"",IF(ISBLANK($R$17),"",IF(B43=0,"",IF($O$28=$I$29,"",IF(AND($I$29=$O$29,D43<1000),"N° Flac.",IF(AND($I$29=$O$30,D43>1000),"N° Flac.",IF(AND(D43>1202,D43<2001),"Err. N°",IF(AND(D43>499,D43<1141),"Err.N°",(((((F43)+'Correction de volume'!$G$7)*(($P$21)*($P$19)*5598)/(($R$16)-($R$17)))-(($P$27)*1000))/((N43)-($P$26)))))))))))) -> 5.5530756 | Q43: =IF(ISBLANK($R$16),"",IF(A43=0,"",IF(ISBLANK($R$17),"",IF(AND(D43>1202,D43<2001),"Err. N°",IF(AND(D43>499,D43<1141),"Err.N°",IF(B43=0,"",IF($O$28=$I$29,"",IF(AND($I$29=$O$29,D43<1000),"N° Flac.",IF(AND($I$29=$O$30,D43>1000),"N° Flac.",P43/M43))))))))) -> 5.4064944 | R43: =IF(ISBLANK($R$16),"",IF(A43=0,"",IF(ISBLANK($R$17),"",IF(B43=0,"",IF(ISBLANK(J43),"",IF(AND(D43>1202,D43<2001),"Err. N°",IF(AND(D43>499,D43<1141),"Err.N°",IF($I$29=$O$28,"",IF(AND($I$29=$O$29,D43<1000),"N° Flac.",IF(AND($I$29=$O$30,D43>1000),"N° Flac.",((44.66*P43)))))))))))) -> 248.00036 | S43: =IF(ISBLANK($R$16),"",IF(A43=0,"",IF(ISBLANK($R$17),"",IF(B43=0,"",IF(ISBLANK(J43),"",IF(AND(D43>1202,D43<2001),"Err. N°",IF(AND(D43>499,D43<1141),"Err.N°",IF($I$29=$O$28,"",IF(AND($I$29=$O$29,D43<1000),"N° Flac.",IF(AND($I$29=$O$30,D43>1000),"N° Flac.",((44.66*P43)/M43))))))))))) -> 241.45404 | T43: 0 | U43: 0 | V43: 23.14 | W43: 22.61 | X43: 23.14 | Y43: 22.61 | Z43: 1.46 | AA43: 1.43 | AB43: 47.13 | AC43: 46.05
A44: =IF(ISBLANK(VLOOKUP(D44,'Volumes flacons'!A5:C623,3)),0,1) -> 1 | B44: =IF(ISBLANK(D44),0,IF(ISBLANK(E44),0,IF(ISBLANK(F44),0,1))) -> 1 | C44: 10 | D44: 2012 | E44: 8.8 | F44: 5.3389 | G44: 34.89065 | H44: 4000 | I44: 4071 | J44: =IF(ISBLANK(D44),"",IF(VLOOKUP(D44,'Volumes flacons'!$A$5:$C$1023,2)=0,"",IF(D44>'Volumes flacons'!$A$1023,"Mauvais numéro",IF(D44<'Volumes flacons'!$A$5,"Mauvais numéro",(VLOOKUP(D44,'Volumes flacons'!$A$5:$C$1023,3)))))) -> 110.46 | K44: =IF(ISBLANK(E44),"",(0.000824493-(0.0000040899*E44)+(0.000000076438*E44^2)-(0.00000000082467*E44^3)+(0.0000000000053875*E44^4))) -> 0.00079389156 | L44: =IF(ISBLANK(E44),"",(-0.00000572466+(0.00000010227*E44)-(0.0000000016546*E44^2))) -> -4.9528162e-06 | M44: =IF(ISBLANK(E44),"",IF(ISBLANK(G44),(O44+(K44*35)+(L44*35^1.5)+(0.00000048314*35^2)),(O44+(K44*G44)+(L44*G44^1.5)+(0.00000048314*G44^2)))) -> 1.0270648 | N44: =IF(ISBLANK(D44),"",IF(ISBLANK(G44),J44*(1+0.00001*(35-20)),J44*(1+0.00001*(G44-20)))) -> 110.47645 | O44: =IF(ISBLANK(E44),"",(0.999842594+(0.00006793952*E44)-(0.00000909529*E44^2)+(0.0000001001685*E44^3)-(0.000000001120083*E44^4)+(0.000000000006536332*E44^5))) -> 0.99979801 | P44: =IF(ISBLANK($R$16),"",IF(A44=0,"",IF(ISBLANK($R$17),"",IF(B44=0,"",IF($O$28=$I$29,"",IF(AND($I$29=$O$29,D44<1000),"N° Flac.",IF(AND($I$29=$O$30,D44>1000),"N° Flac.",IF(AND(D44>1202,D44<2001),"Err. N°",IF(AND(D44>499,D44<1141),"Err.N°",(((((F44)+'Correction de volume'!$G$7)*(($P$21)*($P$19)*5598)/(($R$16)-($R$17)))-(($P$27)*1000))/((N44)-($P$26)))))))))))) -> 5.5400931 | Q44: =IF(ISBLANK($R$16),"",IF(A44=0,"",IF(ISBLANK($R$17),"",IF(AND(D44>1202,D44<2001),"Err. N°",IF(AND(D44>499,D44<1141),"Err.N°",IF(B44=0,"",IF($O$28=$I$29,"",IF(AND($I$29=$O$29,D44<1000),"N° Flac.",IF(AND($I$29=$O$30,D44>1000),"N° Flac.",P44/M44))))))))) -> 5.3941027 | R44: =IF(ISBLANK($R$16),"",IF(A44=0,"",IF(ISBLANK($R$17),"",IF(B44=0,"",IF(ISBLANK(J44),"",IF(AND(D44>1202,D44<2001),"Err. N°",IF(AND(D44>499,D44<1141),"Err.N°",IF($I$29=$O$28,"",IF(AND($I$29=$O$29,D44<1000),"N° Flac.",IF(AND($I$29=$O$30,D44>1000),"N° Flac.",((44.66*P44)))))))))))) -> 247.42056 | S44: =IF(ISBLANK($R$16),"",IF(A44=0,"",IF(ISBLANK($R$17),"",IF(B44=0,"",IF(ISBLANK(J44),"",IF(AND(D44>1202,D44<2001),"Err. N°",IF(AND(D44>499,D44<1141),"Err.N°",IF($I$29=$O$28,"",IF(AND($I$29=$O$29,D44<1000),"N° Flac.",IF(AND($I$29=$O$30,D44>1000),"N° Flac.",((44.66*P44)/M44))))))))))) -> 240.90063 | T44: 0 | U44: 0 | V44: 23.13 | W44: 22.6 | X44: 23.13 | Y44: 22.6 | Z44: 1.48 | AA44: 1.45 | AB44: 47.73 | AC44: 46.64
A45: =IF(ISBLANK(VLOOKUP(D45,'Volumes flacons'!A5:C623,3)),0,1) -> 1 | B45: =IF(ISBLANK(D45),0,IF(ISBLANK(E45),0,IF(ISBLANK(F45),0,1))) -> 1 | C45: 11 | D45: 2013 | E45: 8.9 | F45: 5.3318 | G45: 34.89025 | H45: 4000 | I45: 4072 | J45: =IF(ISBLANK(D45),"",IF(VLOOKUP(D45,'Volumes flacons'!$A$5:$C$1023,2)=0,"",IF(D45>'Volumes flacons'!$A$1023,"Mauvais numéro",IF(D45<'Volumes flacons'!$A$5,"Mauvais numéro",(VLOOKUP(D45,'Volumes flacons'!$A$5:$C$1023,3)))))) -> 109.83 | K45: =IF(ISBLANK(E45),"",(0.000824493-(0.0000040899*E45)+(0.000000076438*E45^2)-(0.00000000082467*E45^3)+(0.0000000000053875*E45^4))) -> 0.00079359998 | L45: =IF(ISBLANK(E45),"",(-0.00000572466+(0.00000010227*E45)-(0.0000000016546*E45^2))) -> -4.9455179e-06 | M45: =IF(ISBLANK(E45),"",IF(ISBLANK(G45),(O45+(K45*35)+(L45*35^1.5)+(0.00000048314*35^2)),(O45+(K45*G45)+(L45*G45^1.5)+(0.00000048314*G45^2)))) -> 1.0270486 | N45: =IF(ISBLANK(D45),"",IF(ISBLANK(G45),J45*(1+0.00001*(35-20)),J45*(1+0.00001*(G45-20)))) -> 109.84635 | O45: =IF(ISBLANK(E45),"",(0.999842594+(0.00006793952*E45)-(0.00000909529*E45^2)+(0.0000001001685*E45^3)-(0.000000001120083*E45^4)+(0.000000000006536332*E45^5))) -> 0.99979077 | P45: =IF(ISBLANK($R$16),"",IF(A45=0,"",IF(ISBLANK($R$17),"",IF(B45=0,"",IF($O$28=$I$29,"",IF(AND($I$29=$O$29,D45<1000),"N° Flac.",IF(AND($I$29=$O$30,D45>1000),"N° Flac.",IF(AND(D45>1202,D45<2001),"Err. N°",IF(AND(D45>499,D45<1141),"Err.N°",(((((F45)+'Correction de volume'!$G$7)*(($P$21)*($P$19)*5598)/(($R$16)-($R$17)))-(($P$27)*1000))/((N45)-($P$26)))))))))))) -> 5.5650385 | Q45: =IF(ISBLANK($R$16),"",IF(A45=0,"",IF(ISBLANK($R$17),"",IF(AND(D45>1202,D45<2001),"Err. N°",IF(AND(D45>499,D45<1141),"Err.N°",IF(B45=0,"",IF($O$28=$I$29,"",IF(AND($I$29=$O$29,D45<1000),"N° Flac.",IF(AND($I$29=$O$30,D45>1000),"N° Flac.",P45/M45))))))))) -> 5.4184764 | R45: =IF(ISBLANK($R$16),"",IF(A45=0,"",IF(ISBLANK($R$17),"",IF(B45=0,"",IF(ISBLANK(J45),"",IF(AND(D45>1202,D45<2001),"Err. N°",IF(AND(D45>499,D45<1141),"Err.N°",IF($I$29=$O$28,"",IF(AND($I$29=$O$29,D45<1000),"N° Flac.",IF(AND($I$29=$O$30,D45>1000),"N° Flac.",((44.66*P45)))))))))))) -> 248.53462 | S45: =IF(ISBLANK($R$16),"",IF(A45=0,"",IF(ISBLANK($R$17),"",IF(B45=0,"",IF(ISBLANK(J45),"",IF(AND(D45>1202,D45<2001),"Err. N°",IF(AND(D45>499,D45<1141),"Err.N°",IF($I$29=$O$28,"",IF(AND($I$29=$O$29,D45<1000),"N° Flac.",IF(AND($I$29=$O$30,D45>1000),"N° Flac.",((44.66*P45)/M45))))))))))) -> 241.98915 | T45: 0.01 | U45: 0.01 | V45: 22.92 | W45: 22.4 | X45: 22.91 | Y45: 22.39 | Z45: 1.44 | AA45: 1.41 | AB45: 47.77 | AC45: 46.68
A46: =IF(ISBLANK(VLOOKUP(D46,'Volumes flacons'!A5:C623,3)),0,1) -> 1 | B46: =IF(ISBLANK(D46),0,IF(ISBLANK(E46),0,IF(ISBLANK(F46),0,1))) -> 1 | C46: 12 | D46: 2014 | E46: 9.5 | F46: 5.4188 | G46: 34.89085 | H46: 4000 | I46: 4072 | J46: =IF(ISBLANK(D46),"",IF(VLOOKUP(D46,'Volumes flacons'!$A$5:$C$1023,2)=0,"",IF(D46>'Volumes flacons'!$A$1023,"Mauvais numéro",IF(D46<'Volumes flacons'!$A$5,"Mauvais numéro",(VLOOKUP(D46,'Volumes flacons'!$A$5:$C$1023,3)))))) -> 112.03 | K46: =IF(ISBLANK(E46),"",(0.000824493-(0.0000040899*E46)+(0.000000076438*E46^2)-(0.00000000082467*E46^3)+(0.0000000000053875*E46^4))) -> 0.00079187431 | L46: =IF(ISBLANK(E46),"",(-0.00000572466+(0.00000010227*E46)-(0.0000000016546*E46^2))) -> -4.9024226e-06 | M46: =IF(ISBLANK(E46),"",IF(ISBLANK(G46),(O46+(K46*35)+(L46*35^1.5)+(0.00000048314*35^2)),(O46+(K46*G46)+(L46*G46^1.5)+(0.00000048314*G46^2)))) -> 1.0269514 | N46: =IF(ISBLANK(D46),"",IF(ISBLANK(G46),J46*(1+0.00001*(35-20)),J46*(1+0.00001*(G46-20)))) -> 112.04668 | O46: =IF(ISBLANK(E46),"",(0.999842594+(0.00006793952*E46)-(0.00000909529*E46^2)+(0.0000001001685*E46^3)-(0.000000001120083*E46^4)+(0.000000000006536332*E46^5))) -> 0.99974443 | P46: =IF(ISBLANK($R$16),"",IF(A46=0,"",IF(ISBLANK($R$17),"",IF(B46=0,"",IF($O$28=$I$29,"",IF(AND($I$29=$O$29,D46<1000),"N° Flac.",IF(AND($I$29=$O$30,D46>1000),"N° Flac.",IF(AND(D46>1202,D46<2001),"Err. N°",IF(AND(D46>499,D46<1141),"Err.N°",(((((F46)+'Correction de volume'!$G$7)*(($P$21)*($P$19)*5598)/(($R$16)-($R$17)))-(($P$27)*1000))/((N46)-($P$26)))))))))))) -> 5.5429819 | Q46: =IF(ISBLANK($R$16),"",IF(A46=0,"",IF(ISBLANK($R$17),"",IF(AND(D46>1202,D46<2001),"Err. N°",IF(AND(D46>499,D46<1141),"Err.N°",IF(B46=0,"",IF($O$28=$I$29,"",IF(AND($I$29=$O$29,D46<1000),"N° Flac.",IF(AND($I$29=$O$30,D46>1000),"N° Flac.",P46/M46))))))))) -> 5.3975114 | R46: =IF(ISBLANK($R$16),"",IF(A46=0,"",IF(ISBLANK($R$17),"",IF(B46=0,"",IF(ISBLANK(J46),"",IF(AND(D46>1202,D46<2001),"Err. N°",IF(AND(D46>499,D46<1141),"Err.N°",IF($I$29=$O$28,"",IF(AND($I$29=$O$29,D46<1000),"N° Flac.",IF(AND($I$29=$O$30,D46>1000),"N° Flac.",((44.66*P46)))))))))))) -> 247.54957 | S46: =IF(ISBLANK($R$16),"",IF(A46=0,"",IF(ISBLANK($R$17),"",IF(B46=0,"",IF(ISBLANK(J46),"",IF(AND(D46>1202,D46<2001),"Err. N°",IF(AND(D46>499,D46<1141),"Err.N°",IF($I$29=$O$28,"",IF(AND($I$29=$O$29,D46<1000),"N° Flac.",IF(AND($I$29=$O$30,D46>1000),"N° Flac.",((44.66*P46)/M46))))))))))) -> 241.05286 | T46: 0 | U46: 0 | V46: 22.83 | W46: 22.31 | X46: 22.83 | Y46: 22.31 | Z46: 1.41 | AA46: 1.38 | AB46: 47.78 | AC46: 46.69
...

Sheet 002_01
C2: Campagne : | F2: PIRATA Fr29
C4: Données de campagne
C6: N° de station : | F6: 2 | H6: N° de palanquée : | P6: 1 | R6: Date d'analyse : | T6: 42066
G8: Position | I8: Degrés | J8: Minutes | P8: Cardinal | Q8: Décimale
G9: Latitude | I9: 8 | J9: 59.92 | K9: : | L9: =IF(P9=M9,"+","-") -> + | M9: N | N9: E | O9: =IF(ISBLANK(I9),"",IF(ISBLANK(J9),"",IF(P9=M10,L9&N11,N11))) -> 8°59,92 | P9: N | Q9: =IF(ISBLANK(I9),"",IF(ISBLANK(J9),"",IF(J9>60,"ERREUR !!",O11*(I9+(J9/60))))) -> 8.9986667
G10: Longitude | I10: 20 | J10: 7.5 | K10: : | L10: =IF(P10=N9,"+","-") -> - | M10: S | N10: W | O10: =IF(ISBLANK(I10),"",IF(ISBLANK(J10),"",IF(P10=N10,L10&N12,N12))) -> -20°7,5 | P10: W | Q10: =IF(ISBLANK(I10),"",IF(ISBLANK(J10),"",IF(J10>60,"ERREUR !!",O12*(I10+(J10/60))))) -> -20.125
G11: Prélèvement | I11: Date | J11: 42065 | N11: =I9&"°"&J9 -> 8°59,92 | O11: =IF(P9=M10,-1,1) -> 1 | P11: =TEXT(J11,"aaaa-mm-jj")&"T"&TEXT(J12,"hh:mm:ss")&"z" -> 2019-03-03T22:07:14z | V11: 4.9585
I12: Heure | J12: 0.92168981 | N12: =I10&"°"&J10 -> 20°7,5 | O12: =IF(P10=N10,-1,1) -> -1 | V12: 4.9613
C13: Données : | V13: 4.963
C14: Température du laboratoire à la calibration ( t°c ) | Q14: t°c = | R14: 24.9 | S14: °C | V14: 4.9619
C15: Température du laboratoire au début de la série d'analyses | Q15: t°lab = | R15: 24.9 | S15: °C | V15: 4.9664
C16: Volume moyen de thiosulfate pour la titration à t°c | Q16: Vmoy.titr.t°c = | R16: 4.96222 | S16: mL | V16: =AVERAGE(V11:V15) -> 4.96222
C17: Volume moyen de thiosulfate pour la détermination du blanc à t°c | Q17: Vmoy.titr.blanc.t°c = | R17: 0.006 | S17: mL
C18: Masse volumique de l'eau pure à la calibration | O18: ρ = | P18: =(0.999842594+(0.00006793952*$R$14)-(0.00000909529*$R$14^2)+(0.0000001001685*$R$14^3)-(0.000000001120083*$R$14^4)+(0.000000000006536332*$R$14^5)) -> 0.99707353
C19: Normalite de l'iodate (NIO3) à la température de calibration | O19: N(IO3) = | P19: =$P$24*($P$18/'Titre d''iodate'!E19) -> 0.020006801 | Q19: N
C20: Vol. de la prise d'essai d'iodate (VIO3) à 20°C | O20: V(IO3)20°C = | P20: =5+'Correction de volume'!G8 -> 5.0112146 | Q20: mL
C21: Vol. de la prise d'essai d'iodate (VIO3) à t°c | O21: V(IO3)t°c= | P21: =P20*(1+0.00001*(R14-20)) -> 5.0114601 | Q21: mL
C22: Volume moyen de thiosulfate pour la titration à 20° C | O22: Vmoy.titr.20°C = | P22: =$R$16*(1+0.00001*(20-$R$14)) -> 4.9619769 | Q22: mL
C23: Volume moyen de thiosulfate pour la détermination du blanc à 20° C | O23: Vmoy.titr.blanc.20°C = | P23: =$R$17*(1+0.00001*(20-$R$14)) -> 0.005999706 | Q23: mL
C24: Normalite de l'iodate (NIO3) à 20°C | O24: N(IO3)20°C = | P24: =MAX('Titre d''iodate'!F7:F10) -> 0.020029531 | Q24: N
C25: Titre du thiosulfate à 20°C | O25: V(Thio)20°C = | P25: =IF(ISBLANK(R14),"",IF(ISBLANK(P21),"",IF(ISBLANK(R17),"",(($P$24*$P$18)/($P$22-$P$23))))) -> 0.0040296625 | Q25: N
C26: Volume de réactif utilisé | O26: Vreg = | P26: =2+('Correction de volume'!G10+'Correction de volume'!G9) -> 2.0304948 | Q26: mL
O27: DOreg = | P27: 0.0017
E29: Choix de la série de flacons : | I29: IRD | O29: IRD
O30: LPO
C31: N° | D31: N° des Flacons | E31: T° prélèv. | F31: Volume de thio. | G31: Salinité | H31: Prof. Théorique | I31: Prof. Effective | J31: V. flacons 20°C | K31: A | L31: B | M31: Densité eau de mer à t° | N31: Vol. à t° prél. des flacons | O31: Densité eau pure à t° | P31: Oxygène dissous | T31: NO2 | V31: NO3 + NO2 | X31: NO3 | Z31: Phosphate | AB31: Silicate | AD31: chlorophyll-c3 | AE31: chlorophyll-c1+c2 | AF31: peridinin | AG31: 19'-butanoyloxyfucoxanthin | AH31: fucoxanthine | AI31: neoxanthin | AJ31: prasinoxanthin | AK31: violaxanthin | AL31: 19'-hexanoyloxyfucoxanthin | AM31: diadinoxanthin | AN31: alloxanthin | AO31: diatoxanthin | AP31: zeaxanthin | AQ31: lutein | AR31: divinyl chlorophyll-b | AS31: chlorophyll-b | AT31: total chlorophyll-b | AU31: alpha-carotene | AV31: beta-carotene | AW31: pheophorbide | AX31: divinyl chlorophyll-a | AY31: chlorophyll-a | AZ31: total chlorophyll-a | BA31: pheophytin_a | BB31: crocoxanthin
C33: BTL | E33: °C | F33: ml | H33: m | I33: dbar | J33: ml | P33: DOX1 | R33: DOXY | S33: DOX2 | T33: NTRI | U33: NTIW | V33: NTRZ | W33: NTZW | X33: NTRA | Y33: NTAW | Z33: PHOS | AA33: PHOW | AB33: SLCA | AC33: SLCW | AD33: CHC3 | AE33: CHCZ | AF33: PERP | AG33: BFUP | AH33: FUCP | AI33: NEXW | AJ33: PXAP | AK33: VIOW | AL33: HFUP | AM33: DXAP | AN33: AXAP | AO33: TXAP | AP33: ZXAP | AQ33: LUTW | AR33: CHBD | AS33: CH2P | AT33: CHLB | AU33: AACP | AV33: BBCP | AW33: PHEP | AX33: CHAD | AY33: CH1P | AZ33: CPHL | BA33: PHEA | BB33: CXAP
N34: mL | P34: ml/l | Q34: ml/kg | R34: µmol/l | S34: µmol/kg | T34: µmol/l | U34: µmol/kg | V34: µmol/l | W34: µmol/kg | X34: µmol/l | Y34: µmol/kg | Z34: µmol/l | AA34: µmol/kg | AB34: µmol/l | AC34: µmol/kg | AD34: µg.l-1 | AE34: µg.l-1 | AF34: µg.l-1 | AG34: µg.l-1 | AH34: µg.l-1 | AI34: µg.l-1 | AJ34: µg.l-1 | AK34: µg.l-1 | AL34: µg.l-1 | AM34: µg.l-1 | AN34: µg.l-1 | AO34: µg.l-1 | AP34: µg.l-1 | AQ34: µg.l-1 | AR34: µg.l-1 | AS34: µg.l-1 | AT34: µg.l-1 | AU34: µg.l-1 | AV34: µg.l-1 | AW34: µg.l-1 | AX34: µg.l-1 | AY34: µg.l-1 | AZ34: µg.l-1 | BA34: µg.l-1 | BB34: µg.l-1
A35: =IF(ISBLANK(VLOOKUP(D35,'Volumes flacons'!A5:C623,3)),0,1) -> 1 | B35: =IF(ISBLANK(D35),0,IF(ISBLANK(E35),0,IF(ISBLANK(F35),0,1))) -> 1 | C35: 1 | D35: 2029 | E35: 7.7 | F35: 5.1386 | G35: 34.9518 | H35: 2000 | I35: 2025.9 | J35: =IF(ISBLANK(D35),"",IF(VLOOKUP(D35,'Volumes flacons'!$A$5:$C$1023,2)=0,"",IF(D35>'Volumes flacons'!$A$1023,"Mauvais numéro",IF(D35<'Volumes flacons'!$A$5,"Mauvais numéro",(VLOOKUP(D35,'Volumes flacons'!$A$5:$C$1023,3)))))) -> 108.87 | K35: =IF(ISBLANK(E35),"",(0.000824493-(0.0000040899*E35)+(0.000000076438*E35^2)-(0.00000000082467*E35^3)+(0.0000000000053875*E35^4))) -> 0.00079717523 | L35: =IF(ISBLANK(E35),"",(-0.00000572466+(0.00000010227*E35)-(0.0000000016546*E35^2))) -> -5.0352822e-06 | M35: =IF(ISBLANK(E35),"",IF(ISBLANK(G35),(O35+(K35*35)+(L35*35^1.5)+(0.00000048314*35^2)),(O35+(K35*G35)+(L35*G35^1.5)+(0.00000048314*G35^2)))) -> 1.0272809 | N35: =IF(ISBLANK(D35),"",IF(ISBLANK(G35),J35*(1+0.00001*(35-20)),J35*(1+0.00001*(G35-20)))) -> 108.88628 | O35: =IF(ISBLANK(E35),"",(0.999842594+(0.00006793952*E35)-(0.00000909529*E35^2)+(0.0000001001685*E35^3)-(0.000000001120083*E35^4)+(0.000000000006536332*E35^5))) -> 0.99986844 | P35: =IF(ISBLANK($R$16),"",IF(A35=0,"",IF(ISBLANK($R$17),"",IF(B35=0,"",IF($O$28=$I$29,"",IF(AND($I$29=$O$29,D35<1000),"N° Flac.",IF(AND($I$29=$O$30,D35>1000),"N° Flac.",IF(AND(D35>1202,D35<2001),"Err. N°",IF(AND(D35>499,D35<1141),"Err.N°",(((((F35)+'Correction de volume'!$G$7)*(($P$21)*($P$19)*5598)/(($R$16)-($R$17)))-(($P$27)*1000))/((N35)-($P$26)))))))))))) -> 5.4298488 | Q35: =IF(ISBLANK($R$16),"",IF(A35=0,"",IF(ISBLANK($R$17),"",IF(AND(D35>1202,D35<2001),"Err. N°",IF(AND(D35>499,D35<1141),"Err.N°",IF(B35=0,"",IF($O$28=$I$29,"",IF(AND($I$29=$O$29,D35<1000),"N° Flac.",IF(AND($I$29=$O$30,D35>1000),"N° Flac.",P35/M35))))))))) -> 5.2856515 | R35: =IF(ISBLANK($R$16),"",IF(A35=0,"",IF(ISBLANK($R$17),"",IF(B35=0,"",IF(ISBLANK(J35),"",IF(AND(D35>1202,D35<2001),"Err. N°",IF(AND(D35>499,D35<1141),"Err.N°",IF($I$29=$O$28,"",IF(AND($I$29=$O$29,D35<1000),"N° Flac.",IF(AND($I$29=$O$30,D35>1000),"N° Flac.",((44.66*P35)))))))))))) -> 242.49705 | S35: =IF(ISBLANK($R$16),"",IF(A35=0,"",IF(ISBLANK($R$17),"",IF(B35=0,"",IF(ISBLANK(J35),"",IF(AND(D35>1202,D35<2001),"Err. N°",IF(AND(D35>499,D35<1141),"Err.N°",IF($I$29=$O$28,"",IF(AND($I$29=$O$29,D35<1000),"N° Flac.",IF(AND($I$29=$O$30,D35>1000),"N° Flac.",((44.66*P35)/M35))))))))))) -> 236.0572 | T35: 0 | U35: 0 | V35: 22 | W35: 21.5 | X35: 22 | Y35: 21.5 | Z35: 1.45 | AA35: 1.42 | AB35: 26.1 | AC35: 25.5
A36: =IF(ISBLANK(VLOOKUP(D36,'Volumes flacons'!A5:C623,3)),0,1) -> 1 | B36: =IF(ISBLANK(D36),0,IF(ISBLANK(E36),0,IF(ISBLANK(F36),0,1))) -> 1 | C36: 2 | D36: 2030 | E36: 8.5 | F36: 5.1913 | G36: 34.9536 | H36: 2000 | I36: 2025.6 | J36: =IF(ISBLANK(D36),"",IF(VLOOKUP(D36,'Volumes flacons'!$A$5:$C$1023,2)=0,"",IF(D36>'Volumes flacons'!$A$1023,"Mauvais numéro",IF(D36<'Volumes flacons'!$A$5,"Mauvais numéro",(VLOOKUP(D36,'Volumes flacons'!$A$5:$C$1023,3)))))) -> 110.13 | K36: =IF(ISBLANK(E36),"",(0.000824493-(0.0000040899*E36)+(0.000000076438*E36^2)-(0.00000000082467*E36^3)+(0.0000000000053875*E36^4))) -> 0.00079477317 | L36: =IF(ISBLANK(E36),"",(-0.00000572466+(0.00000010227*E36)-(0.0000000016546*E36^2))) -> -4.9749099e-06 | M36: =IF(ISBLANK(E36),"",IF(ISBLANK(G36),(O36+(K36*35)+(L36*35^1.5)+(0.00000048314*35^2)),(O36+(K36*G36)+(L36*G36^1.5)+(0.00000048314*G36^2)))) -> 1.0271613 | N36: =IF(ISBLANK(D36),"",IF(ISBLANK(G36),J36*(1+0.00001*(35-20)),J36*(1+0.00001*(G36-20)))) -> 110.14647 | O36: =IF(ISBLANK(E36),"",(0.999842594+(0.00006793952*E36)-(0.00000909529*E36^2)+(0.0000001001685*E36^3)-(0.000000001120083*E36^4)+(0.000000000006536332*E36^5))) -> 0.9998189 | P36: =IF(ISBLANK($R$16),"",IF(A36=0,"",IF(ISBLANK($R$17),"",IF(B36=0,"",IF($O$28=$I$29,"",IF(AND($I$29=$O$29,D36<1000),"N° Flac.",IF(AND($I$29=$O$30,D36>1000),"N° Flac.",IF(AND(D36>1202,D36<2001),"Err. N°",IF(AND(D36>499,D36<1141),"Err.N°",(((((F36)+'Correction de volume'!$G$7)*(($P$21)*($P$19)*5598)/(($R$16)-($R$17)))-(($P$27)*1000))/((N36)-($P$26)))))))))))) -> 5.4217598 | Q36: =IF(ISBLANK($R$16),"",IF(A36=0,"",IF(ISBLANK($R$17),"",IF(AND(D36>1202,D36<2001),"Err. N°",IF(AND(D36>499,D36<1141),"Err.N°",IF(B36=0,"",IF($O$28=$I$29,"",IF(AND($I$29=$O$29,D36<1000),"N° Flac.",IF(AND($I$29=$O$30,D36>1000),"N° Flac.",P36/M36))))))))) -> 5.2783918 | R36: =IF(ISBLANK($R$16),"",IF(A36=0,"",IF(ISBLANK($R$17),"",IF(B36=0,"",IF(ISBLANK(J36),"",IF(AND(D36>1202,D36<2001),"Err. N°",IF(AND(D36>499,D36<1141),"Err.N°",IF($I$29=$O$28,"",IF(AND($I$29=$O$29,D36<1000),"N° Flac.",IF(AND($I$29=$O$30,D36>1000),"N° Flac.",((44.66*P36)))))))))))) -> 242.13579 | S36: =IF(ISBLANK($R$16),"",IF(A36=0,"",IF(ISBLANK($R$17),"",IF(B36=0,"",IF(ISBLANK(J36),"",IF(AND(D36>1202,D36<2001),"Err. N°",IF(AND(D36>499,D36<1141),"Err.N°",IF($I$29=$O$28,"",IF(AND($I$29=$O$29,D36<1000),"N° Flac.",IF(AND($I$29=$O$30,D36>1000),"N° Flac.",((44.66*P36)/M36))))))))))) -> 235.73298 | T36: 0 | U36: 0 | V36: 22.2 | W36: 21.7 | X36: 22.2 | Y36: 21.7 | Z36: 1.45 | AA36: 1.42 | AB36: 26.5 | AC36: 25.9
A37: =IF(ISBLANK(VLOOKUP(D38,'Volumes flacons'!A5:C623,3)),0,1) -> 1 | B37: =IF(ISBLANK(D38),0,IF(ISBLANK(E38),0,IF(ISBLANK(F38),0,1))) -> 1 | C37: 3 | H37: 1750 | I37: 1769.4 | T37: 0 | U37: 0 | V37: 22.5 | W37: 22 | X37: 22.5 | Y37: 22 | Z37: 1.45 | AA37: 1.42 | AB37: 23.4 | AC37: 22.9
A38: =IF(ISBLANK(VLOOKUP(D40,'Volumes flacons'!A5:C623,3)),0,1) -> 1 | B38: =IF(ISBLANK(D40),0,IF(ISBLANK(E40),0,IF(ISBLANK(F40),0,1))) -> 1 | C38: 4 | D38: 2031 | E38: 9.1 | F38: 4.5139 | G38: 34.94065 | H38: 1500 | I38: 1516.6 | J38: =IF(ISBLANK(D38),"",IF(VLOOKUP(D38,'Volumes flacons'!$A$5:$C$1023,2)=0,"",IF(D38>'Volumes flacons'!$A$1023,"Mauvais numéro",IF(D38<'Volumes flacons'!$A$5,"Mauvais numéro",(VLOOKUP(D38,'Volumes flacons'!$A$5:$C$1023,3)))))) -> 107.83 | K38: =IF(ISBLANK(E38),"",(0.000824493-(0.0000040899*E38)+(0.000000076438*E38^2)-(0.00000000082467*E38^3)+(0.0000000000053875*E38^4))) -> 0.00079302024 | L38: =IF(ISBLANK(E38),"",(-0.00000572466+(0.00000010227*E38)-(0.0000000016546*E38^2))) -> -4.9310204e-06 | M38: =IF(ISBLANK(E38),"",IF(ISBLANK(G38),(O38+(K38*35)+(L38*35^1.5)+(0.00000048314*35^2)),(O38+(K38*G38)+(L38*G38^1.5)+(0.00000048314*G38^2)))) -> 1.0270559 | N38: =IF(ISBLANK(D38),"",IF(ISBLANK(G38),J38*(1+0.00001*(35-20)),J38*(1+0.00001*(G38-20)))) -> 107.84611 | O38: =IF(ISBLANK(E38),"",(0.999842594+(0.00006793952*E38)-(0.00000909529*E38^2)+(0.0000001001685*E38^3)-(0.000000001120083*E38^4)+(0.000000000006536332*E38^5))) -> 0.99977587 | P38: =IF(ISBLANK($R$16),"",IF(A37=0,"",IF(ISBLANK($R$17),"",IF(B37=0,"",IF($O$28=$I$29,"",IF(AND($I$29=$O$29,D38<1000),"N° Flac.",IF(AND($I$29=$O$30,D38>1000),"N° Flac.",IF(AND(D38>1202,D38<2001),"Err. N°",IF(AND(D38>499,D38<1141),"Err.N°",(((((F38)+'Correction de volume'!$G$7)*(($P$21)*($P$19)*5598)/(($R$16)-($R$17)))-(($P$27)*1000))/((N38)-($P$26)))))))))))) -> 4.8146556 | Q38: =IF(ISBLANK($R$16),"",IF(A37=0,"",IF(ISBLANK($R$17),"",IF(AND(D38>1202,D38<2001),"Err. N°",IF(AND(D38>499,D38<1141),"Err.N°",IF(B37=0,"",IF($O$28=$I$29,"",IF(AND($I$29=$O$29,D38<1000),"N° Flac.",IF(AND($I$29=$O$30,D38>1000),"N° Flac.",P38/M38))))))))) -> 4.6878223 | R38: =IF(ISBLANK($R$16),"",IF(A37=0,"",IF(ISBLANK($R$17),"",IF(B37=0,"",IF(ISBLANK(J38),"",IF(AND(D38>1202,D38<2001),"Err. N°",IF(AND(D38>499,D38<1141),"Err.N°",IF($I$29=$O$28,"",IF(AND($I$29=$O$29,D38<1000),"N° Flac.",IF(AND($I$29=$O$30,D38>1000),"N° Flac.",((44.66*P38)))))))))))) -> 215.02252 | S38: =IF(ISBLANK($R$16),"",IF(A37=0,"",IF(ISBLANK($R$17),"",IF(B37=0,"",IF(ISBLANK(J38),"",IF(AND(D38>1202,D38<2001),"Err. N°",IF(AND(D38>499,D38<1141),"Err.N°",IF($I$29=$O$28,"",IF(AND($I$29=$O$29,D38<1000),"N° Flac.",IF(AND($I$29=$O$30,D38>1000),"N° Flac.",((44.66*P38)/M38))))))))))) -> 209.35814 | T38: 0 | U38: 0 | V38: 24.4 | W38: 23.9 | X38: 24.4 | Y38: 23.9 | Z38: 1.61 | AA38: 1.57 | AB38: 23.1 | AC38: 22.6
A39: =IF(ISBLANK(VLOOKUP(D42,'Volumes flacons'!A5:C623,3)),0,1) -> 1 | B39: =IF(ISBLANK(D42),0,IF(ISBLANK(E42),0,IF(ISBLANK(F42),0,1))) -> 1 | C39: 5 | H39: 1250 | I39: 1263.1 | T39: 0 | U39: 0 | V39: 29 | W39: 28.3 | X39: 29 | Y39: 28.3 | Z39: 1.89 | AA39: 1.85 | AB39: 25.6 | AC39: 25
A40: =IF(ISBLANK(VLOOKUP(D44,'Volumes flacons'!A5:C623,3)),0,1) -> 1 | B40: =IF(ISBLANK(D44),0,IF(ISBLANK(E44),0,IF(ISBLANK(F44),0,1))) -> 1 | C40: 6 | D40: 2032 | E40: 10.4 | F40: 2.7781 | G40: 34.7458 | H40: 1000 | I40: 1008.4 | J40: =IF(ISBLANK(D40),"",IF(VLOOKUP(D40,'Volumes flacons'!$A$5:$C$1023,2)=0,"",IF(D40>'Volumes flacons'!$A$1023,"Mauvais numéro",IF(D40<'Volumes flacons'!$A$5,"Mauvais numéro",(VLOOKUP(D40,'Volumes flacons'!$A$5:$C$1023,3)))))) -> 111.3 | K40: =IF(ISBLANK(E40),"",(0.000824493-(0.0000040899*E40)+(0.000000076438*E40^2)-(0.00000000082467*E40^3)+(0.0000000000053875*E40^4))) -> 0.00078936096 | L40: =IF(ISBLANK(E40),"",(-0.00000572466+(0.00000010227*E40)-(0.0000000016546*E40^2))) -> -4.8400135e-06 | M40: =IF(ISBLANK(E40),"",IF(ISBLANK(G40),(O40+(K40*35)+(L40*35^1.5)+(0.00000048314*35^2)),(O40+(K40*G40)+(L40*G40^1.5)+(0.00000048314*G40^2)))) -> 1.0266848 | N40: =IF(ISBLANK(D40),"",IF(ISBLANK(G40),J40*(1+0.00001*(35-20)),J40*(1+0.00001*(G40-20)))) -> 111.31641 | O40: =IF(ISBLANK(E40),"",(0.999842594+(0.00006793952*E40)-(0.00000909529*E40^2)+(0.0000001001685*E40^3)-(0.000000001120083*E40^4)+(0.000000000006536332*E40^5))) -> 0.99966579 | P40: =IF(ISBLANK($R$16),"",IF(A38=0,"",IF(ISBLANK($R$17),"",IF(B38=0,"",IF($O$28=$I$29,"",IF(AND($I$29=$O$29,D40<1000),"N° Flac.",IF(AND($I$29=$O$30,D40>1000),"N° Flac.",IF(AND(D40>1202,D40<2001),"Err. N°",IF(AND(D40>499,D40<1141),"Err.N°",(((((F40)+'Correction de volume'!$G$7)*(($P$21)*($P$19)*5598)/(($R$16)-($R$17)))-(($P$27)*1000))/((N40)-($P$26)))))))))))) -> 2.8630653 | Q40: =IF(ISBLANK($R$16),"",IF(A38=0,"",IF(ISBLANK($R$17),"",IF(AND(D40>1202,D40<2001),"Err. N°",IF(AND(D40>499,D40<1141),"Err.N°",IF(B38=0,"",IF($O$28=$I$29,"",IF(AND($I$29=$O$29,D40<1000),"N° Flac.",IF(AND($I$29=$O$30,D40>1000),"N° Flac.",P40/M40))))))))) -> 2.7886509 | R40: =IF(ISBLANK($R$16),"",IF(A38=0,"",IF(ISBLANK($R$17),"",IF(B38=0,"",IF(ISBLANK(J40),"",IF(AND(D40>1202,D40<2001),"Err. N°",IF(AND(D40>499,D40<1141),"Err.N°",IF($I$29=$O$28,"",IF(AND($I$29=$O$29,D40<1000),"N° Flac.",IF(AND($I$29=$O$30,D40>1000),"N° Flac.",((44.66*P40)))))))))))) -> 127.8645 | S40: =IF(ISBLANK($R$16),"",IF(A38=0,"",IF(ISBLANK($R$17),"",IF(B38=0,"",IF(ISBLANK(J40),"",IF(AND(D40>1202,D40<2001),"Err. N°",IF(AND(D40>499,D40<1141),"Err.N°",IF($I$29=$O$28,"",IF(AND($I$29=$O$29,D40<1000),"N° Flac.",IF(AND($I$29=$O$30,D40>1000),"N° Flac.",((44.66*P40)/M40))))))))))) -> 124.54115 | T40: 0 | U40: 0 | V40: 37.7 | W40: 36.9 | X40: 37.7 | Y40: 36.9 | Z40: 2.33 | AA40: 2.28 | AB40: 26.8 | AC40: 26.2
A41: =IF(ISBLANK(VLOOKUP(D46,'Volumes flacons'!A5:C623,3)),0,1) -> 1 | B41: =IF(ISBLANK(D46),0,IF(ISBLANK(E46),0,IF(ISBLANK(F46),0,1))) -> 1 | C41: 7 | H41: 800 | I41: 806.8 | T41: 0 | U41: 0 | V41: 38.6 | W41: 37.7 | X41: 38.6 | Y41: 37.7 | Z41: 2.27 | AA41: 2.22 | AB41: 21.1 | AC41: 20.6
A42: =IF(ISBLANK(VLOOKUP(D47,'Volumes flacons'!A5:C623,3)),0,1) -> 1 | B42: =IF(ISBLANK(D47),0,IF(ISBLANK(E47),0,IF(ISBLANK(F47),0,1))) -> 1 | C42: 8 | D42: 2033 | E42: 12.4 | F42: 1.2151 | G42: 34.8991 | H42: 600 | I42: 604.4 | J42: =IF(ISBLANK(D42),"",IF(VLOOKUP(D42,'Volumes flacons'!$A$5:$C$1023,2)=0,"",IF(D42>'Volumes flacons'!$A$1023,"Mauvais numéro",IF(D42<'Volumes flacons'!$A$5,"Mauvais numéro",(VLOOKUP(D42,'Volumes flacons'!$A$5:$C$1023,3)))))) -> 110.79 | K42: =IF(ISBLANK(E42),"",(0.000824493-(0.0000040899*E42)+(0.000000076438*E42^2)-(0.00000000082467*E42^3)+(0.0000000000053875*E42^4))) -> 0.00078408638 | L42: =IF(ISBLANK(E42),"",(-0.00000572466+(0.00000010227*E42)-(0.0000000016546*E42^2))) -> -4.7109233e-06 | M42: =IF(ISBLANK(E42),"",IF(ISBLANK(G42),(O42+(K42*35)+(L42*35^1.5)+(0.00000048314*35^2)),(O42+(K42*G42)+(L42*G42^1.5)+(0.00000048314*G42^2)))) -> 1.0264341 | N42: =IF(ISBLANK(D42),"",IF(ISBLANK(G42),J42*(1+0.00001*(35-20)),J42*(1+0.00001*(G42-20)))) -> 110.80651 | O42: =IF(ISBLANK(E42),"",(0.999842594+(0.00006793952*E42)-(0.00000909529*E42^2)+(0.0000001001685*E42^3)-(0.000000001120083*E42^4)+(0.000000000006536332*E42^5))) -> 0.99945297 | P42: =IF(ISBLANK($R$16),"",IF(A39=0,"",IF(ISBLANK($R$17),"",IF(B39=0,"",IF($O$28=$I$29,"",IF(AND($I$29=$O$29,D42<1000),"N° Flac.",IF(AND($I$29=$O$30,D42>1000),"N° Flac.",IF(AND(D42>1202,D42<2001),"Err. N°",IF(AND(D42>499,D42<1141),"Err.N°",(((((F42)+'Correction de volume'!$G$7)*(($P$21)*($P$19)*5598)/(($R$16)-($R$17)))-(($P$27)*1000))/((N42)-($P$26)))))))))))) -> 1.2492521 | Q42: =IF(ISBLANK($R$16),"",IF(A39=0,"",IF(ISBLANK($R$17),"",IF(AND(D42>1202,D42<2001),"Err. N°",IF(AND(D42>499,D42<1141),"Err.N°",IF(B39=0,"",IF($O$28=$I$29,"",IF(AND($I$29=$O$29,D42<1000),"N° Flac.",IF(AND($I$29=$O$30,D42>1000),"N° Flac.",P42/M42))))))))) -> 1.2170797 | R42: =IF(ISBLANK($R$16),"",IF(A39=0,"",IF(ISBLANK($R$17),"",IF(B39=0,"",IF(ISBLANK(J42),"",IF(AND(D42>1202,D42<2001),"Err. N°",IF(AND(D42>499,D42<1141),"Err.N°",IF($I$29=$O$28,"",IF(AND($I$29=$O$29,D42<1000),"N° Flac.",IF(AND($I$29=$O$30,D42>1000),"N° Flac.",((44.66*P42)))))))))))) -> 55.7916 | S42: =IF(ISBLANK($R$16),"",IF(A39=0,"",IF(ISBLANK($R$17),"",IF(B39=0,"",IF(ISBLANK(J42),"",IF(AND(D42>1202,D42<2001),"Err. N°",IF(AND(D42>499,D42<1141),"Err.N°",IF($I$29=$O$28,"",IF(AND($I$29=$O$29,D42<1000),"N° Flac.",IF(AND($I$29=$O$30,D42>1000),"N° Flac.",((44.66*P42)/M42))))))))))) -> 54.354781 | T42: 0.01 | U42: 0.01 | V42: 35 | W42: 34.2 | X42: 35 | Y42: 34.2 | Z42: 2.17 | AA42: 2.12 | AB42: 28.3 | AC42: 27.7
A43: =IF(ISBLANK(VLOOKUP(D48,'Volumes flacons'!A5:C623,3)),0,1) -> 1 | B43: =IF(ISBLANK(D48),0,IF(ISBLANK(E48),0,IF(ISBLANK(F48),0,1))) -> 1 | C43: 9 | H43: 400 | I43: 402.7
A44: =IF(ISBLANK(VLOOKUP(D50,'Volumes flacons'!A5:C623,3)),0,1) -> 1 | B44: =IF(ISBLANK(D50),0,IF(ISBLANK(E50),0,IF(ISBLANK(F50),0,1))) -> 1 | C44: 10 | D44: 2034 | E44: 14.2 | F44: 0.8259 | G44: 35.1888 | H44: 400 | I44: 402.1 | J44: =IF(ISBLANK(D44),"",IF(VLOOKUP(D44,'Volumes flacons'!$A$5:$C$1023,2)=0,"",IF(D44>'Volumes flacons'!$A$1023,"Mauvais numéro",IF(D44<'Volumes flacons'!$A$5,"Mauvais numéro",(VLOOKUP(D44,'Volumes flacons'!$A$5:$C$1023,3)))))) -> 109.25 | K44: =IF(ISBLANK(E44),"",(0.000824493-(0.0000040899*E44)+(0.000000076438*E44^2)-(0.00000000082467*E44^3)+(0.0000000000053875*E44^4))) -> 0.00077968716 | L44: =IF(ISBLANK(E44),"",(-0.00000572466+(0.00000010227*E44)-(0.0000000016546*E44^2))) -> -4.6060595e-06 | M44: =IF(ISBLANK(E44),"",IF(ISBLANK(G44),(O44+(K44*35)+(L44*35^1.5)+(0.00000048314*35^2)),(O44+(K44*G44)+(L44*G44^1.5)+(0.00000048314*G44^2)))) -> 1.0262914 | N44: =IF(ISBLANK(D44),"",IF(ISBLANK(G44),J44*(1+0.00001*(35-20)),J44*(1+0.00001*(G44-20)))) -> 109.26659 | O44: =IF(ISBLANK(E44),"",(0.999842594+(0.00006793952*E44)-(0.00000909529*E44^2)+(0.0000001001685*E44^3)-(0.000000001120083*E44^4)+(0.000000000006536332*E44^5))) -> 0.9992184 | P44: =IF(ISBLANK($R$16),"",IF(A40=0,"",IF(ISBLANK($R$17),"",IF(B40=0,"",IF($O$28=$I$29,"",IF(AND($I$29=$O$29,D44<1000),"N° Flac.",IF(AND($I$29=$O$30,D44>1000),"N° Flac.",IF(AND(D44>1202,D44<2001),"Err. N°",IF(AND(D44>499,D44<1141),"Err.N°",(((((F44)+'Correction de volume'!$G$7)*(($P$21)*($P$19)*5598)/(($R$16)-($R$17)))-(($P$27)*1000))/((N44)-($P$26)))))))))))) -> 0.85617792 | Q44: =IF(ISBLANK($R$16),"",IF(A40=0,"",IF(ISBLANK($R$17),"",IF(AND(D44>1202,D44<2001),"Err. N°",IF(AND(D44>499,D44<1141),"Err.N°",IF(B40=0,"",IF($O$28=$I$29,"",IF(AND($I$29=$O$29,D44<1000),"N° Flac.",IF(AND($I$29=$O$30,D44>1000),"N° Flac.",P44/M44))))))))) -> 0.83424444 | R44: =IF(ISBLANK($R$16),"",IF(A40=0,"",IF(ISBLANK($R$17),"",IF(B40=0,"",IF(ISBLANK(J44),"",IF(AND(D44>1202,D44<2001),"Err. N°",IF(AND(D44>499,D44<1141),"Err.N°",IF($I$29=$O$28,"",IF(AND($I$29=$O$29,D44<1000),"N° Flac.",IF(AND($I$29=$O$30,D44>1000),"N° Flac.",((44.66*P44)))))))))))) -> 38.236906 | S44: =IF(ISBLANK($R$16),"",IF(A40=0,"",IF(ISBLANK($R$17),"",IF(B40=0,"",IF(ISBLANK(J44),"",IF(AND(D44>1202,D44<2001),"Err. N°",IF(AND(D44>499,D44<1141),"Err.N°",IF($I$29=$O$28,"",IF(AND($I$29=$O$29,D44<1000),"N° Flac.",IF(AND($I$29=$O$30,D44>1000),"N° Flac.",((44.66*P44)/M44))))))))))) -> 37.257357 | T44: 0 | U44: 0 | V44: 35.4 | W44: 34.6 | X44: 35.4 | Y44: 34.6 | Z44: 1.96 | AA44: 1.92 | AB44: 14.7 | AC44: 14.4
A45: =IF(ISBLANK(VLOOKUP(D51,'Volumes flacons'!A5:C623,3)),0,1) -> 1 | B45: =IF(ISBLANK(D51),0,IF(ISBLANK(E51),0,IF(ISBLANK(F51),0,1))) -> 1 | C45: 11 | H45: 200 | I45: 201.7 | T45: 0.01 | U45: 0.01 | V45: 25.6 | W45: 25 | X45: 25.6 | Y45: 25 | Z45: 1.52 | AA45: 1.49 | AB45: 9.67 | AC45: 9.45
