Workbook

Sheet Station 001
C2: Campagne : | F2: PIRATA FR25
C4: Données de campagne
C6: N° de station : | F6: 1 | H6: N° de palanquée : | P6: 1 | R6: Date d'analyse : | T6: 40625
G8: Position | I8: Degrés | J8: Minutes | P8: Cardinal | Q8: Décimale
G9: Latitude | I9: 6 | J9: 0 | K9: : | L9: =IF(P9=M9,"+","-") -> + | M9: N | N9: E | O9: =IF(ISBLANK(I9),"",IF(ISBLANK(J9),"",IF(P9=M10,L9&N11,N11))) -> 6°0 | P9: N | Q9: 6
G10: Longitude | I10: 15 | J10: 10 | K10: : | L10: =IF(P10=N9,"+","-") -> - | M10: S | N10: W | O10: =IF(ISBLANK(I10),"",IF(ISBLANK(J10),"",IF(P10=N10,L10&N12,N12))) -> -15°10 | P10: W | Q10: -15.17
G11: Prélèvement | I11: Date | J11: 40622 | N11: =I9&"°"&J9 -> 6°0 | O11: =IF(P9=M10,-1,1) -> 1 | P11: 2015-03-21T13:00:00z
I12: Heure | J12: 0.54166667 | N12: =I10&"°"&J10 -> 15°10 | O12: =IF(P10=N10,-1,1) -> -1
C13: Données :
C14: Température du laboratoire à la calibration ( t°c ) | Q14: t°c = | R14: 24.1 | S14: °C
C15: Température du laboratoire au début de la série d'analyses | Q15: t°lab = | R15: 24.3 | S15: °C
C16: Volume moyen de thiosulfate pour la titration à t°c | Q16: Vmoy.titr.t°c = | R16: 5.009 | S16: mL
C17: Volume moyen de thiosulfate pour la détermination du blanc à t°c | Q17: Vmoy.titr.blanc.t°c = | R17: 0.006 | S17: mL
C18: Masse volumique de l'eau pure à la calibration | O18: ρ = | P18: =(0.999842594+(0.00006793952*$R$14)-(0.00000909529*$R$14^2)+(0.0000001001685*$R$14^3)-(0.000000001120083*$R$14^4)+(0.000000000006536332*$R$14^5)) -> 0.9972747
C19: Normalite de l'iodate (NIO3) à la température de calibration | O19: N(IO3) = | P19: =$P$24*($P$18/'Titre d''iodate'!E19) -> 0.019977637 | Q19: N
C20: Vol. de la prise d'essai d'iodate (VIO3) à 20°C | O20: V(IO3)20°C = | P20: =5+'Correction de volume'!G8 -> 5.00309 | Q20: mL
C21: Vol. de la prise d'essai d'iodate (VIO3) à t°c | O21: V(IO3)t°c= | P21: =P20*(1+0.00001*(R14-20)) -> 5.0032951 | Q21: mL
C22: Volume moyen de thiosulfate pour la titration à 20° C | O22: Vmoy.titr.20°C = | P22: =$R$16*(1+0.00001*(20-$R$14)) -> 5.0087946 | Q22: mL
C23: Volume moyen de thiosulfate pour la détermination du blanc à 20° C | O23: Vmoy.titr.blanc.20°C = | P23: =$R$17*(1+0.00001*(20-$R$14)) -> 0.005999754 | Q23: mL
C24: Normalite de l'iodate (NIO3) à 20°C | O24: N(IO3)20°C = | P24: =MAX('Titre d''iodate'!F7:F10) -> 0.019996299 | Q24: N
C25: Titre du thiosulfate à 20°C | O25: V(Thio)20°C = | P25: =IF(ISBLANK(R14),"",IF(ISBLANK(P21),"",IF(ISBLANK(R17),"",(($P$24*$P$18)/($P$22-$P$23))))) -> 0.0039861325 | Q25: N
C26: Volume de réactif utilisé | O26: Vreg = | P26: =2+('Correction de volume'!G10+'Correction de volume'!G9) -> 2.016394 | Q26: mL
O27: DOreg = | P27: 0.0017
E29: Choix de la série de flacons : | I29: LPO | O29: IRD
O30: LPO
C31: N° | D31: N° des Flacons | E31: T° prélèv. | F31: Volume de thio. | G31: Salinité | H31: Prof. Théorique | I31: Prof. Effective | J31: V. flacons 20°C | K31: A | L31: B | M31: Densité eau de mer à t° | N31: Vol. à t° prél. des flacons | O31: Densité eau pure à t° | P31: Oxygène dissous | T31: NO2 | V31: NO3 + NO2 | X31: NO3 | Z31: Phosphate | AB31: Silicate | AD31: chlorophyll-c3 | AE31: chlorophyll-c1+c2 | AF31: peridinin | AG31: 19'-butanoyloxyfucoxanthin | AH31: fucoxanthine | AI31: neoxanthin | AJ31: prasinoxanthin | AK31: violaxanthin | AL31: 19'-hexanoyloxyfucoxanthin | AM31: diadinoxanthin | AN31: alloxanthin | AO31: diatoxanthin | AP31: zeaxanthin | AQ31: lutein | AR31: divinyl chlorophyll-b | AS31: chlorophyll-b | AT31: total chlorophyll-b | AU31: alpha-carotene | AV31: beta-carotene | AW31: pheophorbide | AX31: divinyl chlorophyll-a | AY31: chlorophyll-a | AZ31: total chlorophyll-a | BA31: pheophytin_a | BB31: crocoxanthin
C33: BTL | E33: °C | F33: ml | H33: m | I33: m | J33: ml | P33: DOX1 | R33: DOXY | S33: DOX2 | T33: NTRI | U33: NTIW | V33: NTRZ | W33: NTZW | X33: NTRA | Y33: NTAW | Z33: PHOS | AA33: PHOW | AB33: SLCA | AC33: SLCW | AD33: CHC3 | AE33: CHCZ | AF33: PERP | AG33: BFUP | AH33: FUCP | AI33: NEXW | AJ33: PXAP | AK33: VIOW | AL33: HFUP | AM33: DXAP | AN33: AXAP | AO33: TXAP | AP33: ZXAP | AQ33: LUTW | AR33: CHBD | AS33: CH2P | AT33: CHLB | AU33: AACP | AV33: BBCP | AW33: PHEP | AX33: CHAD | AY33: CH1P | AZ33: CPHL | BA33: PHEA | BB33: CXAP
N34: mL | P34: ml/l | Q34: ml/kg | R34: µmol/l | S34: µmol/kg | T34: µmol/l | U34: µmol/kg | V34: µmol/l | W34: µmol/kg | X34: µmol/l | Y34: µmol/kg | Z34: µmol/l | AA34: µmol/kg | AB34: µmol/l | AC34: µmol/kg | AD34: µg.l-1 | AE34: µg.l-1 | AF34: µg.l-1 | AG34: µg.l-1 | AH34: µg.l-1 | AI34: µg.l-1 | AJ34: µg.l-1 | AK34: µg.l-1 | AL34: µg.l-1 | AM34: µg.l-1 | AN34: µg.l-1 | AO34: µg.l-1 | AP34: µg.l-1 | AQ34: µg.l-1 | AR34: µg.l-1 | AS34: µg.l-1 | AT34: µg.l-1 | AU34: µg.l-1 | AV34: µg.l-1 | AW34: µg.l-1 | AX34: µg.l-1 | AY34: µg.l-1 | AZ34: µg.l-1 | BA34: µg.l-1 | BB34: µg.l-1
A35: =IF(ISBLANK(VLOOKUP(D35,'Volumes flacons'!A5:C623,3)),0,1) -> 1 | B35: =IF(ISBLANK(D35),0,IF(ISBLANK(E35),0,IF(ISBLANK(F35),0,1))) -> 1 | C35: 1 | D35: 326 | E35: 7.5 | F35: 5.711 | G35: 34.951 | H35: 2000 | I35: 2000 | J35: 118.59 | K35: =IF(ISBLANK(E35),"",(0.000824493-(0.0000040899*E35)+(0.000000076438*E35^2)-(0.00000000082467*E35^3)+(0.0000000000053875*E35^4))) -> 0.00079778753 | L35: =IF(ISBLANK(E35),"",(-0.00000572466+(0.00000010227*E35)-(0.0000000016546*E35^2))) -> -5.0507063e-06 | M35: =IF(ISBLANK(E35),"",IF(ISBLANK(G35),(O35+(K35*35)+(L35*35^1.5)+(0.00000048314*35^2)),(O35+(K35*G35)+(L35*G35^1.5)+(0.00000048314*G35^2)))) -> 1.0273094 | N35: =IF(ISBLANK(D35),"",IF(ISBLANK(G35),J35*(1+0.00001*(35-20)),J35*(1+0.00001*(G35-20)))) -> 118.60773 | O35: =IF(ISBLANK(E35),"",(0.999842594+(0.00006793952*E35)-(0.00000909529*E35^2)+(0.0000001001685*E35^3)-(0.000000001120083*E35^4)+(0.000000000006536332*E35^5))) -> 0.9998794 | P35: 5.464 | Q35: 5.318 | R35: 244 | S35: 237.5 | T35: 0 | U35: 0 | V35: 22.1 | W35: 21.6 | X35: 22.1 | Y35: 21.6 | Z35: 1.45 | AA35: 1.41 | AB35: 25.6 | AC35: 25
A36: =IF(ISBLANK(VLOOKUP(D36,'Volumes flacons'!A5:C623,3)),0,1) -> 1 | B36: =IF(ISBLANK(D36),0,IF(ISBLANK(E36),0,IF(ISBLANK(F36),0,1))) -> 1 | C36: 2 | D36: 333 | E36: 7.4 | F36: 5.652 | G36: 34.947 | H36: 2000 | I36: 2000 | J36: 117.98 | K36: =IF(ISBLANK(E36),"",(0.000824493-(0.0000040899*E36)+(0.000000076438*E36^2)-(0.00000000082467*E36^3)+(0.0000000000053875*E36^4))) -> 0.00079809546 | L36: =IF(ISBLANK(E36),"",(-0.00000572466+(0.00000010227*E36)-(0.0000000016546*E36^2))) -> -5.0584679e-06 | M36: =IF(ISBLANK(E36),"",IF(ISBLANK(G36),(O36+(K36*35)+(L36*35^1.5)+(0.00000048314*35^2)),(O36+(K36*G36)+(L36*G36^1.5)+(0.00000048314*G36^2)))) -> 1.0273207 | N36: =IF(ISBLANK(D36),"",IF(ISBLANK(G36),J36*(1+0.00001*(35-20)),J36*(1+0.00001*(G36-20)))) -> 117.99763 | O36: =IF(ISBLANK(E36),"",(0.999842594+(0.00006793952*E36)-(0.00000909529*E36^2)+(0.0000001001685*E36^3)-(0.000000001120083*E36^4)+(0.000000000006536332*E36^5))) -> 0.99988467 | P36: 5.435 | Q36: 5.291 | R36: 242.7 | S36: 236.3 | T36: 0 | U36: 0 | V36: 22.1 | W36: 21.6 | X36: 22.1 | Y36: 21.6 | Z36: 1.48 | AA36: 1.44 | AB36: 24.9 | AC36: 24.4
A37: =IF(ISBLANK(VLOOKUP(D37,'Volumes flacons'!A5:C623,3)),0,1) -> 1 | B37: =IF(ISBLANK(D37),0,IF(ISBLANK(E37),0,IF(ISBLANK(F37),0,1))) -> 1 | C37: 3 | D37: 334 | E37: 10.9 | F37: 4.754 | G37: 35.003 | H37: 2000 | I37: 2000 | J37: 117.64 | K37: =IF(ISBLANK(E37),"",(0.000824493-(0.0000040899*E37)+(0.000000076438*E37^2)-(0.00000000082467*E37^3)+(0.0000000000053875*E37^4))) -> 0.00078800277 | L37: =IF(ISBLANK(E37),"",(-0.00000572466+(0.00000010227*E37)-(0.0000000016546*E37^2))) -> -4.8065e-06 | M37: =IF(ISBLANK(E37),"",IF(ISBLANK(G37),(O37+(K37*35)+(L37*35^1.5)+(0.00000048314*35^2)),(O37+(K37*G37)+(L37*G37^1.5)+(0.00000048314*G37^2)))) -> 1.0267965 | N37: =IF(ISBLANK(D37),"",IF(ISBLANK(G37),J37*(1+0.00001*(35-20)),J37*(1+0.00001*(G37-20)))) -> 117.65765 | O37: =IF(ISBLANK(E37),"",(0.999842594+(0.00006793952*E37)-(0.00000909529*E37^2)+(0.0000001001685*E37^3)-(0.000000001120083*E37^4)+(0.000000000006536332*E37^5))) -> 0.99961744 | P37: 4.583 | Q37: 4.463 | R37: 204.7 | S37: 199.3 | T37: 0.01 | U37: 0.01 | V37: 23.4 | W37: 22.9 | X37: 23.4 | Y37: 22.8 | Z37: 1.55 | AA37: 1.51 | AB37: 22.5 | AC37: 22
A38: =IF(ISBLANK(VLOOKUP(D38,'Volumes flacons'!A5:C623,3)),0,1) -> 1 | B38: =IF(ISBLANK(D38),0,IF(ISBLANK(E38),0,IF(ISBLANK(F38),0,1))) -> 1 | C38: 4 | D38: 336 | E38: 9.3 | F38: 5.651 | G38: 34.947 | H38: 2000 | I38: 2000 | J38: 118.01 | K38: =IF(ISBLANK(E38),"",(0.000824493-(0.0000040899*E38)+(0.000000076438*E38^2)-(0.00000000082467*E38^3)+(0.0000000000053875*E38^4))) -> 0.00079244502 | L38: =IF(ISBLANK(E38),"",(-0.00000572466+(0.00000010227*E38)-(0.0000000016546*E38^2))) -> -4.9166554e-06 | M38: =IF(ISBLANK(E38),"",IF(ISBLANK(G38),(O38+(K38*35)+(L38*35^1.5)+(0.00000048314*35^2)),(O38+(K38*G38)+(L38*G38^1.5)+(0.00000048314*G38^2)))) -> 1.0270283 | N38: =IF(ISBLANK(D38),"",IF(ISBLANK(G38),J38*(1+0.00001*(35-20)),J38*(1+0.00001*(G38-20)))) -> 118.02764 | O38: =IF(ISBLANK(E38),"",(0.999842594+(0.00006793952*E38)-(0.00000909529*E38^2)+(0.0000001001685*E38^3)-(0.000000001120083*E38^4)+(0.000000000006536332*E38^5))) -> 0.99976043 | P38: 5.433 | Q38: 5.29 | R38: 242.6 | S38: 236.3 | T38: 0 | U38: 0 | V38: 22.2 | W38: 21.6 | X38: 22.1 | Y38: 21.6 | Z38: 1.49 | AA38: 1.45 | AB38: 25.4 | AC38: 24.8
A39: =IF(ISBLANK(VLOOKUP(D39,'Volumes flacons'!A5:C623,3)),0,1) -> 1 | B39: =IF(ISBLANK(D39),0,IF(ISBLANK(E39),0,IF(ISBLANK(F39),0,1))) -> 1 | C39: 5 | D39: 337 | E39: 9.5 | F39: 5.662 | G39: 34.939 | H39: 2000 | I39: 2000 | J39: 118.14 | K39: =IF(ISBLANK(E39),"",(0.000824493-(0.0000040899*E39)+(0.000000076438*E39^2)-(0.00000000082467*E39^3)+(0.0000000000053875*E39^4))) -> 0.00079187431 | L39: =IF(ISBLANK(E39),"",(-0.00000572466+(0.00000010227*E39)-(0.0000000016546*E39^2))) -> -4.9024226e-06 | M39: =IF(ISBLANK(E39),"",IF(ISBLANK(G39),(O39+(K39*35)+(L39*35^1.5)+(0.00000048314*35^2)),(O39+(K39*G39)+(L39*G39^1.5)+(0.00000048314*G39^2)))) -> 1.0269891 | N39: =IF(ISBLANK(D39),"",IF(ISBLANK(G39),J39*(1+0.00001*(35-20)),J39*(1+0.00001*(G39-20)))) -> 118.15765 | O39: =IF(ISBLANK(E39),"",(0.999842594+(0.00006793952*E39)-(0.00000909529*E39^2)+(0.0000001001685*E39^3)-(0.000000001120083*E39^4)+(0.000000000006536332*E39^5))) -> 0.99974443 | P39: 5.438 | Q39: 5.295 | R39: 242.8 | S39: 236.5 | T39: 0 | U39: 0 | V39: 22.2 | W39: 21.7 | X39: 22.2 | Y39: 21.7 | Z39: 1.53 | AA39: 1.49 | AB39: 25.5 | AC39: 24.9
A40: =IF(ISBLANK(VLOOKUP(D40,'Volumes flacons'!A5:C623,3)),0,1) -> 1 | B40: =IF(ISBLANK(D40),0,IF(ISBLANK(E40),0,IF(ISBLANK(F40),0,1))) -> 1 | C40: 6 | D40: 339 | E40: 10.2 | F40: 5.59 | G40: 34.947 | H40: 2000 | I40: 2000 | J40: 116.25 | K40: =IF(ISBLANK(E40),"",(0.000824493-(0.0000040899*E40)+(0.000000076438*E40^2)-(0.00000000082467*E40^3)+(0.0000000000053875*E40^4))) -> 0.0007899118 | L40: =IF(ISBLANK(E40),"",(-0.00000572466+(0.00000010227*E40)-(0.0000000016546*E40^2))) -> -4.8536506e-06 | M40: =IF(ISBLANK(E40),"",IF(ISBLANK(G40),(O40+(K40*35)+(L40*35^1.5)+(0.00000048314*35^2)),(O40+(K40*G40)+(L40*G40^1.5)+(0.00000048314*G40^2)))) -> 1.0268766 | N40: =IF(ISBLANK(D40),"",IF(ISBLANK(G40),J40*(1+0.00001*(35-20)),J40*(1+0.00001*(G40-20)))) -> 116.26738 | O40: =IF(ISBLANK(E40),"",(0.999842594+(0.00006793952*E40)-(0.00000909529*E40^2)+(0.0000001001685*E40^3)-(0.000000001120083*E40^4)+(0.000000000006536332*E40^5))) -> 0.9996842 | P40: 5.457 | Q40: 5.314 | R40: 243.7 | S40: 237.3 | T40: 0 | U40: 0 | V40: 22.3 | W40: 21.8 | X40: 22.3 | Y40: 21.8 | Z40: 1.51 | AA40: 1.47 | AB40: 26 | AC40: 25.4
A41: =IF(ISBLANK(VLOOKUP(D41,'Volumes flacons'!A5:C623,3)),0,1) -> 1 | B41: =IF(ISBLANK(D41),0,IF(ISBLANK(E41),0,IF(ISBLANK(F41),0,1))) -> 1 | C41: 7 | D41: 340 | E41: 10.2 | F41: 5.63 | G41: 34.952 | H41: 2000 | I41: 2000 | J41: 117.73 | K41: =IF(ISBLANK(E41),"",(0.000824493-(0.0000040899*E41)+(0.000000076438*E41^2)-(0.00000000082467*E41^3)+(0.0000000000053875*E41^4))) -> 0.0007899118 | L41: =IF(ISBLANK(E41),"",(-0.00000572466+(0.00000010227*E41)-(0.0000000016546*E41^2))) -> -4.8536506e-06 | M41: =IF(ISBLANK(E41),"",IF(ISBLANK(G41),(O41+(K41*35)+(L41*35^1.5)+(0.00000048314*35^2)),(O41+(K41*G41)+(L41*G41^1.5)+(0.00000048314*G41^2)))) -> 1.0268805 | N41: =IF(ISBLANK(D41),"",IF(ISBLANK(G41),J41*(1+0.00001*(35-20)),J41*(1+0.00001*(G41-20)))) -> 117.7476 | O41: =IF(ISBLANK(E41),"",(0.999842594+(0.00006793952*E41)-(0.00000909529*E41^2)+(0.0000001001685*E41^3)-(0.000000001120083*E41^4)+(0.000000000006536332*E41^5))) -> 0.9996842 | P41: 5.426 | Q41: 5.284 | R41: 242.3 | S41: 236 | T41: 0 | U41: 0 | V41: 22.2 | W41: 21.7 | X41: 22.2 | Y41: 21.7 | Z41: 1.54 | AA41: 1.5 | AB41: 25.6 | AC41: 25
A42: =IF(ISBLANK(VLOOKUP(D42,'Volumes flacons'!A5:C623,3)),0,1) -> 1 | B42: =IF(ISBLANK(D42),0,IF(ISBLANK(E42),0,IF(ISBLANK(F42),0,1))) -> 1 | C42: 8 | D42: 346 | E42: 10.4 | F42: 5.692 | G42: 34.946 | H42: 2000 | I42: 2000 | J42: 118.77 | K42: =IF(ISBLANK(E42),"",(0.000824493-(0.0000040899*E42)+(0.000000076438*E42^2)-(0.00000000082467*E42^3)+(0.0000000000053875*E42^4))) -> 0.00078936096 | L42: =IF(ISBLANK(E42),"",(-0.00000572466+(0.00000010227*E42)-(0.0000000016546*E42^2))) -> -4.8400135e-06 | M42: =IF(ISBLANK(E42),"",IF(ISBLANK(G42),(O42+(K42*35)+(L42*35^1.5)+(0.00000048314*35^2)),(O42+(K42*G42)+(L42*G42^1.5)+(0.00000048314*G42^2)))) -> 1.0268409 | N42: =IF(ISBLANK(D42),"",IF(ISBLANK(G42),J42*(1+0.00001*(35-20)),J42*(1+0.00001*(G42-20)))) -> 118.78775 | O42: =IF(ISBLANK(E42),"",(0.999842594+(0.00006793952*E42)-(0.00000909529*E42^2)+(0.0000001001685*E42^3)-(0.000000001120083*E42^4)+(0.000000000006536332*E42^5))) -> 0.99966579 | P42: 5.437 | Q42: 5.295 | R42: 242.8 | S42: 236.5 | T42: 0 | U42: 0 | V42: 22.1 | W42: 21.6 | X42: 22.1 | Y42: 21.6 | Z42: 1.55 | AA42: 1.51 | AB42: 25.7 | AC42: 25.1
A43: =IF(ISBLANK(VLOOKUP(D43,'Volumes flacons'!A5:C623,3)),0,1) -> 1 | B43: =IF(ISBLANK(D43),0,IF(ISBLANK(E43),0,IF(ISBLANK(F43),0,1))) -> 1 | C43: 9 | D43: 349 | E43: 11.2 | F43: 5.681 | G43: 34.946 | H43: 2000 | I43: 2000 | J43: 118.69 | K43: =IF(ISBLANK(E43),"",(0.000824493-(0.0000040899*E43)+(0.000000076438*E43^2)-(0.00000000082467*E43^3)+(0.0000000000053875*E43^4))) -> 0.00078720067 | L43: =IF(ISBLANK(E43),"",(-0.00000572466+(0.00000010227*E43)-(0.0000000016546*E43^2))) -> -4.786789e-06 | M43: =IF(ISBLANK(E43),"",IF(ISBLANK(G43),(O43+(K43*35)+(L43*35^1.5)+(0.00000048314*35^2)),(O43+(K43*G43)+(L43*G43^1.5)+(0.00000048314*G43^2)))) -> 1.0266975 | N43: =IF(ISBLANK(D43),"",IF(ISBLANK(G43),J43*(1+0.00001*(35-20)),J43*(1+0.00001*(G43-20)))) -> 118.70774 | O43: =IF(ISBLANK(E43),"",(0.999842594+(0.00006793952*E43)-(0.00000909529*E43^2)+(0.0000001001685*E43^3)-(0.000000001120083*E43^4)+(0.000000000006536332*E43^5))) -> 0.99958686 | P43: 5.43 | Q43: 5.289 | R43: 242.5 | S43: 236.2 | T43: 0 | U43: 0 | V43: 22 | W43: 21.5 | X43: 22 | Y43: 21.5 | Z43: 1.54 | AA43: 1.51 | AB43: 25.6 | AC43: 25
A44: =IF(ISBLANK(VLOOKUP(D44,'Volumes flacons'!A5:C623,3)),0,1) -> 1 | B44: =IF(ISBLANK(D44),0,IF(ISBLANK(E44),0,IF(ISBLANK(F44),0,1))) -> 1 | C44: 10 | D44: 353 | E44: 12 | F44: 5.749 | G44: 34.947 | H44: 2000 | I44: 2000 | J44: 118.58 | K44: =IF(ISBLANK(E44),"",(0.000824493-(0.0000040899*E44)+(0.000000076438*E44^2)-(0.00000000082467*E44^3)+(0.0000000000053875*E44^4))) -> 0.00078510796 | L44: =IF(ISBLANK(E44),"",(-0.00000572466+(0.00000010227*E44)-(0.0000000016546*E44^2))) -> -4.7356824e-06 | M44: =IF(ISBLANK(E44),"",IF(ISBLANK(G44),(O44+(K44*35)+(L44*35^1.5)+(0.00000048314*35^2)),(O44+(K44*G44)+(L44*G44^1.5)+(0.00000048314*G44^2)))) -> 1.0265485 | N44: =IF(ISBLANK(D44),"",IF(ISBLANK(G44),J44*(1+0.00001*(35-20)),J44*(1+0.00001*(G44-20)))) -> 118.59772 | O44: =IF(ISBLANK(E44),"",(0.999842594+(0.00006793952*E44)-(0.00000909529*E44^2)+(0.0000001001685*E44^3)-(0.000000001120083*E44^4)+(0.000000000006536332*E44^5))) -> 0.99949964 | P44: 5.501 | Q44: 5.358 | R44: 245.7 | S44: 239.3 | T44: 0.01 | U44: 0.01 | V44: 22.1 | W44: 21.6 | X44: 22.1 | Y44: 21.6 | Z44: 1.58 | AA44: 1.54 | AB44: 25.6 | AC44: 25
A45: =IF(ISBLANK(VLOOKUP(D45,'Volumes flacons'!A5:C623,3)),0,1) -> 1 | B45: =IF(ISBLANK(D45),0,IF(ISBLANK(E45),0,IF(ISBLANK(F45),0,1))) -> 1 | C45: 11 | D45: 355 | E45: 14.6 | F45: 5.767 | G45: 34.946 | H45: 2000 | I45: 2000 | J45: 119.95 | K45: =IF(ISBLANK(E45),"",(0.000824493-(0.0000040899*E45)+(0.000000076438*E45^2)-(0.00000000082467*E45^3)+(0.0000000000053875*E45^4))) -> 0.00077875229 | L45: =IF(ISBLANK(E45),"",(-0.00000572466+(0.00000010227*E45)-(0.0000000016546*E45^2))) -> -4.5842125e-06 | M45: =IF(ISBLANK(E45),"",IF(ISBLANK(G45),(O45+(K45*35)+(L45*35^1.5)+(0.00000048314*35^2)),(O45+(K45*G45)+(L45*G45^1.5)+(0.00000048314*G45^2)))) -> 1.0260182 | N45: =IF(ISBLANK(D45),"",IF(ISBLANK(G45),J45*(1+0.00001*(35-20)),J45*(1+0.00001*(G45-20)))) -> 119.96793 | O45: =IF(ISBLANK(E45),"",(0.999842594+(0.00006793952*E45)-(0.00000909529*E45^2)+(0.0000001001685*E45^3)-(0.000000001120083*E45^4)+(0.000000000006536332*E45^5))) -> 0.99916094 | P45: 5.454 | Q45: 5.315 | R45: 243.6 | S45: 237.4 | T45: 0 | U45: 0 | V45: 21.8 | W45: 21.3 | X45: 21.8 | Y45: 21.3 | Z45: 1.52 | AA45: 1.49 | AB45: 23.9 | AC45: 23.3
A46: =IF(ISBLANK(VLOOKUP(D46,'Volumes flacons'!A5:C623,3)),0,1) -> 1 | B46: =IF(ISBLANK(D46),0,IF(ISBLANK(E46),0,IF(ISBLANK(F46),0,1))) -> 0 | C46: 12 | J46: =IF(ISBLANK(D46),"",IF(VLOOKUP(D46,'Volumes flacons'!$A$5:$C$623,2)=0,"",IF(D46>'Volumes flacons'!$A$623,"Mauvais numéro",IF(D46<'Volumes flacons'!$A$5,"Mauvais numéro",(VLOOKUP(D46,'Volumes flacons'!$A$5:$C$623,3)))))) | K46: =IF(ISBLANK(E46),"",(0.000824493-(0.0000040899*E46)+(0.000000076438*E46^2)-(0.00000000082467*E46^3)+(0.0000000000053875*E46^4))) | L46: =IF(ISBLANK(E46),"",(-0.00000572466+(0.00000010227*E46)-(0.0000000016546*E46^2))) | M46: =IF(ISBLANK(E46),"",IF(ISBLANK(G46),(O46+(K46*35)+(L46*35^1.5)+(0.00000048314*35^2)),(O46+(K46*G46)+(L46*G46^1.5)+(0.00000048314*G46^2)))) | N46: =IF(ISBLANK(D46),"",IF(ISBLANK(G46),J46*(1+0.00001*(35-20)),J46*(1+0.00001*(G46-20)))) | O46: =IF(ISBLANK(E46),"",(0.999842594+(0.00006793952*E46)-(0.00000909529*E46^2)+(0.0000001001685*E46^3)-(0.000000001120083*E46^4)+(0.000000000006536332*E46^5))) | P46: =IF(ISBLANK($R$16),"",IF(A46=0,"",IF(ISBLANK($R$17),"",IF(B46=0,"",IF($O$28=$I$29,"",IF(AND($I$29=$O$29,D46<1000),"N° Flac.",IF(AND($I$29=$O$30,D46>1000),"N° Flac.",IF(AND(D46>1202,D46<2001),"Err. N°",IF(AND(D46>499,D46<1141),"Err.N°",(((((F46)+'Correction de volume'!$G$7)*(($P$21)*($P$19)*5598)/(($R$16)-($R$17)))-(($P$27)*1000))/((N46)-($P$26)))))))))))) | Q46: =IF(ISBLANK($R$16),"",IF(A46=0,"",IF(ISBLANK($R$17),"",IF(AND(D46>1202,D46<2001),"Err. N°",IF(AND(D46>499,D46<1141),"Err.N°",IF(B46=0,"",IF($O$28=$I$29,"",IF(AND($I$29=$O$29,D46<1000),"N° Flac.",IF(AND($I$29=$O$30,D46>1000),"N° Flac.",P46*M46))))))))) | R46: =IF(ISBLANK($R$16),"",IF(A46=0,"",IF(ISBLANK($R$17),"",IF(B46=0,"",IF(ISBLANK(J46),"",IF(AND(D46>1202,D46<2001),"Err. N°",IF(AND(D46>499,D46<1141),"Err.N°",IF($I$29=$O$28,"",IF(AND($I$29=$O$29,D46<1000),"N° Flac.",IF(AND($I$29=$O$30,D46>1000),"N° Flac.",((44.66*P46)))))))))))) | S46: =IF(ISBLANK($R$16),"",IF(A46=0,"",IF(ISBLANK($R$17),"",IF(B46=0,"",IF(ISBLANK(J46),"",IF(AND(D46>1202,D46<2001),"Err. N°",IF(AND(D46>499,D46<1141),"Err.N°",IF($I$29=$O$28,"",IF(AND($I$29=$O$29,D46<1000),"N° Flac.",IF(AND($I$29=$O$30,D46>1000),"N° Flac.",((44.66*P46)/M46)))))))))))
...

Sheet Station 002
C2: Campagne : | F2: PIRATA FR25
C4: Données de campagne
C6: N° de station : | F6: 2 | H6: N° de palanquée : | P6: 1 | R6: Date d'analyse : | T6: 40625
G8: Position | I8: Degrés | J8: Minutes | P8: Cardinal | Q8: Décimale
G9: Latitude | I9: 3 | J9: 0 | K9: : | L9: =IF(P9=M9,"+","-") -> + | M9: N | N9: E | O9: =IF(ISBLANK(I9),"",IF(ISBLANK(J9),"",IF(P9=M10,L9&N11,N11))) -> 3°0 | P9: N | Q9: 3
G10: Longitude | I10: 12 | J10: 30 | K10: : | L10: =IF(P10=N9,"+","-") -> - | M10: S | N10: W | O10: =IF(ISBLANK(I10),"",IF(ISBLANK(J10),"",IF(P10=N10,L10&N12,N12))) -> -12°30 | P10: W | Q10: -12.5
G11: Prélèvement | I11: Date | J11: 40623 | N11: =I9&"°"&J9 -> 3°0 | O11: =IF(P9=M10,-1,1) -> 1 | P11: 2015-03-22T15:00:00z
I12: Heure | J12: 0.625 | N12: =I10&"°"&J10 -> 12°30 | O12: =IF(P10=N10,-1,1) -> -1
C13: Données :
C14: Température du laboratoire à la calibration ( t°c ) | Q14: t°c = | R14: 24.1 | S14: °C
C15: Température du laboratoire au début de la série d'analyses | Q15: t°lab = | R15: 24.3 | S15: °C
C16: Volume moyen de thiosulfate pour la titration à t°c | Q16: Vmoy.titr.t°c = | R16: 5.009 | S16: mL
C17: Volume moyen de thiosulfate pour la détermination du blanc à t°c | Q17: Vmoy.titr.blanc.t°c = | R17: 0.006 | S17: mL
C18: Masse volumique de l'eau pure à la calibration | O18: ρ = | P18: =(0.999842594+(0.00006793952*$R$14)-(0.00000909529*$R$14^2)+(0.0000001001685*$R$14^3)-(0.000000001120083*$R$14^4)+(0.000000000006536332*$R$14^5)) -> 0.9972747
C19: Normalite de l'iodate (NIO3) à la température de calibration | O19: N(IO3) = | P19: =$P$24*($P$18/'Titre d''iodate'!E19) -> 0.019977637 | Q19: N
C20: Vol. de la prise d'essai d'iodate (VIO3) à 20°C | O20: V(IO3)20°C = | P20: =5+'Correction de volume'!G8 -> 5.00309 | Q20: mL
C21: Vol. de la prise d'essai d'iodate (VIO3) à t°c | O21: V(IO3)t°c= | P21: =P20*(1+0.00001*(R14-20)) -> 5.0032951 | Q21: mL
C22: Volume moyen de thiosulfate pour la titration à 20° C | O22: Vmoy.titr.20°C = | P22: =$R$16*(1+0.00001*(20-$R$14)) -> 5.0087946 | Q22: mL
C23: Volume moyen de thiosulfate pour la détermination du blanc à 20° C | O23: Vmoy.titr.blanc.20°C = | P23: =$R$17*(1+0.00001*(20-$R$14)) -> 0.005999754 | Q23: mL
C24: Normalite de l'iodate (NIO3) à 20°C | O24: N(IO3)20°C = | P24: =MAX('Titre d''iodate'!F7:F10) -> 0.019996299 | Q24: N
C25: Titre du thiosulfate à 20°C | O25: V(Thio)20°C = | P25: =IF(ISBLANK(R14),"",IF(ISBLANK(P21),"",IF(ISBLANK(R17),"",(($P$24*$P$18)/($P$22-$P$23))))) -> 0.0039861325 | Q25: N
C26: Volume de réactif utilisé | O26: Vreg = | P26: =2+('Correction de volume'!G10+'Correction de volume'!G9) -> 2.016394 | Q26: mL
O27: DOreg = | P27: 0.0017
E29: Choix de la série de flacons : | I29: LPO | O29: IRD
O30: LPO
C31: N° | D31: N° des Flacons | E31: T° prélèv. | F31: Volume de thio. | G31: Salinité | H31: Prof. Théorique | I31: Prof. Effective | J31: V. flacons 20°C | K31: A | L31: B | M31: Densité eau de mer à t° | N31: Vol. à t° prél. des flacons | O31: Densité eau pure à t° | P31: Oxygène dissous | T31: NO2 | V31: NO3 + NO2 | X31: NO3 | Z31: Phosphate | AB31: Silicate | AD31: chlorophyll-c3 | AE31: chlorophyll-c1+c2 | AF31: peridinin | AG31: 19'-butanoyloxyfucoxanthin | AH31: fucoxanthine | AI31: neoxanthin | AJ31: prasinoxanthin | AK31: violaxanthin | AL31: 19'-hexanoyloxyfucoxanthin | AM31: diadinoxanthin | AN31: alloxanthin | AO31: diatoxanthin | AP31: zeaxanthin | AQ31: lutein | AR31: divinyl chlorophyll-b | AS31: chlorophyll-b | AT31: total chlorophyll-b | AU31: alpha-carotene | AV31: beta-carotene | AW31: pheophorbide | AX31: divinyl chlorophyll-a | AY31: chlorophyll-a | AZ31: total chlorophyll-a | BA31: pheophytin_a | BB31: crocoxanthin
C33: BTL | E33: °C | F33: ml | H33: m | I33: m | J33: ml | P33: DOX1 | R33: DOXY | S33: DOX2 | T33: NTRI | U33: NTIW | V33: NTRZ | W33: NTZW | X33: NTRA | Y33: NTAW | Z33: PHOS | AA33: PHOW | AB33: SLCA | AC33: SLCW | AD33: CHC3 | AE33: CHCZ | AF33: PERP | AG33: BFUP | AH33: FUCP | AI33: NEXW | AJ33: PXAP | AK33: VIOW | AL33: HFUP | AM33: DXAP | AN33: AXAP | AO33: TXAP | AP33: ZXAP | AQ33: LUTW | AR33: CHBD | AS33: CH2P | AT33: CHLB | AU33: AACP | AV33: BBCP | AW33: PHEP | AX33: CHAD | AY33: CH1P | AZ33: CPHL | BA33: PHEA | BB33: CXAP
N34: mL | P34: ml/l | Q34: ml/kg | R34: µmol/l | S34: µmol/kg | T34: µmol/l | U34: µmol/kg | V34: µmol/l | W34: µmol/kg | X34: µmol/l | Y34: µmol/kg | Z34: µmol/l | AA34: µmol/kg | AB34: µmol/l | AC34: µmol/kg | AD34: µg.l-1 | AE34: µg.l-1 | AF34: µg.l-1 | AG34: µg.l-1 | AH34: µg.l-1 | AI34: µg.l-1 | AJ34: µg.l-1 | AK34: µg.l-1 | AL34: µg.l-1 | AM34: µg.l-1 | AN34: µg.l-1 | AO34: µg.l-1 | AP34: µg.l-1 | AQ34: µg.l-1 | AR34: µg.l-1 | AS34: µg.l-1 | AT34: µg.l-1 | AU34: µg.l-1 | AV34: µg.l-1 | AW34: µg.l-1 | AX34: µg.l-1 | AY34: µg.l-1 | AZ34: µg.l-1 | BA34: µg.l-1 | BB34: µg.l-1
A35: =IF(ISBLANK(VLOOKUP(D35,'Volumes flacons'!A5:C623,3)),0,1) -> 1 | B35: =IF(ISBLANK(D35),0,IF(ISBLANK(E35),0,IF(ISBLANK(F35),0,1))) -> 1 | C35: 1 | D35: 26 | E35: 7.3 | F35: 6.471 | G35: 34.957 | H35: 2000 | I35: 2021 | J35: 128.22 | K35: =IF(ISBLANK(E35),"",(0.000824493-(0.0000040899*E35)+(0.000000076438*E35^2)-(0.00000000082467*E35^3)+(0.0000000000053875*E35^4))) -> 0.0007984046 | L35: =IF(ISBLANK(E35),"",(-0.00000572466+(0.00000010227*E35)-(0.0000000016546*E35^2))) -> -5.0662626e-06 | M35: =IF(ISBLANK(E35),"",IF(ISBLANK(G35),(O35+(K35*35)+(L35*35^1.5)+(0.00000048314*35^2)),(O35+(K35*G35)+(L35*G35^1.5)+(0.00000048314*G35^2)))) -> 1.0273429 | N35: =IF(ISBLANK(D35),"",IF(ISBLANK(G35),J35*(1+0.00001*(35-20)),J35*(1+0.00001*(G35-20)))) -> 128.23918 | O35: =IF(ISBLANK(E35),"",(0.999842594+(0.00006793952*E35)-(0.00000909529*E35^2)+(0.0000001001685*E35^3)-(0.000000001120083*E35^4)+(0.000000000006536332*E35^5))) -> 0.99988979 | P35: 5.72 | Q35: 5.568 | R35: 255.5 | S35: 248.7 | T35: 0 | U35: 0 | V35: 20.8 | W35: 20.3 | X35: 20.8 | Y35: 20.3 | Z35: 1.43 | AA35: 1.39 | AB35: 23.5 | AC35: 23
A36: =IF(ISBLANK(VLOOKUP(D36,'Volumes flacons'!A5:C623,3)),0,1) -> 1 | B36: =IF(ISBLANK(D36),0,IF(ISBLANK(E36),0,IF(ISBLANK(F36),0,1))) -> 1 | C36: 2 | D36: 32 | E36: 7.6 | F36: 6.6262 | G36: 34.955 | H36: 2000 | I36: 2021 | J36: 125.28 | K36: =IF(ISBLANK(E36),"",(0.000824493-(0.0000040899*E36)+(0.000000076438*E36^2)-(0.00000000082467*E36^3)+(0.0000000000053875*E36^4))) -> 0.00079748078 | L36: =IF(ISBLANK(E36),"",(-0.00000572466+(0.00000010227*E36)-(0.0000000016546*E36^2))) -> -5.0429777e-06 | M36: =IF(ISBLANK(E36),"",IF(ISBLANK(G36),(O36+(K36*35)+(L36*35^1.5)+(0.00000048314*35^2)),(O36+(K36*G36)+(L36*G36^1.5)+(0.00000048314*G36^2)))) -> 1.0272981 | N36: =IF(ISBLANK(D36),"",IF(ISBLANK(G36),J36*(1+0.00001*(35-20)),J36*(1+0.00001*(G36-20)))) -> 125.29874 | O36: =IF(ISBLANK(E36),"",(0.999842594+(0.00006793952*E36)-(0.00000909529*E36^2)+(0.0000001001685*E36^3)-(0.000000001120083*E36^4)+(0.000000000006536332*E36^5))) -> 0.99987399 | P36: 5.997 | Q36: 5.838 | R36: 267.8 | S36: 260.7 | T36: 0.01 | U36: 0.01 | V36: 20.9 | W36: 20.4 | X36: 20.9 | Y36: 20.4 | Z36: 1.44 | AA36: 1.41 | AB36: 24.1 | AC36: 23.5
A37: =IF(ISBLANK(VLOOKUP(D37,'Volumes flacons'!A5:C623,3)),0,1) -> 1 | B37: =IF(ISBLANK(D37),0,IF(ISBLANK(E37),0,IF(ISBLANK(F37),0,1))) -> 1 | C37: 3 | D37: 40 | E37: 10.8 | F37: 3.91 | G37: 34.647 | H37: 1000 | I37: 1008.8 | J37: 122.34 | K37: =IF(ISBLANK(E37),"",(0.000824493-(0.0000040899*E37)+(0.000000076438*E37^2)-(0.00000000082467*E37^3)+(0.0000000000053875*E37^4))) -> 0.00078827226 | L37: =IF(ISBLANK(E37),"",(-0.00000572466+(0.00000010227*E37)-(0.0000000016546*E37^2))) -> -4.8131365e-06 | M37: =IF(ISBLANK(E37),"",IF(ISBLANK(G37),(O37+(K37*35)+(L37*35^1.5)+(0.00000048314*35^2)),(O37+(K37*G37)+(L37*G37^1.5)+(0.00000048314*G37^2)))) -> 1.026537 | N37: =IF(ISBLANK(D37),"",IF(ISBLANK(G37),J37*(1+0.00001*(35-20)),J37*(1+0.00001*(G37-20)))) -> 122.35792 | O37: =IF(ISBLANK(E37),"",(0.999842594+(0.00006793952*E37)-(0.00000909529*E37^2)+(0.0000001001685*E37^3)-(0.000000001120083*E37^4)+(0.000000000006536332*E37^5))) -> 0.99962737 | P37: 3.62 | Q37: 3.526 | R37: 161.7 | S37: 157.5 | T37: 0.01 | U37: 0.01 | V37: 33.7 | W37: 33 | X37: 33.7 | Y37: 33 | Z37: 2.46 | AA37: 2.41 | AB37: 29.1 | AC37: 28.4
A38: =IF(ISBLANK(VLOOKUP(D38,'Volumes flacons'!A5:C623,3)),0,1) -> 1 | B38: =IF(ISBLANK(D38),0,IF(ISBLANK(E38),0,IF(ISBLANK(F38),0,1))) -> 1 | C38: 4 | D38: 44 | E38: 11.4 | F38: 2.568 | G38: 34.68 | H38: 500 | I38: 503.1 | J38: 129.67 | K38: =IF(ISBLANK(E38),"",(0.000824493-(0.0000040899*E38)+(0.000000076438*E38^2)-(0.00000000082467*E38^3)+(0.0000000000053875*E38^4))) -> 0.00078667123 | L38: =IF(ISBLANK(E38),"",(-0.00000572466+(0.00000010227*E38)-(0.0000000016546*E38^2))) -> -4.7738138e-06 | M38: =IF(ISBLANK(E38),"",IF(ISBLANK(G38),(O38+(K38*35)+(L38*35^1.5)+(0.00000048314*35^2)),(O38+(K38*G38)+(L38*G38^1.5)+(0.00000048314*G38^2)))) -> 1.0264537 | N38: =IF(ISBLANK(D38),"",IF(ISBLANK(G38),J38*(1+0.00001*(35-20)),J38*(1+0.00001*(G38-20)))) -> 129.68904 | O38: =IF(ISBLANK(E38),"",(0.999842594+(0.00006793952*E38)-(0.00000909529*E38^2)+(0.0000001001685*E38^3)-(0.000000001120083*E38^4)+(0.000000000006536332*E38^5))) -> 0.99956583 | P38: 2.236 | Q38: 2.178 | R38: 99.9 | S38: 97.3 | T38: 0.01 | U38: 0.01 | V38: 35.9 | W38: 35.1 | X38: 35.9 | Y38: 35 | Z38: 2.48 | AA38: 2.42 | AB38: 19 | AC38: 18.5
A39: =IF(ISBLANK(VLOOKUP(D39,'Volumes flacons'!A5:C623,3)),0,1) -> 1 | B39: =IF(ISBLANK(D39),0,IF(ISBLANK(E39),0,IF(ISBLANK(F39),0,1))) -> 1 | C39: 5 | D39: 55 | E39: 17.5 | F39: 2.502 | G39: 35.63 | H39: 100 | I39: 101 | J39: 126.67 | K39: =IF(ISBLANK(E39),"",(0.000824493-(0.0000040899*E39)+(0.000000076438*E39^2)-(0.00000000082467*E39^3)+(0.0000000000053875*E39^4))) -> 0.00077241446 | L39: =IF(ISBLANK(E39),"",(-0.00000572466+(0.00000010227*E39)-(0.0000000016546*E39^2))) -> -4.4416562e-06 | M39: =IF(ISBLANK(E39),"",IF(ISBLANK(G39),(O39+(K39*35)+(L39*35^1.5)+(0.00000048314*35^2)),(O39+(K39*G39)+(L39*G39^1.5)+(0.00000048314*G39^2)))) -> 1.0258784 | N39: =IF(ISBLANK(D39),"",IF(ISBLANK(G39),J39*(1+0.00001*(35-20)),J39*(1+0.00001*(G39-20)))) -> 126.6898 | O39: =IF(ISBLANK(E39),"",(0.999842594+(0.00006793952*E39)-(0.00000909529*E39^2)+(0.0000001001685*E39^3)-(0.000000001120083*E39^4)+(0.000000000006536332*E39^5))) -> 0.99868862 | P39: 2.231 | Q39: 2.174 | R39: 99.6 | S39: 97.1 | T39: 0.03 | U39: 0.03 | V39: 20.9 | W39: 20.4 | X39: 20.9 | Y39: 20.4 | Z39: 1.35 | AA39: 1.32 | AB39: 6.7 | AC39: 6.6 | AD39: 0.0311 | AE39: 0.0155 | AF39: 0.0018 | AG39: 0.0293 | AH39: 0.0211 | AI39: 0.0021 | AJ39: 0.0026 | AK39: 0.0012 | AL39: 0.0467 | AM39: 0.0034 | AN39: -99999 | AO39: -99999 | AP39: 0.0077 | AR39: 0.0573 | AS39: 0.0371 | AU39: 0.0202 | AV39: -99999 | AX39: 0.0369 | AY39: 0.1121 | BA39: 0.0017
A40: =IF(ISBLANK(VLOOKUP(D40,'Volumes flacons'!A5:C623,3)),0,1) -> 1 | B40: =IF(ISBLANK(D40),0,IF(ISBLANK(E40),0,IF(ISBLANK(F40),0,1))) -> 1 | C40: 6 | D40: 98 | E40: 18.4 | F40: 2.625 | G40: 35.753 | H40: 80 | I40: 80.3 | J40: 126.98 | K40: =IF(ISBLANK(E40),"",(0.000824493-(0.0000040899*E40)+(0.000000076438*E40^2)-(0.00000000082467*E40^3)+(0.0000000000053875*E40^4))) -> 0.00077059793 | L40: =IF(ISBLANK(E40),"",(-0.00000572466+(0.00000010227*E40)-(0.0000000016546*E40^2))) -> -4.4030734e-06 | M40: =IF(ISBLANK(E40),"",IF(ISBLANK(G40),(O40+(K40*35)+(L40*35^1.5)+(0.00000048314*35^2)),(O40+(K40*G40)+(L40*G40^1.5)+(0.00000048314*G40^2)))) -> 1.0257503 | N40: =IF(ISBLANK(D40),"",IF(ISBLANK(G40),J40*(1+0.00001*(35-20)),J40*(1+0.00001*(G40-20)))) -> 127 | O40: =IF(ISBLANK(E40),"",(0.999842594+(0.00006793952*E40)-(0.00000909529*E40^2)+(0.0000001001685*E40^3)-(0.000000001120083*E40^4)+(0.000000000006536332*E40^5))) -> 0.99852278 | P40: 2.335 | Q40: 2.277 | R40: 104.3 | S40: 101.7 | T40: 0.08 | U40: 0.07 | V40: 19.5 | W40: 19 | X40: 19.4 | Y40: 19 | Z40: 1.28 | AA40: 1.25 | AB40: 5.6 | AC40: 5.5 | AD40: 0.0662 | AE40: 0.0365 | AF40: 0.0061 | AG40: 0.0689 | AH40: 0.0465 | AI40: 0.0043 | AJ40: 0.0055 | AK40: 0.002 | AL40: 0.079 | AM40: 0.0075 | AN40: 0.0014 | AO40: -99999 | AP40: 0.0272 | AR40: 0.1129 | AS40: 0.0604 | AU40: 0.0371 | AV40: -99999 | AX40: 0.0773 | AY40: 0.2393 | BA40: 0.0043
A41: =IF(ISBLANK(VLOOKUP(D41,'Volumes flacons'!A5:C623,3)),0,1) -> 1 | B41: =IF(ISBLANK(D41),0,IF(ISBLANK(E41),0,IF(ISBLANK(F41),0,1))) -> 1 | C41: 7 | D41: 104 | E41: 19.2 | F41: 3.157 | G41: 35.8 | H41: 60 | I41: 60.5 | J41: 127.33 | K41: =IF(ISBLANK(E41),"",(0.000824493-(0.0000040899*E41)+(0.000000076438*E41^2)-(0.00000000082467*E41^3)+(0.0000000000053875*E41^4))) -> 0.00076904024 | L41: =IF(ISBLANK(E41),"",(-0.00000572466+(0.00000010227*E41)-(0.0000000016546*E41^2))) -> -4.3710277e-06 | M41: =IF(ISBLANK(E41),"",IF(ISBLANK(G41),(O41+(K41*35)+(L41*35^1.5)+(0.00000048314*35^2)),(O41+(K41*G41)+(L41*G41^1.5)+(0.00000048314*G41^2)))) -> 1.0255825 | N41: =IF(ISBLANK(D41),"",IF(ISBLANK(G41),J41*(1+0.00001*(35-20)),J41*(1+0.00001*(G41-20)))) -> 127.35012 | O41: =IF(ISBLANK(E41),"",(0.999842594+(0.00006793952*E41)-(0.00000909529*E41^2)+(0.0000001001685*E41^3)-(0.000000001120083*E41^4)+(0.000000000006536332*E41^5))) -> 0.99836797 | P41: 2.803 | Q41: 2.733 | R41: 125.2 | S41: 122.1 | T41: 0.43 | U41: 0.42 | V41: 15.8 | W41: 15.4 | X41: 15.4 | Y41: 15 | Z41: 1.01 | AA41: 0.99 | AB41: 4 | AC41: 3.9 | AD41: 0.0922 | AE41: 0.0593 | AF41: 0.0088 | AG41: 0.1024 | AH41: 0.0432 | AI41: 0.017 | AJ41: 0.0298 | AK41: 0.0055 | AL41: 0.1257 | AM41: 0.0117 | AN41: 0.0056 | AO41: -99999 | AP41: 0.0429 | AR41: 0.072 | AS41: 0.2017 | AU41: 0.0403 | AV41: -99999 | AX41: 0.0805 | AY41: 0.4869 | BA41: -99999
A42: =IF(ISBLANK(VLOOKUP(D42,'Volumes flacons'!A5:C623,3)),0,1) -> 1 | B42: =IF(ISBLANK(D42),0,IF(ISBLANK(E42),0,IF(ISBLANK(F42),0,1))) -> 1 | C42: 8 | D42: 109 | E42: 23.2 | F42: 4.685 | G42: 35.809 | H42: 40 | I42: 42.1 | J42: 125.56 | K42: =IF(ISBLANK(E42),"",(0.000824493-(0.0000040899*E42)+(0.000000076438*E42^2)-(0.00000000082467*E42^3)+(0.0000000000053875*E42^4))) -> 0.00076201229 | L42: =IF(ISBLANK(E42),"",(-0.00000572466+(0.00000010227*E42)-(0.0000000016546*E42^2))) -> -4.2425679e-06 | M42: =IF(ISBLANK(E42),"",IF(ISBLANK(G42),(O42+(K42*35)+(L42*35^1.5)+(0.00000048314*35^2)),(O42+(K42*G42)+(L42*G42^1.5)+(0.00000048314*G42^2)))) -> 1.0244909 | N42: =IF(ISBLANK(D42),"",IF(ISBLANK(G42),J42*(1+0.00001*(35-20)),J42*(1+0.00001*(G42-20)))) -> 125.57985 | O42: =IF(ISBLANK(E42),"",(0.999842594+(0.00006793952*E42)-(0.00000909529*E42^2)+(0.0000001001685*E42^3)-(0.000000001120083*E42^4)+(0.000000000006536332*E42^5))) -> 0.9974936 | P42: 4.227 | Q42: 4.126 | R42: 188.8 | S42: 184.3 | T42: 0.02 | U42: 0.02 | V42: 0.5 | W42: 0.5 | X42: 0.5 | Y42: 0.5 | Z42: 0.06 | AA42: 0.06 | AB42: 1.7 | AC42: 1.7 | AD42: 0.0473 | AE42: 0.1253 | AF42: 0.0292 | AG42: 0.1535 | AH42: 0.0607 | AI42: 0.0118 | AJ42: 0.0282 | AK42: 0.0182 | AL42: 0.3104 | AM42: 0.0311 | AN42: 0.0084 | AO42: -99999 | AP42: 0.1334 | AR42: 0.0319 | AS42: 0.2129 | AU42: 0.0665 | AV42: -99999 | AX42: 0.1459 | AY42: 0.9194 | BA42: -99999
A43: =IF(ISBLANK(VLOOKUP(D43,'Volumes flacons'!A5:C623,3)),0,1) -> 1 | B43: =IF(ISBLANK(D43),0,IF(ISBLANK(E43),0,IF(ISBLANK(F43),0,1))) -> 1 | C43: 9 | D43: 130 | E43: 28.8 | F43: 5.14 | G43: 35.348 | H43: 20 | I43: 21.5 | J43: 122.45 | K43: =IF(ISBLANK(E43),"",(0.000824493-(0.0000040899*E43)+(0.000000076438*E43^2)-(0.00000000082467*E43^3)+(0.0000000000053875*E43^4))) -> 0.00075411145 | L43: =IF(ISBLANK(E43),"",(-0.00000572466+(0.00000010227*E43)-(0.0000000016546*E43^2))) -> -4.1516754e-06 | M43: =IF(ISBLANK(E43),"",IF(ISBLANK(G43),(O43+(K43*35)+(L43*35^1.5)+(0.00000048314*35^2)),(O43+(K43*G43)+(L43*G43^1.5)+(0.00000048314*G43^2)))) -> 1.0223945 | N43: =IF(ISBLANK(D43),"",IF(ISBLANK(G43),J43*(1+0.00001*(35-20)),J43*(1+0.00001*(G43-20)))) -> 122.46879 | O43: =IF(ISBLANK(E43),"",(0.999842594+(0.00006793952*E43)-(0.00000909529*E43^2)+(0.0000001001685*E43^3)-(0.000000001120083*E43^4)+(0.000000000006536332*E43^5))) -> 0.99600699 | P43: 4.758 | Q43: 4.654 | R43: 212.5 | S43: 207.8 | T43: 0 | U43: 0 | V43: 0.1 | W43: 0.1 | X43: 0.1 | Y43: 0.1 | Z43: 0 | AA43: 0 | AB43: 1.2 | AC43: 1.1 | AD43: 0.0076 | AE43: 0.0143 | AF43: 0.0097 | AG43: 0.0089 | AH43: 0.0083 | AI43: 0.0012 | AJ43: -99999 | AK43: 0.0022 | AL43: 0.0326 | AM43: 0.0094 | AN43: -99999 | AO43: -99999 | AP43: 0.1324 | AR43: 0.0057 | AS43: 0.0116 | AU43: 0.025 | AV43: -99999 | AX43: 0.0838 | AY43: 0.1342 | BA43: -99999
A44: =IF(ISBLANK(VLOOKUP(D44,'Volumes flacons'!A5:C623,3)),0,1) -> 1 | B44: =IF(ISBLANK(D44),0,IF(ISBLANK(E44),0,IF(ISBLANK(F44),0,1))) -> 1 | C44: 10 | D44: 135 | E44: 29.2 | F44: 4.984 | G44: 35.064 | H44: 10 | I44: 11.3 | J44: 121.11 | K44: =IF(ISBLANK(E44),"",(0.000824493-(0.0000040899*E44)+(0.000000076438*E44^2)-(0.00000000082467*E44^3)+(0.0000000000053875*E44^4))) -> 0.00075362682 | L44: =IF(ISBLANK(E44),"",(-0.00000572466+(0.00000010227*E44)-(0.0000000016546*E44^2))) -> -4.1491541e-06 | M44: =IF(ISBLANK(E44),"",IF(ISBLANK(G44),(O44+(K44*35)+(L44*35^1.5)+(0.00000048314*35^2)),(O44+(K44*G44)+(L44*G44^1.5)+(0.00000048314*G44^2)))) -> 1.0220475 | N44: =IF(ISBLANK(D44),"",IF(ISBLANK(G44),J44*(1+0.00001*(35-20)),J44*(1+0.00001*(G44-20)))) -> 121.12824 | O44: =IF(ISBLANK(E44),"",(0.999842594+(0.00006793952*E44)-(0.00000909529*E44^2)+(0.0000001001685*E44^3)-(0.000000001120083*E44^4)+(0.000000000006536332*E44^5))) -> 0.99588978 | P44: 4.665 | Q44: 4.565 | R44: 208.4 | S44: 203.9 | T44: 0 | U44: 0 | V44: 0.1 | W44: 0.1 | X44: 0.1 | Y44: 0.1 | Z44: 0 | AA44: 0 | AB44: 1.3 | AC44: 1.2
A45: =IF(ISBLANK(VLOOKUP(D45,'Volumes flacons'!A5:C623,3)),0,1) -> 1 | B45: =IF(ISBLANK(D45),0,IF(ISBLANK(E45),0,IF(ISBLANK(F45),0,1))) -> 1 | C45: 11 | D45: 146 | E45: 29.5 | F45: 5.126 | G45: 35.069 | H45: 0 | I45: 2.9 | J45: 126.45 | K45: =IF(ISBLANK(E45),"",(0.000824493-(0.0000040899*E45)+(0.000000076438*E45^2)-(0.00000000082467*E45^3)+(0.0000000000053875*E45^4))) -> 0.00075327002 | L45: =IF(ISBLANK(E45),"",(-0.00000572466+(0.00000010227*E45)-(0.0000000016546*E45^2))) -> -4.1476107e-06 | M45: =IF(ISBLANK(E45),"",IF(ISBLANK(G45),(O45+(K45*35)+(L45*35^1.5)+(0.00000048314*35^2)),(O45+(K45*G45)+(L45*G45^1.5)+(0.00000048314*G45^2)))) -> 1.0219502 | N45: =IF(ISBLANK(D45),"",IF(ISBLANK(G45),J45*(1+0.00001*(35-20)),J45*(1+0.00001*(G45-20)))) -> 126.46905 | O45: =IF(ISBLANK(E45),"",(0.999842594+(0.00006793952*E45)-(0.00000909529*E45^2)+(0.0000001001685*E45^3)-(0.000000001120083*E45^4)+(0.000000000006536332*E45^5))) -> 0.99580095 | P45: 4.593 | Q45: 4.494 | R45: 205.1 | S45: 200.7 | T45: 0 | U45: 0 | V45: 0 | W45: 0 | X45: 0 | Y45: 0 | Z45: 0 | AA45: 0 | AB45: 1.1 | AC45: 1 | AD45: 0.0049 | AE45: 0.0081 | AF45: 0.0048 | AG45: 0.0052 | AH45: 0.0065 | AI45: 0.001 | AJ45: -99999 | AK45: 0.0032 | AL45: 0.0221 | AM45: 0.0099 | AN45: -99999 | AO45: -99999 | AP45: 0.1345 | AR45: 0.0024 | AS45: 0.0067 | AU45: 0.0186 | AV45: -99999 | AX45: 0.0622 | AY45: 0.0919 | BA45: -99999
A46: =IF(ISBLANK(VLOOKUP(D46,'Volumes flacons'!A5:C623,3)),0,1) -> 1 | B46: =IF(ISBLANK(D46),0,IF(ISBLANK(E46),0,IF(ISBLANK(F46),0,1))) -> 0 | C46: 12 | J46: =IF(ISBLANK(D46),"",IF(VLOOKUP(D46,'Volumes flacons'!$A$5:$C$623,2)=0,"",IF(D46>'Volumes flacons'!$A$623,"Mauvais numéro",IF(D46<'Volumes flacons'!$A$5,"Mauvais numéro",(VLOOKUP(D46,'Volumes flacons'!$A$5:$C$623,3)))))) | K46: =IF(ISBLANK(E46),"",(0.000824493-(0.0000040899*E46)+(0.000000076438*E46^2)-(0.00000000082467*E46^3)+(0.0000000000053875*E46^4))) | L46: =IF(ISBLANK(E46),"",(-0.00000572466+(0.00000010227*E46)-(0.0000000016546*E46^2))) | M46: =IF(ISBLANK(E46),"",IF(ISBLANK(G46),(O46+(K46*35)+(L46*35^1.5)+(0.00000048314*35^2)),(O46+(K46*G46)+(L46*G46^1.5)+(0.00000048314*G46^2)))) | N46: =IF(ISBLANK(D46),"",IF(ISBLANK(G46),J46*(1+0.00001*(35-20)),J46*(1+0.00001*(G46-20)))) | O46: =IF(ISBLANK(E46),"",(0.999842594+(0.00006793952*E46)-(0.00000909529*E46^2)+(0.0000001001685*E46^3)-(0.000000001120083*E46^4)+(0.000000000006536332*E46^5))) | P46: =IF(ISBLANK($R$16),"",IF(A46=0,"",IF(ISBLANK($R$17),"",IF(B46=0,"",IF($O$28=$I$29,"",IF(AND($I$29=$O$29,D46<1000),"N° Flac.",IF(AND($I$29=$O$30,D46>1000),"N° Flac.",IF(AND(D46>1202,D46<2001),"Err. N°",IF(AND(D46>499,D46<1141),"Err.N°",(((((F46)+'Correction de volume'!$G$7)*(($P$21)*($P$19)*5598)/(($R$16)-($R$17)))-(($P$27)*1000))/((N46)-($P$26)))))))))))) | Q46: =IF(ISBLANK($R$16),"",IF(A46=0,"",IF(ISBLANK($R$17),"",IF(AND(D46>1202,D46<2001),"Err. N°",IF(AND(D46>499,D46<1141),"Err.N°",IF(B46=0,"",IF($O$28=$I$29,"",IF(AND($I$29=$O$29,D46<1000),"N° Flac.",IF(AND($I$29=$O$30,D46>1000),"N° Flac.",P46*M46))))))))) | R46: =IF(ISBLANK($R$16),"",IF(A46=0,"",IF(ISBLANK($R$17),"",IF(B46=0,"",IF(ISBLANK(J46),"",IF(AND(D46>1202,D46<2001),"Err. N°",IF(AND(D46>499,D46<1141),"Err.N°",IF($I$29=$O$28,"",IF(AND($I$29=$O$29,D46<1000),"N° Flac.",IF(AND($I$29=$O$30,D46>1000),"N° Flac.",((44.66*P46)))))))))))) | S46: =IF(ISBLANK($R$16),"",IF(A46=0,"",IF(ISBLANK($R$17),"",IF(B46=0,"",IF(ISBLANK(J46),"",IF(AND(D46>1202,D46<2001),"Err. N°",IF(AND(D46>499,D46<1141),"Err.N°",IF($I$29=$O$28,"",IF(AND($I$29=$O$29,D46<1000),"N° Flac.",IF(AND($I$29=$O$30,D46>1000),"N° Flac.",((44.66*P46)/M46)))))))))))
...

Sheet Station 003
C2: Campagne : | F2: PIRATA FR25
C4: Données de campagne
C6: N° de station : | F6: 2 | H6: N° de palanquée : | P6: 1 | R6: Date d'analyse : | T6: 40625
G8: Position | I8: Degrés | J8: Minutes | P8: Cardinal | Q8: Décimale
G9: Latitude | I9: 0 | J9: 0 | K9: : | L9: =IF(P9=M9,"+","-") -> + | M9: N | N9: E | O9: =IF(ISBLANK(I9),"",IF(ISBLANK(J9),"",IF(P9=M10,L9&N11,N11))) -> 0°0 | P9: N | Q9: 0
G10: Longitude | I10: 10 | J10: 0 | K10: : | L10: =IF(P10=N9,"+","-") -> - | M10: S | N10: W | O10: =IF(ISBLANK(I10),"",IF(ISBLANK(J10),"",IF(P10=N10,L10&N12,N12))) -> -10°0 | P10: W | Q10: -10
G11: Prélèvement | I11: Date | J11: 40624 | N11: =I9&"°"&J9 -> 0°0 | O11: =IF(P9=M10,-1,1) -> 1 | P11: 2015-03-23T15:00:00z
I12: Heure | J12: 0.625 | N12: =I10&"°"&J10 -> 10°0 | O12: =IF(P10=N10,-1,1) -> -1
C13: Données :
C14: Température du laboratoire à la calibration ( t°c ) | Q14: t°c = | R14: 24.1 | S14: °C
C15: Température du laboratoire au début de la série d'analyses | Q15: t°lab = | R15: 24.3 | S15: °C
C16: Volume moyen de thiosulfate pour la titration à t°c | Q16: Vmoy.titr.t°c = | R16: 5.009 | S16: mL
C17: Volume moyen de thiosulfate pour la détermination du blanc à t°c | Q17: Vmoy.titr.blanc.t°c = | R17: 0.006 | S17: mL
C18: Masse volumique de l'eau pure à la calibration | O18: ρ = | P18: =(0.999842594+(0.00006793952*$R$14)-(0.00000909529*$R$14^2)+(0.0000001001685*$R$14^3)-(0.000000001120083*$R$14^4)+(0.000000000006536332*$R$14^5)) -> 0.9972747
C19: Normalite de l'iodate (NIO3) à la température de calibration | O19: N(IO3) = | P19: =$P$24*($P$18/'Titre d''iodate'!E19) -> 0.019977637 | Q19: N
C20: Vol. de la prise d'essai d'iodate (VIO3) à 20°C | O20: V(IO3)20°C = | P20: =5+'Correction de volume'!G8 -> 5.00309 | Q20: mL
C21: Vol. de la prise d'essai d'iodate (VIO3) à t°c | O21: V(IO3)t°c= | P21: =P20*(1+0.00001*(R14-20)) -> 5.0032951 | Q21: mL
C22: Volume moyen de thiosulfate pour la titration à 20° C | O22: Vmoy.titr.20°C = | P22: =$R$16*(1+0.00001*(20-$R$14)) -> 5.0087946 | Q22: mL
C23: Volume moyen de thiosulfate pour la détermination du blanc à 20° C | O23: Vmoy.titr.blanc.20°C = | P23: =$R$17*(1+0.00001*(20-$R$14)) -> 0.005999754 | Q23: mL
C24: Normalite de l'iodate (NIO3) à 20°C | O24: N(IO3)20°C = | P24: =MAX('Titre d''iodate'!F7:F10) -> 0.019996299 | Q24: N
C25: Titre du thiosulfate à 20°C | O25: V(Thio)20°C = | P25: =IF(ISBLANK(R14),"",IF(ISBLANK(P21),"",IF(ISBLANK(R17),"",(($P$24*$P$18)/($P$22-$P$23))))) -> 0.0039861325 | Q25: N
C26: Volume de réactif utilisé | O26: Vreg = | P26: =2+('Correction de volume'!G10+'Correction de volume'!G9) -> 2.016394 | Q26: mL
O27: DOreg = | P27: 0.0017
E29: Choix de la série de flacons : | I29: LPO | O29: IRD
O30: LPO
C31: N° | D31: N° des Flacons | E31: T° prélèv. | F31: Volume de thio. | G31: Salinité | H31: Prof. Théorique | I31: Prof. Effective | J31: V. flacons 20°C | K31: A | L31: B | M31: Densité eau de mer à t° | N31: Vol. à t° prél. des flacons | O31: Densité eau pure à t° | P31: Oxygène dissous | T31: NO2 | V31: NO3 + NO2 | X31: NO3 | Z31: Phosphate | AB31: Silicate | AD31: chlorophyll-c3 | AE31: chlorophyll-c1+c2 | AF31: peridinin | AG31: 19'-butanoyloxyfucoxanthin | AH31: fucoxanthine | AI31: neoxanthin | AJ31: prasinoxanthin | AK31: violaxanthin | AL31: 19'-hexanoyloxyfucoxanthin | AM31: diadinoxanthin | AN31: alloxanthin | AO31: diatoxanthin | AP31: zeaxanthin | AQ31: lutein | AR31: divinyl chlorophyll-b | AS31: chlorophyll-b | AT31: total chlorophyll-b | AU31: alpha-carotene | AV31: beta-carotene | AW31: pheophorbide | AX31: divinyl chlorophyll-a | AY31: chlorophyll-a | AZ31: total chlorophyll-a | BA31: pheophytin_a | BB31: crocoxanthin
C33: BTL | E33: °C | F33: ml | H33: m | I33: m | J33: ml | P33: DOX1 | R33: DOXY | S33: DOX2 | T33: NTRI | U33: NTIW | V33: NTRZ | W33: NTZW | X33: NTRA | Y33: NTAW | Z33: PHOS | AA33: PHOW | AB33: SLCA | AC33: SLCW | AD33: CHC3 | AE33: CHCZ | AF33: PERP | AG33: BFUP | AH33: FUCP | AI33: NEXW | AJ33: PXAP | AK33: VIOW | AL33: HFUP | AM33: DXAP | AN33: AXAP | AO33: TXAP | AP33: ZXAP | AQ33: LUTW | AR33: CHBD | AS33: CH2P | AT33: CHLB | AU33: AACP | AV33: BBCP | AW33: PHEP | AX33: CHAD | AY33: CH1P | AZ33: CPHL | BA33: PHEA | BB33: CXAP
N34: mL | P34: ml/l | Q34: ml/kg | R34: µmol/l | S34: µmol/kg | T34: µmol/l | U34: µmol/kg | V34: µmol/l | W34: µmol/kg | X34: µmol/l | Y34: µmol/kg | Z34: µmol/l | AA34: µmol/kg | AB34: µmol/l | AC34: µmol/kg | AD34: µg.l-1 | AE34: µg.l-1 | AF34: µg.l-1 | AG34: µg.l-1 | AH34: µg.l-1 | AI34: µg.l-1 | AJ34: µg.l-1 | AK34: µg.l-1 | AL34: µg.l-1 | AM34: µg.l-1 | AN34: µg.l-1 | AO34: µg.l-1 | AP34: µg.l-1 | AQ34: µg.l-1 | AR34: µg.l-1 | AS34: µg.l-1 | AT34: µg.l-1 | AU34: µg.l-1 | AV34: µg.l-1 | AW34: µg.l-1 | AX34: µg.l-1 | AY34: µg.l-1 | AZ34: µg.l-1 | BA34: µg.l-1 | BB34: µg.l-1
A35: =IF(ISBLANK(VLOOKUP(D35,'Volumes flacons'!A5:C623,3)),0,1) -> 1 | B35: =IF(ISBLANK(D35),0,IF(ISBLANK(E35),0,IF(ISBLANK(F35),0,1))) -> 1 | C35: 1 | D35: 386 | E35: 7.4 | F35: 6.077 | G35: 34.963 | H35: 2000 | I35: 2020 | J35: 119.69 | K35: =IF(ISBLANK(E35),"",(0.000824493-(0.0000040899*E35)+(0.000000076438*E35^2)-(0.00000000082467*E35^3)+(0.0000000000053875*E35^4))) -> 0.00079809546 | L35: =IF(ISBLANK(E35),"",(-0.00000572466+(0.00000010227*E35)-(0.0000000016546*E35^2))) -> -5.0584679e-06 | M35: =IF(ISBLANK(E35),"",IF(ISBLANK(G35),(O35+(K35*35)+(L35*35^1.5)+(0.00000048314*35^2)),(O35+(K35*G35)+(L35*G35^1.5)+(0.00000048314*G35^2)))) -> 1.0273333 | N35: =IF(ISBLANK(D35),"",IF(ISBLANK(G35),J35*(1+0.00001*(35-20)),J35*(1+0.00001*(G35-20)))) -> 119.70791 | O35: =IF(ISBLANK(E35),"",(0.999842594+(0.00006793952*E35)-(0.00000909529*E35^2)+(0.0000001001685*E35^3)-(0.000000001120083*E35^4)+(0.000000000006536332*E35^5))) -> 0.99988467 | P35: 5.76 | Q35: 5.607 | R35: 257.3 | S35: 250.4
A36: =IF(ISBLANK(VLOOKUP(D36,'Volumes flacons'!A5:C623,3)),0,1) -> 1 | B36: =IF(ISBLANK(D36),0,IF(ISBLANK(E36),0,IF(ISBLANK(F36),0,1))) -> 1 | C36: 2 | D36: 389 | E36: 7.4 | F36: 3.823 | G36: 34.654 | H36: 1000 | I36: 1009 | J36: 117.22 | K36: =IF(ISBLANK(E36),"",(0.000824493-(0.0000040899*E36)+(0.000000076438*E36^2)-(0.00000000082467*E36^3)+(0.0000000000053875*E36^4))) -> 0.00079809546 | L36: =IF(ISBLANK(E36),"",(-0.00000572466+(0.00000010227*E36)-(0.0000000016546*E36^2))) -> -5.0584679e-06 | M36: =IF(ISBLANK(E36),"",IF(ISBLANK(G36),(O36+(K36*35)+(L36*35^1.5)+(0.00000048314*35^2)),(O36+(K36*G36)+(L36*G36^1.5)+(0.00000048314*G36^2)))) -> 1.0270901 | N36: =IF(ISBLANK(D36),"",IF(ISBLANK(G36),J36*(1+0.00001*(35-20)),J36*(1+0.00001*(G36-20)))) -> 117.23718 | O36: =IF(ISBLANK(E36),"",(0.999842594+(0.00006793952*E36)-(0.00000909529*E36^2)+(0.0000001001685*E36^3)-(0.000000001120083*E36^4)+(0.000000000006536332*E36^5))) -> 0.99988467 | P36: 3.696 | Q36: 3.598 | R36: 165.1 | S36: 160.7
A37: =IF(ISBLANK(VLOOKUP(D37,'Volumes flacons'!A5:C623,3)),0,1) -> 1 | B37: =IF(ISBLANK(D37),0,IF(ISBLANK(E37),0,IF(ISBLANK(F37),0,1))) -> 1 | C37: 3 | D37: 391 | E37: 12.8 | F37: 3.97 | G37: 34.752 | H37: 1000 | I37: 1009 | J37: 117.57 | K37: =IF(ISBLANK(E37),"",(0.000824493-(0.0000040899*E37)+(0.000000076438*E37^2)-(0.00000000082467*E37^3)+(0.0000000000053875*E37^4))) -> 0.00078308104 | L37: =IF(ISBLANK(E37),"",(-0.00000572466+(0.00000010227*E37)-(0.0000000016546*E37^2))) -> -4.6866937e-06 | M37: =IF(ISBLANK(E37),"",IF(ISBLANK(G37),(O37+(K37*35)+(L37*35^1.5)+(0.00000048314*35^2)),(O37+(K37*G37)+(L37*G37^1.5)+(0.00000048314*G37^2)))) -> 1.0262413 | N37: =IF(ISBLANK(D37),"",IF(ISBLANK(G37),J37*(1+0.00001*(35-20)),J37*(1+0.00001*(G37-20)))) -> 117.58734 | O37: =IF(ISBLANK(E37),"",(0.999842594+(0.00006793952*E37)-(0.00000909529*E37^2)+(0.0000001001685*E37^3)-(0.000000001120083*E37^4)+(0.000000000006536332*E37^5))) -> 0.99940429 | P37: 3.827 | Q37: 3.729 | R37: 170.9 | S37: 166.5
A38: =IF(ISBLANK(VLOOKUP(D38,'Volumes flacons'!A5:C623,3)),0,1) -> 1 | B38: =IF(ISBLANK(D38),0,IF(ISBLANK(E38),0,IF(ISBLANK(F38),0,1))) -> 1 | C38: 4 | D38: 392 | E38: 10.2 | F38: 3.106 | G38: 34.612 | H38: 500 | I38: 504.4 | J38: 120.37 | K38: =IF(ISBLANK(E38),"",(0.000824493-(0.0000040899*E38)+(0.000000076438*E38^2)-(0.00000000082467*E38^3)+(0.0000000000053875*E38^4))) -> 0.0007899118 | L38: =IF(ISBLANK(E38),"",(-0.00000572466+(0.00000010227*E38)-(0.0000000016546*E38^2))) -> -4.8536506e-06 | M38: =IF(ISBLANK(E38),"",IF(ISBLANK(G38),(O38+(K38*35)+(L38*35^1.5)+(0.00000048314*35^2)),(O38+(K38*G38)+(L38*G38^1.5)+(0.00000048314*G38^2)))) -> 1.0266151 | N38: =IF(ISBLANK(D38),"",IF(ISBLANK(G38),J38*(1+0.00001*(35-20)),J38*(1+0.00001*(G38-20)))) -> 120.38759 | O38: =IF(ISBLANK(E38),"",(0.999842594+(0.00006793952*E38)-(0.00000909529*E38^2)+(0.0000001001685*E38^3)-(0.000000001120083*E38^4)+(0.000000000006536332*E38^5))) -> 0.9996842 | P38: 2.92 | Q38: 2.845 | R38: 130.4 | S38: 127
A39: =IF(ISBLANK(VLOOKUP(D39,'Volumes flacons'!A5:C623,3)),0,1) -> 1 | B39: =IF(ISBLANK(D39),0,IF(ISBLANK(E39),0,IF(ISBLANK(F39),0,1))) -> 1 | C39: 5 | D39: 397 | E39: 17.4 | F39: 3.946 | G39: 35.603 | H39: 100 | I39: 101.3 | J39: 118.96 | K39: =IF(ISBLANK(E39),"",(0.000824493-(0.0000040899*E39)+(0.000000076438*E39^2)-(0.00000000082467*E39^3)+(0.0000000000053875*E39^4))) -> 0.00077262057 | L39: =IF(ISBLANK(E39),"",(-0.00000572466+(0.00000010227*E39)-(0.0000000016546*E39^2))) -> -4.4461087e-06 | M39: =IF(ISBLANK(E39),"",IF(ISBLANK(G39),(O39+(K39*35)+(L39*35^1.5)+(0.00000048314*35^2)),(O39+(K39*G39)+(L39*G39^1.5)+(0.00000048314*G39^2)))) -> 1.025882 | N39: =IF(ISBLANK(D39),"",IF(ISBLANK(G39),J39*(1+0.00001*(35-20)),J39*(1+0.00001*(G39-20)))) -> 118.97856 | O39: =IF(ISBLANK(E39),"",(0.999842594+(0.00006793952*E39)-(0.00000909529*E39^2)+(0.0000001001685*E39^3)-(0.000000001120083*E39^4)+(0.000000000006536332*E39^5))) -> 0.9987065 | P39: 3.758 | Q39: 3.664 | R39: 167.9 | S39: 163.6 | T39: 0.03 | U39: 0.03 | V39: 12.9 | W39: 12.6 | X39: 12.9 | Y39: 12.6 | Z39: 0.92 | AA39: 0.9 | AB39: 4.8 | AC39: 4.7 | AD39: 0.0265 | AE39: 0.0142 | AF39: 0.0018 | AG39: 0.0343 | AH39: 0.0073 | AI39: 0.0012 | AJ39: -99999 | AK39: -99999 | AL39: 0.0418 | AM39: 0.0029 | AN39: -99999 | AO39: -99999 | AP39: 0.009 | AR39: 0.0818 | AS39: -99999 | AU39: 0.0172 | AV39: -99999 | AX39: 0.0418 | AY39: 0.0958 | BA39: 0.0021
A40: =IF(ISBLANK(VLOOKUP(D40,'Volumes flacons'!A5:C623,3)),0,1) -> 1 | B40: =IF(ISBLANK(D40),0,IF(ISBLANK(E40),0,IF(ISBLANK(F40),0,1))) -> 1 | C40: 6 | D40: 445 | E40: 21 | F40: 3.774 | G40: 35.935 | H40: 80 | I40: 83 | J40: 118.48 | K40: =IF(ISBLANK(E40),"",(0.000824493-(0.0000040899*E40)+(0.000000076438*E40^2)-(0.00000000082467*E40^3)+(0.0000000000053875*E40^4))) -> 0.00076572476 | L40: =IF(ISBLANK(E40),"",(-0.00000572466+(0.00000010227*E40)-(0.0000000016546*E40^2))) -> -4.3066686e-06 | M40: =IF(ISBLANK(E40),"",IF(ISBLANK(G40),(O40+(K40*35)+(L40*35^1.5)+(0.00000048314*35^2)),(O40+(K40*G40)+(L40*G40^1.5)+(0.00000048314*G40^2)))) -> 1.0252073 | N40: =IF(ISBLANK(D40),"",IF(ISBLANK(G40),J40*(1+0.00001*(35-20)),J40*(1+0.00001*(G40-20)))) -> 118.49888 | O40: =IF(ISBLANK(E40),"",(0.999842594+(0.00006793952*E40)-(0.00000909529*E40^2)+(0.0000001001685*E40^3)-(0.000000001120083*E40^4)+(0.000000000006536332*E40^5))) -> 0.99799482 | P40: 3.609 | Q40: 3.52 | R40: 161.2 | S40: 157.2 | T40: 0.13 | U40: 0.13 | V40: 10.8 | W40: 10.5 | X40: 10.6 | Y40: 10.4 | Z40: 0.78 | AA40: 0.77 | AB40: 3.6 | AC40: 3.6 | AD40: 0.04 | AE40: 0.0217 | AF40: 0.0031 | AG40: 0.0485 | AH40: 0.0119 | AI40: 0.0017 | AJ40: 0.0027 | AK40: 0.0011 | AL40: 0.0641 | AM40: 0.0047 | AN40: 0.0008 | AO40: -99999 | AP40: 0.0136 | AR40: 0.0755 | AS40: 0.0154 | AU40: 0.0204 | AV40: -99999 | AX40: 0.0503 | AY40: 0.1408 | BA40: -99999
A41: =IF(ISBLANK(VLOOKUP(D41,'Volumes flacons'!A5:C623,3)),0,1) -> 1 | B41: =IF(ISBLANK(D41),0,IF(ISBLANK(E41),0,IF(ISBLANK(F41),0,1))) -> 1 | C41: 7 | D41: 399 | E41: 22.6 | F41: 4.177 | G41: 36.404 | H41: 60 | I41: 62.3 | J41: 113.43 | K41: =IF(ISBLANK(E41),"",(0.000824493-(0.0000040899*E41)+(0.000000076438*E41^2)-(0.00000000082467*E41^3)+(0.0000000000053875*E41^4))) -> 0.00076298889 | L41: =IF(ISBLANK(E41),"",(-0.00000572466+(0.00000010227*E41)-(0.0000000016546*E41^2))) -> -4.2584615e-06 | M41: =IF(ISBLANK(E41),"",IF(ISBLANK(G41),(O41+(K41*35)+(L41*35^1.5)+(0.00000048314*35^2)),(O41+(K41*G41)+(L41*G41^1.5)+(0.00000048314*G41^2)))) -> 1.0251159 | N41: =IF(ISBLANK(D41),"",IF(ISBLANK(G41),J41*(1+0.00001*(35-20)),J41*(1+0.00001*(G41-20)))) -> 113.44861 | O41: =IF(ISBLANK(E41),"",(0.999842594+(0.00006793952*E41)-(0.00000909529*E41^2)+(0.0000001001685*E41^3)-(0.000000001120083*E41^4)+(0.000000000006536332*E41^5))) -> 0.99763511 | P41: 4.177 | Q41: 4.074 | R41: 186.5 | S41: 182 | T41: 0.33 | U41: 0.32 | V41: 3.9 | W41: 3.8 | X41: 3.6 | Y41: 3.5 | Z41: 0.4 | AA41: 0.39 | AB41: 1.8 | AC41: 1.7 | AD41: 0.057 | AE41: 0.0411 | AF41: 0.0067 | AG41: 0.0732 | AH41: 0.0203 | AI41: 0.0054 | AJ41: 0.0078 | AK41: 0.003 | AL41: 0.1047 | AM41: 0.0091 | AN41: 0.0024 | AO41: -99999 | AP41: 0.0463 | AR41: 0.0512 | AS41: 0.0932 | AU41: 0.0321 | AV41: -99999 | AX41: 0.1054 | AY41: 0.2646 | BA41: -99999
A42: =IF(ISBLANK(VLOOKUP(D42,'Volumes flacons'!A5:C623,3)),0,1) -> 1 | B42: =IF(ISBLANK(D42),0,IF(ISBLANK(E42),0,IF(ISBLANK(F42),0,1))) -> 1 | C42: 8 | D42: 401 | E42: 22.3 | F42: 4.909 | G42: 36.188 | H42: 40 | I42: 41 | J42: 119.4 | K42: =IF(ISBLANK(E42),"",(0.000824493-(0.0000040899*E42)+(0.000000076438*E42^2)-(0.00000000082467*E42^3)+(0.0000000000053875*E42^4))) -> 0.00076348716 | L42: =IF(ISBLANK(E42),"",(-0.00000572466+(0.00000010227*E42)-(0.0000000016546*E42^2))) -> -4.266855e-06 | M42: =IF(ISBLANK(E42),"",IF(ISBLANK(G42),(O42+(K42*35)+(L42*35^1.5)+(0.00000048314*35^2)),(O42+(K42*G42)+(L42*G42^1.5)+(0.00000048314*G42^2)))) -> 1.0250374 | N42: =IF(ISBLANK(D42),"",IF(ISBLANK(G42),J42*(1+0.00001*(35-20)),J42*(1+0.00001*(G42-20)))) -> 119.41933 | O42: =IF(ISBLANK(E42),"",(0.999842594+(0.00006793952*E42)-(0.00000909529*E42^2)+(0.0000001001685*E42^3)-(0.000000001120083*E42^4)+(0.000000000006536332*E42^5))) -> 0.99770453 | P42: 4.662 | Q42: 4.548 | R42: 208.2 | S42: 203.1 | T42: 0 | U42: 0 | V42: 0 | W42: 0 | X42: 0 | Y42: 0 | Z42: 0.09 | AA42: 0.09 | AB42: 0.9 | AC42: 0.9 | AD42: 0.0296 | AE42: 0.0302 | AF42: 0.0114 | AG42: 0.0247 | AH42: 0.0154 | AI42: -99999 | AJ42: -99999 | AK42: 0.0013 | AL42: 0.0801 | AM42: 0.0093 | AN42: -99999 | AO42: -99999 | AP42: 0.0913 | AR42: 0.0294 | AS42: 0.022 | AU42: 0.037 | AV42: -99999 | AX42: 0.1876 | AY42: 0.2007 | BA42: 0.0024
A43: =IF(ISBLANK(VLOOKUP(D43,'Volumes flacons'!A5:C623,3)),0,1) -> 1 | B43: =IF(ISBLANK(D43),0,IF(ISBLANK(E43),0,IF(ISBLANK(F43),0,1))) -> 1 | C43: 9 | D43: 402 | E43: 27.9 | F43: 4.841 | G43: 35.623 | H43: 20 | I43: 21 | J43: 119.3 | K43: =IF(ISBLANK(E43),"",(0.000824493-(0.0000040899*E43)+(0.000000076438*E43^2)-(0.00000000082467*E43^3)+(0.0000000000053875*E43^4))) -> 0.00075523941 | L43: =IF(ISBLANK(E43),"",(-0.00000572466+(0.00000010227*E43)-(0.0000000016546*E43^2))) -> -4.1592842e-06 | M43: =IF(ISBLANK(E43),"",IF(ISBLANK(G43),(O43+(K43*35)+(L43*35^1.5)+(0.00000048314*35^2)),(O43+(K43*G43)+(L43*G43^1.5)+(0.00000048314*G43^2)))) -> 1.0228981 | N43: =IF(ISBLANK(D43),"",IF(ISBLANK(G43),J43*(1+0.00001*(35-20)),J43*(1+0.00001*(G43-20)))) -> 119.31864 | O43: =IF(ISBLANK(E43),"",(0.999842594+(0.00006793952*E43)-(0.00000909529*E43^2)+(0.0000001001685*E43^3)-(0.000000001120083*E43^4)+(0.000000000006536332*E43^5))) -> 0.99626548 | P43: 4.601 | Q43: 4.498 | R43: 205.5 | S43: 200.9 | T43: 0 | U43: 0 | V43: 0 | W43: 0 | X43: 0 | Y43: 0 | Z43: 0.05 | AA43: 0.04 | AB43: 0.6 | AC43: 0.6 | AD43: 0.0134 | AE43: 0.0158 | AF43: 0.0045 | AG43: 0.0106 | AH43: 0.008 | AI43: -99999 | AJ43: -99999 | AK43: 0.0013 | AL43: 0.0434 | AM43: 0.0072 | AN43: -99999 | AO43: -99999 | AP43: 0.0972 | AR43: 0.0137 | AS43: 0.0118 | AU43: 0.0247 | AV43: -99999 | AX43: 0.1103 | AY43: 0.1394 | BA43: 0.0016
A44: =IF(ISBLANK(VLOOKUP(D44,'Volumes flacons'!A5:C623,3)),0,1) -> 1 | B44: =IF(ISBLANK(D44),0,IF(ISBLANK(E44),0,IF(ISBLANK(F44),0,1))) -> 1 | C44: 10 | D44: 403 | E44: 28.2 | F44: 4.779 | G44: 35.19 | H44: 10 | I44: 11 | J44: 118.54 | K44: =IF(ISBLANK(E44),"",(0.000824493-(0.0000040899*E44)+(0.000000076438*E44^2)-(0.00000000082467*E44^3)+(0.0000000000053875*E44^4))) -> 0.00075485761 | L44: =IF(ISBLANK(E44),"",(-0.00000572466+(0.00000010227*E44)-(0.0000000016546*E44^2))) -> -4.1564501e-06 | M44: =IF(ISBLANK(E44),"",IF(ISBLANK(G44),(O44+(K44*35)+(L44*35^1.5)+(0.00000048314*35^2)),(O44+(K44*G44)+(L44*G44^1.5)+(0.00000048314*G44^2)))) -> 1.0224742 | N44: =IF(ISBLANK(D44),"",IF(ISBLANK(G44),J44*(1+0.00001*(35-20)),J44*(1+0.00001*(G44-20)))) -> 118.55801 | O44: =IF(ISBLANK(E44),"",(0.999842594+(0.00006793952*E44)-(0.00000909529*E44^2)+(0.0000001001685*E44^3)-(0.000000001120083*E44^4)+(0.000000000006536332*E44^5))) -> 0.99618013 | P44: 4.571 | Q44: 4.471 | R44: 204.2 | S44: 199.7 | T44: 0 | U44: 0 | V44: 0 | W44: 0 | X44: 0 | Y44: 0 | Z44: 0.03 | AA44: 0.03 | AB44: 0.6 | AC44: 0.5
A45: =IF(ISBLANK(VLOOKUP(D45,'Volumes flacons'!A5:C623,3)),0,1) -> 1 | B45: =IF(ISBLANK(D45),0,IF(ISBLANK(E45),0,IF(ISBLANK(F45),0,1))) -> 1 | C45: 11 | D45: 404 | E45: 28.1 | F45: 4.601 | G45: 35 | H45: 0 | I45: 2 | J45: 113.87 | K45: =IF(ISBLANK(E45),"",(0.000824493-(0.0000040899*E45)+(0.000000076438*E45^2)-(0.00000000082467*E45^3)+(0.0000000000053875*E45^4))) -> 0.00075498423 | L45: =IF(ISBLANK(E45),"",(-0.00000572466+(0.00000010227*E45)-(0.0000000016546*E45^2))) -> -4.1573617e-06 | M45: =IF(ISBLANK(E45),"",IF(ISBLANK(G45),(O45+(K45*35)+(L45*35^1.5)+(0.00000048314*35^2)),(O45+(K45*G45)+(L45*G45^1.5)+(0.00000048314*G45^2)))) -> 1.0223641 | N45: =IF(ISBLANK(D45),"",IF(ISBLANK(G45),J45*(1+0.00001*(35-20)),J45*(1+0.00001*(G45-20)))) -> 113.88708 | O45: =IF(ISBLANK(E45),"",(0.999842594+(0.00006793952*E45)-(0.00000909529*E45^2)+(0.0000001001685*E45^3)-(0.000000001120083*E45^4)+(0.000000000006536332*E45^5))) -> 0.99620867 | P45: 4.584 | Q45: 4.484 | R45: 204.7 | S45: 200.3 | T45: 0 | U45: 0 | V45: 0.1 | W45: 0.1 | X45: 0.1 | Y45: 0.1 | Z45: 0.04 | AA45: 0.03 | AB45: 0.6 | AC45: 0.6 | AD45: 0.0148 | AE45: 0.0212 | AF45: 0.0204 | AG45: 0.0103 | AH45: 0.01 | AI45: -99999 | AJ45: -99999 | AK45: 0.003 | AL45: 0.0488 | AM45: 0.0198 | AN45: 0.0005 | AO45: 0.0026 | AP45: 0.0901 | AR45: 0.01 | AS45: 0.0103 | AU45: 0.0229 | AV45: -99999 | AX45: 0.0812 | AY45: 0.1848 | BA45: 0.0015
