Workbook

Sheet 001_01
C2: Campagne : | F2: PIRATA-FR30
C4: Données de campagne
C6: N° de station : | F6: 1 | H6: N° de palanquée : | P6: 1 | R6: Date d'analyse : | T6: 42418
X7: 4.9448
G8: Position | I8: Degrés | J8: Minutes | P8: Cardinal | Q8: Décimale | X8: 4.9503
G9: Latitude | I9: 11° | J9: 28.85' | K9: N | L9: + | M9: N | N9: E | O9: 11°28,85 | P9: N | Q9: 11.480833 | X9: 4.9442
G10: Longitude | I10: 023° | J10: 00.59' | K10: W | L10: - | M10: S | N10: W | O10: -23°0,59 | P10: W | Q10: -23.009833 | X10: 4.9501
G11: Prélèvement | I11: Date | J11: 42417 | N11: 11°28,85 | O11: 1 | P11: 2020-02-18T19:04:19z | X11: 4.9503
I12: Heure | J12: 0.79466435 | N12: 23°0,59 | O12: -1 | X12: 4.94794
C13: Données :
C14: Température du laboratoire à la calibration ( t°c ) | Q14: t°c = | R14: 22 | S14: °C
C15: Température du laboratoire au début de la série d'analyses | Q15: t°lab = | R15: 22.2 | S15: °C
C16: Volume moyen de thiosulfate pour la titration à t°c | Q16: Vmoy.titr.t°c = | R16: 4.9479 | S16: mL
C17: Volume moyen de thiosulfate pour la détermination du blanc à t°c | Q17: Vmoy.titr.blanc.t°c = | R17: 0.005 | S17: mL
C18: Masse volumique de l'eau pure à la calibration | O18: ρ = | P18: 0.99777304
C19: Normalite de l'iodate (NIO3) à la température de calibration | O19: N(IO3) = | P19: 0.020003747 | Q19: N
C20: Vol. de la prise d'essai d'iodate (VIO3) à 20°C | O20: V(IO3)20°C = | P20: 5.0112146 | Q20: mL
C21: Vol. de la prise d'essai d'iodate (VIO3) à t°c | O21: V(IO3)t°c= | P21: 5.0113148 | Q21: mL
C22: Volume moyen de thiosulfate pour la titration à 20° C | O22: Vmoy.titr.20°C = | P22: 4.947801 | Q22: mL
C23: Volume moyen de thiosulfate pour la détermination du blanc à 20° C | O23: Vmoy.titr.blanc.20°C = | P23: 0.0049999 | Q23: mL
C24: Normalite de l'iodate (NIO3) à 20°C | O24: N(IO3)20°C = | P24: 0.020012434 | Q24: N
C25: Titre du thiosulfate à 20°C | O25: V(Thio)20°C = | P25: 0.0040397876 | Q25: N
C26: Volume de réactif utilisé | O26: Vreg = | P26: 2.0367937 | Q26: mL
O27: DOreg = | P27: 0.0017
E29: Choix de la série de flacons : | I29: IRD | O29: IRD
O30: LPO
C31: N° | D31: N° des Flacons | E31: T° prélèv. | F31: Volume de thio. | G31: Salinité | H31: Prof. Théorique | I31: Prof. Effective | J31: V. flacons 20°C | K31: A | L31: B | M31: Densité eau de mer à t° | N31: Vol. à t° prél. des flacons | O31: Densité eau pure à t° | P31: Oxygène dissous | T31: NO2 | V31: NO3 + NO2 | X31: NO3 | Z31: Phosphate | AB31: Silicate | AD31: chlorophyll-c3 | AE31: chlorophyll-c1+c2 | AF31: peridinin | AG31: 19'-butanoyloxyfucoxanthin | AH31: fucoxanthine | AI31: neoxanthin | AJ31: prasinoxanthin | AK31: violaxanthin | AL31: 19'-hexanoyloxyfucoxanthin | AM31: diadinoxanthin | AN31: alloxanthin | AO31: diatoxanthin | AP31: zeaxanthin | AQ31: lutein | AR31: divinyl chlorophyll-b | AS31: chlorophyll-b | AT31: total chlorophyll-b | AU31: alpha-carotene | AV31: beta-carotene | AW31: pheophorbide | AX31: divinyl chlorophyll-a | AY31: chlorophyll-a | AZ31: total chlorophyll-a | BA31: pheophytin_a | BB31: crocoxanthin
C33: BTL | E33: °C | F33: ml | H33: m | I33: dbar | J33: ml | P33: DOX1 | R33: DOXY | S33: DOX2 | T33: NTRI | U33: NTIW | V33: NTRZ | W33: NTZW | X33: NTRA | Y33: NTAW | Z33: PHOS | AA33: PHOW | AB33: SLCA | AC33: SLCW | AD33: CHC3 | AE33: CHCZ | AF33: PERP | AG33: BFUP | AH33: FUCP | AI33: NEXW | AJ33: PXAP | AK33: VIOW | AL33: HFUP | AM33: DXAP | AN33: AXAP | AO33: TXAP | AP33: ZXAP | AQ33: LUTW | AR33: CHBD | AS33: CH2P | AT33: CHLB | AU33: AACP | AV33: BBCP | AW33: PHEP | AX33: CHAD | AY33: CH1P | AZ33: CPHL | BA33: PHEA | BB33: CXAP
N34: mL | P34: ml/l | Q34: ml/kg | R34: µmol/l | S34: µmol/kg | T34: µmol/l | U34: µmol/kg | V34: µmol/l | W34: µmol/kg | X34: µmol/l | Y34: µmol/kg | Z34: µmol/l | AA34: µmol/kg | AB34: µmol/l | AC34: µmol/kg | AD34: µg.l-1 | AE34: µg.l-1 | AF34: µg.l-1 | AG34: µg.l-1 | AH34: µg.l-1 | AI34: µg.l-1 | AJ34: µg.l-1 | AK34: µg.l-1 | AL34: µg.l-1 | AM34: µg.l-1 | AN34: µg.l-1 | AO34: µg.l-1 | AP34: µg.l-1 | AQ34: µg.l-1 | AR34: µg.l-1 | AS34: µg.l-1 | AT34: µg.l-1 | AU34: µg.l-1 | AV34: µg.l-1 | AW34: µg.l-1 | AX34: µg.l-1 | AY34: µg.l-1 | AZ34: µg.l-1 | BA34: µg.l-1 | BB34: µg.l-1
A35: 1 | B35: 1 | C35: 1 | D35: 2029 | E35: 5 | F35: 5.3738 | G35: 34.8948 | H35: 4000 | I35: 4061 | J35: 108.87 | K35: 0.00080585473 | L35: -5.254675e-06 | M35: 1.027592 | N35: 108.88622 | O35: 0.99996675 | P35: 5.6937637 | Q35: 5.5408795 | R35: 254.28349 | S35: 247.45568
A36: 1 | B36: 1 | C36: 2 | D36: 2030 | E36: 5.7 | F36: 5.3455 | G36: 34.8931 | H36: 4000 | I36: 4061 | J36: 110.13 | K36: 0.000803517 | L36: -5.195479e-06 | M36: 1.0275063 | N36: 110.1464 | O36: 0.99995175 | P36: 5.5976749 | Q36: 5.4478252 | R36: 249.99216 | S36: 243.29988
A37: 1 | B37: 1 | C37: 3 | D37: 2031 | E37: 5.9 | F37: 5.2209 | G37: 34.88915 | H37: 4000 | I37: 4061 | J37: 107.83 | K37: 0.00080286056 | L37: -5.1788636e-06 | M37: 1.0274781 | N37: 107.84605 | O37: 0.99994609 | P37: 5.5856782 | Q37: 5.4362993 | R37: 249.45639 | S37: 242.78513
A38: 1 | B38: 1 | C38: 4 | D38: 2032 | E38: 6.2 | F38: 5.4049 | G38: 34.89145 | H38: 4000 | I38: 4061 | J38: 111.3 | K38: 0.00080188532 | L38: -5.1541888e-06 | M38: 1.0274413 | N38: 111.31657 | O38: 0.99993647 | P38: 5.5994455 | Q38: 5.4498932 | R38: 250.07124 | S38: 243.39223
A39: 1 | B39: 1 | C39: 5 | D39: 2033 | E39: 6.5 | F39: 5.3765 | G39: 34.8877 | H39: 4000 | I39: 4061 | J39: 110.79 | K39: 0.0008009213 | L39: -5.1298118e-06 | M39: 1.0273988 | N39: 110.80649 | O39: 0.99992551 | P39: 5.5960612 | Q39: 5.4468248 | R39: 249.92009 | S39: 243.2552
A40: 1 | B40: 1 | C40: 6 | D40: 2034 | E40: 7.1 | F40: 5.2995 | G40: 34.89145 | H40: 4000 | I40: 4061 | J40: 109.25 | K40: 0.00079902648 | L40: -5.0819514e-06 | M40: 1.0273196 | N40: 109.26627 | O40: 0.99989959 | P40: 5.594917 | Q40: 5.446131 | R40: 249.86899 | S40: 243.22421
A41: 1 | B41: 1 | C41: 7 | D41: 2035 | E41: 7.3 | F41: 5.3494 | G41: 34.8912 | H41: 4000 | I41: 4061 | J41: 110.1 | K41: 0.0007984046 | L41: -5.0662626e-06 | M41: 1.0272911 | N41: 110.1164 | O41: 0.99988979 | P41: 5.6033257 | Q41: 5.4544672 | R41: 250.24453 | S41: 243.59651
A42: 1 | B42: 1 | C42: 8 | D42: 2036 | E42: 7.5 | F42: 5.3327 | G42: 34.8911 | H42: 4000 | I42: 4061 | J42: 109.39 | K42: 0.00079778753 | L42: -5.0507063e-06 | M42: 1.0272623 | N42: 109.40629 | O42: 0.9998794 | P42: 5.6227259 | Q42: 5.4735054 | R42: 251.11094 | S42: 244.44675
A43: 1 | B43: 1 | C43: 9 | D43: 2037 | E43: 7.9 | F43: 5.3621 | G43: 34.89025 | H43: 4000 | I43: 4061 | J43: 110.47 | K43: 0.00079656768 | L43: -5.0199906e-06 | M43: 1.0272029 | N43: 110.48645 | O43: 0.9998569 | P43: 5.597501 | Q43: 5.449265 | R43: 249.98439 | S43: 243.36418
A44: 1 | B44: 1 | C44: 10 | D44: 2038 | E44: 8.5 | F44: 5.4078 | G44: 34.888 | H44: 4000 | I44: 4061 | J44: 111.51 | K44: 0.00079477317 | L44: -4.9749099e-06 | M44: 1.0271098 | N44: 111.5266 | O44: 0.9998189 | P44: 5.5917115 | Q44: 5.4441222 | R44: 249.72583 | S44: 243.1345
A45: 1 | B45: 1 | C45: 11 | D45: 2039 | E45: 8.5 | F45: 5.4233 | G45: 34.88947 | H45: 4000 | I45: 4061 | J45: 111.47 | K45: 0.00079477317 | L45: -4.9749099e-06 | M45: 1.027111 | N45: 111.4866 | O45: 0.9998189 | P45: 5.6098332 | Q45: 5.4617595 | R45: 250.53515 | S45: 243.92218
...

Sheet 002_01
C2: Campagne : | F2: PIRATA-FR30
C4: Données de campagne
C6: N° de station : | F6: 2 | H6: N° de palanquée : | P6: 1 | R6: Date d'analyse : | T6: 42419
W7: 4.9458
G8: Position | I8: Degrés | J8: Minutes | P8: Cardinal | Q8: Décimale | W8: 4.9434
G9: Latitude | I9: 09° | J9: 59.99' | K9: N | L9: + | M9: N | N9: E | O9: 9°59,99 | P9: N | Q9: 9.9998333 | W9: 4.9453
G10: Longitude | I10: 021° | J10: 16.94' | K10: W | L10: - | M10: S | N10: W | O10: -21°16,94 | P10: W | Q10: -21.282333 | W10: 4.9485
G11: Prélèvement | I11: Date | J11: 42418 | N11: 9°59,99 | O11: 1 | P11: 2020-02-19T11:47:28z | W11: 4.9513
I12: Heure | J12: 0.4912963 | N12: 21°16,94 | O12: -1 | W12: 4.94686
C13: Données :
C14: Température du laboratoire à la calibration ( t°c ) | Q14: t°c = | R14: 23.5 | S14: °C
C15: Température du laboratoire au début de la série d'analyses | Q15: t°lab = | R15: 23.5 | S15: °C
C16: Volume moyen de thiosulfate pour la titration à t°c | Q16: Vmoy.titr.t°c = | R16: 4.9469 | S16: mL
C17: Volume moyen de thiosulfate pour la détermination du blanc à t°c | Q17: Vmoy.titr.blanc.t°c = | R17: 0.005 | S17: mL
C18: Masse volumique de l'eau pure à la calibration | O18: ρ = | P18: 0.99742152
C19: Normalite de l'iodate (NIO3) à la température de calibration | O19: N(IO3) = | P19: 0.0199967 | Q19: N
C20: Vol. de la prise d'essai d'iodate (VIO3) à 20°C | O20: V(IO3)20°C = | P20: 5.0112146 | Q20: mL
C21: Vol. de la prise d'essai d'iodate (VIO3) à t°c | O21: V(IO3)t°c= | P21: 5.01139 | Q21: mL
C22: Volume moyen de thiosulfate pour la titration à 20° C | O22: Vmoy.titr.20°C = | P22: 4.9467269 | Q22: mL
C23: Volume moyen de thiosulfate pour la détermination du blanc à 20° C | O23: Vmoy.titr.blanc.20°C = | P23: 0.004999825 | Q23: mL
C24: Normalite de l'iodate (NIO3) à 20°C | O24: N(IO3)20°C = | P24: 0.020012434 | Q24: N
C25: Titre du thiosulfate à 20°C | O25: V(Thio)20°C = | P25: 0.0040392421 | Q25: N
C26: Volume de réactif utilisé | O26: Vreg = | P26: 2.0367937 | Q26: mL
O27: DOreg = | P27: 0.0017
E29: Choix de la série de flacons : | I29: IRD | O29: IRD
O30: LPO
C31: N° | D31: N° des Flacons | E31: T° prélèv. | F31: Volume de thio. | G31: Salinité | H31: Prof. Théorique | I31: Prof. Effective | J31: V. flacons 20°C | K31: A | L31: B | M31: Densité eau de mer à t° | N31: Vol. à t° prél. des flacons | O31: Densité eau pure à t° | P31: Oxygène dissous | T31: NO2 | V31: NO3 + NO2 | X31: NO3 | Z31: Phosphate | AB31: Silicate | AD31: chlorophyll-c3 | AE31: chlorophyll-c1+c2 | AF31: peridinin | AG31: 19'-butanoyloxyfucoxanthin | AH31: fucoxanthine | AI31: neoxanthin | AJ31: prasinoxanthin | AK31: violaxanthin | AL31: 19'-hexanoyloxyfucoxanthin | AM31: diadinoxanthin | AN31: alloxanthin | AO31: diatoxanthin | AP31: zeaxanthin | AQ31: lutein | AR31: divinyl chlorophyll-b | AS31: chlorophyll-b | AT31: total chlorophyll-b | AU31: alpha-carotene | AV31: beta-carotene | AW31: pheophorbide | AX31: divinyl chlorophyll-a | AY31: chlorophyll-a | AZ31: total chlorophyll-a | BA31: pheophytin_a | BB31: crocoxanthin
C33: BTL | E33: °C | F33: ml | H33: m | I33: dbar | J33: ml | P33: DOX1 | R33: DOXY | S33: DOX2 | T33: NTRI | U33: NTIW | V33: NTRZ | W33: NTZW | X33: NTRA | Y33: NTAW | Z33: PHOS | AA33: PHOW | AB33: SLCA | AC33: SLCW | AD33: CHC3 | AE33: CHCZ | AF33: PERP | AG33: BFUP | AH33: FUCP | AI33: NEXW | AJ33: PXAP | AK33: VIOW | AL33: HFUP | AM33: DXAP | AN33: AXAP | AO33: TXAP | AP33: ZXAP | AQ33: LUTW | AR33: CHBD | AS33: CH2P | AT33: CHLB | AU33: AACP | AV33: BBCP | AW33: PHEP | AX33: CHAD | AY33: CH1P | AZ33: CPHL | BA33: PHEA | BB33: CXAP
N34: mL | P34: ml/l | Q34: ml/kg | R34: µmol/l | S34: µmol/kg | T34: µmol/l | U34: µmol/kg | V34: µmol/l | W34: µmol/kg | X34: µmol/l | Y34: µmol/kg | Z34: µmol/l | AA34: µmol/kg | AB34: µmol/l | AC34: µmol/kg | AD34: µg.l-1 | AE34: µg.l-1 | AF34: µg.l-1 | AG34: µg.l-1 | AH34: µg.l-1 | AI34: µg.l-1 | AJ34: µg.l-1 | AK34: µg.l-1 | AL34: µg.l-1 | AM34: µg.l-1 | AN34: µg.l-1 | AO34: µg.l-1 | AP34: µg.l-1 | AQ34: µg.l-1 | AR34: µg.l-1 | AS34: µg.l-1 | AT34: µg.l-1 | AU34: µg.l-1 | AV34: µg.l-1 | AW34: µg.l-1 | AX34: µg.l-1 | AY34: µg.l-1 | AZ34: µg.l-1 | BA34: µg.l-1 | BB34: µg.l-1
A35: 1 | B35: 1 | C35: 1 | D35: 2075 | E35: 9.1 | F35: 2.8476 | G35: 34.76895 | H35: 1000 | I35: 1000 | J35: 110.99771 | K35: 0.00079302024 | L35: -4.9310204e-06 | M35: 1.0269215 | N35: 111.0141 | O35: 0.99977587 | P35: 2.9504301 | Q35: 2.8730825 | R35: 131.76621 | S35: 128.31187
A36: 1 | B36: 1 | C36: 2 | D36: 2076 | E36: 9.4 | F36: 2.7254 | G36: 34.7657 | H36: 1000 | I36: 1001 | J36: 106.39863 | K36: 0.00079215911 | L36: -4.9095225e-06 | M36: 1.02687 | N36: 106.41434 | O36: 0.9997525 | P36: 2.9475529 | Q36: 2.8704245 | R36: 131.63771 | S36: 128.19316
A37: 1 | B37: 0 | C37: 3 | H37: 750 | I37: 755
A38: 1 | B38: 1 | C38: 4 | D38: 2077 | E38: 12.6 | F38: 1.0343 | G38: 35.00795 | H38: 500 | I38: 505 | J38: 117.65506 | K38: 0.0007835817 | L38: -4.6987423e-06 | M38: 1.0264793 | N38: 117.67272 | O38: 0.99942888 | P38: 1.0004861 | Q38: 0.97467731 | R38: 44.681709 | S38: 43.529089
A39: 1 | B39: 0 | C39: 5 | H39: 250 | I39: 252 | AD39: -9999.9999 | AE39: -9999.9999 | AF39: -9999.9999 | AG39: -9999.9999 | AH39: -9999.9999 | AI39: -9999.9999 | AJ39: -9999.9999 | AK39: -9999.9999 | AL39: -9999.9999 | AM39: -9999.9999 | AN39: -9999.9999 | AO39: -9999.9999 | AP39: -9999.9999 | AQ39: -9999.9999 | AR39: -9999.9999 | AS39: -9999.9999 | AT39: -9999.9999 | AU39: -9999.9999 | AV39: -9999.9999 | AW39: -9999.9999 | AX39: -9999.9999 | AY39: -9999.9999 | AZ39: -9999.9999 | BA39: -9999.9999 | BB39: ND
A40: 1 | B40: 1 | C40: 6 | D40: 2078 | E40: 16.6 | F40: 2.3077 | G40: 35.4682 | H40: 100 | I40: 101 | J40: 110.09049 | K40: 0.00077430072 | L40: -4.4829196e-06 | M40: 1.0259694 | N40: 110.10752 | O40: 0.99884548 | P40: 2.4080792 | Q40: 2.3471258 | R40: 107.54482 | S40: 104.82264 | AD40: 0.0121 | AE40: 0.0046 | AF40: 0.0017 | AG40: 0.0113 | AH40: 0.0073 | AI40: -9999.9999 | AJ40: -9999.9999 | AK40: -9999.9999 | AL40: 0.0226 | AM40: 0.0016 | AN40: -9999.9999 | AO40: -9999.9999 | AP40: 0.0015 | AQ40: -9999.9999 | AR40: 0.0034 | AS40: 0.008 | AT40: 0.0114 | AU40: 0.0026 | AV40: -9999.9999 | AW40: -9999.9999 | AX40: 0.0023 | AY40: 0.0404 | AZ40: 0.0427 | BA40: 0.0032 | BB40: ND
A41: 1 | B41: 0 | C41: 7 | H41: 90 | I41: 91 | AD41: 0.0153 | AE41: 0.0056 | AF41: 0.0043 | AG41: 0.0111 | AH41: 0.0105 | AI41: 0.001 | AJ41: 0.0011 | AK41: -9999.9999 | AL41: 0.0263 | AM41: 0.002 | AN41: 0.0013 | AO41: -9999.9999 | AP41: 0.0026 | AQ41: -9999.9999 | AR41: 0.0044 | AS41: 0.01 | AT41: 0.0144 | AU41: 0.0042 | AV41: -9999.9999 | AW41: -9999.9999 | AX41: 0.0029 | AY41: 0.0514 | AZ41: 0.0543 | BA41: 0.004 | BB41: ND
A42: 1 | B42: 1 | C42: 8 | D42: 2079 | E42: 17.1 | F42: 2.2299 | G42: 35.5252 | H42: 80 | I42: 81 | J42: 107.71659 | K42: 0.00077324407 | L42: -4.4596646e-06 | M42: 1.0258946 | N42: 107.73331 | O42: 0.99875946 | P42: 2.3786154 | Q42: 2.3185769 | R42: 106.22896 | S42: 103.54764 | AD42: 0.0164 | AE42: 0.0076 | AF42: 0.005 | AG42: 0.0124 | AH42: 0.0118 | AI42: 0.0013 | AJ42: -9999.9999 | AK42: -9999.9999 | AL42: 0.0295 | AM42: 0.0023 | AN42: 0.0012 | AO42: -9999.9999 | AP42: 0.0029 | AQ42: -9999.9999 | AR42: 0.0039 | AS42: 0.0143 | AT42: 0.0182 | AU42: 0.004 | AV42: -9999.9999 | AW42: -9999.9999 | AX42: 0.0034 | AY42: 0.0593 | AZ42: 0.0627 | BA42: 0.0035 | BB42: ND
A43: 1 | B43: 0 | C43: 9 | H43: 70 | I43: 70 | AD43: 0.0245 | AE43: 0.0127 | AF43: 0.01 | AG43: 0.0207 | AH43: 0.0192 | AI43: 0.0022 | AJ43: 0.0014 | AK43: -9999.9999 | AL43: 0.0405 | AM43: 0.0035 | AN43: 0.0023 | AO43: -9999.9999 | AP43: 0.0045 | AQ43: -9999.9999 | AR43: 0.0072 | AS43: 0.0198 | AT43: 0.027 | AU43: 0.0068 | AV43: -9999.9999 | AW43: -9999.9999 | AX43: 0.0059 | AY43: 0.0928 | AZ43: 0.0987 | BA43: 0.0051 | BB43: ND
A44: 1 | B44: 1 | C44: 10 | D44: 2080 | E44: 18 | F44: 2.2364 | G44: 35.6243 | H44: 60 | I44: 60 | J44: 108.72896 | K44: 0.00077139679 | L44: -4.4198904e-06 | M44: 1.0257514 | N44: 108.74594 | O44: 0.99859758 | P44: 2.3629577 | Q44: 2.3036358 | R44: 105.52969 | S44: 102.88038 | AD44: 0.0269 | AE44: 0.0161 | AF44: 0.0118 | AG44: 0.0204 | AH44: 0.0243 | AI44: 0.0024 | AJ44: 0.0018 | AK44: 0.0007 | AL44: 0.0428 | AM44: 0.0039 | AN44: 0.0032 | AO44: -9999.9999 | AP44: 0.0048 | AQ44: -9999.9999 | AR44: 0.0101 | AS44: 0.0225 | AT44: 0.0326 | AU44: 0.007 | AV44: -9999.9999 | AW44: 0.0039 | AX44: 0.0076 | AY44: 0.1103 | AZ44: 0.1179 | BA44: 0.0046 | BB44: ND
A45: 1 | B45: 0 | C45: 11 | H45: 50 | I45: 51 | AD45: 0.0261 | AE45: 0.0208 | AF45: 0.019 | AG45: 0.021 | AH45: 0.0236 | AI45: 0.0062 | AJ45: 0.0028 | AK45: 0.0015 | AL45: 0.0499 | AM45: 0.0051 | AN45: 0.0051 | AO45: -9999.9999 | AP45: 0.0086 | AQ45: -9999.9999 | AR45: 0.0088 | AS45: 0.0427 | AT45: 0.0515 | AU45: 0.0113 | AV45: -9999.9999 | AW45: 0.0043 | AX45: 0.0134 | AY45: 0.1425 | AZ45: 0.1559 | BA45: 0.0057 | BB45: ND
...

Sheet 003_01
C2: Campagne : | F2: PIRATA-FR30
C4: Données de campagne
C6: N° de station : | F6: 3 | H6: N° de palanquée : | P6: 1 | R6: Date d'analyse : | T6: 42419
G8: Position | I8: Degrés | J8: Minutes | P8: Cardinal | Q8: Décimale
G9: Latitude | I9: 09° | J9: 00.06' | K9: N | L9: + | M9: N | N9: E | O9: 9°0,06 | P9: N | Q9: 9.001
G10: Longitude | I10: 020° | J10: 06.92' | K10: W | L10: - | M10: S | N10: W | O10: -20°6,92 | P10: W | Q10: -20.115333
G11: Prélèvement | I11: Date | J11: 42418 | N11: 9°0,06 | O11: 1 | P11: 2020-02-19T21:45:54z
I12: Heure | J12: 0.906875 | N12: 20°6,92 | O12: -1
C13: Données :
C14: Température du laboratoire à la calibration ( t°c ) | Q14: t°c = | R14: 23.5 | S14: °C
C15: Température du laboratoire au début de la série d'analyses | Q15: t°lab = | R15: 24.1 | S15: °C
C16: Volume moyen de thiosulfate pour la titration à t°c | Q16: Vmoy.titr.t°c = | R16: 4.9469 | S16: mL
C17: Volume moyen de thiosulfate pour la détermination du blanc à t°c | Q17: Vmoy.titr.blanc.t°c = | R17: 0.005 | S17: mL
C18: Masse volumique de l'eau pure à la calibration | O18: ρ = | P18: 0.99742152
C19: Normalite de l'iodate (NIO3) à la température de calibration | O19: N(IO3) = | P19: 0.0199967 | Q19: N
C20: Vol. de la prise d'essai d'iodate (VIO3) à 20°C | O20: V(IO3)20°C = | P20: 5.0112146 | Q20: mL
C21: Vol. de la prise d'essai d'iodate (VIO3) à t°c | O21: V(IO3)t°c= | P21: 5.01139 | Q21: mL
C22: Volume moyen de thiosulfate pour la titration à 20° C | O22: Vmoy.titr.20°C = | P22: 4.9467269 | Q22: mL
C23: Volume moyen de thiosulfate pour la détermination du blanc à 20° C | O23: Vmoy.titr.blanc.20°C = | P23: 0.004999825 | Q23: mL
C24: Normalite de l'iodate (NIO3) à 20°C | O24: N(IO3)20°C = | P24: 0.020012434 | Q24: N
C25: Titre du thiosulfate à 20°C | O25: V(Thio)20°C = | P25: 0.0040392421 | Q25: N
C26: Volume de réactif utilisé | O26: Vreg = | P26: 2.0367937 | Q26: mL
O27: DOreg = | P27: 0.0017
E29: Choix de la série de flacons : | I29: IRD | O29: IRD
O30: LPO
C31: N° | D31: N° des Flacons | E31: T° prélèv. | F31: Volume de thio. | G31: Salinité | H31: Prof. Théorique | I31: Prof. Effective | J31: V. flacons 20°C | K31: A | L31: B | M31: Densité eau de mer à t° | N31: Vol. à t° prél. des flacons | O31: Densité eau pure à t° | P31: Oxygène dissous | T31: NO2 | V31: NO3 + NO2 | X31: NO3 | Z31: Phosphate | AB31: Silicate | AD31: chlorophyll-c3 | AE31: chlorophyll-c1+c2 | AF31: peridinin | AG31: 19'-butanoyloxyfucoxanthin | AH31: fucoxanthine | AI31: neoxanthin | AJ31: prasinoxanthin | AK31: violaxanthin | AL31: 19'-hexanoyloxyfucoxanthin | AM31: diadinoxanthin | AN31: alloxanthin | AO31: diatoxanthin | AP31: zeaxanthin | AQ31: lutein | AR31: divinyl chlorophyll-b | AS31: chlorophyll-b | AT31: total chlorophyll-b | AU31: alpha-carotene | AV31: beta-carotene | AW31: pheophorbide | AX31: divinyl chlorophyll-a | AY31: chlorophyll-a | AZ31: total chlorophyll-a | BA31: pheophytin_a | BB31: crocoxanthin
C33: BTL | E33: °C | F33: ml | H33: m | I33: dbar | J33: ml | P33: DOX1 | R33: DOXY | S33: DOX2 | T33: NTRI | U33: NTIW | V33: NTRZ | W33: NTZW | X33: NTRA | Y33: NTAW | Z33: PHOS | AA33: PHOW | AB33: SLCA | AC33: SLCW | AD33: CHC3 | AE33: CHCZ | AF33: PERP | AG33: BFUP | AH33: FUCP | AI33: NEXW | AJ33: PXAP | AK33: VIOW | AL33: HFUP | AM33: DXAP | AN33: AXAP | AO33: TXAP | AP33: ZXAP | AQ33: LUTW | AR33: CHBD | AS33: CH2P | AT33: CHLB | AU33: AACP | AV33: BBCP | AW33: PHEP | AX33: CHAD | AY33: CH1P | AZ33: CPHL | BA33: PHEA | BB33: CXAP
N34: mL | P34: ml/l | Q34: ml/kg | R34: µmol/l | S34: µmol/kg | T34: µmol/l | U34: µmol/kg | V34: µmol/l | W34: µmol/kg | X34: µmol/l | Y34: µmol/kg | Z34: µmol/l | AA34: µmol/kg | AB34: µmol/l | AC34: µmol/kg | AD34: µg.l-1 | AE34: µg.l-1 | AF34: µg.l-1 | AG34: µg.l-1 | AH34: µg.l-1 | AI34: µg.l-1 | AJ34: µg.l-1 | AK34: µg.l-1 | AL34: µg.l-1 | AM34: µg.l-1 | AN34: µg.l-1 | AO34: µg.l-1 | AP34: µg.l-1 | AQ34: µg.l-1 | AR34: µg.l-1 | AS34: µg.l-1 | AT34: µg.l-1 | AU34: µg.l-1 | AV34: µg.l-1 | AW34: µg.l-1 | AX34: µg.l-1 | AY34: µg.l-1 | AZ34: µg.l-1 | BA34: µg.l-1 | BB34: µg.l-1
A35: 1 | B35: 1 | C35: 1 | D35: 3196 | E35: 8.6 | F35: 2.9299 | G35: 34.76315 | H35: 1000 | I35: 1007 | J35: 117.25 | K35: 0.00079447815 | L35: -4.9675122e-06 | M35: 1.0269963 | N35: 117.26731 | O35: 0.99981208 | P35: 2.8713944 | Q35: 2.795915 | R35: 128.23648 | S35: 124.86556
A36: 1 | B36: 1 | C36: 2 | D36: 3198 | E36: 9.4 | F36: 1.0514 | G36: 34.7342 | H36: 750 | I36: 758 | J36: 117.21 | K36: 0.00079215911 | L36: -4.9095225e-06 | M36: 1.0268454 | N36: 117.22727 | O36: 0.9997525 | P36: 1.0212064 | Q36: 0.99450844 | R36: 45.607078 | S36: 44.414747
A37: 1 | B37: 1 | C37: 3 | D37: 3199 | E37: 9.5 | F37: 2.086 | G37: 34.7331 | H37: 750 | I37: 760 | J37: 119.84 | K37: 0.00079187431 | L37: -4.9024226e-06 | M37: 1.026828 | N37: 119.85766 | O37: 0.99974443 | P37: 1.9952024 | Q37: 1.9430736 | R37: 89.105739 | S37: 86.777667
A38: 1 | B38: 1 | C38: 4 | D38: 3200 | E38: 11.6 | F38: 1.0873 | G38: 34.9702 | H38: 500 | I38: 503 | J38: 118.34 | K38: 0.00078614598 | L38: -4.760971e-06 | M38: 1.0266422 | N38: 118.35772 | O38: 0.99954428 | P38: 1.0463162 | Q38: 1.0191634 | R38: 46.72848 | S38: 45.515836
A39: 1 | B39: 0 | C39: 5 | H39: 250 | I39: 251 | AD39: 0.01 | AE39: 0.0047 | AF39: 0.0027 | AG39: 0.0086 | AH39: 0.0046 | AI39: -9999.9999 | AJ39: 0.0009 | AK39: -9999.9999 | AL39: 0.0234 | AM39: 0.0013 | AN39: -9999.9999 | AO39: -9999.9999 | AP39: 0.0012 | AQ39: -9999.9999 | AR39: 0.0026 | AS39: 0.007 | AT39: =AS39+AR39 -> 0.0096 | AU39: 0.0021 | AV39: -9999.9999 | AW39: -9999.9999 | AX39: -9999.9999 | AY39: 0.0312 | AZ39: =AY39 -> 0.0312 | BA39: -9999.9999 | BB39: ND
A40: 1 | B40: 1 | C40: 6 | D40: 3201 | E40: 16.7 | F40: 1.9186 | G40: 35.5964 | H40: 100 | I40: 101 | J40: 120.41 | K40: 0.00077408763 | L40: -4.4782024e-06 | M40: 1.0260444 | N40: 120.42878 | O40: 0.9988285 | P40: 1.8250725 | Q40: 1.7787462 | R40: 81.507739 | S40: 79.438807 | AD40: 0.0122 | AE40: 0.0054 | AF40: 0.0018 | AG40: 0.0105 | AH40: 0.0054 | AI40: -9999.9999 | AJ40: 0.0009 | AK40: -9999.9999 | AL40: 0.0275 | AM40: 0.0015 | AN40: -9999.9999 | AO40: -9999.9999 | AP40: 0.0009 | AQ40: -9999.9999 | AR40: 0.0029 | AS40: 0.0066 | AT40: =AS40+AR40 -> 0.0095 | AU40: 0.0021 | AV40: -9999.9999 | AW40: -9999.9999 | AX40: -9999.9999 | AY40: 0.036 | AZ40: =AY40 -> 0.036 | BA40: -9999.9999 | BB40: ND
A41: 1 | B41: 0 | C41: 7 | H41: 90 | I41: 91 | AD41: 0.0155 | AE41: 0.0078 | AF41: 0.0022 | AG41: 0.0161 | AH41: 0.0082 | AI41: -9999.9999 | AJ41: 0.0011 | AK41: -9999.9999 | AL41: 0.0325 | AM41: 0.002 | AN41: -9999.9999 | AO41: -9999.9999 | AP41: 0.0013 | AQ41: -9999.9999 | AR41: 0.0055 | AS41: 0.008 | AT41: =AS41+AR41 -> 0.0135 | AU41: 0.0036 | AV41: -9999.9999 | AW41: -9999.9999 | AX41: 0.0043 | AY41: 0.0509 | AZ41: =AX41+AY41 -> 0.0552 | BA41: -9999.9999 | BB41: ND
A42: 1 | B42: 1 | C42: 8 | D42: 3204 | E42: 17.1 | F42: 1.8762 | G42: 35.6266 | H42: 80 | I42: 81 | J42: 118.41 | K42: 0.00077324407 | L42: -4.4596646e-06 | M42: 1.0259724 | N42: 118.4285 | O42: 0.99875946 | P42: 1.8150855 | Q42: 1.7691367 | R42: 81.061717 | S42: 79.009646 | AD42: 0.0233 | AE42: 0.0141 | AF42: 0.0041 | AG42: 0.0251 | AH42: 0.0129 | AI42: 0.0014 | AJ42: 0.0014 | AK42: 0.0009 | AL42: 0.0457 | AM42: 0.0031 | AN42: 0.0008 | AO42: -9999.9999 | AP42: 0.0017 | AQ42: -9999.9999 | AR42: 0.0083 | AS42: 0.0109 | AT42: =AS42+AR42 -> 0.0192 | AU42: 0.006 | AV42: -9999.9999 | AW42: -9999.9999 | AX42: 0.0067 | AY42: 0.0794 | AZ42: =AX42+AY42 -> 0.0861 | BA42: 0.0017 | BB42: ND
A43: 1 | B43: 0 | C43: 9 | H43: 70 | I43: 71 | AD43: 0.0417 | AE43: 0.0283 | AF43: 0.0081 | AG43: 0.0493 | AH43: 0.024 | AI43: 0.0045 | AJ43: 0.0032 | AK43: 0.0015 | AL43: 0.0816 | AM43: 0.0065 | AN43: 0.0032 | AO43: -9999.9999 | AP43: 0.0046 | AQ43: -9999.9999 | AR43: 0.0116 | AS43: 0.0306 | AT43: =AS43+AR43 -> 0.0422 | AU43: 0.0099 | AV43: -9999.9999 | AW43: -9999.9999 | AX43: 0.0164 | AY43: 0.183 | AZ43: =AX43+AY43 -> 0.1994 | BA43: 0.0019 | BB43: ND
A44: 1 | B44: 1 | C44: 10 | D44: 3206 | E44: 18.7 | F44: 2.1415 | G44: 35.7487 | H44: 60 | I44: 61 | J44: 117.45 | K44: 0.00077000759 | L44: -4.3908081e-06 | M44: 1.0256712 | N44: 117.4685 | O44: 0.99846553 | P44: 2.091077 | Q44: 2.03874 | R44: 93.3875 | S44: 91.05013 | AD44: 0.075 | AE44: 0.0641 | AF44: 0.034 | AG44: 0.0822 | AH44: 0.0379 | AI44: 0.0206 | AJ44: 0.005 | AK44: 0.0069 | AL44: 0.1733 | AM44: 0.0178 | AN44: 0.0087 | AO44: -9999.9999 | AP44: 0.0171 | AQ44: -9999.9999 | AR44: -9999.9999 | AS44: 0.1174 | AT44: =AS44 -> 0.1174 | AU44: -9999.9999 | AV44: 0.0189 | AW44: -9999.9999 | AX44: 0.0289 | AY44: 0.4329 | AZ44: =AX44+AY44 -> 0.4618 | BA44: 0.0036 | BB44: ND
A45: 1 | B45: 0 | C45: 11 | H45: 50 | I45: 50 | AD45: 0.0369 | AE45: 0.0429 | AF45: 0.0352 | AG45: 0.029 | AH45: 0.0181 | AI45: 0.0054 | AJ45: 0.002 | AK45: 0.0045 | AL45: 0.1351 | AM45: 0.0201 | AN45: 0.0018 | AO45: -9999.9999 | AP45: 0.0411 | AQ45: -9999.9999 | AR45: 0.0315 | AS45: -9999.9999 | AT45: =AR45 -> 0.0315 | AU45: -9999.9999 | AV45: 0.0228 | AW45: -9999.9999 | AX45: 0.0353 | AY45: 0.2992 | AZ45: =AX45+AY45 -> 0.3345 | BA45: 0.0032 | BB45: ND
A46: 1 | B46: 1 | C46: 12 | D46: 3207 | E46: 24.1 | F46: 4.7223 | G46: 35.906 | H46: 40 | I46: 40 | J46: 116.98 | K46: 0.00076059645 | L46: -4.2209612e-06 | M46: 1.0242994 | N46: 116.99861 | O46: 0.9972747 | P46: 4.6479572 | Q46: 4.5376939 | R46: 207.57777 | S46: 202.65341 | AD46: 0.0128 | AE46: 0.021 | AF46: 0.0216 | AG46: 0.009 | AH46: 0.0075 | AI46: 0.0026 | AJ46: -9999.9999 | AK46: 0.0015 | AL46: 0.0501 | AM46: 0.0142 | AN46: 0.0016 | AO46: 0.0023 | AP46: 0.0365 | AQ46: -9999.9999 | AR46: 0.0159 | AS46: -9999.9999 | AT46: =AR46 -> 0.0159 | AU46: -9999.9999 | AV46: 0.022 | AW46: -9999.9999 | AX46: 0.0206 | AY46: 0.1982 | AZ46: =AX46+AY46 -> 0.2188 | BA46: 0.002 | BB46: ND
...

Sheet 004_01
C2: Campagne : | F2: PIRATA-FR30
C4: Données de campagne
C6: N° de station : | F6: 4 | H6: N° de palanquée : | P6: 1 | R6: Date d'analyse : | T6: 42419
G8: Position | I8: Degrés | J8: Minutes | P8: Cardinal | Q8: Décimale
G9: Latitude | I9: 07° | J9: 59.92' | K9: N | L9: + | M9: N | N9: E | O9: 7°59,92 | P9: N | Q9: 7.9986667
G10: Longitude | I10: 018° | J10: 57.90' | K10: W | L10: - | M10: S | N10: W | O10: -18°57,9 | P10: W | Q10: -18.965
G11: Prélèvement | I11: Date | J11: 42419 | N11: 7°59,92 | O11: 1 | P11: 2020-02-20T07:21:36z
I12: Heure | J12: 0.30666667 | N12: 18°57,9 | O12: -1
C13: Données :
C14: Température du laboratoire à la calibration ( t°c ) | Q14: t°c = | R14: 23.5 | S14: °C
C15: Température du laboratoire au début de la série d'analyses | Q15: t°lab = | R15: 24.7 | S15: °C
C16: Volume moyen de thiosulfate pour la titration à t°c | Q16: Vmoy.titr.t°c = | R16: 4.9469 | S16: mL
C17: Volume moyen de thiosulfate pour la détermination du blanc à t°c | Q17: Vmoy.titr.blanc.t°c = | R17: 0.005 | S17: mL
C18: Masse volumique de l'eau pure à la calibration | O18: ρ = | P18: 0.99742152
C19: Normalite de l'iodate (NIO3) à la température de calibration | O19: N(IO3) = | P19: 0.0199967 | Q19: N
C20: Vol. de la prise d'essai d'iodate (VIO3) à 20°C | O20: V(IO3)20°C = | P20: 5.0112146 | Q20: mL
C21: Vol. de la prise d'essai d'iodate (VIO3) à t°c | O21: V(IO3)t°c= | P21: 5.01139 | Q21: mL
C22: Volume moyen de thiosulfate pour la titration à 20° C | O22: Vmoy.titr.20°C = | P22: 4.9467269 | Q22: mL
C23: Volume moyen de thiosulfate pour la détermination du blanc à 20° C | O23: Vmoy.titr.blanc.20°C = | P23: 0.004999825 | Q23: mL
C24: Normalite de l'iodate (NIO3) à 20°C | O24: N(IO3)20°C = | P24: 0.020012434 | Q24: N
C25: Titre du thiosulfate à 20°C | O25: V(Thio)20°C = | P25: 0.0040392421 | Q25: N
C26: Volume de réactif utilisé | O26: Vreg = | P26: 2.0367937 | Q26: mL
O27: DOreg = | P27: 0.0017
E29: Choix de la série de flacons : | I29: IRD | O29: IRD
O30: LPO
C31: N° | D31: N° des Flacons | E31: T° prélèv. | F31: Volume de thio. | G31: Salinité | H31: Prof. Théorique | I31: Prof. Effective | J31: V. flacons 20°C | K31: A | L31: B | M31: Densité eau de mer à t° | N31: Vol. à t° prél. des flacons | O31: Densité eau pure à t° | P31: Oxygène dissous | T31: NO2 | V31: NO3 + NO2 | X31: NO3 | Z31: Phosphate | AB31: Silicate | AD31: chlorophyll-c3 | AE31: chlorophyll-c1+c2 | AF31: peridinin | AG31: 19'-butanoyloxyfucoxanthin | AH31: fucoxanthine | AI31: neoxanthin | AJ31: prasinoxanthin | AK31: violaxanthin | AL31: 19'-hexanoyloxyfucoxanthin | AM31: diadinoxanthin | AN31: alloxanthin | AO31: diatoxanthin | AP31: zeaxanthin | AQ31: lutein | AR31: divinyl chlorophyll-b | AS31: chlorophyll-b | AT31: total chlorophyll-b | AU31: alpha-carotene | AV31: beta-carotene | AW31: pheophorbide | AX31: divinyl chlorophyll-a | AY31: chlorophyll-a | AZ31: total chlorophyll-a | BA31: pheophytin_a | BB31: crocoxanthin
C33: BTL | E33: °C | F33: ml | H33: m | I33: dbar | J33: ml | P33: DOX1 | R33: DOXY | S33: DOX2 | T33: NTRI | U33: NTIW | V33: NTRZ | W33: NTZW | X33: NTRA | Y33: NTAW | Z33: PHOS | AA33: PHOW | AB33: SLCA | AC33: SLCW | AD33: CHC3 | AE33: CHCZ | AF33: PERP | AG33: BFUP | AH33: FUCP | AI33: NEXW | AJ33: PXAP | AK33: VIOW | AL33: HFUP | AM33: DXAP | AN33: AXAP | AO33: TXAP | AP33: ZXAP | AQ33: LUTW | AR33: CHBD | AS33: CH2P | AT33: CHLB | AU33: AACP | AV33: BBCP | AW33: PHEP | AX33: CHAD | AY33: CH1P | AZ33: CPHL | BA33: PHEA | BB33: CXAP
N34: mL | P34: ml/l | Q34: ml/kg | R34: µmol/l | S34: µmol/kg | T34: µmol/l | U34: µmol/kg | V34: µmol/l | W34: µmol/kg | X34: µmol/l | Y34: µmol/kg | Z34: µmol/l | AA34: µmol/kg | AB34: µmol/l | AC34: µmol/kg | AD34: µg.l-1 | AE34: µg.l-1 | AF34: µg.l-1 | AG34: µg.l-1 | AH34: µg.l-1 | AI34: µg.l-1 | AJ34: µg.l-1 | AK34: µg.l-1 | AL34: µg.l-1 | AM34: µg.l-1 | AN34: µg.l-1 | AO34: µg.l-1 | AP34: µg.l-1 | AQ34: µg.l-1 | AR34: µg.l-1 | AS34: µg.l-1 | AT34: µg.l-1 | AU34: µg.l-1 | AV34: µg.l-1 | AW34: µg.l-1 | AX34: µg.l-1 | AY34: µg.l-1 | AZ34: µg.l-1 | BA34: µg.l-1 | BB34: µg.l-1
A35: 1 | B35: 1 | C35: 1 | D35: 3229 | E35: 8.8 | F35: 3.1872 | G35: 34.76695 | H35: 1000 | I35: 1007 | J35: 120.3 | K35: 0.00079389156 | L35: -4.9528162e-06 | M35: 1.0269679 | N35: 120.31776 | O35: 0.99979801 | P35: 3.0442752 | Q35: 2.9643334 | R35: 135.95733 | S35: 132.38713
A36: 1 | B36: 1 | C36: 2 | D36: 3230 | E36: 10.5 | F36: 1.8042 | G36: 34.7899 | H36: 750 | I36: 755 | J36: 115.77 | K36: 0.00078908717 | L36: -4.8332446e-06 | M36: 1.0267016 | N36: 115.78712 | O36: 0.99965638 | P36: 1.7853819 | Q36: 1.7389491 | R36: 79.735156 | S36: 77.661469
A37: 1 | B37: 1 | C37: 3 | D37: 3231 | E37: 12.4 | F37: 0.9581 | G37: 35.069 | H37: 500 | I37: 504 | J37: 114.15 | K37: 0.00078408638 | L37: -4.7109233e-06 | M37: 1.0265659 | N37: 114.1672 | O37: 0.99945297 | P37: 0.95462284 | Q37: 0.92991868 | R37: 42.633456 | S37: 41.530168
A38: 1 | B38: 1 | C38: 4 | D38: 3232 | E38: 13.1 | F38: 0.9536 | G38: 35.0692 | H38: 500 | I38: 503 | J38: 115.71 | K38: 0.00078233756 | L38: -4.6688689e-06 | M38: 1.026427 | N38: 115.72744 | O38: 0.99936648 | P38: 0.93702898 | Q38: 0.91290367 | R38: 41.847714 | S38: 40.770278
A39: 1 | B39: 0 | C39: 5 | H39: 250 | I39: 252 | AD39: -9999.9999 | AE39: -9999.9999 | AF39: -9999.9999 | AG39: -9999.9999 | AH39: -9999.9999 | AI39: -9999.9999 | AJ39: -9999.9999 | AK39: -9999.9999 | AL39: -9999.9999 | AM39: -9999.9999 | AN39: -9999.9999 | AO39: -9999.9999 | AP39: -9999.9999 | AQ39: -9999.9999 | AR39: -9999.9999 | AS39: -9999.9999 | AT39: =AS39 -> -9999.9999 | AU39: -9999.9999 | AV39: -9999.9999 | AW39: -9999.9999 | AX39: -9999.9999 | AY39: -9999.9999 | AZ39: =AY39 -> -9999.9999 | BA39: -9999.9999 | BB39: ND
A40: 1 | B40: 1 | C40: 6 | D40: 3233 | E40: 17.4 | F40: 1.7746 | G40: 35.5972 | H40: 100 | I40: 100 | J40: 117.93 | K40: 0.00077262057 | L40: -4.4461087e-06 | M40: 1.0258776 | N40: 117.94839 | O40: 0.9987065 | P40: 1.7231038 | Q40: 1.6796388 | R40: 76.953815 | S40: 75.012671 | AD40: 0.0089 | AE40: 0.0046 | AF40: -9999.9999 | AG40: 0.011 | AH40: 0.0079 | AI40: -9999.9999 | AJ40: -9999.9999 | AK40: -9999.9999 | AL40: 0.0228 | AM40: 0.0014 | AN40: -9999.9999 | AO40: -9999.9999 | AP40: 0.0019 | AQ40: -9999.9999 | AR40: 0.0032 | AS40: 0.0092 | AT40: =AS40+AR40 -> 0.0124 | AU40: 0.002 | AV40: -9999.9999 | AW40: -9999.9999 | AX40: -9999.9999 | AY40: 0.0365 | AZ40: =AY40 -> 0.0365 | BA40: -9999.9999 | BB40: ND
A41: 1 | B41: 0 | C41: 7 | H41: 90 | I41: 91 | AD41: 0.0121 | AE41: 0.0055 | AF41: 0.0026 | AG41: 0.0121 | AH41: 0.0089 | AI41: 0.0024 | AJ41: 0.0011 | AK41: -9999.9999 | AL41: 0.0265 | AM41: 0.0015 | AN41: -9999.9999 | AO41: -9999.9999 | AP41: 0.0023 | AQ41: -9999.9999 | AR41: 0.0042 | AS41: 0.0114 | AT41: =AS41+AR41 -> 0.0156 | AU41: 0.0032 | AV41: -9999.9999 | AW41: -9999.9999 | AX41: 0.0064 | AY41: 0.0459 | AZ41: =AX41+AY41 -> 0.0523 | BA41: 0.0015 | BB41: ND
A42: 1 | B42: 1 | C42: 8 | D42: 3237 | E42: 18.2 | F42: 1.9888 | G42: 35.6684 | H42: 80 | I42: 81 | J42: 118.47 | K42: 0.00077099568 | L42: -4.4114157e-06 | M42: 1.0257355 | N42: 118.48856 | O42: 0.9985604 | P42: 1.9239103 | Q42: 1.8756397 | R42: 85.921833 | S42: 83.76607 | AD42: 0.0184 | AE42: 0.0098 | AF42: 0.005 | AG42: 0.0166 | AH42: 0.0147 | AI42: 0.0029 | AJ42: 0.0019 | AK42: -9999.9999 | AL42: 0.039 | AM42: 0.0025 | AN42: 0.0011 | AO42: -9999.9999 | AP42: 0.0033 | AQ42: -9999.9999 | AR42: 0.0065 | AS42: 0.0156 | AT42: =AS42+AR42 -> 0.0221 | AU42: 0.0054 | AV42: -9999.9999 | AW42: -9999.9999 | AX42: 0.0096 | AY42: 0.0797 | AZ42: =AX42+AY42 -> 0.0893 | BA42: 0.0019 | BB42: ND
A43: 1 | B43: 0 | C43: 9 | H43: 70 | I43: 71 | AD43: 0.0355 | AE43: 0.0244 | AF43: 0.0113 | AG43: 0.031 | AH43: 0.0253 | AI43: 0.0079 | AJ43: 0.0064 | AK43: 0.0023 | AL43: 0.0782 | AM43: 0.0062 | AN43: 0.003 | AO43: -9999.9999 | AP43: 0.0065 | AQ43: -9999.9999 | AR43: 0.0091 | AS43: 0.0462 | AT43: =AS43+AR43 -> 0.0553 | AU43: 0.0082 | AV43: -9999.9999 | AW43: -9999.9999 | AX43: 0.015 | AY43: 0.1874 | AZ43: =AX43+AY43 -> 0.2024 | BA43: 0.0027 | BB43: ND
A44: 1 | B44: 1 | C44: 10 | D44: 3238 | E44: 20.8 | F44: 2.5715 | G44: 35.83445 | H44: 60 | I44: 60 | J44: 117.73 | K44: 0.0007660805 | L44: -4.3132901e-06 | M44: 1.0251852 | N44: 117.74864 | O44: 0.99803795 | P44: 2.5078528 | Q44: 2.4462437 | R44: 112.00071 | S44: 109.24924 | AD44: 0.0338 | AE44: 0.0233 | AF44: 0.0107 | AG44: 0.0295 | AH44: 0.0241 | AI44: 0.0075 | AJ44: 0.0061 | AK44: 0.0022 | AL44: 0.0745 | AM44: 0.006 | AN44: 0.0028 | AO44: -9999.9999 | AP44: 0.0062 | AQ44: -9999.9999 | AR44: 0.0087 | AS44: 0.044 | AT44: =AS44+AR44 -> 0.0527 | AU44: 0.0078 | AV44: -9999.9999 | AW44: -9999.9999 | AX44: 0.0143 | AY44: 0.1786 | AZ44: =AX44+AY44 -> 0.1929 | BA44: 0.0026 | BB44: ND
A45: 1 | B45: 0 | C45: 11 | H45: 50 | I45: 51 | AD45: 0.088 | AE45: 0.0707 | AF45: 0.0523 | AG45: 0.0709 | AH45: 0.0498 | AI45: 0.0241 | AJ45: 0.0081 | AK45: 0.0078 | AL45: 0.2098 | AM45: 0.0209 | AN45: 0.0064 | AO45: -9999.9999 | AP45: 0.017 | AQ45: -9999.9999 | AR45: -9999.9999 | AS45: 0.1563 | AT45: =AS45 -> 0.1563 | AU45: -9999.9999 | AV45: 0.0232 | AW45: -9999.9999 | AX45: 0.0283 | AY45: 0.5219 | AZ45: =AX45+AY45 -> 0.5502 | BA45: 0.0058 | BB45: ND
A46: 1 | B46: 1 | C46: 12 | D46: 3239 | E46: 27.3 | F46: 4.5427 | G46: 35.837 | H46: 40 | I46: 40 | J46: 113.98 | K46: 0.00075602065 | L46: -4.1658458e-06 | M46: 1.023254 | N46: 113.99805 | O46: 0.99643374 | P46: 4.5904289 | Q46: 4.4861088 | R46: 205.00855 | S46: 200.34962 | AD46: 0.0437 | AE46: 0.0446 | AF46: 0.0461 | AG46: 0.0259 | AH46: 0.0171 | AI46: 0.005 | AJ46: 0.0009 | AK46: 0.005 | AL46: 0.1507 | AM46: 0.0188 | AN46: 0.0016 | AO46: -9999.9999 | AP46: 0.0299 | AQ46: -9999.9999 | AR46: -9999.9999 | AS46: 0.054 | AT46: =AS46 -> 0.054 | AU46: -9999.9999 | AV46: 0.02 | AW46: -9999.9999 | AX46: 0.0328 | AY46: 0.3121 | AZ46: =AX46+AY46 -> 0.3449 | BA46: 0.0045 | BB46: ND
...

Sheet 006_01
C2: Campagne : | F2: PIRATA-FR30
C4: Données de campagne
C6: N° de station : | F6: 6 | H6: N° de palanquée : | P6: 1 | R6: Date d'analyse : | T6: 42423
G8: Position | I8: Degrés | J8: Minutes | P8: Cardinal | Q8: Décimale | V8: 4.9436
G9: Latitude | I9: 00° | J9: 02.03' | K9: N | L9: + | M9: N | N9: E | O9: 0°2,03 | P9: N | Q9: 0.033833333 | V9: 4.9539
G10: Longitude | I10: 009° | J10: 53.21' | K10: W | L10: - | M10: S | N10: W | O10: -9°53,21 | P10: W | Q10: -9.8868333 | V10: 4.954
G11: Prélèvement | I11: Date | J11: 42422 | N11: 0°2,03 | O11: 1 | P11: 2020-02-23T21:29:31z | V11: 4.9575
I12: Heure | J12: 0.89549769 | N12: 9°53,21 | O12: -1 | V12: 4.9497
C13: Données : | V13: 4.95174
C14: Température du laboratoire à la calibration ( t°c ) | Q14: t°c = | R14: 22.2 | S14: °C
C15: Température du laboratoire au début de la série d'analyses | Q15: t°lab = | R15: 22.3 | S15: °C
C16: Volume moyen de thiosulfate pour la titration à t°c | Q16: Vmoy.titr.t°c = | R16: 4.95174 | S16: mL
C17: Volume moyen de thiosulfate pour la détermination du blanc à t°c | Q17: Vmoy.titr.blanc.t°c = | R17: 0.005 | S17: mL
C18: Masse volumique de l'eau pure à la calibration | O18: ρ = | P18: 0.99772746
C19: Normalite de l'iodate (NIO3) à la température de calibration | O19: N(IO3) = | P19: 0.020002833 | Q19: N
C20: Vol. de la prise d'essai d'iodate (VIO3) à 20°C | O20: V(IO3)20°C = | P20: 5.0112146 | Q20: mL
C21: Vol. de la prise d'essai d'iodate (VIO3) à t°c | O21: V(IO3)t°c= | P21: 5.0113248 | Q21: mL
C22: Volume moyen de thiosulfate pour la titration à 20° C | O22: Vmoy.titr.20°C = | P22: 4.9516311 | Q22: mL
C23: Volume moyen de thiosulfate pour la détermination du blanc à 20° C | O23: Vmoy.titr.blanc.20°C = | P23: 0.00499989 | Q23: mL
C24: Normalite de l'iodate (NIO3) à 20°C | O24: N(IO3)20°C = | P24: 0.020012434 | Q24: N
C25: Titre du thiosulfate à 20°C | O25: V(Thio)20°C = | P25: 0.0040364753 | Q25: N
C26: Volume de réactif utilisé | O26: Vreg = | P26: 2.0367937 | Q26: mL
O27: DOreg = | P27: 0.0017
E29: Choix de la série de flacons : | I29: IRD | O29: IRD
O30: LPO
C31: N° | D31: N° des Flacons | E31: T° prélèv. | F31: Volume de thio. | G31: Salinité | H31: Prof. Théorique | I31: Prof. Effective | J31: V. flacons 20°C | K31: A | L31: B | M31: Densité eau de mer à t° | N31: Vol. à t° prél. des flacons | O31: Densité eau pure à t° | P31: Oxygène dissous | T31: NO2 | V31: NO3 + NO2 | X31: NO3 | Z31: Phosphate | AB31: Silicate | AD31: chlorophyll-c3 | AE31: chlorophyll-c1+c2 | AF31: peridinin | AG31: 19'-butanoyloxyfucoxanthin | AH31: fucoxanthine | AI31: neoxanthin | AJ31: prasinoxanthin | AK31: violaxanthin | AL31: 19'-hexanoyloxyfucoxanthin | AM31: diadinoxanthin | AN31: alloxanthin | AO31: diatoxanthin | AP31: zeaxanthin | AQ31: lutein | AR31: divinyl chlorophyll-b | AS31: chlorophyll-b | AT31: total chlorophyll-b | AU31: alpha-carotene | AV31: beta-carotene | AW31: pheophorbide | AX31: divinyl chlorophyll-a | AY31: chlorophyll-a | AZ31: total chlorophyll-a | BA31: pheophytin_a | BB31: crocoxanthin
C33: BTL | E33: °C | F33: ml | H33: m | I33: dbar | J33: ml | P33: DOX1 | R33: DOXY | S33: DOX2 | T33: NTRI | U33: NTIW | V33: NTRZ | W33: NTZW | X33: NTRA | Y33: NTAW | Z33: PHOS | AA33: PHOW | AB33: SLCA | AC33: SLCW | AD33: CHC3 | AE33: CHCZ | AF33: PERP | AG33: BFUP | AH33: FUCP | AI33: NEXW | AJ33: PXAP | AK33: VIOW | AL33: HFUP | AM33: DXAP | AN33: AXAP | AO33: TXAP | AP33: ZXAP | AQ33: LUTW | AR33: CHBD | AS33: CH2P | AT33: CHLB | AU33: AACP | AV33: BBCP | AW33: PHEP | AX33: CHAD | AY33: CH1P | AZ33: CPHL | BA33: PHEA | BB33: CXAP
N34: mL | P34: ml/l | Q34: ml/kg | R34: µmol/l | S34: µmol/kg | T34: µmol/l | U34: µmol/kg | V34: µmol/l | W34: µmol/kg | X34: µmol/l | Y34: µmol/kg | Z34: µmol/l | AA34: µmol/kg | AB34: µmol/l | AC34: µmol/kg | AD34: µg.l-1 | AE34: µg.l-1 | AF34: µg.l-1 | AG34: µg.l-1 | AH34: µg.l-1 | AI34: µg.l-1 | AJ34: µg.l-1 | AK34: µg.l-1 | AL34: µg.l-1 | AM34: µg.l-1 | AN34: µg.l-1 | AO34: µg.l-1 | AP34: µg.l-1 | AQ34: µg.l-1 | AR34: µg.l-1 | AS34: µg.l-1 | AT34: µg.l-1 | AU34: µg.l-1 | AV34: µg.l-1 | AW34: µg.l-1 | AX34: µg.l-1 | AY34: µg.l-1 | AZ34: µg.l-1 | BA34: µg.l-1 | BB34: µg.l-1
A35: 1 | B35: 1 | C35: 1 | D35: 3229 | E35: 9.1 | F35: 3.239 | G35: 34.58535 | H35: 500 | I35: 505 | J35: 120.3 | K35: 0.00079302024 | L35: -4.9310204e-06 | M35: 1.0267777 | N35: 120.31755 | O35: 0.99977587 | P35: 3.0918648 | Q35: 3.0112309 | R35: 138.08268 | S35: 134.48157
A36: 1 | B36: 0 | C36: 2 | H36: 400 | I36: 404
A37: 1 | B37: 1 | C37: 3 | D37: 3230 | E37: 12.4 | F37: 2.4075 | G37: 35.01425 | H37: 300 | I37: 302 | J37: 115.77 | K37: 0.00078408638 | L37: -4.7109233e-06 | M37: 1.0265234 | N37: 115.78738 | O37: 0.99945297 | P37: 2.3857858 | Q37: 2.3241416 | R37: 106.5492 | S37: 103.79616
A38: 1 | B38: 0 | C38: 4 | H38: 200 | I38: 202
A39: 1 | B39: 1 | C39: 5 | D39: 3231 | E39: 16.7 | F39: 3.6297 | G39: 35.6163 | H39: 100 | I39: 100 | J39: 114.15 | K39: 0.00077408763 | L39: -4.4782024e-06 | M39: 1.0260596 | N39: 114.16783 | O39: 0.9988285 | P39: 3.6566884 | Q39: 3.5638166 | R39: 163.30771 | S39: 159.16005
A40: 1 | B40: 1 | C40: 6 | D40: 3232 | E40: 17.1 | F40: 3.6707 | G40: 35.61975 | H40: 100 | I40: 100 | J40: 115.71 | K40: 0.00077324407 | L40: -4.4596646e-06 | M40: 1.0259671 | N40: 115.72807 | O40: 0.99875946 | P40: 3.6474143 | Q40: 3.5550985 | R40: 162.89352 | S40: 158.7707 | AD40: 0.0287 | AE40: 0.0185 | AF40: -9999.9999 | AG40: 0.0471 | AH40: 0.0101 | AI40: 0.0011 | AJ40: -9999.9999 | AK40: -9999.9999 | AL40: 0.0519 | AM40: 0.0041 | AN40: 0.0013 | AO40: -9999.9999 | AP40: 0.0151 | AQ40: -9999.9999 | AR40: 0.0531 | AS40: 0.0127 | AT40: =AS40+AR40 -> 0.0658 | AU40: 0.0152 | AV40: -9999.9999 | AW40: -9999.9999 | AX40: 0.0405 | AY40: 0.1028 | AZ40: =AX40+AY40 -> 0.1433 | BA40: 0.0028 | BB40: ND
A41: 1 | B41: 1 | C41: 7 | D41: 3233 | E41: 17.7 | F41: 3.7591 | G41: 35.72245 | H41: 80 | I41: 81 | J41: 117.93 | K41: 0.00077200483 | L41: -4.4328506e-06 | M41: 1.0259005 | N41: 117.94854 | O41: 0.99865254 | P41: 3.6640557 | Q41: 3.5715507 | R41: 163.63673 | S41: 159.50545 | AD41: 0.0411 | AE41: 0.0272 | AF41: 0.0026 | AG41: 0.0655 | AH41: 0.0141 | AI41: 0.0025 | AJ41: 0.0017 | AK41: 0.0007 | AL41: 0.075 | AM41: 0.006 | AN41: 0.0023 | AO41: -9999.9999 | AP41: 0.0237 | AQ41: -9999.9999 | AR41: 0.0672 | AS41: 0.0201 | AT41: =AS41+AR41 -> 0.0873 | AU41: 0.0193 | AV41: -9999.9999 | AW41: -9999.9999 | AX41: 0.0557 | AY41: 0.1568 | AZ41: =AX41+AY41 -> 0.2125 | BA41: 0.0032 | BB41: ND
A42: 1 | B42: 1 | C42: 8 | D42: 3237 | E42: 20.7 | F42: 4.1966 | G42: 36.13805 | H42: 60 | I42: 60 | J42: 118.47 | K42: 0.00076625954 | L42: -4.3166506e-06 | M42: 1.0254437 | N42: 118.48912 | O42: 0.99805936 | P42: 4.0732218 | Q42: 3.9721555 | R42: 181.91009 | S42: 177.39647 | AD42: 0.0576 | AE42: 0.0402 | AF42: 0.0042 | AG42: 0.0836 | AH42: 0.0158 | AI42: 0.0087 | AJ42: 0.0079 | AK42: 0.0022 | AL42: 0.1163 | AM42: 0.0088 | AN42: 0.002 | AO42: -9999.9999 | AP42: 0.0423 | AQ42: -9999.9999 | AR42: 0.0553 | AS42: 0.0797 | AT42: =AS42+AR42 -> 0.135 | AU42: 0.024 | AV42: -9999.9999 | AW42: -9999.9999 | AX42: 0.0815 | AY42: 0.2477 | AZ42: =AX42+AY42 -> 0.3292 | BA42: 0.0057 | BB42: ND
A43: 1 | B43: 1 | C43: 9 | D43: 3238 | E43: 24.4 | F43: 4.4476 | G43: 36.47075 | H43: 40 | I43: 40 | J43: 117.73 | K43: 0.00076013738 | L43: -4.2143547e-06 | M43: 1.0246372 | N43: 117.74939 | O43: 0.99719999 | P43: 4.3453267 | Q43: 4.2408443 | R43: 194.06229 | S43: 189.39611 | AD43: 0.0629 | AE43: 0.0509 | AF43: 0.0079 | AG43: 0.0789 | AH43: 0.0146 | AI43: 0.0026 | AJ43: 0.0034 | AK43: 0.0016 | AL43: 0.1866 | AM43: 0.015 | AN43: -9999.9999 | AO43: -9999.9999 | AP43: 0.0343 | AQ43: -9999.9999 | AR43: 0.0177 | AS43: 0.0445 | AT43: =AS43+AR43 -> 0.0622 | AU43: 0.0171 | AV43: -9999.9999 | AW43: -9999.9999 | AX43: 0.0528 | AY43: 0.2689 | AZ43: =AX43+AY43 -> 0.3217 | BA43: -9999.9999 | BB43: ND
A44: 1 | B44: 1 | C44: 10 | D44: 3239 | E44: 27.7 | F44: 4.5037 | G44: 35.73905 | H44: 20 | I44: 20 | J44: 113.98 | K44: 0.00075549721 | L44: -4.161339e-06 | M44: 1.0230507 | N44: 113.99794 | O44: 0.99632193 | P44: 4.5477643 | Q44: 4.4452972 | R44: 203.10316 | S44: 198.52697 | AD44: 0.0035 | AE44: 0.0069 | AF44: 0.0026 | AG44: 0.0063 | AH44: 0.0048 | AI44: -9999.9999 | AJ44: -9999.9999 | AK44: -9999.9999 | AL44: 0.0208 | AM44: 0.0068 | AN44: -9999.9999 | AO44: -9999.9999 | AP44: 0.0887 | AQ44: -9999.9999 | AR44: 0.0046 | AS44: 0.0049 | AT44: =AS44+AR44 -> 0.0095 | AU44: -9999.9999 | AV44: 0.016 | AW44: -9999.9999 | AX44: 0.054 | AY44: 0.0759 | AZ44: =AX44+AY44 -> 0.1299 | BA44: 0.0025 | BB44: ND
A45: 1 | B45: 0 | C45: 11 | H45: 20 | I45: 20
A46: 1 | B46: 1 | C46: 12 | D46: 3240 | E46: 28.4 | F46: 4.6037 | G46: 35.5369 | H46: 0 | I46: 4 | J46: 117.01 | K46: 0.00075460631 | L46: -4.1547262e-06 | M46: 1.0226691 | N46: 117.02818 | O46: 0.99612277 | P46: 4.5265711 | Q46: 4.4262323 | R46: 202.15667 | S46: 197.67554 | AD46: 0.0029 | AE46: 0.0068 | AF46: 0.0035 | AG46: 0.0049 | AH46: 0.0048 | AI46: -9999.9999 | AJ46: -9999.9999 | AK46: 0.0008 | AL46: 0.0196 | AM46: 0.0092 | AN46: -9999.9999 | AO46: -9999.9999 | AP46: 0.123 | AQ46: -9999.9999 | AR46: 0.0043 | AS46: 0.0033 | AT46: =AS46+AR46 -> 0.0076 | AU46: -9999.9999 | AV46: 0.0234 | AW46: -9999.9999 | AX46: 0.0559 | AY46: 0.092 | AZ46: =AX46+AY46 -> 0.1479 | BA46: 0.0027 | BB46: ND
...

Sheet 007_01
C2: Campagne : | F2: PIRATA-FR30
C4: Données de campagne
C6: N° de station : | F6: 7 | H6: N° de palanquée : | P6: 1 | R6: Date d'analyse : | T6: 42425
G8: Position | I8: Degrés | J8: Minutes | P8: Cardinal | Q8: Décimale
G9: Latitude | I9: 00° | J9: 00.83' | K9: N | L9: + | M9: N | N9: E | O9: 0°0,83 | P9: N | Q9: 0.013833333 | V9: 4.9549
G10: Longitude | I10: 000° | J10: 00.47' | K10: W | L10: - | M10: S | N10: W | O10: -0°0,47 | P10: W | Q10: -0.0078333333 | V10: 4.9541
G11: Prélèvement | I11: Date | J11: 42425 | N11: 0°0,83 | O11: 1 | P11: 2020-02-26T06:13:22z | V11: 4.9524
I12: Heure | J12: 0.25928241 | N12: 0°0,47 | O12: -1 | V12: 4.9468
C13: Données : | V13: 4.9514
C14: Température du laboratoire à la calibration ( t°c ) | Q14: t°c = | R14: 22.9 | S14: °C | V14: 4.95192
C15: Température du laboratoire au début de la série d'analyses | Q15: t°lab = | R15: 23.1 | S15: °C
C16: Volume moyen de thiosulfate pour la titration à t°c | Q16: Vmoy.titr.t°c = | R16: 4.95192 | S16: mL
C17: Volume moyen de thiosulfate pour la détermination du blanc à t°c | Q17: Vmoy.titr.blanc.t°c = | R17: 0.0047 | S17: mL
C18: Masse volumique de l'eau pure à la calibration | O18: ρ = | P18: 0.9975648
C19: Normalite de l'iodate (NIO3) à la température de calibration | O19: N(IO3) = | P19: 0.019999572 | Q19: N
C20: Vol. de la prise d'essai d'iodate (VIO3) à 20°C | O20: V(IO3)20°C = | P20: 5.0112146 | Q20: mL
C21: Vol. de la prise d'essai d'iodate (VIO3) à t°c | O21: V(IO3)t°c= | P21: 5.0113599 | Q21: mL
C22: Volume moyen de thiosulfate pour la titration à 20° C | O22: Vmoy.titr.20°C = | P22: 4.9517764 | Q22: mL
C23: Volume moyen de thiosulfate pour la détermination du blanc à 20° C | O23: Vmoy.titr.blanc.20°C = | P23: 0.0046998637 | Q23: mL
C24: Normalite de l'iodate (NIO3) à 20°C | O24: N(IO3)20°C = | P24: 0.020012434 | Q24: N
C25: Titre du thiosulfate à 20°C | O25: V(Thio)20°C = | P25: 0.0040354539 | Q25: N
C26: Volume de réactif utilisé | O26: Vreg = | P26: 2.0367937 | Q26: mL
O27: DOreg = | P27: 0.0017
E29: Choix de la série de flacons : | I29: IRD | O29: IRD
O30: LPO
C31: N° | D31: N° des Flacons | E31: T° prélèv. | F31: Volume de thio. | G31: Salinité | H31: Prof. Théorique | I31: Prof. Effective | J31: V. flacons 20°C | K31: A | L31: B | M31: Densité eau de mer à t° | N31: Vol. à t° prél. des flacons | O31: Densité eau pure à t° | P31: Oxygène dissous | T31: NO2 | V31: NO3 + NO2 | X31: NO3 | Z31: Phosphate | AB31: Silicate | AD31: chlorophyll-c3 | AE31: chlorophyll-c1+c2 | AF31: peridinin | AG31: 19'-butanoyloxyfucoxanthin | AH31: fucoxanthine | AI31: neoxanthin | AJ31: prasinoxanthin | AK31: violaxanthin | AL31: 19'-hexanoyloxyfucoxanthin | AM31: diadinoxanthin | AN31: alloxanthin | AO31: diatoxanthin | AP31: zeaxanthin | AQ31: lutein | AR31: divinyl chlorophyll-b | AS31: chlorophyll-b | AT31: total chlorophyll-b | AU31: alpha-carotene | AV31: beta-carotene | AW31: pheophorbide | AX31: divinyl chlorophyll-a | AY31: chlorophyll-a | AZ31: total chlorophyll-a | BA31: pheophytin_a | BB31: crocoxanthin
C33: BTL | E33: °C | F33: ml | H33: m | I33: dbar | J33: ml | P33: DOX1 | R33: DOXY | S33: DOX2 | T33: NTRI | U33: NTIW | V33: NTRZ | W33: NTZW | X33: NTRA | Y33: NTAW | Z33: PHOS | AA33: PHOW | AB33: SLCA | AC33: SLCW | AD33: CHC3 | AE33: CHCZ | AF33: PERP | AG33: BFUP | AH33: FUCP | AI33: NEXW | AJ33: PXAP | AK33: VIOW | AL33: HFUP | AM33: DXAP | AN33: AXAP | AO33: TXAP | AP33: ZXAP | AQ33: LUTW | AR33: CHBD | AS33: CH2P | AT33: CHLB | AU33: AACP | AV33: BBCP | AW33: PHEP | AX33: CHAD | AY33: CH1P | AZ33: CPHL | BA33: PHEA | BB33: CXAP
N34: mL | P34: ml/l | Q34: ml/kg | R34: µmol/l | S34: µmol/kg | T34: µmol/l | U34: µmol/kg | V34: µmol/l | W34: µmol/kg | X34: µmol/l | Y34: µmol/kg | Z34: µmol/l | AA34: µmol/kg | AB34: µmol/l | AC34: µmol/kg | AD34: µg.l-1 | AE34: µg.l-1 | AF34: µg.l-1 | AG34: µg.l-1 | AH34: µg.l-1 | AI34: µg.l-1 | AJ34: µg.l-1 | AK34: µg.l-1 | AL34: µg.l-1 | AM34: µg.l-1 | AN34: µg.l-1 | AO34: µg.l-1 | AP34: µg.l-1 | AQ34: µg.l-1 | AR34: µg.l-1 | AS34: µg.l-1 | AT34: µg.l-1 | AU34: µg.l-1 | AV34: µg.l-1 | AW34: µg.l-1 | AX34: µg.l-1 | AY34: µg.l-1 | AZ34: µg.l-1 | BA34: µg.l-1 | BB34: µg.l-1
A35: 1 | B35: 1 | C35: 1 | D35: 3229 | E35: 6.6 | F35: 5.8953 | G35: 34.9585 | H35: 2000 | I35: 2022 | J35: 120.3 | K35: 0.00080060243 | L35: -5.1217524e-06 | M35: 1.0274412 | N35: 120.318 | O35: 0.99992156 | P35: 5.6379522 | Q35: 5.487372 | R35: 251.79095 | S35: 245.06603
A36: 1 | B36: 0 | C36: 2 | G36: 34.97105 | H36: 1750 | I36: 1768
A37: 1 | B37: 1 | C37: 3 | D37: 3230 | E37: 7.7 | F37: 5.1109 | G37: 34.951 | H37: 1500 | I37: 1514 | J37: 115.77 | K37: 0.00079717523 | L37: -5.0352822e-06 | M37: 1.0272803 | N37: 115.78731 | O37: 0.99986844 | P37: 5.0804662 | Q37: 4.9455503 | R37: 226.89362 | S37: 220.86828
A38: 1 | B38: 0 | C38: 4 | G38: 34.65625 | H38: 1250 | I38: 1007
A39: 1 | B39: 1 | C39: 5 | D39: 3231 | E39: 8.2 | F39: 3.6199 | G39: 34.65335 | H39: 1000 | I39: 1007 | J39: 114.15 | K39: 0.00079566517 | L39: -4.9973013e-06 | M39: 1.0269718 | N39: 114.16673 | O39: 0.99983854 | P39: 3.6458833 | Q39: 3.5501301 | R39: 162.82515 | S39: 158.54881
A40: 1 | B40: 1 | C40: 6 | D40: 3232 | E40: 8.9 | F40: 3.4053 | G40: 34.50175 | H40: 750 | I40: 756 | J40: 115.71 | K40: 0.00079359998 | L40: -4.9455179e-06 | M40: 1.0267442 | N40: 115.72678 | O40: 0.99979077 | P40: 3.3817847 | Q40: 3.2936973 | R40: 151.03051 | S40: 147.09652
A41: 1 | B41: 1 | C41: 7 | D41: 3233 | E41: 9.6 | F41: 3.4623 | G41: 34.5033 | H41: 750 | I41: 756 | J41: 117.93 | K41: 0.00079159063 | L41: -4.8953559e-06 | M41: 1.0266317 | N41: 117.9471 | O41: 0.99973623 | P41: 3.3727749 | Q41: 3.2852821 | R41: 150.62812 | S41: 146.7207
A42: 1 | B42: 1 | C42: 8 | D42: 3237 | E42: 11.4 | F42: 2.7709 | G42: 34.6313 | H42: 500 | I42: 504 | J42: 118.47 | K42: 0.00078667123 | L42: -4.7738138e-06 | M42: 1.0264158 | N42: 118.48733 | O42: 0.99956583 | P42: 2.6837859 | Q42: 2.614716 | R42: 119.85788 | S42: 116.77322
A43: 1 | B43: 1 | C43: 9 | D43: 3238 | E43: 13.2 | F43: 1.6477 | G43: 35.0198 | H43: 300 | I43: 303 | J43: 117.73 | K43: 0.00078209172 | L43: -4.6629935e-06 | M43: 1.0263685 | N43: 117.74768 | O43: 0.99935363 | P43: 1.6000844 | Q43: 1.5589766 | R43: 71.459771 | S43: 69.623894
A44: 1 | B44: 0 | C44: 10 | G44: 35.4479 | H44: 200 | I44: 201
A45: 1 | B45: 1 | C45: 11 | D45: 3239 | E45: 18.6 | F45: 3.6255 | G45: 35.7138 | H45: 100 | I45: 100 | J45: 113.98 | K45: 0.00077020354 | L45: -4.3948634e-06 | M45: 1.0256699 | N45: 113.99791 | O45: 0.99848472 | P45: 3.6570531 | Q45: 3.5655265 | R45: 163.32399 | S45: 159.23641 | AD45: 0.0295 | AE45: 0.0185 | AF45: 0.0031 | AG45: 0.0466 | AH45: 0.0107 | AI45: 0.0023 | AJ45: 0.0021 | AK45: 0.0012 | AL45: 0.0496 | AM45: 0.0042 | AN45: 0.0008 | AO45: -9999.9999 | AP45: 0.0157 | AQ45: -9999.9999 | AR45: -9999.9999 | AS45: 0.1071 | AT45: =AS45 -> 0.1071 | AU45: -9999.9999 | AV45: 0.0199 | AW45: -9999.9999 | AX45: 0.0585 | AY45: 0.1068 | AZ45: =AX45+AY45 -> 0.1653 | BA45: 0.0027 | BB45: ND
A46: 1 | B46: 0 | C46: 12 | G46: 35.8029 | H46: 80 | I46: 81 | AD46: 0.033 | AE46: 0.0257 | AF46: 0.0096 | AG46: 0.0387 | AH46: 0.0156 | AI46: 0.0052 | AJ46: 0.0028 | AK46: 0.0016 | AL46: 0.0924 | AM46: 0.0063 | AN46: 0.0052 | AO46: -9999.9999 | AP46: 0.0051 | AQ46: -9999.9999 | AR46: 0.0056 | AS46: 0.0247 | AT46: =AR46+AS46 -> 0.0303 | AU46: 0.0082 | AV46: -9999.9999 | AW46: -9999.9999 | AX46: 0.0153 | AY46: 0.1713 | AZ46: =AX46+AY46 -> 0.1866 | BA46: 0.0029 | BB46: ND
...

Sheet 008_01
C2: Campagne : | F2: PIRATA-FR30
C4: Données de campagne
C6: N° de station : | F6: 8 | H6: N° de palanquée : | P6: 1 | R6: Date d'analyse : | T6: 42426
G8: Position | I8: Degrés | J8: Minutes | P8: Cardinal | Q8: Décimale
G9: Latitude | I9: 00° | J9: 39.70' | K9: N | L9: + | M9: N | N9: E | O9: 0°39,7 | P9: N | Q9: 0.66166667 | V9: 4.9567
G10: Longitude | I10: 000° | J10: 00.16' | K10: E | L10: + | M10: S | N10: W | O10: 0°0,16 | P10: E | Q10: 0.0026666667 | V10: 4.9632
G11: Prélèvement | I11: Date | J11: 42425 | N11: 0°39,7 | O11: 1 | P11: 2020-02-26T20:45:44z | V11: 4.9702
I12: Heure | J12: 0.86509259 | N12: 0°0,16 | O12: 1 | V12: 4.9497
C13: Données : | V13: 4.956
C14: Température du laboratoire à la calibration ( t°c ) | Q14: t°c = | R14: 23 | S14: °C | V14: 4.9487
C15: Température du laboratoire au début de la série d'analyses | Q15: t°lab = | R15: 23.5 | S15: °C | V15: 4.9574167
C16: Volume moyen de thiosulfate pour la titration à t°c | Q16: Vmoy.titr.t°c = | R16: 4.9574167 | S16: mL
C17: Volume moyen de thiosulfate pour la détermination du blanc à t°c | Q17: Vmoy.titr.blanc.t°c = | R17: 0.0047 | S17: mL
C18: Masse volumique de l'eau pure à la calibration | O18: ρ = | P18: 0.99754117
C19: Normalite de l'iodate (NIO3) à la température de calibration | O19: N(IO3) = | P19: 0.019999099 | Q19: N
C20: Vol. de la prise d'essai d'iodate (VIO3) à 20°C | O20: V(IO3)20°C = | P20: 5.0112146 | Q20: mL
C21: Vol. de la prise d'essai d'iodate (VIO3) à t°c | O21: V(IO3)t°c= | P21: 5.0113649 | Q21: mL
C22: Volume moyen de thiosulfate pour la titration à 20° C | O22: Vmoy.titr.20°C = | P22: 4.9572679 | Q22: mL
C23: Volume moyen de thiosulfate pour la détermination du blanc à 20° C | O23: Vmoy.titr.blanc.20°C = | P23: 0.004699859 | Q23: mL
C24: Normalite de l'iodate (NIO3) à 20°C | O24: N(IO3)20°C = | P24: 0.020012434 | Q24: N
C25: Titre du thiosulfate à 20°C | O25: V(Thio)20°C = | P25: 0.0040308838 | Q25: N
C26: Volume de réactif utilisé | O26: Vreg = | P26: 2.0367937 | Q26: mL
O27: DOreg = | P27: 0.0017
E29: Choix de la série de flacons : | I29: IRD | O29: IRD
O30: LPO
C31: N° | D31: N° des Flacons | E31: T° prélèv. | F31: Volume de thio. | G31: Salinité | H31: Prof. Théorique | I31: Prof. Effective | J31: V. flacons 20°C | K31: A | L31: B | M31: Densité eau de mer à t° | N31: Vol. à t° prél. des flacons | O31: Densité eau pure à t° | P31: Oxygène dissous | T31: NO2 | V31: NO3 + NO2 | X31: NO3 | Z31: Phosphate | AB31: Silicate | AD31: chlorophyll-c3 | AE31: chlorophyll-c1+c2 | AF31: peridinin | AG31: 19'-butanoyloxyfucoxanthin | AH31: fucoxanthine | AI31: neoxanthin | AJ31: prasinoxanthin | AK31: violaxanthin | AL31: 19'-hexanoyloxyfucoxanthin | AM31: diadinoxanthin | AN31: alloxanthin | AO31: diatoxanthin | AP31: zeaxanthin | AQ31: lutein | AR31: divinyl chlorophyll-b | AS31: chlorophyll-b | AT31: total chlorophyll-b | AU31: alpha-carotene | AV31: beta-carotene | AW31: pheophorbide | AX31: divinyl chlorophyll-a | AY31: chlorophyll-a | AZ31: total chlorophyll-a | BA31: pheophytin_a | BB31: crocoxanthin
C33: BTL | E33: °C | F33: ml | H33: m | I33: dbar | J33: ml | P33: DOX1 | R33: DOXY | S33: DOX2 | T33: NTRI | U33: NTIW | V33: NTRZ | W33: NTZW | X33: NTRA | Y33: NTAW | Z33: PHOS | AA33: PHOW | AB33: SLCA | AC33: SLCW | AD33: CHC3 | AE33: CHCZ | AF33: PERP | AG33: BFUP | AH33: FUCP | AI33: NEXW | AJ33: PXAP | AK33: VIOW | AL33: HFUP | AM33: DXAP | AN33: AXAP | AO33: TXAP | AP33: ZXAP | AQ33: LUTW | AR33: CHBD | AS33: CH2P | AT33: CHLB | AU33: AACP | AV33: BBCP | AW33: PHEP | AX33: CHAD | AY33: CH1P | AZ33: CPHL | BA33: PHEA | BB33: CXAP
N34: mL | P34: ml/l | Q34: ml/kg | R34: µmol/l | S34: µmol/kg | T34: µmol/l | U34: µmol/kg | V34: µmol/l | W34: µmol/kg | X34: µmol/l | Y34: µmol/kg | Z34: µmol/l | AA34: µmol/kg | AB34: µmol/l | AC34: µmol/kg | AD34: µg.l-1 | AE34: µg.l-1 | AF34: µg.l-1 | AG34: µg.l-1 | AH34: µg.l-1 | AI34: µg.l-1 | AJ34: µg.l-1 | AK34: µg.l-1 | AL34: µg.l-1 | AM34: µg.l-1 | AN34: µg.l-1 | AO34: µg.l-1 | AP34: µg.l-1 | AQ34: µg.l-1 | AR34: µg.l-1 | AS34: µg.l-1 | AT34: µg.l-1 | AU34: µg.l-1 | AV34: µg.l-1 | AW34: µg.l-1 | AX34: µg.l-1 | AY34: µg.l-1 | AZ34: µg.l-1 | BA34: µg.l-1 | BB34: µg.l-1
A35: 1 | B35: 1 | C35: 1 | D35: 2075 | E35: 9.7 | F35: 2.5437 | G35: 34.64585 | H35: 500 | I35: 504 | J35: 110.99771 | K35: 0.00079130806 | L35: -4.8883223e-06 | M35: 1.0267265 | N35: 111.01396 | O35: 0.9997279 | P35: 2.6283953 | Q35: 2.5599761 | R35: 117.38413 | S35: 114.32853
A36: 1 | B36: 1 | C36: 2 | D36: 2076 | E36: 11.4 | F36: 1.5648 | G36: 34.85875 | H36: 400 | I36: 403 | J36: 106.39863 | K36: 0.00078667123 | L36: -4.7738138e-06 | M36: 1.0265928 | N36: 106.41444 | O36: 0.99956583 | P36: 1.681822 | Q36: 1.6382563 | R36: 75.110172 | S36: 73.164524
A37: 1 | B37: 1 | C37: 3 | D37: 2077 | E37: 12.8 | F37: 1.5715 | G37: 35.0477 | H37: 300 | I37: 302 | J37: 117.65506 | K37: 0.00078308104 | L37: -4.6866937e-06 | M37: 1.0264705 | N37: 117.67276 | O37: 0.99940429 | P37: 1.5246432 | Q37: 1.4853259 | R37: 68.090567 | S37: 66.334654
A38: 1 | B38: 1 | C38: 4 | D38: 2078 | E38: 15.9 | F38: 2.3825 | G38: 35.43995 | H38: 200 | I38: 202 | J38: 110.09049 | K38: 0.0007758173 | L38: -4.5168664e-06 | M38: 1.0261099 | N38: 110.10749 | O38: 0.99896115 | P38: 2.4814704 | Q38: 2.418328 | R38: 110.82247 | S38: 108.00253
A39: 1 | B39: 1 | C39: 5 | D39: 2079 | E39: 17.4 | F39: 3.1287 | G39: 35.6775 | H39: 100 | I39: 101 | J39: 107.71659 | K39: 0.00077262057 | L39: -4.4461087e-06 | M39: 1.0259392 | N39: 107.73347 | O39: 0.9987065 | P39: 3.3369476 | Q39: 3.2525784 | R39: 149.02808 | S39: 145.26015 | AD39: 0.01 | AE39: 0.0059 | AF39: -9999.9999 | AG39: 0.0159 | AH39: 0.0071 | AI39: -9999.9999 | AJ39: -9999.9999 | AK39: -9999.9999 | AL39: 0.0257 | AM39: 0.0014 | AN39: -9999.9999 | AO39: -9999.9999 | AP39: 0.0028 | AQ39: -9999.9999 | AR39: 0.0062 | AS39: 0.006 | AT39: =AR39+AS39 -> 0.0122 | AU39: 0.0035 | AV39: -9999.9999 | AW39: -9999.9999 | AX39: 0.0061 | AY39: 0.0378 | AZ39: =AX39+AY39 -> 0.0439 | BA39: 0.0013 | BB39: ND
A40: 1 | B40: 1 | C40: 6 | D40: 2080 | E40: 18.4 | F40: 3.1988 | G40: 35.7892 | H40: 80 | I40: 81 | J40: 108.72896 | K40: 0.00077059793 | L40: -4.4030734e-06 | M40: 1.025778 | N40: 108.74612 | O40: 0.99852278 | P40: 3.3796975 | Q40: 3.2947651 | R40: 150.93729 | S40: 147.14421 | AD40: 0.0251 | AE40: 0.0128 | AF40: 0.0027 | AG40: 0.031 | AH40: 0.0129 | AI40: 0.004 | AJ40: 0.0025 | AK40: 0.0016 | AL40: 0.0478 | AM40: 0.0034 | AN40: -9999.9999 | AO40: -9999.9999 | AP40: 0.0067 | AQ40: -9999.9999 | AR40: 0.0215 | AS40: 0.0193 | AT40: =AR40+AS40 -> 0.0408 | AU40: 0.0079 | AV40: -9999.9999 | AW40: -9999.9999 | AX40: 0.0189 | AY40: 0.0851 | AZ40: =AX40+AY40 -> 0.104 | BA40: 0.0016 | BB40: ND
A41: 1 | B41: 1 | C41: 7 | D41: 2081 | E41: 20.6 | F41: 3.5104 | G41: 35.91525 | H41: 60 | I41: 61 | J41: 119.40087 | K41: 0.00076643936 | L41: -4.3200441e-06 | M41: 1.0253009 | N41: 119.41987 | O41: 0.99808067 | P41: 3.3730885 | Q41: 3.2898523 | R41: 150.64213 | S41: 146.9248
