Workbook

Sheet station 01
D1: MdP = | E1: oxygene
C2: Campagne : | F2: PIRATA-FR31
C4: Données de campagne
C6: N° de station : | F6: 1 | H6: N° de palanquée : | R6: Date d'analyse : | T6: 44259
G8: Position | I8: Degrés | J8: Minutes | P8: Cardinal | Q8: Décimale
G9: Latitude | I9: 13 | J9: 30.05' | K9: N | L9: + | M9: N | N9: E | O9: 13°30 | P9: N | Q9: 13.500833
G10: Longitude | I10: 20 | J10: 07.52' | K10: W | L10: - | M10: S | N10: W | O10: -20°7 | P10: W | Q10: -20.125333
G11: Prélèvement | I11: Date | J11: 44259 | N11: 13°30 | O11: 1 | P11: 2021-03-04T15:49:06z
I12: Heure | J12: 0.75347222 | N12: 20°7 | O12: -1
C13: Données :
C14: Température du laboratoire à la calibration ( t°c ) | Q14: t°c = | R14: 22.7 | S14: °C
C15: Température du laboratoire au début de la série d'analyses | Q15: t°lab = | R15: 22.9 | S15: °C
C16: Volume moyen de thiosulfate pour la titration à t°c | Q16: Vmoy.titr.t°c = | R16: 4.88696 | S16: mL | T16: identifiant de la burette : | U16: 1
C17: Volume moyen de thiosulfate pour la détermination du blanc à t°c | Q17: Vmoy.titr.blanc.t°c = | R17: 0.005 | S17: mL
C18: Masse volumique de l'eau pure à la calibration | O18: ρ = | P18: 0.99761178
C19: Normalite de l'iodate (NIO3) à la température de calibration | O19: N(IO3) = | P19: 0.01999248 | Q19: N
C20: Vol. de la prise d'essai d'iodate (VIO3) à 20°C | O20: V(IO3)20°C = | P20: 5.0010585 | Q20: mL | T20: pipette n° : | U20: pipette O
C21: Vol. de la prise d'essai d'iodate (VIO3) à t°c | O21: V(IO3)t°c= | P21: 5.0040389 | Q21: mL
C22: Volume moyen de thiosulfate pour la titration à 20° C | O22: Vmoy.titr.20°C = | P22: 4.8840493 | Q22: mL
C23: Volume moyen de thiosulfate pour la détermination du blanc à 20° C | O23: Vmoy.titr.blanc.20°C = | P23: 0.0049970219 | Q23: mL | T23: 4.8845
C24: Normalite de l'iodate (NIO3) à 20°C | O24: N(IO3)20°C = | P24: 0.020004395 | Q24: N | T24: 4.8892
C25: Titre du thiosulfate à 20°C | O25: N(Thio)20°C = | P25: 0.020504628 | Q25: N | T25: 4.8947
C26: Volume de réactif utilisé | O26: Vreg = | P26: 2 | Q26: mL | T26: 4.8885
O27: DOreg = | P27: 0.0017 | T27: 4.8779
T28: 4.88696
E29: Choix de la série de flacons : | I29: IRD | O29: IRD
O30: LPO
C31: N° | D31: N° des Flacons | E31: T° prélèv. | F31: Volume de thio. | G31: Salinité | H31: Prof. Théorique | I31: Prof. Effective | J31: V. flacons 20°C | K31: masse volumique de l'eau de mer moyenne standard | L31: A | M31: B | N31: Masse volumique eau de mer à t° | O31: Vol. à t° prél. des flacons | P31: Oxygène dissous | T31: NO2 | V31: NO3 + NO2 | X31: NO3 | Z31: Phosphate | AB31: Silicate | AD31: chlorophyll-c3 | AE31: chlorophyll-c1+c2 | AF31: peridinin | AG31: 19'-butanoyloxyfucoxanthin | AH31: fucoxanthine | AI31: neoxanthin | AJ31: prasinoxanthin | AK31: violaxanthin | AL31: 19'-hexanoyloxyfucoxanthin | AM31: diadinoxanthin | AN31: alloxanthin | AO31: diatoxanthin | AP31: zeaxanthin | AQ31: lutein | AR31: divinyl chlorophyll-b | AS31: chlorophyll-b | AT31: total chlorophyll-b | AU31: alpha-carotene | AV31: beta-carotene | AW31: pheophorbide | AX31: divinyl chlorophyll-a | AY31: chlorophyll-a | AZ31: total chlorophyll-a | BA31: pheophytin_a | BB31: crocoxanthin
C33: BTL | E33: °C | F33: ml | H33: m | I33: m | J33: ml | O33: mL | P33: DOX1 | R33: DOXY | S33: DOX2 | T33: NTRI | U33: NTIW | V33: NTRZ | W33: NTZW | X33: NTRA | Y33: NTAW | Z33: PHOS | AA33: PHOW | AB33: SLCA | AC33: SLCW | AD33: CHC3 | AE33: CHCZ | AF33: PERP | AG33: BFUP | AH33: FUCP | AI33: NEXW | AJ33: PXAP | AK33: VIOW | AL33: HFUP | AM33: DXAP | AN33: AXAP | AO33: TXAP | AP33: ZXAP | AQ33: LUTW | AR33: CHBD | AS33: CH2P | AT33: CHLB | AU33: AACP | AV33: BBCP | AW33: PHEP | AX33: CHAD | AY33: CH1P | AZ33: CPHL | BA33: PHEA | BB33: CXAP
P34: ml/l | Q34: ml/kg | R34: µmol/l | S34: µmol/kg | T34: µmol/l | U34: µmol/kg | V34: µmol/l | W34: µmol/kg | X34: µmol/l | Y34: µmol/kg | Z34: µmol/l | AA34: µmol/kg | AB34: µmol/l | AC34: µmol/kg | AD34: µg.l-1 | AE34: µg.l-1 | AF34: µg.l-1 | AG34: µg.l-1 | AH34: µg.l-1 | AI34: µg.l-1 | AJ34: µg.l-1 | AK34: µg.l-1 | AL34: µg.l-1 | AM34: µg.l-1 | AN34: µg.l-1 | AO34: µg.l-1 | AP34: µg.l-1 | AQ34: µg.l-1 | AR34: µg.l-1 | AS34: µg.l-1 | AT34: µg.l-1 | AU34: µg.l-1 | AV34: µg.l-1 | AW34: µg.l-1 | AX34: µg.l-1 | AY34: µg.l-1 | AZ34: µg.l-1 | BA34: µg.l-1 | BB34: µg.l-1
P35: ml/l | Q35: ml/kg | R35: µmol/l | S35: µmol/kg | T35: µmol/l | U35: µmol/kg | V35: µmol/l | W35: µmol/kg | X35: µmol/l | Y35: µmol/kg | Z35: µmol/l | AA35: µmol/kg | AB35: µmol/l | AC35: µmol/kg | AD35: µg.l-1 | AE35: µg.l-1 | AF35: µg.l-1 | AG35: µg.l-1 | AH35: µg.l-1 | AI35: µg.l-1 | AJ35: µg.l-1 | AK35: µg.l-1 | AL35: µg.l-1 | AM35: µg.l-1 | AN35: µg.l-1 | AO35: µg.l-1 | AP35: µg.l-1 | AQ35: µg.l-1 | AR35: µg.l-1 | AS35: µg.l-1 | AT35: µg.l-1 | AU35: µg.l-1 | AV35: µg.l-1 | AW35: µg.l-1 | AX35: µg.l-1 | AY35: µg.l-1 | AZ35: µg.l-1 | BA35: µg.l-1 | BB35: µg.l-1
C36: 1 | D36: 2212 | E36: 5.5 | F36: 5.3224 | G36: 34.972 | H36: 2000 | I36: 2001 | J36: 116.91506 | K36: 0.9999568 | L36: 0.00080417852 | M36: -5.2122266e-06 | N36: 1.0275935 | O36: 116.89811 | P36: 5.2942013 | Q36: 5.1520387 | R36: 236.43903 | S36: 230.09005 | T36: 0.0083333333 | U36: 0.0081323895 | V36: 22.692 | W36: 22.144822 | X36: 22.683667 | Y36: 22.13669 | Z36: 1.522 | AA36: 1.4852996 | AB36: 26.115333 | AC36: 25.485608
C37: 2 | D37: 2213 | E37: 5.7 | F37: 5.3835 | G37: 34.972 | H37: 2000 | I37: 2001 | J37: 118.20947 | K37: 0.99995175 | L37: 0.000803517 | M37: -5.195479e-06 | N37: 1.0275687 | O37: 118.19257 | P37: 5.2955443 | Q37: 5.1534696 | R37: 236.49901 | S37: 230.15395 | T37: 0.0073333333 | U37: 0.0071565028 | V37: 22.743 | W37: 22.194592 | X37: 22.735667 | Y37: 22.187436 | Z37: 1.516 | AA37: 1.4794443 | AB37: 26.161333 | AC37: 25.530498
C38: 3 | D38: 2214 | E38: 5.9 | F38: 5.3922 | G38: 34.967 | H38: 2000 | I38: 2001 | J38: 118.49848 | K38: 0.99994609 | L38: 0.00080286056 | M38: -5.1788636e-06 | N38: 1.0275396 | O38: 118.48177 | P38: 5.2909649 | Q38: 5.149159 | R38: 236.29449 | S38: 229.96144 | T38: 0.0083333333 | U38: 0.0081323895 | Z38: 1.515 | AA38: 1.4784684 | AB38: 26.140333 | AC38: 25.510005
C39: 4 | D39: 2215 | E39: 6.3 | F39: 5.361 | G39: 34.969 | H39: 2000 | I39: 2001 | J39: 117.76867 | K39: 0.99993297 | L39: 0.00080156273 | M39: -5.1460301e-06 | N39: 1.0274895 | O39: 117.75253 | P39: 5.2933769 | Q39: 5.1517577 | R39: 236.40221 | S39: 230.0775 | T39: 0.0083333333 | U39: 0.0081323895 | V39: 22.793 | W39: 22.243387 | X39: 22.784667 | Y39: 22.235254 | Z39: 1.508 | AA39: 1.4716372 | AB39: 26.036333 | AC39: 25.408513
C40: 5 | D40: 2216 | E40: 6.6 | F40: 5.404 | G40: 34.968 | H40: 2000 | I40: 2002 | J40: 118.72183 | K40: 0.99992156 | L40: 0.00080060243 | M40: -5.1217524e-06 | N40: 1.0274487 | O40: 118.70592 | P40: 5.2924014 | Q40: 5.1510127 | R40: 236.35865 | S40: 230.04423 | T40: 0.014333333 | U40: 0.01398771 | V40: 22.712 | W40: 22.16434 | X40: 22.697667 | Y40: 22.150352 | Z40: 1.498 | AA40: 1.4618783 | AB40: 26.028333 | AC40: 25.400705
C41: 6 | D41: 2217 | E41: 6.8 | F41: 5.2539 | G41: 34.968 | H41: 2000 | I41: 2002 | J41: 114.93014 | K41: 0.99991321 | L41: 0.00079996839 | M41: -5.1057327e-06 | N41: 1.0274215 | O41: 114.91497 | P41: 5.3175911 | Q41: 5.1756664 | R41: 237.48362 | S41: 231.14526 | T41: 0.0083333333 | U41: 0.0081323895 | V41: 22.751 | W41: 22.202399 | X41: 22.742667 | Y41: 22.194267 | Z41: 1.492 | AA41: 1.456023 | AB41: 26.066333 | AC41: 25.437789
C42: 7 | D42: 2218 | E42: 7 | F42: 5.383 | G42: 34.971 | H42: 2000 | I42: 2002 | J42: 118.02415 | K42: 0.99990428 | L42: 0.00079933924 | M42: -5.0898454e-06 | N42: 1.0273962 | O42: 118.00881 | P42: 5.3034383 | Q42: 5.1620184 | R42: 236.85155 | S42: 230.53574 | T42: 0.010333333 | U42: 0.010084163 | V42: 22.774 | W42: 22.224845 | X42: 22.763667 | Y42: 22.214761 | Z42: 1.499 | AA42: 1.4628542 | AB42: 26.045333 | AC42: 25.417296
C43: 8 | D43: 2219 | E43: 7.7 | F43: 5.2752 | G43: 34.969 | H43: 2000 | I43: 2002 | J43: 115.88027 | K43: 0.99986844 | L43: 0.00079717523 | M43: -5.0352822e-06 | N43: 1.0272944 | O43: 115.86602 | P43: 5.2946359 | Q43: 5.1539615 | R43: 236.45844 | S43: 230.17592 | T43: 0.0063333333 | U43: 0.0061806165 | V43: 22.832 | W43: 22.281448 | X43: 22.825667 | Y43: 22.275267 | Z43: 1.486 | AA43: 1.4501678 | AB43: 26.090333 | AC43: 25.461212
C44: 9 | D44: 2220 | E44: 7.9 | F44: 5.3435 | G44: 34.968 | H44: 2000 | I44: 2002 | J44: 117.46457 | K44: 0.9998569 | L44: 0.00079656768 | M44: -5.0199906e-06 | N44: 1.027264 | O44: 117.45036 | P44: 5.2898429 | Q44: 5.1494482 | R44: 236.24438 | S44: 229.97436 | T44: 0.0043333333 | U44: 0.0042288429 | V44: 22.824 | W44: 22.273641 | X44: 22.819667 | Y44: 22.269412 | Z44: 1.496 | AA44: 1.4599267 | AB44: 26.048333 | AC44: 25.420225
...

Sheet station 02
D1: MdP = | E1: oxygene
C2: Campagne : | F2: PIRATA-FR31
C4: Données de campagne
C6: N° de station : | F6: 2 | H6: N° de palanquée : | R6: Date d'analyse : | T6: 44261
G8: Position | I8: Degrés | J8: Minutes | P8: Cardinal | Q8: Décimale
G9: Latitude | I9: 8 | J9: 59.93' | K9: N | L9: + | M9: N | N9: E | P9: N | Q9: 8.9988333
G10: Longitude | I10: 20 | J10: 03.84' | K10: W | L10: - | M10: S | N10: W | P10: W | Q10: -20.064
G11: Prélèvement | I11: Date | N11: ° | O11: 1 | P11: 2021-03-05T20:34:53z
I12: Heure | N12: ° | O12: -1
C13: Données :
C14: Température du laboratoire à la calibration ( t°c ) | Q14: t°c = | R14: 24.1 | S14: °C
C15: Température du laboratoire au début de la série d'analyses | Q15: t°lab = | R15: 24.1 | S15: °C
C16: Volume moyen de thiosulfate pour la titration à t°c | Q16: Vmoy.titr.t°c = | R16: 4.88792 | S16: mL | T16: identifiant de la burette : | U16: 1
C17: Volume moyen de thiosulfate pour la détermination du blanc à t°c | Q17: Vmoy.titr.blanc.t°c = | R17: 0.005 | S17: mL
C18: Masse volumique de l'eau pure à la calibration | O18: ρ = | P18: 0.9972747
C19: Normalite de l'iodate (NIO3) à la température de calibration | O19: N(IO3) = | P19: 0.019985725 | Q19: N
C20: Vol. de la prise d'essai d'iodate (VIO3) à 20°C | O20: V(IO3)20°C = | P20: 5.0010585 | Q20: mL | T20: pipette n° : | U20: pipette O
C21: Vol. de la prise d'essai d'iodate (VIO3) à t°c | O21: V(IO3)t°c= | P21: 5.0057303 | Q21: mL
C22: Volume moyen de thiosulfate pour la titration à 20° C | O22: Vmoy.titr.20°C = | P22: 4.8833581 | Q22: mL
C23: Volume moyen de thiosulfate pour la détermination du blanc à 20° C | O23: Vmoy.titr.blanc.20°C = | P23: 0.0049953335 | Q23: mL | T23: 4.8868
C24: Normalite de l'iodate (NIO3) à 20°C | O24: N(IO3)20°C = | P24: 0.020004395 | Q24: N | T24: 4.8871
C25: Titre du thiosulfate à 20°C | O25: N(Thio)20°C = | P25: 0.020507525 | Q25: N | T25: 4.8877
C26: Volume de réactif utilisé | O26: Vreg = | P26: 2 | Q26: mL | T26: 4.8842
O27: DOreg = | P27: 0.0017 | T27: 4.8938
T28: 4.88792
E29: Choix de la série de flacons : | I29: IRD | O29: IRD
O30: LPO
C31: N° | D31: N° des Flacons | E31: T° prélèv. | F31: Volume de thio. | G31: Salinité | H31: Prof. Théorique | I31: Prof. Effective | J31: V. flacons 20°C | K31: masse volumique de l'eau de mer moyenne standard | L31: A | M31: B | N31: Masse volumique eau de mer à t° | O31: Vol. à t° prél. des flacons | P31: Oxygène dissous | T31: NO2 | V31: NO3 + NO2 | X31: NO3 | Z31: Phosphate | AB31: Silicate | AD31: chlorophyll-c3 | AE31: chlorophyll-c1+c2 | AF31: peridinin | AG31: 19'-butanoyloxyfucoxanthin | AH31: fucoxanthine | AI31: neoxanthin | AJ31: prasinoxanthin | AK31: violaxanthin | AL31: 19'-hexanoyloxyfucoxanthin | AM31: diadinoxanthin | AN31: alloxanthin | AO31: diatoxanthin | AP31: zeaxanthin | AQ31: lutein | AR31: divinyl chlorophyll-b | AS31: chlorophyll-b | AT31: total chlorophyll-b | AU31: alpha-carotene | AV31: beta-carotene | AW31: pheophorbide | AX31: divinyl chlorophyll-a | AY31: chlorophyll-a | AZ31: total chlorophyll-a | BA31: pheophytin_a | BB31: crocoxanthin
C33: BTL | E33: °C | F33: ml | H33: m | I33: m | J33: ml | O33: mL | P33: DOX1 | R33: DOXY | S33: DOX2 | T33: NTRI | U33: NTIW | V33: NTRZ | W33: NTZW | X33: NTRA | Y33: NTAW | Z33: PHOS | AA33: PHOW | AB33: SLCA | AC33: SLCW | AD33: CHC3 | AE33: CHCZ | AF33: PERP | AG33: BFUP | AH33: FUCP | AI33: NEXW | AJ33: PXAP | AK33: VIOW | AL33: HFUP | AM33: DXAP | AN33: AXAP | AO33: TXAP | AP33: ZXAP | AQ33: LUTW | AR33: CHBD | AS33: CH2P | AT33: CHLB | AU33: AACP | AV33: BBCP | AW33: PHEP | AX33: CHAD | AY33: CH1P | AZ33: CPHL | BA33: PHEA | BB33: CXAP
P34: ml/l | Q34: ml/kg | R34: µmol/l | S34: µmol/kg | T34: µmol/l | U34: µmol/kg | V34: µmol/l | W34: µmol/kg | X34: µmol/l | Y34: µmol/kg | Z34: µmol/l | AA34: µmol/kg | AB34: µmol/l | AC34: µmol/kg | AD34: µg.l-1 | AE34: µg.l-1 | AF34: µg.l-1 | AG34: µg.l-1 | AH34: µg.l-1 | AI34: µg.l-1 | AJ34: µg.l-1 | AK34: µg.l-1 | AL34: µg.l-1 | AM34: µg.l-1 | AN34: µg.l-1 | AO34: µg.l-1 | AP34: µg.l-1 | AQ34: µg.l-1 | AR34: µg.l-1 | AS34: µg.l-1 | AT34: µg.l-1 | AU34: µg.l-1 | AV34: µg.l-1 | AW34: µg.l-1 | AX34: µg.l-1 | AY34: µg.l-1 | AZ34: µg.l-1 | BA34: µg.l-1 | BB34: µg.l-1
P35: ml/l | Q35: ml/kg | R35: µmol/l | S35: µmol/kg | T35: µmol/l | U35: µmol/kg | V35: µmol/l | W35: µmol/kg | X35: µmol/l | Y35: µmol/kg | Z35: µmol/l | AA35: µmol/kg | AB35: µmol/l | AC35: µmol/kg | AD35: µg.l-1 | AE35: µg.l-1 | AF35: µg.l-1 | AG35: µg.l-1 | AH35: µg.l-1 | AI35: µg.l-1 | AJ35: µg.l-1 | AK35: µg.l-1 | AL35: µg.l-1 | AM35: µg.l-1 | AN35: µg.l-1 | AO35: µg.l-1 | AP35: µg.l-1 | AQ35: µg.l-1 | AR35: µg.l-1 | AS35: µg.l-1 | AT35: µg.l-1 | AU35: µg.l-1 | AV35: µg.l-1 | AW35: µg.l-1 | AX35: µg.l-1 | AY35: µg.l-1 | AZ35: µg.l-1 | BA35: µg.l-1 | BB35: µg.l-1
C36: 1 | D36: 3053 | E36: 8.8 | F36: 5.3815 | G36: 34.95295 | H36: 2000 | I36: 2000 | J36: 116.42 | K36: 0.99979801 | L36: 0.00079389156 | M36: -4.9528162e-06 | N36: 1.0271136 | O36: 116.40696 | P36: 5.3751293 | Q36: 5.2332372 | R36: 240.05327 | S36: 233.71637 | T36: 0.0073333333 | U36: 0.0071565838 | V36: 23.103 | W36: 22.546167 | X36: 23.095667 | Y36: 22.53901 | Z36: 1.464 | AA36: 1.4287144 | AB36: 26.179333 | AC36: 25.548353
C37: 2 | D37: 3155 | E37: 8.9 | F37: 5.3672 | G37: 34.9525 | H37: 2000 | I37: 2000 | J37: 116.07 | K37: 0.99979077 | L37: 0.00079359998 | M37: -4.9455179e-06 | N37: 1.0270974 | O37: 116.05712 | P37: 5.3772365 | Q37: 5.2353717 | R37: 240.14738 | S37: 233.8117 | T37: 0.0093333333 | U37: 0.0091083793 | V37: 23.08 | W37: 22.523721 | X37: 23.070667 | Y37: 22.514612 | Z37: 1.461 | AA37: 1.4257867 | AB37: 26.089333 | AC37: 25.460523
C38: 3 | D38: 3230 | E38: 9.5 | F38: 4.745 | G38: 34.9416 | H38: 1500 | I38: 1501 | J38: 115.77 | K38: 0.99974443 | L38: 0.00079187431 | M38: -4.9024226e-06 | N38: 1.0269911 | O38: 115.75784 | P38: 4.7640626 | Q38: 4.6388548 | R38: 212.76303 | S38: 207.17126 | T38: 0.013333333 | U38: 0.013012072 | V38: 25.765 | W38: 25.144203 | X38: 25.751667 | Y38: 25.131191 | Z38: 1.633 | AA38: 1.5936535 | AB38: 23.250333 | AC38: 22.690126
C39: 4 | D39: 3231 | E39: 10.7 | F39: 2.979 | G39: 34.7616 | H39: 1000 | I39: 1001 | J39: 114.15 | K39: 0.99963717 | L39: 0.00078854282 | M39: -4.8198062e-06 | N39: 1.0266442 | O39: 114.13938 | P39: 3.0265898 | Q39: 2.9480416 | R39: 135.1675 | S39: 131.65954 | T39: 0.016333333 | U39: 0.015941907 | V39: 35.765 | W39: 34.907895 | X39: 35.748667 | Y39: 34.891953 | Z39: 2.288 | AA39: 2.2331683 | AB39: 28.316333 | AC39: 27.637735
C40: 5 | D40: 3232 | E40: 11 | F40: 2.2217 | G40: 34.7174 | H40: 800 | I40: 799 | J40: 115.71 | K40: 0.99960738 | L40: 0.00078773434 | M40: -4.7998966e-06 | N40: 1.0265559 | O40: 115.69959 | P40: 2.2211352 | Q40: 2.1636768 | R40: 99.195899 | S40: 96.629805 | T40: 0.020333333 | U40: 0.019846716 | V40: 39.137 | W40: 38.200374 | X40: 39.116667 | Y40: 38.180527 | Z40: 2.506 | AA40: 2.4460264 | AB40: 27.008333 | AC40: 26.36197
C41: 6 | D41: 3233 | E41: 14 | F41: 0.8705 | G41: 35.17945 | H41: 400 | I41: 400 | J41: 117.93 | K41: 0.99924642 | L41: 0.00078016032 | M41: -4.6171816e-06 | N41: 1.0263266 | O41: 117.92292 | P41: 0.84165961 | Q41: 0.82007 | R41: 37.588518 | S41: 36.624326 | T41: 0.0073333333 | U41: 0.0071553644 | V41: 36.669 | W41: 35.779099 | X41: 36.661667 | Y41: 35.771944 | Z41: 2.136 | AA41: 2.0841625 | AB41: 15.099333 | AC41: 14.732895
C42: 7 | D42: 3237 | E42: 15.7 | F42: 2.0825 | G42: 35.31585 | H42: 200 | I42: 200 | J42: 118.47 | K42: 0.99899317 | L42: 0.00077625872 | M42: -4.5268634e-06 | N42: 1.0260599 | O42: 118.46491 | P42: 2.0313137 | Q42: 1.9797222 | R42: 90.718468 | S42: 88.414396 | T42: 0.014333333 | U42: 0.013984056 | V42: 26.442 | W42: 25.797656 | X42: 26.427667 | Y42: 25.783672 | Z42: 1.593 | AA42: 1.5541815 | AB42: 9.5893333 | AC42: 9.3556585
C43: 8 | D43: 3238 | E43: 16.9 | F43: 1.8076 | G43: 35.5119 | H43: 100 | I43: 101 | J43: 117.73 | K43: 0.9987942 | L43: 0.0007736641 | M43: -4.4688673e-06 | N43: 1.0259321 | O43: 117.72635 | P43: 1.7718296 | Q43: 1.7270438 | R43: 79.129911 | S43: 77.129777 | T43: 0.020333333 | U43: 0.019834953 | V43: 25.472 | W43: 24.847668 | X43: 25.451667 | Y43: 24.827833 | Z43: 1.55 | AA43: 1.5120087 | AB43: 8.2613333 | AC43: 8.0588437 | AD43: 0.0094 | AE43: 0.005 | AF43: -9999.9999 | AG43: 0.0042 | AH43: 0.0036 | AI43: -9999.9999 | AJ43: -9999.9999 | AK43: -9999.9999 | AL43: 0.0138 | AM43: 0.0014 | AN43: -9999.9999 | AO43: -9999.9999 | AP43: 0.0015 | AR43: 0.0183 | AS43: 0.0078 | AT43: 0.0261 | AU43: 0.0029 | AV43: absent | AW43: -9999.9999 | AX43: 0.0067 | AY43: 0.0269 | AZ43: 0.0336 | BA43: -9999.9999
C44: 9 | I44: 94 | T44: 0.026333333 | U44: 0.025687427 | V44: 25.363 | W44: 24.740894 | X44: 25.336667 | Y44: 24.715206 | Z44: 1.552 | AA44: 1.5139324 | AB44: 7.9103333 | AC44: 7.7163079 | AD44: 0.0181 | AE44: 0.0085 | AF44: 0.0025 | AG44: 0.0107 | AH44: 0.0078 | AI44: -9999.9999 | AJ44: -9999.9999 | AK44: -9999.9999 | AL44: 0.0311 | AM44: 0.0024 | AN44: -9999.9999 | AO44: -9999.9999 | AP44: 0.0024 | AR44: 0.0463 | AS44: 0.0106 | AT44: 0.0569 | AU44: 0.0057 | AV44: absent | AW44: -9999.9999 | AX44: 0.012 | AY44: 0.0544 | AZ44: 0.0664 | BA44: 0.0021
...

Sheet station 03
D1: MdP = | E1: oxygene
C2: Campagne : | F2: PIRATA-FR31
C4: Données de campagne
C6: N° de station : | F6: 3 | H6: N° de palanquée : | R6: Date d'analyse : | T6: 44261
G8: Position | I8: Degrés | J8: Minutes | P8: Cardinal | Q8: Décimale
G9: Latitude | I9: 8 | J9: 29.93' | K9: N | L9: + | M9: N | N9: E | O9: 8°29,97 | P9: N | Q9: 8.4988333
G10: Longitude | I10: 19 | J10: 27.16' | K10: W | L10: - | M10: S | N10: W | O10: -19°27,23 | P10: W | Q10: -19.452667
G11: Prélèvement | I11: Date | J11: 44261 | N11: 8°29,97 | O11: 1 | P11: 2021-03-06T03:10:08z
I12: Heure | J12: 0.19791667 | N12: 19°27,23 | O12: -1
C13: Données :
C14: Température du laboratoire à la calibration ( t°c ) | Q14: t°c = | R14: 24.3 | S14: °C
C15: Température du laboratoire au début de la série d'analyses | Q15: t°lab = | R15: 24.3 | S15: °C
C16: Volume moyen de thiosulfate pour la titration à t°c | Q16: Vmoy.titr.t°c = | R16: 4.88592 | S16: mL | T16: identifiant de la burette : | U16: 1
C17: Volume moyen de thiosulfate pour la détermination du blanc à t°c | Q17: Vmoy.titr.blanc.t°c = | R17: 0.005 | S17: mL
C18: Masse volumique de l'eau pure à la calibration | O18: ρ = | P18: 0.99722499
C19: Normalite de l'iodate (NIO3) à la température de calibration | O19: N(IO3) = | P19: 0.019984729 | Q19: N
C20: Vol. de la prise d'essai d'iodate (VIO3) à 20°C | O20: V(IO3)20°C = | P20: 5.0010585 | Q20: mL | T20: pipette n° : | U20: pipette O
C21: Vol. de la prise d'essai d'iodate (VIO3) à t°c | O21: V(IO3)t°c= | P21: 5.0059798 | Q21: mL
C22: Volume moyen de thiosulfate pour la titration à 20° C | O22: Vmoy.titr.20°C = | P22: 4.8811167 | Q22: mL
C23: Volume moyen de thiosulfate pour la détermination du blanc à 20° C | O23: Vmoy.titr.blanc.20°C = | P23: 0.0049950845 | Q23: mL | T23: 4.8868
C24: Normalite de l'iodate (NIO3) à 20°C | O24: N(IO3)20°C = | P24: 0.020004395 | Q24: N | T24: 4.8871
C25: Titre du thiosulfate à 20°C | O25: N(Thio)20°C = | P25: 0.020516951 | Q25: N | T25: 4.8877
C26: Volume de réactif utilisé | O26: Vreg = | P26: 2 | Q26: mL | T26: 4.8842
O27: DOreg = | P27: 0.0017 | T27: 4.8838
T28: 4.88592
E29: Choix de la série de flacons : | I29: IRD | O29: IRD
O30: LPO
C31: N° | D31: N° des Flacons | E31: T° prélèv. | F31: Volume de thio. | G31: Salinité | H31: Prof. Théorique | I31: Prof. Effective | J31: V. flacons 20°C | K31: masse volumique de l'eau de mer moyenne standard | L31: A | M31: B | N31: Masse volumique eau de mer à t° | O31: Vol. à t° prél. des flacons | P31: Oxygène dissous | T31: NO2 | V31: NO3 + NO2 | X31: NO3 | Z31: Phosphate | AB31: Silicate | AD31: chlorophyll-c3 | AE31: chlorophyll-c1+c2 | AF31: peridinin | AG31: 19'-butanoyloxyfucoxanthin | AH31: fucoxanthine | AI31: neoxanthin | AJ31: prasinoxanthin | AK31: violaxanthin | AL31: 19'-hexanoyloxyfucoxanthin | AM31: diadinoxanthin | AN31: alloxanthin | AO31: diatoxanthin | AP31: zeaxanthin | AQ31: lutein | AR31: divinyl chlorophyll-b | AS31: chlorophyll-b | AT31: total chlorophyll-b | AU31: alpha-carotene | AV31: beta-carotene | AW31: pheophorbide | AX31: divinyl chlorophyll-a | AY31: chlorophyll-a | AZ31: total chlorophyll-a | BA31: pheophytin_a | BB31: crocoxanthin
C33: BTL | E33: °C | F33: ml | H33: m | I33: m | J33: ml | O33: mL | P33: DOX1 | R33: DOXY | S33: DOX2 | T33: NTRI | U33: NTIW | V33: NTRZ | W33: NTZW | X33: NTRA | Y33: NTAW | Z33: PHOS | AA33: PHOW | AB33: SLCA | AC33: SLCW | AD33: CHC3 | AE33: CHCZ | AF33: PERP | AG33: BFUP | AH33: FUCP | AI33: NEXW | AJ33: PXAP | AK33: VIOW | AL33: HFUP | AM33: DXAP | AN33: AXAP | AO33: TXAP | AP33: ZXAP | AQ33: LUTW | AR33: CHBD | AS33: CH2P | AT33: CHLB | AU33: AACP | AV33: BBCP | AW33: PHEP | AX33: CHAD | AY33: CH1P | AZ33: CPHL | BA33: PHEA | BB33: CXAP
P34: ml/l | Q34: ml/kg | R34: µmol/l | S34: µmol/kg | T34: µmol/l | U34: µmol/kg | V34: µmol/l | W34: µmol/kg | X34: µmol/l | Y34: µmol/kg | Z34: µmol/l | AA34: µmol/kg | AB34: µmol/l | AC34: µmol/kg | AD34: µg.l-1 | AE34: µg.l-1 | AF34: µg.l-1 | AG34: µg.l-1 | AH34: µg.l-1 | AI34: µg.l-1 | AJ34: µg.l-1 | AK34: µg.l-1 | AL34: µg.l-1 | AM34: µg.l-1 | AN34: µg.l-1 | AO34: µg.l-1 | AP34: µg.l-1 | AQ34: µg.l-1 | AR34: µg.l-1 | AS34: µg.l-1 | AT34: µg.l-1 | AU34: µg.l-1 | AV34: µg.l-1 | AW34: µg.l-1 | AX34: µg.l-1 | AY34: µg.l-1 | AZ34: µg.l-1 | BA34: µg.l-1 | BB34: µg.l-1
P35: ml/l | Q35: ml/kg | R35: µmol/l | S35: µmol/kg | T35: µmol/l | U35: µmol/kg | V35: µmol/l | W35: µmol/kg | X35: µmol/l | Y35: µmol/kg | Z35: µmol/l | AA35: µmol/kg | AB35: µmol/l | AC35: µmol/kg | AD35: µg.l-1 | AE35: µg.l-1 | AF35: µg.l-1 | AG35: µg.l-1 | AH35: µg.l-1 | AI35: µg.l-1 | AJ35: µg.l-1 | AK35: µg.l-1 | AL35: µg.l-1 | AM35: µg.l-1 | AN35: µg.l-1 | AO35: µg.l-1 | AP35: µg.l-1 | AQ35: µg.l-1 | AR35: µg.l-1 | AS35: µg.l-1 | AT35: µg.l-1 | AU35: µg.l-1 | AV35: µg.l-1 | AW35: µg.l-1 | AX35: µg.l-1 | AY35: µg.l-1 | AZ35: µg.l-1 | BA35: µg.l-1 | BB35: µg.l-1
C36: 1 | D36: 2002 | E36: 9.6 | F36: 2.8811 | G36: 34.7486 | H36: 1000 | I36: 1000 | J36: 108.59 | K36: 0.99973623 | L36: 0.00079159063 | M36: -4.8953559e-06 | N36: 1.0268235 | O36: 108.57871 | P36: 3.080414 | Q36: 2.9999449 | R36: 137.57129 | S36: 133.97754 | T36: 0.0093333333 | U36: 0.0091097308 | V36: 35.346 | W36: 34.499201 | X36: 35.336667 | Y36: 34.490091 | Z36: 2.306 | AA36: 2.2507542 | AB36: 28.451333 | AC36: 27.769713
C37: 2 | D37: 2004 | E37: 10.1 | F37: 2.2056 | G37: 34.705 | H37: 800 | I37: 800 | J37: 110.33 | K37: 0.99969321 | L37: 0.00079018885 | M37: -4.8605187e-06 | N37: 1.0267049 | O37: 110.31908 | P37: 2.3153724 | Q37: 2.2551489 | R37: 103.40453 | S37: 100.71495 | T37: 0.020333333 | U37: 0.019846839 | V37: 38.774 | W37: 37.846295 | X37: 38.753667 | Y37: 37.826448 | Z37: 2.49 | AA37: 2.4304244 | AB37: 27.458333 | AC37: 26.801367
C38: 3 | D38: 2006 | E38: 10.2 | F38: 2.1875 | G38: 34.705 | H38: 800 | I38: 800 | J38: 108.87 | K38: 0.9996842 | L38: 0.0007899118 | M38: -4.8536506e-06 | N38: 1.0266877 | O38: 108.85933 | P38: 2.3275664 | Q38: 2.2670638 | R38: 103.94912 | S38: 101.24707 | T38: 0.0083333333 | U38: 0.0081339498 | V38: 38.63 | W38: 37.705738 | X38: 38.621667 | Y38: 37.697604 | Z38: 2.503 | AA38: 2.4431132 | AB38: 27.376333 | AC38: 26.721326
C39: 4 | D39: 2007 | E39: 13.4 | F39: 0.8452 | G39: 35.13595 | H39: 400 | I39: 400 | J39: 109.77 | K39: 0.99932756 | L39: 0.00078160301 | M39: -4.651342e-06 | N39: 1.0264176 | O39: 109.76276 | P39: 0.87883214 | Q39: 0.85621301 | R39: 39.248643 | S39: 38.238473 | T39: 0.012333333 | U39: 0.01203439 | V39: 37.097 | W39: 36.197819 | X39: 37.084667 | Y39: 36.185785 | Z39: 2.192 | AA39: 2.1388689 | AB39: 15.506333 | AC39: 15.130481
C40: 5 | D40: 2008 | E40: 15.6 | F40: 2.3648 | G40: 35.29175 | H40: 200 | I40: 201 | J40: 108.85 | K40: 0.99900901 | L40: 0.00077648079 | M40: -4.5319115e-06 | N40: 1.026064 | O40: 108.84521 | P40: 2.5182764 | Q40: 2.4543073 | R40: 112.46622 | S40: 109.60937 | T40: 0.0073333333 | U40: 0.0071547647 | V40: 24.286 | W40: 23.694629 | X40: 24.278667 | Y40: 23.687475 | Z40: 1.503 | AA40: 1.4664016 | AB40: 9.0433333 | AC40: 8.8231258
C41: 6 | D41: 2009 | E41: 16.8 | F41: 1.6273 | G41: 35.5209 | H41: 100 | I41: 101 | J41: 109.15 | K41: 0.99881141 | L41: 0.00077387542 | M41: -4.4735183e-06 | N41: 1.0259627 | O41: 109.14651 | P41: 1.7214214 | Q41: 1.6778597 | R41: 76.878681 | S41: 74.933213 | T41: 0.019333333 | U41: 0.018859345 | V41: 25.668 | W41: 25.038707 | X41: 25.648667 | Y41: 25.019848 | Z41: 1.556 | AA41: 1.5178521 | AB41: 7.9373333 | AC41: 7.7427367
C42: 7 | I42: 93 | T42: 0.027333333 | U42: 0.02666272 | V42: 25.65 | W42: 25.020687 | X42: 25.622667 | Y42: 24.994024 | Z42: 1.555 | AA42: 1.5168486 | AB42: 7.7723333 | AC42: 7.581642
C43: 8 | D43: 2010 | E43: 17.3 | F43: 1.5681 | G43: 35.3869 | H43: 80 | I43: 83 | J43: 109.42 | K43: 0.99872426 | L43: 0.00077282753 | M43: -4.4505942e-06 | N43: 1.0257404 | O43: 109.41705 | P43: 1.6538495 | Q43: 1.6123471 | R43: 73.860919 | S43: 72.007422 | T43: 0.037333333 | U43: 0.036416333 | V43: 24.949 | W43: 24.33619 | X43: 24.911667 | Y43: 24.299774 | Z43: 1.535 | AA43: 1.4972965 | AB43: 7.4553333 | AC43: 7.2722116
C44: 9 | I44: 73 | T44: 0.057333333 | U44: 0.055923492 | V44: 23.77 | W44: 23.18549 | X44: 23.712667 | Y44: 23.129566 | Z44: 1.435 | AA44: 1.399713 | AB44: 7.0053333 | AC44: 6.8330705
...

Sheet station 04
D1: MdP = | E1: oxygene
C2: Campagne : | F2: PIRATA-FR31
C4: Données de campagne
C6: N° de station : | F6: 4 | H6: N° de palanquée : | R6: Date d'analyse : | T6: 44261
G8: Position | I8: Degrés | J8: Minutes | P8: Cardinal | Q8: Décimale
G9: Latitude | I9: 7 | J9: 59.90' | K9: N | L9: =IF(P9=M9,"+","-") -> + | M9: N | N9: E | O9: =IF(ISBLANK(I9),"",IF(ISBLANK(J9),"",IF(P9=M10,L9&N11,N11))) -> 7°59.90' | P9: N | Q9: 7.9983333
G10: Longitude | I10: 18 | J10: 50.87' | K10: W | L10: =IF(P10=N9,"+","-") -> - | M10: S | N10: W | O10: =IF(ISBLANK(I10),"",IF(ISBLANK(J10),"",IF(P10=N10,L10&N12,N12))) -> -18°50.87' | P10: W | Q10: -18.847833
G11: Prélèvement | I11: Date | J11: 44261 | N11: =I9&"°"&J9 -> 7°59.90' | O11: =IF(P9=M10,-1,1) -> 1 | P11: 2021-03-06T08:44:18z
I12: Heure | J12: 0.41597222 | N12: =I10&"°"&J10 -> 18°50.87' | O12: =IF(P10=N10,-1,1) -> -1
C13: Données :
C14: Température du laboratoire à la calibration ( t°c ) | Q14: t°c = | R14: 24.3 | S14: °C
C15: Température du laboratoire au début de la série d'analyses | Q15: t°lab = | R15: 24.3 | S15: °C
C16: Volume moyen de thiosulfate pour la titration à t°c | Q16: Vmoy.titr.t°c = | R16: 4.88592 | S16: mL | T16: identifiant de la burette : | U16: ='Correction de volume'!J7 -> 1
C17: Volume moyen de thiosulfate pour la détermination du blanc à t°c | Q17: Vmoy.titr.blanc.t°c = | R17: 0.005 | S17: mL
C18: Masse volumique de l'eau pure à la calibration | O18: ρ = | P18: =(0.999842594+(0.00006793952*$R$14)-(0.00000909529*$R$14^2)+(0.0000001001685*$R$14^3)-(0.000000001120083*$R$14^4)+(0.000000000006536332*$R$14^5)) -> 0.99722499
C19: Normalite de l'iodate (NIO3) à la température de calibration | O19: N(IO3) = | P19: =$P$24*($P$18/'Titre de l''Iodate'!E19) -> 0.019984729 | Q19: N
C20: Vol. de la prise d'essai d'iodate (VIO3) à 20°C | O20: V(IO3)20°C = | P20: ='Correction de volume'!F8 -> 5.0010585 | Q20: mL | T20: pipette n° : | U20: ='Correction de volume'!J8 -> pipette O
C21: Vol. de la prise d'essai d'iodate (VIO3) à t°c | O21: V(IO3)t°c= | P21: =P20*'Correction de volume'!$C$11/'station 04'!$P$18 -> 5.0059798 | Q21: mL
C22: Volume moyen de thiosulfate pour la titration à 20° C | O22: Vmoy.titr.20°C = | P22: =$R$16*P18/'Correction de volume'!C11 -> 4.8811167 | Q22: mL
C23: Volume moyen de thiosulfate pour la détermination du blanc à 20° C | O23: Vmoy.titr.blanc.20°C = | P23: =$R$17*P18/'Correction de volume'!C11 -> 0.0049950845 | Q23: mL | T23: 4.8868
C24: Normalite de l'iodate (NIO3) à 20°C | O24: N(IO3)20°C = | P24: ='Titre de l''Iodate'!F7 -> 0.020004395 | Q24: N | T24: 4.8871
C25: Titre du thiosulfate à 20°C | O25: N(Thio)20°C = | P25: =IF(ISBLANK(R14),"",IF(ISBLANK(P21),"",IF(ISBLANK(R17),"",(($P$24*$P$20)/($P$22-$P$23))))) -> 0.020516951 | Q25: N | T25: 4.8877
C26: Volume de réactif utilisé | O26: Vreg = | P26: 2 | Q26: mL | T26: 4.8842
O27: DOreg = | P27: 0.0017 | T27: 4.8838
T28: =AVERAGE(T23:T27) -> 4.88592
E29: Choix de la série de flacons : | I29: IRD | O29: IRD
O30: LPO
C31: N° | D31: N° des Flacons | E31: T° prélèv. | F31: Volume de thio. | G31: Salinité | H31: Prof. Théorique | I31: Prof. Effective | J31: V. flacons 20°C | K31: masse volumique de l'eau de mer moyenne standard | L31: A | M31: B | N31: Masse volumique eau de mer à t° | O31: Vol. à t° prél. des flacons | P31: Oxygène dissous | T31: NO2 | V31: NO3 + NO2 | X31: NO3 | Z31: Phosphate | AB31: Silicate | AD31: chlorophyll-c3 | AE31: chlorophyll-c1+c2 | AF31: peridinin | AG31: 19'-butanoyloxyfucoxanthin | AH31: fucoxanthine | AI31: neoxanthin | AJ31: prasinoxanthin | AK31: violaxanthin | AL31: 19'-hexanoyloxyfucoxanthin | AM31: diadinoxanthin | AN31: alloxanthin | AO31: diatoxanthin | AP31: zeaxanthin | AQ31: lutein | AR31: divinyl chlorophyll-b | AS31: chlorophyll-b | AT31: total chlorophyll-b | AU31: alpha-carotene | AV31: beta-carotene | AW31: pheophorbide | AX31: divinyl chlorophyll-a | AY31: chlorophyll-a | AZ31: total chlorophyll-a | BA31: pheophytin_a | BB31: crocoxanthin
C33: BTL | E33: °C | F33: ml | H33: m | I33: m | J33: ml | O33: mL | P33: DOX1 | R33: DOXY | S33: DOX2 | T33: NTRI | U33: NTIW | V33: NTRZ | W33: NTZW | X33: NTRA | Y33: NTAW | Z33: PHOS | AA33: PHOW | AB33: SLCA | AC33: SLCW | AD33: CHC3 | AE33: CHCZ | AF33: PERP | AG33: BFUP | AH33: FUCP | AI33: NEXW | AJ33: PXAP | AK33: VIOW | AL33: HFUP | AM33: DXAP | AN33: AXAP | AO33: TXAP | AP33: ZXAP | AQ33: LUTW | AR33: CHBD | AS33: CH2P | AT33: CHLB | AU33: AACP | AV33: BBCP | AW33: PHEP | AX33: CHAD | AY33: CH1P | AZ33: CPHL | BA33: PHEA | BB33: CXAP
P34: ml/l | Q34: ml/kg | R34: µmol/l | S34: µmol/kg | T34: µmol/l | U34: µmol/kg | V34: µmol/l | W34: µmol/kg | X34: µmol/l | Y34: µmol/kg | Z34: µmol/l | AA34: µmol/kg | AB34: µmol/l | AC34: µmol/kg | AD34: µg.l-1 | AE34: µg.l-1 | AF34: µg.l-1 | AG34: µg.l-1 | AH34: µg.l-1 | AI34: µg.l-1 | AJ34: µg.l-1 | AK34: µg.l-1 | AL34: µg.l-1 | AM34: µg.l-1 | AN34: µg.l-1 | AO34: µg.l-1 | AP34: µg.l-1 | AQ34: µg.l-1 | AR34: µg.l-1 | AS34: µg.l-1 | AT34: µg.l-1 | AU34: µg.l-1 | AV34: µg.l-1 | AW34: µg.l-1 | AX34: µg.l-1 | AY34: µg.l-1 | AZ34: µg.l-1 | BA34: µg.l-1 | BB34: µg.l-1
P35: ml/l | Q35: ml/kg | R35: µmol/l | S35: µmol/kg | T35: µmol/l | U35: µmol/kg | V35: µmol/l | W35: µmol/kg | X35: µmol/l | Y35: µmol/kg | Z35: µmol/l | AA35: µmol/kg | AB35: µmol/l | AC35: µmol/kg | AD35: µg.l-1 | AE35: µg.l-1 | AF35: µg.l-1 | AG35: µg.l-1 | AH35: µg.l-1 | AI35: µg.l-1 | AJ35: µg.l-1 | AK35: µg.l-1 | AL35: µg.l-1 | AM35: µg.l-1 | AN35: µg.l-1 | AO35: µg.l-1 | AP35: µg.l-1 | AQ35: µg.l-1 | AR35: µg.l-1 | AS35: µg.l-1 | AT35: µg.l-1 | AU35: µg.l-1 | AV35: µg.l-1 | AW35: µg.l-1 | AX35: µg.l-1 | AY35: µg.l-1 | AZ35: µg.l-1 | BA35: µg.l-1 | BB35: µg.l-1
C36: 1 | D36: 3008 | E36: 8.2 | F36: 3.0172 | G36: 34.75775 | H36: 1000 | I36: 1001 | J36: 116 | K36: 0.99983854 | L36: 0.00079566517 | M36: -4.9973013e-06 | N36: 1.0270537 | O36: 115.98631 | P36: 3.0172288 | Q36: 2.9377517 | R36: 134.74944 | S36: 131.19999 | T36: 0.0063333333 | U36: 0.0061815598 | V36: 35.181 | W36: 34.337914 | X36: 35.174667 | Y36: 34.331732 | Z36: 2.3 | AA36: 2.2448822 | AB36: 28.244333 | AC36: 27.567479
C37: 2 | D37: 3167 | E37: 8.9 | F37: 2.5019 | G37: 34.6568 | H37: 800 | I37: 800 | J37: 117.58 | K37: 0.99979077 | L37: 0.00079359998 | M37: -4.9455179e-06 | N37: 1.0268657 | O37: 117.56695 | P37: 2.4643443 | Q37: 2.3998702 | R37: 110.05762 | S37: 107.1782 | T37: 0.012333333 | U37: 0.012038674 | V37: 38.465 | W37: 37.546021 | X37: 38.452667 | Y37: 37.533983 | Z37: 2.532 | AA37: 2.4715072 | AB37: 28.244333 | AC37: 27.56954
C38: 3 | D38: 3010 | E38: 12.5 | F38: 0.9702 | G38: 35.1179 | H38: 400 | I38: 400 | J38: 117.32 | K38: 0.99944099 | L38: 0.00078383353 | M38: -4.7048162e-06 | N38: 1.0265843 | O38: 117.3112 | P38: 0.94568433 | Q38: 0.921195 | R38: 42.234262 | S38: 41.140569 | T38: 0.013333333 | U38: 0.013010314 | V38: 36.5 | W38: 35.615735 | X38: 36.486667 | Y38: 35.602725 | Z38: 2.195 | AA38: 2.141823 | AB38: 15.128333 | AC38: 14.761828
C39: 4 | D39: 3011 | E39: 12.7 | F39: 0.9437 | G39: 35.11925 | H39: 400 | I39: 400 | J39: 116.23 | K39: 0.99941665 | L39: 0.00078333087 | M39: -4.6927014e-06 | N39: 1.0265459 | O39: 116.22152 | P39: 0.92808574 | Q39: 0.90408598 | R39: 41.448309 | S39: 40.37648 | T39: 0.0083333333 | U39: 0.008131447 | V39: 36.439 | W39: 35.556216 | X39: 36.430667 | Y39: 35.548084 | Z39: 2.174 | AA39: 2.1213319 | AB39: 15.139333 | AC39: 14.772562
C40: 5 | D40: 3013 | E40: 15 | F40: 2.2498 | G40: 35.3278 | H40: 200 | I40: 201 | J40: 117.17 | K40: 0.99910157 | L40: 0.00077783253 | M40: -4.562895e-06 | N40: 1.0262256 | O40: 117.16414 | P40: 2.2217902 | Q40: 2.1650115 | R40: 99.225148 | S40: 96.689414 | T40: 0.016333333 | U40: 0.015935177 | V40: 25.071 | W40: 24.459846 | X40: 25.054667 | Y40: 24.443911 | Z40: 1.561 | AA40: 1.5229476 | AB40: 9.0853333 | AC40: 8.8638609 | AD40: 0.0241 | AE40: 0.0125 | AF40: 0.0031 | AG40: 0.0253 | AH40: 0.0142 | AI40: 0.002 | AJ40: -9999.9999 | AK40: -9999.9999 | AL40: 0.0349 | AM40: 0.0029 | AN40: -9999.9999 | AO40: -9999.9999 | AP40: 0.0085 | AR40: 0.1435 | AS40: 0.0136 | AT40: 0.1571 | AU40: 0.0144 | AV40: absent | AW40: -9999.9999 | AX40: 0.0274 | AY40: 0.0737 | AZ40: 0.1011 | BA40: 0.0025
C41: 6 | D41: 3026 | E41: 16.6 | F41: 1.8194 | G41: 35.5642 | H41: 100 | I41: 99 | J41: 117.7 | K41: 0.99884548 | L41: 0.00077430072 | M41: -4.4829196e-06 | N41: 1.0260432 | O41: 117.696 | P41: 1.7847293 | Q41: 1.7394291 | R41: 79.70601 | S41: 77.682901 | T41: 0.029333333 | U41: 0.02861308 | V41: 24.591 | W41: 23.98719 | X41: 24.561667 | Y41: 23.958577 | Z41: 1.529 | AA41: 1.4914568 | AB41: 7.5193333 | AC41: 7.3347029 | AD41: 0.029 | AE41: 0.016 | AF41: 0.0042 | AG41: 0.028 | AH41: 0.0172 | AI41: 0.0031 | AJ41: -9999.9999 | AK41: -9999.9999 | AL41: 0.0434 | AM41: 0.0046 | AN41: -9999.9999 | AO41: -9999.9999 | AP41: 0.0119 | AR41: 0.1762 | AS41: 0.0205 | AT41: 0.1967 | AU41: 0.0186 | AV41: absent | AW41: -9999.9999 | AX41: 0.0372 | AY41: 0.0985 | AZ41: 0.1357 | BA41: 0.0029
C42: 7 | I42: 90 | T42: 0.037333333 | U42: 0.03641565 | V42: 24.439 | W42: 23.83827 | X42: 24.401667 | Y42: 23.801854 | Z42: 1.5 | AA42: 1.4631288 | AB42: 7.1783333 | AC42: 7.0018841 | AD42: 0.0425 | AE42: 0.026 | AF42: 0.0082 | AG42: 0.0372 | AH42: 0.0305 | AI42: 0.0087 | AJ42: 0.0074 | AK42: 0.0022 | AL42: 0.0585 | AM42: 0.0066 | AN42: 0.0036 | AO42: -9999.9999 | AP42: 0.0241 | AR42: 0.2199 | AS42: 0.0559 | AT42: 0.2758 | AU42: 0.0273 | AV42: absent | AW42: -9999.9999 | AX42: 0.0583 | AY42: 0.1765 | AZ42: 0.2348 | BA42: 0.004
C43: 8 | D43: 3027 | E43: 17.6 | F43: 1.7006 | G43: 35.6582 | H43: 80 | I43: 80 | J43: 116.45 | K43: 0.99867063 | L43: 0.00077220922 | M43: -4.4372369e-06 | N43: 1.0258757 | O43: 116.44721 | P43: 1.6850985 | Q43: 1.6425951 | R43: 75.256497 | S43: 73.358298 | T43: 0.056333333 | U43: 0.05494668 | V43: 23.59 | W43: 23.009329 | X43: 23.533667 | Y43: 22.954382 | Z43: 1.452 | AA43: 1.4162588 | AB43: 6.6923333 | AC43: 6.5276005 | AD43: 0.0422 | AE43: 0.0257 | AF43: 0.0081 | AG43: 0.0369 | AH43: 0.0302 | AI43: 0.0086 | AJ43: 0.0074 | AK43: 0.0022 | AL43: 0.058 | AM43: 0.0066 | AN43: 0.0036 | AO43: -9999.9999 | AP43: 0.0239 | AR43: 0.2181 | AS43: 0.0554 | AT43: 0.2735 | AU43: 0.027 | AV43: absent | AW43: -9999.9999 | AX43: 0.0578 | AY43: 0.175 | AZ43: 0.2328 | BA43: 0.004
C44: 9 | I44: 70 | T44: 0.11633333 | U44: 0.11346296 | V44: 20.278 | W44: 19.777666 | X44: 20.161667 | Y44: 19.664203 | Z44: 1.217 | AA44: 1.1869721 | AB44: 5.6533333 | AC44: 5.5138445 | AD44: 0.0487 | AE44: 0.0326 | AF44: 0.01 | AG44: 0.0455 | AH44: 0.0358 | AI44: 0.0099 | AJ44: 0.0116 | AK44: 0.0034 | AL44: 0.0706 | AM44: 0.008 | AN44: 0.0054 | AO44: -9999.9999 | AP44: 0.0347 | AR44: 0.2389 | AS44: 0.0791 | AT44: 0.318 | AU44: 0.0315 | AV44: absent | AW44: -9999.9999 | AX44: 0.0746 | AY44: 0.2277 | AZ44: 0.3023 | BA44: 0.005
...

Sheet station 05
D1: MdP = | E1: oxygene
C2: Campagne : | F2: PIRATA-FR31
C4: Données de campagne
C6: N° de station : | F6: 5 | H6: N° de palanquée : | R6: Date d'analyse : | T6: 44264
G8: Position | I8: Degrés | J8: Minutes | P8: Cardinal | Q8: Décimale
G9: Latitude | I9: 1 | J9: 29.95' | K9: N | L9: =IF(P9=M9,"+","-") -> + | M9: N | N9: E | O9: =IF(ISBLANK(I9),"",IF(ISBLANK(J9),"",IF(P9=M10,L9&N11,N11))) -> 1°29.95' | P9: N | Q9: 1.4991667
G10: Longitude | I10: 10 | J10: 00.19' | K10: W | L10: =IF(P10=N9,"+","-") -> - | M10: S | N10: W | O10: =IF(ISBLANK(I10),"",IF(ISBLANK(J10),"",IF(P10=N10,L10&N12,N12))) -> -10°00.19' | P10: W | Q10: -10.003167
G11: Prélèvement | I11: Date | J11: 44263 | N11: =I9&"°"&J9 -> 1°29.95' | O11: =IF(P9=M10,-1,1) -> 1 | P11: 2021-03-08T18:51:29z
I12: Heure | J12: 0.85763889 | N12: =I10&"°"&J10 -> 10°00.19' | O12: =IF(P10=N10,-1,1) -> -1
C13: Données :
C14: Température du laboratoire à la calibration ( t°c ) | Q14: t°c = | R14: 26.4 | S14: °C
C15: Température du laboratoire au début de la série d'analyses | Q15: t°lab = | R15: 24.3 | S15: °C
C16: Volume moyen de thiosulfate pour la titration à t°c | Q16: Vmoy.titr.t°c = | R16: 4.87518 | S16: mL | T16: identifiant de la burette : | U16: ='Correction de volume'!J7 -> 1
C17: Volume moyen de thiosulfate pour la détermination du blanc à t°c | Q17: Vmoy.titr.blanc.t°c = | R17: 0.005 | S17: mL
C18: Masse volumique de l'eau pure à la calibration | O18: ρ = | P18: =(0.999842594+(0.00006793952*$R$14)-(0.00000909529*$R$14^2)+(0.0000001001685*$R$14^3)-(0.000000001120083*$R$14^4)+(0.000000000006536332*$R$14^5)) -> 0.99667996
C19: Normalite de l'iodate (NIO3) à la température de calibration | O19: N(IO3) = | P19: =$P$24*($P$18/'Titre de l''Iodate'!E19) -> 0.019973806 | Q19: N
C20: Vol. de la prise d'essai d'iodate (VIO3) à 20°C | O20: V(IO3)20°C = | P20: ='Correction de volume'!F8 -> 5.0010585 | Q20: mL | T20: pipette n° : | U20: ='Correction de volume'!J8 -> pipette O
C21: Vol. de la prise d'essai d'iodate (VIO3) à t°c | O21: V(IO3)t°c= | P21: =P20*'Correction de volume'!$C$11/'station 05'!$P$18 -> 5.0087173 | Q21: mL
C22: Volume moyen de thiosulfate pour la titration à 20° C | O22: Vmoy.titr.20°C = | P22: =$R$16*P18/'Correction de volume'!C11 -> 4.8677253 | Q22: mL
C23: Volume moyen de thiosulfate pour la détermination du blanc à 20° C | O23: Vmoy.titr.blanc.20°C = | P23: =$R$17*P18/'Correction de volume'!C11 -> 0.0049923545 | Q23: mL | T23: 4.8754
C24: Normalite de l'iodate (NIO3) à 20°C | O24: N(IO3)20°C = | P24: ='Titre de l''Iodate'!F7 -> 0.020004395 | Q24: N | T24: 4.873
C25: Titre du thiosulfate à 20°C | O25: N(Thio)20°C = | P25: =IF(ISBLANK(R14),"",IF(ISBLANK(P21),"",IF(ISBLANK(R17),"",(($P$24*$P$20)/($P$22-$P$23))))) -> 0.020573441 | Q25: N | T25: 4.8745
C26: Volume de réactif utilisé | O26: Vreg = | P26: 2 | Q26: mL | T26: 4.876
O27: DOreg = | P27: 0.0017 | T27: 4.877
T28: =AVERAGE(T23:T27) -> 4.87518
E29: Choix de la série de flacons : | I29: IRD | O29: IRD
O30: LPO
C31: N° | D31: N° des Flacons | E31: T° prélèv. | F31: Volume de thio. | G31: Salinité | H31: Prof. Théorique | I31: Prof. Effective | J31: V. flacons 20°C | K31: masse volumique de l'eau de mer moyenne standard | L31: A | M31: B | N31: Masse volumique eau de mer à t° | O31: Vol. à t° prél. des flacons | P31: Oxygène dissous | T31: NO2 | V31: NO3 + NO2 | X31: NO3 | Z31: Phosphate | AB31: Silicate | AD31: chlorophyll-c3 | AE31: chlorophyll-c1+c2 | AF31: peridinin | AG31: 19'-butanoyloxyfucoxanthin | AH31: fucoxanthine | AI31: neoxanthin | AJ31: prasinoxanthin | AK31: violaxanthin | AL31: 19'-hexanoyloxyfucoxanthin | AM31: diadinoxanthin | AN31: alloxanthin | AO31: diatoxanthin | AP31: zeaxanthin | AQ31: lutein | AR31: divinyl chlorophyll-b | AS31: chlorophyll-b | AT31: total chlorophyll-b | AU31: alpha-carotene | AV31: beta-carotene | AW31: pheophorbide | AX31: divinyl chlorophyll-a | AY31: chlorophyll-a | AZ31: total chlorophyll-a | BA31: pheophytin_a | BB31: crocoxanthin
C33: BTL | E33: °C | F33: ml | H33: m | I33: m | J33: ml | O33: mL | P33: DOX1 | R33: DOXY | S33: DOX2 | T33: NTRI | U33: NTIW | V33: NTRZ | W33: NTZW | X33: NTRA | Y33: NTAW | Z33: PHOS | AA33: PHOW | AB33: SLCA | AC33: SLCW | AD33: CHC3 | AE33: CHCZ | AF33: PERP | AG33: BFUP | AH33: FUCP | AI33: NEXW | AJ33: PXAP | AK33: VIOW | AL33: HFUP | AM33: DXAP | AN33: AXAP | AO33: TXAP | AP33: ZXAP | AQ33: LUTW | AR33: CHBD | AS33: CH2P | AT33: CHLB | AU33: AACP | AV33: BBCP | AW33: PHEP | AX33: CHAD | AY33: CH1P | AZ33: CPHL | BA33: PHEA | BB33: CXAP
P34: ml/l | Q34: ml/kg | R34: µmol/l | S34: µmol/kg | T34: µmol/l | U34: µmol/kg | V34: µmol/l | W34: µmol/kg | X34: µmol/l | Y34: µmol/kg | Z34: µmol/l | AA34: µmol/kg | AB34: µmol/l | AC34: µmol/kg | AD34: µg.l-1 | AE34: µg.l-1 | AF34: µg.l-1 | AG34: µg.l-1 | AH34: µg.l-1 | AI34: µg.l-1 | AJ34: µg.l-1 | AK34: µg.l-1 | AL34: µg.l-1 | AM34: µg.l-1 | AN34: µg.l-1 | AO34: µg.l-1 | AP34: µg.l-1 | AQ34: µg.l-1 | AR34: µg.l-1 | AS34: µg.l-1 | AT34: µg.l-1 | AU34: µg.l-1 | AV34: µg.l-1 | AW34: µg.l-1 | AX34: µg.l-1 | AY34: µg.l-1 | AZ34: µg.l-1 | BA34: µg.l-1 | BB34: µg.l-1
P35: ml/l | Q35: ml/kg | R35: µmol/l | S35: µmol/kg | T35: µmol/l | U35: µmol/kg | V35: µmol/l | W35: µmol/kg | X35: µmol/l | Y35: µmol/kg | Z35: µmol/l | AA35: µmol/kg | AB35: µmol/l | AC35: µmol/kg | AD35: µg.l-1 | AE35: µg.l-1 | AF35: µg.l-1 | AG35: µg.l-1 | AH35: µg.l-1 | AI35: µg.l-1 | AJ35: µg.l-1 | AK35: µg.l-1 | AL35: µg.l-1 | AM35: µg.l-1 | AN35: µg.l-1 | AO35: µg.l-1 | AP35: µg.l-1 | AQ35: µg.l-1 | AR35: µg.l-1 | AS35: µg.l-1 | AT35: µg.l-1 | AU35: µg.l-1 | AV35: µg.l-1 | AW35: µg.l-1 | AX35: µg.l-1 | AY35: µg.l-1 | AZ35: µg.l-1 | BA35: µg.l-1 | BB35: µg.l-1
C36: 1 | D36: 3008 | E36: 6.7 | F36: 5.6134 | G36: 34.9625 | H36: 2000 | I36: 2001 | J36: 116 | K36: 0.99991746 | L36: 0.0008002848 | M36: -5.113726e-06 | N36: 1.0274308 | O36: 115.98457 | P36: 5.6431535 | Q36: 5.4924899 | R36: 252.02323 | S36: 245.2946 | T36: 0.001 | U36: 0.00097588943 | V36: 20.899 | W36: 20.395113 | X36: 20.898 | Y36: 20.394137 | Z36: 1.3566667 | AA36: 1.3239567 | AB36: 21.874333 | AC36: 21.346931
C37: 2 | D37: 3009 | E37: 7.5 | F37: 5.1797 | G37: 34.9561 | H37: 1500 | I37: 1503 | J37: 117.65 | K37: 0.9998794 | L37: 0.00079778753 | M37: -5.0507063e-06 | N37: 1.0273135 | O37: 117.63529 | P37: 5.1313013 | Q37: 4.994874 | R37: 229.16391 | S37: 223.07107 | T37: 0 | U37: 0 | V37: 23.17 | W37: 22.611484 | X37: 23.17 | Y37: 22.611484 | Z37: 1.5086667 | AA37: 1.4723001 | AB37: 19.470333 | AC37: 19.000999
C38: 3 | D38: 3010 | E38: 8.5 | F38: 3.2838 | G38: 34.5169 | H38: 800 | I38: 800 | J38: 117.32 | K38: 0.9998189 | L38: 0.00079477317 | M38: -4.9749099e-06 | N38: 1.0268188 | O38: 117.30651 | P38: 3.2551708 | Q38: 3.1701512 | R38: 145.37593 | S38: 141.57895 | T38: -0.002 | U38: -0.0019524251 | V38: 36.438 | W38: 35.571233 | X38: 36.44 | Y38: 35.573186 | Z38: 2.4036667 | AA38: 2.3464896 | AB38: 28.922333 | AC38: 28.234345
C39: 4 | D39: 3011 | E39: 10.3 | F39: 2.7049 | G39: 34.6469 | H39: 500 | I39: 500 | J39: 116.23 | K39: 0.99967506 | L39: 0.00078963584 | M39: -4.8468155e-06 | N39: 1.026625 | O39: 116.21873 | P39: 2.7033425 | Q39: 2.6332327 | R39: 120.73128 | S39: 117.60017 | T39: 0.004 | U39: 0.0039044883 | V39: 34.909 | W39: 34.075446 | X39: 34.905 | Y39: 34.071541 | Z39: 2.2366667 | AA39: 2.1832597 | AB39: 20.514333 | AC39: 20.024494
C40: 5 | D40: 3013 | E40: 10.6 | F40: 2.7276 | G40: 34.6475 | H40: 500 | I40: 500 | J40: 117.17 | K40: 0.99964684 | L40: 0.00078881445 | M40: -4.8265089e-06 | N40: 1.0265729 | O40: 117.15899 | P40: 2.7039375 | Q40: 2.6339458 | R40: 120.75785 | S40: 117.63202 | T40: -0.001 | U40: -0.00097611975 | V40: 34.903 | W40: 34.069508 | X40: 34.904 | Y40: 34.070484 | Z40: 2.1966667 | AA40: 2.1442097 | AB40: 20.451333 | AC40: 19.96295
C41: 6 | D41: 3026 | E41: 14.5 | F41: 2.074 | G41: 34.0735 | H41: 300 | I41: 301 | J41: 117.7 | K41: 0.99917548 | L41: 0.00077898458 | M41: -4.5896247e-06 | N41: 1.0253663 | O41: 117.69353 | P41: 2.0417963 | Q41: 1.9912848 | R41: 91.186624 | S41: 88.93078 | T41: 0 | U41: 0 | V41: 30.007 | W41: 29.281286 | X41: 30.007 | Y41: 29.281286 | Z41: 1.8516667 | AA41: 1.8068845 | AB41: 12.455333 | AC41: 12.154103
C42: 7 | D42: 3027 | E42: 17.5 | F42: 2.9092 | G42: 35.5996 | H42: 100 | I42: 100 | J42: 116.45 | K42: 0.99868862 | L42: 0.00077241446 | M42: -4.4416562e-06 | N42: 1.0258551 | O42: 116.44709 | P42: 2.9032247 | Q42: 2.8300533 | R42: 129.65802 | S42: 126.39018 | T42: 0.033 | U42: 0.032188886 | V42: 17.895 | W42: 17.455155 | X42: 17.862 | Y42: 17.422966 | Z42: 1.2036667 | AA42: 1.1740815 | AB42: 6.2923333 | AC42: 6.1376727
C43: 8 | D43: 3028 | E43: 18.3 | F43: 2.8543 | G43: 35.6504 | H43: 80 | I43: 81 | J43: 115.96 | K43: 0.99854164 | L43: 0.00077079639 | M43: -4.407228e-06 | N43: 1.0256968 | O43: 115.95803 | P43: 2.8602851 | Q43: 2.7886264 | R43: 127.74033 | S43: 124.54005 | T43: 0.101 | U43: 0.098514405 | V43: 17.567 | W43: 17.134679 | X43: 17.466 | Y43: 17.036164 | Z43: 1.1866667 | AA43: 1.157463 | AB43: 6.0343333 | AC43: 5.8858293
C44: 9 | D44: 3034 | E44: 19.5 | F44: 3.0768 | G44: 35.7482 | H44: 60 | I44: 61 | J44: 116.21 | K44: 0.99830814 | L44: 0.00076846965 | M44: -4.3595566e-06 | N44: 1.0254652 | O44: 116.20942 | P44: 3.0780177 | Q44: 3.0015819 | R44: 137.46427 | S44: 134.05065 | T44: 0.274 | U44: 0.26723494 | V44: 14.069 | W44: 13.721636 | X44: 13.795 | Y44: 13.454402 | Z44: 1.0046667 | AA44: 0.97986145 | AB44: 3.8433333 | AC44: 3.7484415
...

Sheet station 06
D1: MdP = | E1: oxygene
C2: Campagne : | F2: PIRATA-FR31
C4: Données de campagne
C6: N° de station : | F6: 6 | H6: N° de palanquée : | R6: Date d'analyse : | T6: 44264
G8: Position | I8: Degrés | J8: Minutes | P8: Cardinal | Q8: Décimale
G9: Latitude | I9: 0 | J9: 59.99' | K9: N | L9: =IF(P9=M9,"+","-") -> + | M9: N | N9: E | O9: =IF(ISBLANK(I9),"",IF(ISBLANK(J9),"",IF(P9=M10,L9&N11,N11))) -> 0°59.99' | P9: N | Q9: 0.99983333
G10: Longitude | I10: 10 | J10: 00.21' | K10: W | L10: =IF(P10=N9,"+","-") -> - | M10: S | N10: W | O10: =IF(ISBLANK(I10),"",IF(ISBLANK(J10),"",IF(P10=N10,L10&N12,N12))) -> -10°00.21' | P10: W | Q10: -10.0035
G11: Prélèvement | I11: Date | J11: 44264 | N11: =I9&"°"&J9 -> 0°59.99' | O11: =IF(P9=M10,-1,1) -> 1 | P11: 2021-03-08T23:37:19z
I12: Heure | J12: 0.059027778 | N12: =I10&"°"&J10 -> 10°00.21' | O12: =IF(P10=N10,-1,1) -> -1
C13: Données :
C14: Température du laboratoire à la calibration ( t°c ) | Q14: t°c = | R14: 26.4 | S14: °C
C15: Température du laboratoire au début de la série d'analyses | Q15: t°lab = | R15: 26.4 | S15: °C
C16: Volume moyen de thiosulfate pour la titration à t°c | Q16: Vmoy.titr.t°c = | R16: 4.87518 | S16: mL | T16: identifiant de la burette : | U16: ='Correction de volume'!J7 -> 1
C17: Volume moyen de thiosulfate pour la détermination du blanc à t°c | Q17: Vmoy.titr.blanc.t°c = | R17: 0.005 | S17: mL
C18: Masse volumique de l'eau pure à la calibration | O18: ρ = | P18: =(0.999842594+(0.00006793952*$R$14)-(0.00000909529*$R$14^2)+(0.0000001001685*$R$14^3)-(0.000000001120083*$R$14^4)+(0.000000000006536332*$R$14^5)) -> 0.99667996
C19: Normalite de l'iodate (NIO3) à la température de calibration | O19: N(IO3) = | P19: =$P$24*($P$18/'Titre de l''Iodate'!E19) -> 0.019973806 | Q19: N
C20: Vol. de la prise d'essai d'iodate (VIO3) à 20°C | O20: V(IO3)20°C = | P20: ='Correction de volume'!F8 -> 5.0010585 | Q20: mL | T20: pipette n° : | U20: ='Correction de volume'!J8 -> pipette O
C21: Vol. de la prise d'essai d'iodate (VIO3) à t°c | O21: V(IO3)t°c= | P21: =P20*'Correction de volume'!$C$11/'station 06'!$P$18 -> 5.0087173 | Q21: mL
C22: Volume moyen de thiosulfate pour la titration à 20° C | O22: Vmoy.titr.20°C = | P22: =$R$16*P18/'Correction de volume'!C11 -> 4.8677253 | Q22: mL
C23: Volume moyen de thiosulfate pour la détermination du blanc à 20° C | O23: Vmoy.titr.blanc.20°C = | P23: =$R$17*P18/'Correction de volume'!C11 -> 0.0049923545 | Q23: mL | T23: 4.8754
C24: Normalite de l'iodate (NIO3) à 20°C | O24: N(IO3)20°C = | P24: ='Titre de l''Iodate'!F7 -> 0.020004395 | Q24: N | T24: 4.873
C25: Titre du thiosulfate à 20°C | O25: N(Thio)20°C = | P25: =IF(ISBLANK(R14),"",IF(ISBLANK(P21),"",IF(ISBLANK(R17),"",(($P$24*$P$20)/($P$22-$P$23))))) -> 0.020573441 | Q25: N | T25: 4.8745
C26: Volume de réactif utilisé | O26: Vreg = | P26: 2 | Q26: mL | T26: 4.876
O27: DOreg = | P27: 0.0017 | T27: 4.877
T28: =AVERAGE(T23:T27) -> 4.87518
E29: Choix de la série de flacons : | I29: IRD | O29: IRD
O30: LPO
C31: N° | D31: N° des Flacons | E31: T° prélèv. | F31: Volume de thio. | G31: Salinité | H31: Prof. Théorique | I31: Prof. Effective | J31: V. flacons 20°C | K31: masse volumique de l'eau de mer moyenne standard | L31: A | M31: B | N31: Masse volumique eau de mer à t° | O31: Vol. à t° prél. des flacons | P31: Oxygène dissous | T31: NO2 | V31: NO3 + NO2 | X31: NO3 | Z31: Phosphate | AB31: Silicate | AD31: chlorophyll-c3 | AE31: chlorophyll-c1+c2 | AF31: peridinin | AG31: 19'-butanoyloxyfucoxanthin | AH31: fucoxanthine | AI31: neoxanthin | AJ31: prasinoxanthin | AK31: violaxanthin | AL31: 19'-hexanoyloxyfucoxanthin | AM31: diadinoxanthin | AN31: alloxanthin | AO31: diatoxanthin | AP31: zeaxanthin | AQ31: lutein | AR31: divinyl chlorophyll-b | AS31: chlorophyll-b | AT31: total chlorophyll-b | AU31: alpha-carotene | AV31: beta-carotene | AW31: pheophorbide | AX31: divinyl chlorophyll-a | AY31: chlorophyll-a | AZ31: total chlorophyll-a | BA31: pheophytin_a | BB31: crocoxanthin
C33: BTL | E33: °C | F33: ml | H33: m | I33: m | J33: ml | O33: mL | P33: DOX1 | R33: DOXY | S33: DOX2 | T33: NTRI | U33: NTIW | V33: NTRZ | W33: NTZW | X33: NTRA | Y33: NTAW | Z33: PHOS | AA33: PHOW | AB33: SLCA | AC33: SLCW | AD33: CHC3 | AE33: CHCZ | AF33: PERP | AG33: BFUP | AH33: FUCP | AI33: NEXW | AJ33: PXAP | AK33: VIOW | AL33: HFUP | AM33: DXAP | AN33: AXAP | AO33: TXAP | AP33: ZXAP | AQ33: LUTW | AR33: CHBD | AS33: CH2P | AT33: CHLB | AU33: AACP | AV33: BBCP | AW33: PHEP | AX33: CHAD | AY33: CH1P | AZ33: CPHL | BA33: PHEA | BB33: CXAP
P34: ml/l | Q34: ml/kg | R34: µmol/l | S34: µmol/kg | T34: µmol/l | U34: µmol/kg | V34: µmol/l | W34: µmol/kg | X34: µmol/l | Y34: µmol/kg | Z34: µmol/l | AA34: µmol/kg | AB34: µmol/l | AC34: µmol/kg | AD34: µg.l-1 | AE34: µg.l-1 | AF34: µg.l-1 | AG34: µg.l-1 | AH34: µg.l-1 | AI34: µg.l-1 | AJ34: µg.l-1 | AK34: µg.l-1 | AL34: µg.l-1 | AM34: µg.l-1 | AN34: µg.l-1 | AO34: µg.l-1 | AP34: µg.l-1 | AQ34: µg.l-1 | AR34: µg.l-1 | AS34: µg.l-1 | AT34: µg.l-1 | AU34: µg.l-1 | AV34: µg.l-1 | AW34: µg.l-1 | AX34: µg.l-1 | AY34: µg.l-1 | AZ34: µg.l-1 | BA34: µg.l-1 | BB34: µg.l-1
P35: ml/l | Q35: ml/kg | R35: µmol/l | S35: µmol/kg | T35: µmol/l | U35: µmol/kg | V35: µmol/l | W35: µmol/kg | X35: µmol/l | Y35: µmol/kg | Z35: µmol/l | AA35: µmol/kg | AB35: µmol/l | AC35: µmol/kg | AD35: µg.l-1 | AE35: µg.l-1 | AF35: µg.l-1 | AG35: µg.l-1 | AH35: µg.l-1 | AI35: µg.l-1 | AJ35: µg.l-1 | AK35: µg.l-1 | AL35: µg.l-1 | AM35: µg.l-1 | AN35: µg.l-1 | AO35: µg.l-1 | AP35: µg.l-1 | AQ35: µg.l-1 | AR35: µg.l-1 | AS35: µg.l-1 | AT35: µg.l-1 | AU35: µg.l-1 | AV35: µg.l-1 | AW35: µg.l-1 | AX35: µg.l-1 | AY35: µg.l-1 | AZ35: µg.l-1 | BA35: µg.l-1 | BB35: µg.l-1
C36: 1 | D36: 3045 | E36: 9.5 | F36: 5.7766 | G36: 34.9629 | H36: 2000 | I36: 1999 | J36: 118.7 | K36: 0.99974443 | L36: 0.00079187431 | M36: -4.9024226e-06 | N36: 1.0270078 | O36: 118.68754 | P36: 5.6732662 | Q36: 5.5240734 | R36: 253.36807 | S36: 246.70512 | T36: -0.005 | U36: -0.0048794493 | V36: 21.064 | W36: 20.556144 | X36: 21.069 | Y36: 20.561024 | Z36: 1.3726667 | AA36: 1.3395715 | AB36: 22.453333 | AC36: 21.91198
C37: 2 | D37: 3049 | E37: 10 | F37: 4.9593 | G37: 34.94655 | H37: 1500 | I37: 1502 | J37: 115.27 | K37: 0.99970208 | L37: 0.000790467 | M37: -4.86742e-06 | N37: 1.0269107 | O37: 115.25847 | P37: 5.0152084 | Q37: 4.8837826 | R37: 223.97921 | S37: 218.10973 | T37: -0.004 | U37: -0.0039036033 | V37: 23.962 | W37: 23.384536 | X37: 23.966 | Y37: 23.388439 | Z37: 1.5616667 | AA37: 1.5240318 | AB37: 20.189333 | AC37: 19.702787
C38: 3 | D38: 3050 | E38: 10.7 | F38: 3.3443 | G38: 34.5172 | H38: 800 | I38: 801 | J38: 116.74 | K38: 0.99963717 | L38: 0.00078854282 | M38: -4.8198062e-06 | N38: 1.0264537 | O38: 116.72914 | P38: 3.3321918 | Q38: 3.2463149 | R38: 148.81569 | S38: 144.98042 | T38: -0.003 | U38: -0.0029286359 | V38: 36.501 | W38: 35.632713 | X38: 36.504 | Y38: 35.635642 | Z38: 2.4146667 | AA38: 2.3572265 | AB38: 30.029333 | AC38: 29.314995
C39: 4 | D39: 3051 | E39: 12.9 | F39: 2.9643 | G39: 34.6128 | H39: 500 | I39: 500 | J39: 117.34 | K39: 0.99939181 | L39: 0.00078283222 | M39: -4.680719e-06 | N39: 1.0261135 | O39: 117.33167 | P39: 2.935896 | Q39: 2.8611806 | R39: 131.11712 | S39: 127.78033 | T39: 0 | U39: 0 | V39: 34.542 | W39: 33.717902 | X39: 34.542 | Y39: 33.717902 | Z39: 2.2056667 | AA39: 2.1530442 | AB39: 21.039333 | AC39: 20.53738
C40: 5 | D40: 3156 | E40: 15.3 | F40: 2.2411 | G40: 35.004 | H40: 300 | I40: 302 | J40: 115.6 | K40: 0.99905582 | L40: 0.00077715251 | M40: -4.5472543e-06 | N40: 1.0259095 | O40: 115.59457 | P40: 2.2486825 | Q40: 2.1918917 | R40: 100.42616 | S40: 97.889882 | T40: 0.002 | U40: 0.0019517158 | V40: 29.666 | W40: 28.949801 | X40: 29.664 | Y40: 28.947849 | Z40: 1.8466667 | AA40: 1.8020843 | AB40: 12.600333 | AC40: 12.296135
C41: 6 | D41: 3157 | E41: 15.2 | F41: 2.2095 | G41: 35.0052 | H41: 300 | I41: 302 | J41: 114.35 | K41: 0.99907119 | L41: 0.00077737825 | M41: -4.5524348e-06 | N41: 1.0259326 | O41: 114.34451 | P41: 2.2413583 | Q41: 2.1847032 | R41: 100.09906 | S41: 97.568845 | T41: 0 | U41: 0 | V41: 29.594 | W41: 28.879534 | X41: 29.594 | Y41: 28.879534 | Z41: 1.8466667 | AA41: 1.802084 | AB41: 12.641333 | AC41: 12.336143
C42: 7 | D42: 3159 | E42: 18.3 | F42: 2.7573 | G42: 35.5937 | H42: 100 | I42: 101 | J42: 116.17 | K42: 0.99854164 | L42: 0.00077079639 | M42: -4.407228e-06 | N42: 1.0256533 | O42: 116.16803 | P42: 2.7573222 | Q42: 2.6883568 | R42: 123.14201 | S42: 120.06202 | T42: 0.041 | U42: 0.039992654 | V42: 18.934 | W42: 18.468803 | X42: 18.893 | Y42: 18.42881 | Z42: 1.2696667 | AA42: 1.2384717 | AB42: 6.5673333 | AC42: 6.4059778 | AD42: 0.0226 | AE42: 0.0111 | AF42: 0.0022 | AG42: 0.023 | AH42: 0.0139 | AI42: -9999.9999 | AJ42: 0.0019 | AK42: -9999.9999 | AL42: 0.0274 | AM42: 0.0023 | AN42: -9999.9999 | AO42: -9999.9999 | AP42: 0.0068 | AR42: 0.1509 | AS42: 0.0105 | AT42: 0.1614 | AU42: 0.0156 | AV42: absent | AW42: -9999.9999 | AX42: 0.0331 | AY42: 0.0671 | AZ42: 0.1002 | BA42: -9999.9999
C43: 8 | D43: 3160 | E43: 19.1 | F43: 2.8343 | G43: 35.6754 | H43: 80 | I43: 80 | J43: 116.77 | K43: 0.99838769 | L43: 0.00076923207 | M43: -4.3749176e-06 | N43: 1.025513 | O43: 116.76895 | P43: 2.820036 | Q43: 2.7498782 | R43: 125.94281 | S43: 122.80956 | T43: 0.146 | U43: 0.14240427 | V43: 17.493 | W43: 17.062177 | X43: 17.347 | Y43: 16.919773 | Z43: 1.1676667 | AA43: 1.138909 | AB43: 5.7583333 | AC43: 5.6165154 | AD43: 0.0418 | AE43: 0.0216 | AF43: 0.0035 | AG43: 0.0397 | AH43: 0.0351 | AI43: 0.004 | AJ43: 0.005 | AK43: 0.0016 | AL43: 0.0473 | AM43: 0.0056 | AN43: 0.0024 | AO43: -9999.9999 | AP43: 0.0219 | AR43: 0.2091 | AS43: 0.0254 | AT43: 0.2345 | AU43: 0.0252 | AV43: absent | AW43: -9999.9999 | AX43: 0.0629 | AY43: 0.153 | AZ43: 0.2159 | BA43: -9999.9999
C44: 9 | D44: 3161 | E44: 20.3 | F44: 3.1825 | G44: 35.7853 | H44: 60 | I44: 61 | J44: 119.09 | K44: 0.99814396 | L44: 0.00076698354 | M44: -4.3304231e-06 | N44: 1.0252824 | O44: 119.09036 | P44: 3.1060925 | Q44: 3.0294995 | R44: 138.71809 | S44: 135.29745 | T44: 0.189 | U44: 0.18433024 | V44: 12.227 | W44: 11.924899 | X44: 12.038 | Y44: 11.740569 | Z44: 0.92166667 | AA44: 0.8988944 | AB44: 3.9913333 | AC44: 3.8927166 | AD44: 0.2589 | AE44: 0.1613 | AF44: 0.0147 | AG44: 0.1276 | AH44: 0.4547 | AI44: 0.0058 | AJ44: 0.02 | AK44: 0.0034 | AL44: 0.1382 | AM44: 0.032 | AN44: 0.0081 | AO44: -9999.9999 | AP44: 0.0577 | AR44: 0.1425 | AS44: 0.1051 | AT44: 0.2476 | AU44: 0.0478 | AV44: absent | AW44: 0.0399 | AX44: 0.1318 | AY44: 1.0275 | AZ44: 1.1593 | BA44: 0.0164
...

Sheet station 07
D1: MdP = | E1: oxygene
C2: Campagne : | F2: PIRATA-FR31
C4: Données de campagne
C6: N° de station : | F6: 7 | H6: N° de palanquée : | R6: Date d'analyse : | T6: 44264
G8: Position | I8: Degrés | J8: Minutes | P8: Cardinal | Q8: Décimale
G9: Latitude | I9: 0 | J9: 29.96' | K9: N | L9: =IF(P9=M9,"+","-") -> + | M9: N | N9: E | O9: =IF(ISBLANK(I9),"",IF(ISBLANK(J9),"",IF(P9=M10,L9&N11,N11))) -> 0°29.96' | P9: N | Q9: 0.49933333
G10: Longitude | I10: 10 | J10: 00.13' | K10: W | L10: =IF(P10=N9,"+","-") -> - | M10: S | N10: W | O10: =IF(ISBLANK(I10),"",IF(ISBLANK(J10),"",IF(P10=N10,L10&N12,N12))) -> -10°00.13' | P10: W | Q10: -10.002167
G11: Prélèvement | I11: Date | J11: 44264 | N11: =I9&"°"&J9 -> 0°29.96' | O11: =IF(P9=M10,-1,1) -> 1 | P11: 2021-03-09T04:25:16z
I12: Heure | J12: 0.25763889 | N12: =I10&"°"&J10 -> 10°00.13' | O12: =IF(P10=N10,-1,1) -> -1
C13: Données :
C14: Température du laboratoire à la calibration ( t°c ) | Q14: t°c = | R14: 26.4 | S14: °C
C15: Température du laboratoire au début de la série d'analyses | Q15: t°lab = | R15: 26.4 | S15: °C
C16: Volume moyen de thiosulfate pour la titration à t°c | Q16: Vmoy.titr.t°c = | R16: 4.87518 | S16: mL | T16: identifiant de la burette : | U16: ='Correction de volume'!J7 -> 1
C17: Volume moyen de thiosulfate pour la détermination du blanc à t°c | Q17: Vmoy.titr.blanc.t°c = | R17: 0.005 | S17: mL
C18: Masse volumique de l'eau pure à la calibration | O18: ρ = | P18: =(0.999842594+(0.00006793952*$R$14)-(0.00000909529*$R$14^2)+(0.0000001001685*$R$14^3)-(0.000000001120083*$R$14^4)+(0.000000000006536332*$R$14^5)) -> 0.99667996
C19: Normalite de l'iodate (NIO3) à la température de calibration | O19: N(IO3) = | P19: =$P$24*($P$18/'Titre de l''Iodate'!E19) -> 0.019973806 | Q19: N
C20: Vol. de la prise d'essai d'iodate (VIO3) à 20°C | O20: V(IO3)20°C = | P20: ='Correction de volume'!F8 -> 5.0010585 | Q20: mL | T20: pipette n° : | U20: ='Correction de volume'!J8 -> pipette O
C21: Vol. de la prise d'essai d'iodate (VIO3) à t°c | O21: V(IO3)t°c= | P21: =P20*'Correction de volume'!$C$11/'station 07'!$P$18 -> 5.0087173 | Q21: mL
C22: Volume moyen de thiosulfate pour la titration à 20° C | O22: Vmoy.titr.20°C = | P22: =$R$16*P18/'Correction de volume'!C11 -> 4.8677253 | Q22: mL
C23: Volume moyen de thiosulfate pour la détermination du blanc à 20° C | O23: Vmoy.titr.blanc.20°C = | P23: =$R$17*P18/'Correction de volume'!C11 -> 0.0049923545 | Q23: mL | T23: 4.8754
C24: Normalite de l'iodate (NIO3) à 20°C | O24: N(IO3)20°C = | P24: ='Titre de l''Iodate'!F7 -> 0.020004395 | Q24: N | T24: 4.873
C25: Titre du thiosulfate à 20°C | O25: N(Thio)20°C = | P25: =IF(ISBLANK(R14),"",IF(ISBLANK(P21),"",IF(ISBLANK(R17),"",(($P$24*$P$20)/($P$22-$P$23))))) -> 0.020573441 | Q25: N | T25: 4.8745
C26: Volume de réactif utilisé | O26: Vreg = | P26: 2 | Q26: mL | T26: 4.876
O27: DOreg = | P27: 0.0017 | T27: 4.877
T28: =AVERAGE(T23:T27) -> 4.87518
E29: Choix de la série de flacons : | I29: IRD | O29: IRD
O30: LPO
